Workbook

Sheet 밸런스 문서
A1: 챕터 | B1: 콘텐츠 진행 순서 | C1: 플레이 난이도 | D1: 플레이 흥미도 | E1: 플레이 목표 | F1: 플레이 난관 | G1: 공략 방법 | H1: 체감 난이도 | I1: 수행 과제 수 | J1: 목표 달성 조건 | K1: 실패 결과 | L1: 예상 소요 시간 | M1: 난이도 조절 요소 | N1: 누적 플레이 시간 | O1: 스테이지 | P1: 콘텐츠 진행 포인트 누적 | Q1: X 콘텐츠 진행 포인트 | R1: Y 레벨업을 위한 필요 경험치 | S1: 한마리 몬스터가 주는 경험치 | T1: 한마리 몬스터와 전투시간(초) | U1: 레벨 업을 위한 전투시간(초) | V1: 레벨 업을 위해 잡아야하는 몬스터 수
A2: 1 | 첫 각성 | B2: 1 | C2: 1 | D2: 5 | E2: 과거 오프닝 감상하기 | F2: 전투 규칙·인물 감정·다음 목표가 한 장면에 함께 제시되어 핵심 정보를 놓칠 수 있음 | G2: 강조 자막과 기록 메뉴를 확인해 현재 임무·인물 관계·전투 목적을 구분함 | H2: 1/10 – 주요 난이도 요인: 정보량·장면 전환 속도·감정적 부담 | I2: 1 | J2: 필수 대화와 연출을 마지막 장면까지 확인 | K2: - | L2: 0.0020833333 | M2: 핵심 전투 정보 자막 유지·기록 메뉴 자동 등록 | N2: =L2 -> 0.0020833333 | O2: 1-A | 아파트·생존 튜토리얼 | P2: 2 | Q2: =P2 -> 2 | R2: =ROUND(60+0.8*Q2+0.0012*Q2^2,0) -> 62 | U2: =IF(S2="","",ROUNDUP(R2/S2,0)*T2) | V2: =IF(S2="","",ROUNDUP(R2/S2,0))
A3: 1 | 첫 각성 | B3: 2 | C3: 2 | D3: 7 | E3: 정전된 거실에서 가족 찾기 | F3: 조사 지점이 넓게 흩어져 있고 일부는 적의 순찰 범위 안에 있어 탐색 동선이 길어질 수 있음 | G3: 미니맵의 미확인 구역을 기준으로 짧은 동선을 만들고 적 순찰이 비는 순서대로 조사함 | H3: 2/10 – 주요 난이도 요인: 탐색 범위·필수 조사 수·적 순찰 밀도 | I3: 4 | J3: 필수 조사 지점 4곳 확인 | K3: 체력 0 시 마지막 안전 지점에서 재시작 | L3: 0.0017361111 | M3: 일정 시간 미발견 시 가장 가까운 조사 구역 반짝임 표시 | N3: =N2+L3 -> 0.0038194444 | O3: 1-A | 아파트·생존 튜토리얼 | P3: 6 | Q3: =P3 -> 6 | R3: =ROUND(60+0.8*Q3+0.0012*Q3^2,0) -> 65 | U3: =IF(S3="","",ROUNDUP(R3/S3,0)*T3) | V3: =IF(S3="","",ROUNDUP(R3/S3,0))
A4: 1 | 첫 각성 | B4: 3 | C4: 1 | D4: 5 | E4: 가족 대피 요청 받기 | F4: 전투 규칙·인물 감정·다음 목표가 한 장면에 함께 제시되어 핵심 정보를 놓칠 수 있음 | G4: 강조 자막과 기록 메뉴를 확인해 현재 임무·인물 관계·전투 목적을 구분함 | H4: 1/10 – 주요 난이도 요인: 정보량·장면 전환 속도·감정적 부담 | I4: 1 | J4: 필수 대화와 연출을 마지막 장면까지 확인 | K4: - | L4: 0.0013888889 | M4: 핵심 전투 정보 자막 유지·기록 메뉴 자동 등록 | N4: =N3+L4 -> 0.0052083333 | O4: 1-A | 아파트·생존 튜토리얼 | P4: 8 | Q4: =P4 -> 8 | R4: =ROUND(60+0.8*Q4+0.0012*Q4^2,0) -> 66 | U4: =IF(S4="","",ROUNDUP(R4/S4,0)*T4) | V4: =IF(S4="","",ROUNDUP(R4/S4,0))
A5: 1 | 첫 각성 | B5: 4 | C5: 2 | D5: 7 | E5: 비상용 손전등 찾기 | F5: 조사 지점이 넓게 흩어져 있고 일부는 적의 순찰 범위 안에 있어 탐색 동선이 길어질 수 있음 | G5: 미니맵의 미확인 구역을 기준으로 짧은 동선을 만들고 적 순찰이 비는 순서대로 조사함 | H5: 2/10 – 주요 난이도 요인: 탐색 범위·필수 조사 수·적 순찰 밀도 | I5: 4 | J5: 필수 조사 지점 4곳 확인 | K5: 체력 0 시 마지막 안전 지점에서 재시작 | L5: 0.0017361111 | M5: 일정 시간 미발견 시 가장 가까운 조사 구역 반짝임 표시 | N5: =N4+L5 -> 0.0069444444 | O5: 1-A | 아파트·생존 튜토리얼 | P5: 12 | Q5: =P5 -> 12 | R5: =ROUND(60+0.8*Q5+0.0012*Q5^2,0) -> 70 | U5: =IF(S5="","",ROUNDUP(R5/S5,0)*T5) | V5: =IF(S5="","",ROUNDUP(R5/S5,0))
A6: 1 | 첫 각성 | B6: 5 | C6: 4 | D6: 7 | E6: 첫 괴물의 시야 피하기 | F6: 괴물의 시야와 소리 감지 범위가 겹쳐 한 번에 통과할 수 있는 안전 구간이 짧음 | G6: 시야 원뿔과 발소리 게이지를 확인해 엄폐물 사이를 이동하고 필요할 때 소리 유도 오브젝트를 사용함 | H6: 4/10 – 주요 난이도 요인: 시야 범위·감지 속도·엄폐물 간 거리 | I6: 3 | J6: 괴물에게 들키지 않고 안전 구역 도착 | K6: 경계 게이지 최대 시 추격 발생, 추격 중 피격 누적 시 체크포인트 재시작 | L6: 0.0020833333 | M6: 실패 후 괴물 시야 범위 축소·소리 유도 오브젝트 추가 | N6: =N5+L6 -> 0.0090277778 | O6: 1-A | 아파트·생존 튜토리얼 | P6: 17 | Q6: =P6 -> 17 | R6: =ROUND(60+0.8*Q6+0.0012*Q6^2,0) -> 74 | U6: =IF(S6="","",ROUNDUP(R6/S6,0)*T6) | V6: =IF(S6="","",ROUNDUP(R6/S6,0))
A7: 1 | 첫 각성 | B7: 6 | C7: 2 | D7: 6 | E7: 붕괴하는 계단 통과하기 | F7: 붕괴 지형과 적의 공격 예고가 이동 경로를 제한해 안전한 타이밍을 판단해야 함 | G7: 공격 예고 범위를 본 뒤 안전 지점에서 대기하고 이동 가능한 순간에 다음 엄폐물까지 이동함 | H7: 2/10 – 주요 난이도 요인: 공격 예고 시간·안전 지점 간 거리·지형 붕괴 속도 | I7: 1 | J7: 목표 지점의 도착 트리거 진입 | K7: 낙하 공격 3회 피격 또는 체력 0 시 직전 체크포인트 재시작 | L7: 0.0011574074 | M7: 연속 실패 시 공격 예고 시간 증가·안전 지점 추가 표시 | N7: =N6+L7 -> 0.010185185 | O7: 1-A | 아파트·생존 튜토리얼 | P7: 20 | Q7: =P7 -> 20 | R7: =ROUND(60+0.8*Q7+0.0012*Q7^2,0) -> 76 | U7: =IF(S7="","",ROUNDUP(R7/S7,0)*T7) | V7: =IF(S7="","",ROUNDUP(R7/S7,0))
A8: 1 | 첫 각성 | B8: 7 | C8: 4 | D8: 8 | E8: 아이를 안전구역까지 호위하기 | F8: 정전과 낙하물 때문에 아이의 이동이 자주 멈추고 혼란한 주민들 사이에서 경로가 막힘 | G8: 아이보다 반 걸음 앞에서 안전한 경로를 확보하고 낙하물 예고가 끝난 뒤 함께 이동함 | H8: 4/10 – 주요 난이도 요인: 호위 거리·낙하물 주기·군중 이동 방해 | I8: 3 | J8: 아이와 함께 안전 지점 3곳 통과 | K8: 아이와 거리 초과 또는 낙하물 3회 피격 시 마지막 안전 지점부터 재시작 | L8: 0.0030092593 | M8: 아이 이동속도 향상·안전 경로 화살표 표시 | N8: =N7+L8 -> 0.013194444 | O8: 1-A | 아파트·생존 튜토리얼 | P8: 26 | Q8: =P8 -> 26 | R8: =ROUND(60+0.8*Q8+0.0012*Q8^2,0) -> 82 | U8: =IF(S8="","",ROUNDUP(R8/S8,0)*T8) | V8: =IF(S8="","",ROUNDUP(R8/S8,0))
A9: 1 | 첫 각성 | B9: 8 | C9: 1 | D9: 9 | E9: 괴물과 접촉해 소멸시키기 | F9: 자동 연출 속에서 괴물 소멸의 원인과 주인공의 반응을 짧은 시간 안에 이해해야 함 | G9: 연출 속 괴물의 반응과 주인공의 손에 나타나는 선의 효과를 확인함 | H9: 1/10 – 주요 난이도 요인: 연출 길이·원인 정보의 은폐 정도 | I9: 1 | J9: 괴물 소멸 연출 종료 후 이동 가능 상태 전환 | K9: - | L9: 0.00081018519 | M9: 다시 보기와 장면별 일시정지 제공 | N9: =N8+L9 -> 0.01400463 | O9: 1-A | 아파트·생존 튜토리얼 | P9: 29 | Q9: =P9 -> 29 | R9: =ROUND(60+0.8*Q9+0.0012*Q9^2,0) -> 84 | U9: =IF(S9="","",ROUNDUP(R9/S9,0)*T9) | V9: =IF(S9="","",ROUNDUP(R9/S9,0))
A10: 1 | 첫 각성 | B10: 9 | C10: 2 | D10: 6 | E10: 대피소에 도착하기 | F10: 붕괴 지형과 적의 공격 예고가 이동 경로를 제한해 안전한 타이밍을 판단해야 함 | G10: 공격 예고 범위를 본 뒤 안전 지점에서 대기하고 이동 가능한 순간에 다음 엄폐물까지 이동함 | H10: 2/10 – 주요 난이도 요인: 공격 예고 시간·안전 지점 간 거리·지형 붕괴 속도 | I10: 1 | J10: 목표 지점의 도착 트리거 진입 | K10: 낙하 공격 3회 피격 또는 체력 0 시 직전 체크포인트 재시작 | L10: 0.0011574074 | M10: 연속 실패 시 공격 예고 시간 증가·안전 지점 추가 표시 | N10: =N9+L10 -> 0.015162037 | O10: 1-B | 대피소·전투 훈련 | P10: 32 | Q10: =P10 -> 32 | R10: =ROUND(60+0.8*Q10+0.0012*Q10^2,0) -> 87 | U10: =IF(S10="","",ROUNDUP(R10/S10,0)*T10) | V10: =IF(S10="","",ROUNDUP(R10/S10,0))
A11: 1 | 첫 각성 | B11: 10 | C11: 1 | D11: 6 | E11: 고등급자의 전투 관찰하기 | F11: 전투 규칙·인물 감정·다음 목표가 한 장면에 함께 제시되어 핵심 정보를 놓칠 수 있음 | G11: 강조 자막과 기록 메뉴를 확인해 현재 임무·인물 관계·전투 목적을 구분함 | H11: 1/10 – 주요 난이도 요인: 정보량·장면 전환 속도·감정적 부담 | I11: 1 | J11: 필수 대화와 연출을 마지막 장면까지 확인 | K11: - | L11: 0.0013888889 | M11: 핵심 전투 정보 자막 유지·기록 메뉴 자동 등록 | N11: =N10+L11 -> 0.016550926 | O11: 1-B | 대피소·전투 훈련 | P11: 34 | Q11: =P11 -> 34 | R11: =ROUND(60+0.8*Q11+0.0012*Q11^2,0) -> 89 | U11: =IF(S11="","",ROUNDUP(R11/S11,0)*T11) | V11: =IF(S11="","",ROUNDUP(R11/S11,0))
A12: 1 | 첫 각성 | B12: 11 | C12: 2 | D12: 7 | E12: 기본 공격 훈련하기 | F12: 공격·회피·스태미나 입력을 정해진 순서와 타이밍에 맞춰 반복해야 함 | G12: 안내되는 입력을 한 단계씩 수행하고 성공 판정이 확인된 뒤 다음 조작으로 넘어감 | H12: 2/10 – 주요 난이도 요인: 입력 수·타이밍 허용 범위·연속 성공 횟수 | I12: 3 | J12: 지정 조작 3회 성공 | K12: 연속 3회 실패 시 현재 훈련 단계부터 다시 진행 | L12: 0.0017361111 | M12: 입력 타이밍 완화·느린 시범 재생·자동 조작 안내 | N12: =N11+L12 -> 0.018287037 | O12: 1-B | 대피소·전투 훈련 | P12: 38 | Q12: =P12 -> 38 | R12: =ROUND(60+0.8*Q12+0.0012*Q12^2,0) -> 92 | S12: 20 | T12: 25 | U12: =IF(S12="","",ROUNDUP(R12/S12,0)*T12) -> 125 | V12: =IF(S12="","",ROUNDUP(R12/S12,0)) -> 5
A13: 1 | 첫 각성 | B13: 12 | C13: 2 | D13: 7 | E13: 회피와 스태미나 훈련하기 | F13: 공격·회피·스태미나 입력을 정해진 순서와 타이밍에 맞춰 반복해야 함 | G13: 안내되는 입력을 한 단계씩 수행하고 성공 판정이 확인된 뒤 다음 조작으로 넘어감 | H13: 2/10 – 주요 난이도 요인: 입력 수·타이밍 허용 범위·연속 성공 횟수 | I13: 3 | J13: 지정 조작 3회 성공 | K13: 연속 3회 실패 시 현재 훈련 단계부터 다시 진행 | L13: 0.0017361111 | M13: 입력 타이밍 완화·느린 시범 재생·자동 조작 안내 | N13: =N12+L13 -> 0.020023148 | O13: 1-B | 대피소·전투 훈련 | P13: 42 | Q13: =P13 -> 42 | R13: =ROUND(60+0.8*Q13+0.0012*Q13^2,0) -> 96 | S13: 20 | T13: 25 | U13: =IF(S13="","",ROUNDUP(R13/S13,0)*T13) -> 125 | V13: =IF(S13="","",ROUNDUP(R13/S13,0)) -> 5
A14: 1 | 첫 각성 | B14: 13 | C14: 2 | D14: 7 | E14: 약점 표식 확인하기 | F14: 공격·회피·스태미나 입력을 정해진 순서와 타이밍에 맞춰 반복해야 함 | G14: 안내되는 입력을 한 단계씩 수행하고 성공 판정이 확인된 뒤 다음 조작으로 넘어감 | H14: 2/10 – 주요 난이도 요인: 입력 수·타이밍 허용 범위·연속 성공 횟수 | I14: 3 | J14: 지정 조작 3회 성공 | K14: 연속 3회 실패 시 현재 훈련 단계부터 다시 진행 | L14: 0.0017361111 | M14: 입력 타이밍 완화·느린 시범 재생·자동 조작 안내 | N14: =N13+L14 -> 0.021759259 | O14: 1-B | 대피소·전투 훈련 | P14: 46 | Q14: =P14 -> 46 | R14: =ROUND(60+0.8*Q14+0.0012*Q14^2,0) -> 99 | S14: 20 | T14: 25 | U14: =IF(S14="","",ROUNDUP(R14/S14,0)*T14) -> 125 | V14: =IF(S14="","",ROUNDUP(R14/S14,0)) -> 5
A15: 1 | 첫 각성 | B15: 14 | C15: 4 | D15: 8 | E15: 훈련용 변이체 3마리 처치하기 | F15: 여러 적이 동시에 접근하며 근거리·원거리 공격이 겹쳐 표적 우선순위를 빠르게 바꿔야 함 | G15: 원거리·지원형 적을 먼저 처치하고 회피 후 생기는 빈틈에 기본 공격과 선의 스킬을 연계함 | H15: 4/10 – 주요 난이도 요인: 동시 적 수·공격 유형 수·회피 빈도 | I15: 3 | J15: 지정 구역의 적 3마리 처치 | K15: 체력 0 시 전투 시작 지점에서 재시작 | L15: 0.0025462963 | M15: 연속 실패 시 적 체력 10% 감소·회복 아이템 추가 배치 | N15: =N14+L15 -> 0.024305556 | O15: 1-B | 대피소·전투 훈련 | P15: 53 | Q15: =P15 -> 53 | R15: =ROUND(60+0.8*Q15+0.0012*Q15^2,0) -> 106 | S15: 30 | T15: 30 | U15: =IF(S15="","",ROUNDUP(R15/S15,0)*T15) -> 120 | V15: =IF(S15="","",ROUNDUP(R15/S15,0)) -> 4
A16: 1 | 첫 각성 | B16: 15 | C16: 2 | D16: 7 | E16: 선의 충격파 습득하기 | F16: 공격·회피·스태미나 입력을 정해진 순서와 타이밍에 맞춰 반복해야 함 | G16: 안내되는 입력을 한 단계씩 수행하고 성공 판정이 확인된 뒤 다음 조작으로 넘어감 | H16: 2/10 – 주요 난이도 요인: 입력 수·타이밍 허용 범위·연속 성공 횟수 | I16: 3 | J16: 지정 조작 3회 성공 | K16: 연속 3회 실패 시 현재 훈련 단계부터 다시 진행 | L16: 0.0017361111 | M16: 입력 타이밍 완화·느린 시범 재생·자동 조작 안내 | N16: =N15+L16 -> 0.026041667 | O16: 1-B | 대피소·전투 훈련 | P16: 57 | Q16: =P16 -> 57 | R16: =ROUND(60+0.8*Q16+0.0012*Q16^2,0) -> 109 | S16: 20 | T16: 25 | U16: =IF(S16="","",ROUNDUP(R16/S16,0)*T16) -> 150 | V16: =IF(S16="","",ROUNDUP(R16/S16,0)) -> 6
A17: 1 | 첫 각성 | B17: 16 | C17: 1 | D17: 6 | E17: 첫 장비 슬롯 설정하기 | F17: 장비 효과가 서로 연계되어 현재 전투 역할과 다음 구간에 맞는 조합을 판단해야 함 | G17: 다음 스테이지의 적 속성·전투 역할을 확인해 공격, 생존, 자원 회복 장비를 균형 있게 선택함 | H17: 1/10 – 주요 난이도 요인: 선택지 수·효과 연계성·추천 정보 명확성 | I17: 3 | J17: 필수 장비·스킬 슬롯 3개 설정 후 저장 | K17: - | L17: 0.0012731481 | M17: 추천 장비 자동 표시·현재 장비와 효과 비교 | N17: =N16+L17 -> 0.027314815 | O17: 1-B | 대피소·전투 훈련 | P17: 60 | Q17: =P17 -> 60 | R17: =ROUND(60+0.8*Q17+0.0012*Q17^2,0) -> 112 | U17: =IF(S17="","",ROUNDUP(R17/S17,0)*T17) | V17: =IF(S17="","",ROUNDUP(R17/S17,0))
A18: 1 | 첫 각성 | B18: 17 | C18: 1 | D18: 6 | E18: 아파트 구조대에 합류하기 | F18: 전투 규칙·인물 감정·다음 목표가 한 장면에 함께 제시되어 핵심 정보를 놓칠 수 있음 | G18: 강조 자막과 기록 메뉴를 확인해 현재 임무·인물 관계·전투 목적을 구분함 | H18: 1/10 – 주요 난이도 요인: 정보량·장면 전환 속도·감정적 부담 | I18: 1 | J18: 필수 대화와 연출을 마지막 장면까지 확인 | K18: - | L18: 0.0013888889 | M18: 핵심 전투 정보 자막 유지·기록 메뉴 자동 등록 | N18: =N17+L18 -> 0.028703704 | O18: 1-C | 아파트 구조 작전 | P18: 62 | Q18: =P18 -> 62 | R18: =ROUND(60+0.8*Q18+0.0012*Q18^2,0) -> 114 | U18: =IF(S18="","",ROUNDUP(R18/S18,0)*T18) | V18: =IF(S18="","",ROUNDUP(R18/S18,0))
A19: 1 | 첫 각성 | B19: 18 | C19: 4 | D19: 8 | E19: 복도 변이체 무리 처치하기 | F19: 여러 적이 동시에 접근하며 근거리·원거리 공격이 겹쳐 표적 우선순위를 빠르게 바꿔야 함 | G19: 원거리·지원형 적을 먼저 처치하고 회피 후 생기는 빈틈에 기본 공격과 선의 스킬을 연계함 | H19: 4/10 – 주요 난이도 요인: 동시 적 수·공격 유형 수·회피 빈도 | I19: 4 | J19: 지정 구역의 적 4마리 처치 | K19: 체력 0 시 전투 시작 지점에서 재시작 | L19: 0.0025462963 | M19: 연속 실패 시 적 체력 10% 감소·회복 아이템 추가 배치 | N19: =N18+L19 -> 0.03125 | O19: 1-C | 아파트 구조 작전 | P19: 69 | Q19: =P19 -> 69 | R19: =ROUND(60+0.8*Q19+0.0012*Q19^2,0) -> 121 | S19: 35 | T19: 35 | U19: =IF(S19="","",ROUNDUP(R19/S19,0)*T19) -> 140 | V19: =IF(S19="","",ROUNDUP(R19/S19,0)) -> 4
A20: 1 | 첫 각성 | B20: 19 | C20: 5 | D20: 8 | E20: 갇힌 주민을 지키며 문 개방하기 | F20: 여러 방향에서 적이 몰려오고 방어 대상의 내구도도 함께 관리해야 함 | G20: 위험도가 높은 진입로부터 차단하고 광역 스킬은 웨이브가 겹치는 순간에 사용함 | H20: 5/10 – 주요 난이도 요인: 진입로 수·웨이브 수·방어 대상 내구도 | I20: 3 | J20: 방어 목표를 유지하며 3개 웨이브 종료 | K20: 방어 대상 내구도 0 또는 플레이어 체력 0 시 웨이브 재시작 | L20: 0.003587963 | M20: 재도전 시 방어 대상 내구도 증가·첫 웨이브 적 수 감소 | N20: =N19+L20 -> 0.034837963 | O20: 1-C | 아파트 구조 작전 | P20: 77 | Q20: =P20 -> 77 | R20: =ROUND(60+0.8*Q20+0.0012*Q20^2,0) -> 129 | S20: 30 | T20: 30 | U20: =IF(S20="","",ROUNDUP(R20/S20,0)*T20) -> 150 | V20: =IF(S20="","",ROUNDUP(R20/S20,0)) -> 5
A21: 1 | 첫 각성 | B21: 20 | C21: 6 | D21: 9 | E21: 지하 주차장 강습체 처치하기 | F21: 높은 강인도와 연계 패턴을 가진 정예 적이 일반 적을 소환해 공격 창이 짧음 | G21: 강인도 게이지를 먼저 무너뜨리고 패턴 종료 후 노출되는 약점에 고위력 스킬을 집중함 | H21: 6/10 – 주요 난이도 요인: 패턴 수·강인도·약점 노출 시간 | I21: 1 | J21: 정예 적의 체력을 0으로 만들고 전투 구역 정리 | K21: 체력 0 시 정예 전투 시작 지점에서 재시작 | L21: 0.003587963 | M21: 패턴 예고 강화·강인도 회복 속도 감소 | N21: =N20+L21 -> 0.038425926 | O21: 1-C | 아파트 구조 작전 | P21: 87 | Q21: =P21 -> 87 | R21: =ROUND(60+0.8*Q21+0.0012*Q21^2,0) -> 139 | S21: 105 | T21: 105 | U21: =IF(S21="","",ROUNDUP(R21/S21,0)*T21) -> 210 | V21: =IF(S21="","",ROUNDUP(R21/S21,0)) -> 2
A22: 1 | 첫 각성 | B22: 21 | C22: 4 | D22: 8 | E22: 옥상 탈출로 확보하기 | F22: 여러 적이 동시에 접근하며 근거리·원거리 공격이 겹쳐 표적 우선순위를 빠르게 바꿔야 함 | G22: 원거리·지원형 적을 먼저 처치하고 회피 후 생기는 빈틈에 기본 공격과 선의 스킬을 연계함 | H22: 4/10 – 주요 난이도 요인: 동시 적 수·공격 유형 수·회피 빈도 | I22: 4 | J22: 지정 구역의 적 4마리 처치 | K22: 체력 0 시 전투 시작 지점에서 재시작 | L22: 0.0025462963 | M22: 연속 실패 시 적 체력 10% 감소·회복 아이템 추가 배치 | N22: =N21+L22 -> 0.040972222 | O22: 1-C | 아파트 구조 작전 | P22: 94 | Q22: =P22 -> 94 | R22: =ROUND(60+0.8*Q22+0.0012*Q22^2,0) -> 146 | S22: 35 | T22: 35 | U22: =IF(S22="","",ROUNDUP(R22/S22,0)*T22) -> 175 | V22: =IF(S22="","",ROUNDUP(R22/S22,0)) -> 5
A23: 1 | 첫 각성 | B23: 22 | C23: 8 | D23: 10 | E23: 첫 균열 수호체 처치하기 | F23: 체력 구간마다 패턴과 전장 구조가 바뀌며 회피·약점 공격·자원 관리가 동시에 요구됨 | G23: 패턴 예고와 체력 단계 전환을 관찰해 회피 자원을 남기고 약점 노출 구간에 궁극기를 사용함 | H23: 8/10 – 주요 난이도 요인: 페이즈 수·패턴 복합도·자원 관리 압박 | I23: 1 | J23: 보스의 모든 페이즈를 돌파하고 최종 체력을 0으로 만듦 | K23: 체력 0 시 현재 보스 페이즈 시작 지점에서 재시작 | L23: 0.0056712963 | M23: 페이즈 체크포인트·패턴 예고 강화·회복 아이템 보충 | N23: =N22+L23 -> 0.046643519 | O23: 1-C | 아파트 구조 작전 | P23: 111 | Q23: =P23 -> 111 | R23: =ROUND(60+0.8*Q23+0.0012*Q23^2,0) -> 164 | S23: 310 | T23: 360 | U23: =IF(S23="","",ROUNDUP(R23/S23,0)*T23) -> 360 | V23: =IF(S23="","",ROUNDUP(R23/S23,0)) -> 1
A24: 2 | 대피소 방어 | B24: 23 | C24: 2 | D24: 7 | E24: 출정 장비 점검하기 | F24: 장비 효과가 서로 연계되어 현재 전투 역할과 다음 구간에 맞는 조합을 판단해야 함 | G24: 다음 스테이지의 적 속성·전투 역할을 확인해 공격, 생존, 자원 회복 장비를 균형 있게 선택함 | H24: 2/10 – 주요 난이도 요인: 선택지 수·효과 연계성·추천 정보 명확성 | I24: 3 | J24: 필수 장비·스킬 슬롯 3개 설정 후 저장 | K24: - | L24: 0.0015046296 | M24: 추천 장비 자동 표시·현재 장비와 효과 비교 | N24: =N23+L24 -> 0.048148148 | O24: 2-A | 보급로 확보 | P24: 115 | Q24: =P24 -> 115 | R24: =ROUND(60+0.8*Q24+0.0012*Q24^2,0) -> 168 | U24: =IF(S24="","",ROUNDUP(R24/S24,0)*T24) | V24: =IF(S24="","",ROUNDUP(R24/S24,0))
A25: 2 | 대피소 방어 | B25: 24 | C25: 2 | D25: 7 | E25: 회복약과 투척 도구 선택하기 | F25: 장비 효과가 서로 연계되어 현재 전투 역할과 다음 구간에 맞는 조합을 판단해야 함 | G25: 다음 스테이지의 적 속성·전투 역할을 확인해 공격, 생존, 자원 회복 장비를 균형 있게 선택함 | H25: 2/10 – 주요 난이도 요인: 선택지 수·효과 연계성·추천 정보 명확성 | I25: 3 | J25: 필수 장비·스킬 슬롯 3개 설정 후 저장 | K25: - | L25: 0.0015046296 | M25: 추천 장비 자동 표시·현재 장비와 효과 비교 | N25: =N24+L25 -> 0.049652778 | O25: 2-A | 보급로 확보 | P25: 119 | Q25: =P25 -> 119 | R25: =ROUND(60+0.8*Q25+0.0012*Q25^2,0) -> 172 | U25: =IF(S25="","",ROUNDUP(R25/S25,0)*T25) | V25: =IF(S25="","",ROUNDUP(R25/S25,0))
A26: 2 | 대피소 방어 | B26: 25 | C26: 3 | D26: 7 | E26: 폐상가 보급로에 진입하기 | F26: 붕괴 지형과 적의 공격 예고가 이동 경로를 제한해 안전한 타이밍을 판단해야 함 | G26: 공격 예고 범위를 본 뒤 안전 지점에서 대기하고 이동 가능한 순간에 다음 엄폐물까지 이동함 | H26: 3/10 – 주요 난이도 요인: 공격 예고 시간·안전 지점 간 거리·지형 붕괴 속도 | I26: 1 | J26: 목표 지점의 도착 트리거 진입 | K26: 낙하 공격 3회 피격 또는 체력 0 시 직전 체크포인트 재시작 | L26: 0.0013888889 | M26: 연속 실패 시 공격 예고 시간 증가·안전 지점 추가 표시 | N26: =N25+L26 -> 0.051041667 | O26: 2-A | 보급로 확보 | P26: 123 | Q26: =P26 -> 123 | R26: =ROUND(60+0.8*Q26+0.0012*Q26^2,0) -> 177 | U26: =IF(S26="","",ROUNDUP(R26/S26,0)*T26) | V26: =IF(S26="","",ROUNDUP(R26/S26,0))
A27: 2 | 대피소 방어 | B27: 26 | C27: 5 | D27: 9 | E27: 매복 변이체 처치하기 | F27: 여러 적이 동시에 접근하며 근거리·원거리 공격이 겹쳐 표적 우선순위를 빠르게 바꿔야 함 | G27: 원거리·지원형 적을 먼저 처치하고 회피 후 생기는 빈틈에 기본 공격과 선의 스킬을 연계함 | H27: 5/10 – 주요 난이도 요인: 동시 적 수·공격 유형 수·회피 빈도 | I27: 5 | J27: 지정 구역의 적 5마리 처치 | K27: 체력 0 시 전투 시작 지점에서 재시작 | L27: 0.0028935185 | M27: 연속 실패 시 적 체력 10% 감소·회복 아이템 추가 배치 | N27: =N26+L27 -> 0.053935185 | O27: 2-A | 보급로 확보 | P27: 130 | Q27: =P27 -> 130 | R27: =ROUND(60+0.8*Q27+0.0012*Q27^2,0) -> 184 | S27: 40 | T27: 35 | U27: =IF(S27="","",ROUNDUP(R27/S27,0)*T27) -> 175 | V27: =IF(S27="","",ROUNDUP(R27/S27,0)) -> 5
A28: 2 | 대피소 방어 | B28: 27 | C28: 5 | D28: 9 | E28: 포식형 괴물의 추격 피하기 | F28: 여러 적이 동시에 접근하며 근거리·원거리 공격이 겹쳐 표적 우선순위를 빠르게 바꿔야 함 | G28: 원거리·지원형 적을 먼저 처치하고 회피 후 생기는 빈틈에 기본 공격과 선의 스킬을 연계함 | H28: 5/10 – 주요 난이도 요인: 동시 적 수·공격 유형 수·회피 빈도 | I28: 5 | J28: 지정 구역의 적 5마리 처치 | K28: 체력 0 시 전투 시작 지점에서 재시작 | L28: 0.0028935185 | M28: 연속 실패 시 적 체력 10% 감소·회복 아이템 추가 배치 | N28: =N27+L28 -> 0.056828704 | O28: 2-A | 보급로 확보 | P28: 137 | Q28: =P28 -> 137 | R28: =ROUND(60+0.8*Q28+0.0012*Q28^2,0) -> 192 | S28: 40 | T28: 35 | U28: =IF(S28="","",ROUNDUP(R28/S28,0)*T28) -> 175 | V28: =IF(S28="","",ROUNDUP(R28/S28,0)) -> 5
A29: 2 | 대피소 방어 | B29: 28 | C29: 6 | D29: 9 | E29: 의약품 상자를 지키기 | F29: 여러 방향에서 적이 몰려오고 방어 대상의 내구도도 함께 관리해야 함 | G29: 위험도가 높은 진입로부터 차단하고 광역 스킬은 웨이브가 겹치는 순간에 사용함 | H29: 6/10 – 주요 난이도 요인: 진입로 수·웨이브 수·방어 대상 내구도 | I29: 3 | J29: 방어 목표를 유지하며 3개 웨이브 종료 | K29: 방어 대상 내구도 0 또는 플레이어 체력 0 시 웨이브 재시작 | L29: 0.0039351852 | M29: 재도전 시 방어 대상 내구도 증가·첫 웨이브 적 수 감소 | N29: =N28+L29 -> 0.060763889 | O29: 2-A | 보급로 확보 | P29: 146 | Q29: =P29 -> 146 | R29: =ROUND(60+0.8*Q29+0.0012*Q29^2,0) -> 202 | S29: 35 | T29: 30 | U29: =IF(S29="","",ROUNDUP(R29/S29,0)*T29) -> 180 | V29: =IF(S29="","",ROUNDUP(R29/S29,0)) -> 6
A30: 2 | 대피소 방어 | B30: 29 | C30: 5 | D30: 9 | E30: 부상자를 대피소까지 호위하기 | F30: 호위 대상이 공격에 취약하고 이동을 멈추는 구간마다 적 증원이 발생함 | G30: 호위 대상보다 앞서 이동해 적을 끌어내고 위험 구간에서는 방어 스킬로 이동 시간을 확보함 | H30: 5/10 – 주요 난이도 요인: 호위 거리·적 증원 수·호위 대상 생존력 | I30: 3 | J30: 호위 대상과 함께 3개 안전 지점 통과 | K30: 호위 대상 체력 0 또는 플레이어와 거리 초과 시 마지막 지점부터 재시작 | L30: 0.0034722222 | M30: 호위 대상 방어력 증가·위험 구간 이동 속도 향상 | N30: =N29+L30 -> 0.064236111 | O30: 2-A | 보급로 확보 | P30: 153 | Q30: =P30 -> 153 | R30: =ROUND(60+0.8*Q30+0.0012*Q30^2,0) -> 210 | S30: 40 | T30: 35 | U30: =IF(S30="","",ROUNDUP(R30/S30,0)*T30) -> 210 | V30: =IF(S30="","",ROUNDUP(R30/S30,0)) -> 6
A31: 2 | 대피소 방어 | B31: 30 | C31: 7 | D31: 10 | E31: 보급로 정찰대장 처치하기 | F31: 높은 강인도와 연계 패턴을 가진 정예 적이 일반 적을 소환해 공격 창이 짧음 | G31: 강인도 게이지를 먼저 무너뜨리고 패턴 종료 후 노출되는 약점에 고위력 스킬을 집중함 | H31: 7/10 – 주요 난이도 요인: 패턴 수·강인도·약점 노출 시간 | I31: 1 | J31: 정예 적의 체력을 0으로 만들고 전투 구역 정리 | K31: 체력 0 시 정예 전투 시작 지점에서 재시작 | L31: 0.0039351852 | M31: 패턴 예고 강화·강인도 회복 속도 감소 | N31: =N30+L31 -> 0.068171296 | O31: 2-A | 보급로 확보 | P31: 164 | Q31: =P31 -> 164 | R31: =ROUND(60+0.8*Q31+0.0012*Q31^2,0) -> 223 | S31: 120 | T31: 115 | U31: =IF(S31="","",ROUNDUP(R31/S31,0)*T31) -> 230 | V31: =IF(S31="","",ROUNDUP(R31/S31,0)) -> 2
A32: 2 | 대피소 방어 | B32: 31 | C32: 2 | D32: 7 | E32: 대피소 경보에 대응하기 | F32: 전투 규칙·인물 감정·다음 목표가 한 장면에 함께 제시되어 핵심 정보를 놓칠 수 있음 | G32: 강조 자막과 기록 메뉴를 확인해 현재 임무·인물 관계·전투 목적을 구분함 | H32: 2/10 – 주요 난이도 요인: 정보량·장면 전환 속도·감정적 부담 | I32: 1 | J32: 필수 대화와 연출을 마지막 장면까지 확인 | K32: - | L32: 0.0016203704 | M32: 핵심 전투 정보 자막 유지·기록 메뉴 자동 등록 | N32: =N31+L32 -> 0.069791667 | O32: 2-B | 대피소 공성전 | P32: 167 | Q32: =P32 -> 167 | R32: =ROUND(60+0.8*Q32+0.0012*Q32^2,0) -> 227 | U32: =IF(S32="","",ROUNDUP(R32/S32,0)*T32) | V32: =IF(S32="","",ROUNDUP(R32/S32,0))
A33: 2 | 대피소 방어 | B33: 32 | C33: 2 | D33: 7 | E33: 방어 인원과 포탑 배치하기 | F33: 장비 효과가 서로 연계되어 현재 전투 역할과 다음 구간에 맞는 조합을 판단해야 함 | G33: 다음 스테이지의 적 속성·전투 역할을 확인해 공격, 생존, 자원 회복 장비를 균형 있게 선택함 | H33: 2/10 – 주요 난이도 요인: 선택지 수·효과 연계성·추천 정보 명확성 | I33: 3 | J33: 필수 장비·스킬 슬롯 3개 설정 후 저장 | K33: - | L33: 0.0015046296 | M33: 추천 장비 자동 표시·현재 장비와 효과 비교 | N33: =N32+L33 -> 0.071296296 | O33: 2-B | 대피소 공성전 | P33: 171 | Q33: =P33 -> 171 | R33: =ROUND(60+0.8*Q33+0.0012*Q33^2,0) -> 232 | U33: =IF(S33="","",ROUNDUP(R33/S33,0)*T33) | V33: =IF(S33="","",ROUNDUP(R33/S33,0))
A34: 2 | 대피소 방어 | B34: 33 | C34: 6 | D34: 9 | E34: 1차 침입 웨이브 막기 | F34: 여러 방향에서 적이 몰려오고 방어 대상의 내구도도 함께 관리해야 함 | G34: 위험도가 높은 진입로부터 차단하고 광역 스킬은 웨이브가 겹치는 순간에 사용함 | H34: 6/10 – 주요 난이도 요인: 진입로 수·웨이브 수·방어 대상 내구도 | I34: 1 | J34: 방어 목표를 유지하며 1개 웨이브 종료 | K34: 방어 대상 내구도 0 또는 플레이어 체력 0 시 웨이브 재시작 | L34: 0.0039351852 | M34: 재도전 시 방어 대상 내구도 증가·첫 웨이브 적 수 감소 | N34: =N33+L34 -> 0.075231481 | O34: 2-B | 대피소 공성전 | P34: 180 | Q34: =P34 -> 180 | R34: =ROUND(60+0.8*Q34+0.0012*Q34^2,0) -> 243 | S34: 40 | T34: 30 | U34: =IF(S34="","",ROUNDUP(R34/S34,0)*T34) -> 210 | V34: =IF(S34="","",ROUNDUP(R34/S34,0)) -> 7
A35: 2 | 대피소 방어 | B35: 34 | C35: 5 | D35: 9 | E35: 동쪽 출입구 지원하기 | F35: 여러 적이 동시에 접근하며 근거리·원거리 공격이 겹쳐 표적 우선순위를 빠르게 바꿔야 함 | G35: 원거리·지원형 적을 먼저 처치하고 회피 후 생기는 빈틈에 기본 공격과 선의 스킬을 연계함 | H35: 5/10 – 주요 난이도 요인: 동시 적 수·공격 유형 수·회피 빈도 | I35: 5 | J35: 지정 구역의 적 5마리 처치 | K35: 체력 0 시 전투 시작 지점에서 재시작 | L35: 0.0028935185 | M35: 연속 실패 시 적 체력 10% 감소·회복 아이템 추가 배치 | N35: =N34+L35 -> 0.078125 | O35: 2-B | 대피소 공성전 | P35: 187 | Q35: =P35 -> 187 | R35: =ROUND(60+0.8*Q35+0.0012*Q35^2,0) -> 252 | S35: 45 | T35: 35 | U35: =IF(S35="","",ROUNDUP(R35/S35,0)*T35) -> 210 | V35: =IF(S35="","",ROUNDUP(R35/S35,0)) -> 6
A36: 2 | 대피소 방어 | B36: 35 | C36: 5 | D36: 9 | E36: 침식 벌레 둥지 파괴하기 | F36: 여러 적이 동시에 접근하며 근거리·원거리 공격이 겹쳐 표적 우선순위를 빠르게 바꿔야 함 | G36: 원거리·지원형 적을 먼저 처치하고 회피 후 생기는 빈틈에 기본 공격과 선의 스킬을 연계함 | H36: 5/10 – 주요 난이도 요인: 동시 적 수·공격 유형 수·회피 빈도 | I36: 5 | J36: 지정 구역의 적 5마리 처치 | K36: 체력 0 시 전투 시작 지점에서 재시작 | L36: 0.0028935185 | M36: 연속 실패 시 적 체력 10% 감소·회복 아이템 추가 배치 | N36: =N35+L36 -> 0.081018519 | O36: 2-B | 대피소 공성전 | P36: 194 | Q36: =P36 -> 194 | R36: =ROUND(60+0.8*Q36+0.0012*Q36^2,0) -> 260 | S36: 45 | T36: 35 | U36: =IF(S36="","",ROUNDUP(R36/S36,0)*T36) -> 210 | V36: =IF(S36="","",ROUNDUP(R36/S36,0)) -> 6
A37: 2 | 대피소 방어 | B37: 36 | C37: 6 | D37: 9 | E37: 2차 침입 웨이브 막기 | F37: 여러 방향에서 적이 몰려오고 방어 대상의 내구도도 함께 관리해야 함 | G37: 위험도가 높은 진입로부터 차단하고 광역 스킬은 웨이브가 겹치는 순간에 사용함 | H37: 6/10 – 주요 난이도 요인: 진입로 수·웨이브 수·방어 대상 내구도 | I37: 2 | J37: 방어 목표를 유지하며 2개 웨이브 종료 | K37: 방어 대상 내구도 0 또는 플레이어 체력 0 시 웨이브 재시작 | L37: 0.0039351852 | M37: 재도전 시 방어 대상 내구도 증가·첫 웨이브 적 수 감소 | N37: =N36+L37 -> 0.084953704 | O37: 2-B | 대피소 공성전 | P37: 203 | Q37: =P37 -> 203 | R37: =ROUND(60+0.8*Q37+0.0012*Q37^2,0) -> 272 | S37: 40 | T37: 30 | U37: =IF(S37="","",ROUNDUP(R37/S37,0)*T37) -> 210 | V37: =IF(S37="","",ROUNDUP(R37/S37,0)) -> 7
A38: 2 | 대피소 방어 | B38: 37 | C38: 6 | D38: 9 | E38: 비상 발전기 보호하기 | F38: 여러 방향에서 적이 몰려오고 방어 대상의 내구도도 함께 관리해야 함 | G38: 위험도가 높은 진입로부터 차단하고 광역 스킬은 웨이브가 겹치는 순간에 사용함 | H38: 6/10 – 주요 난이도 요인: 진입로 수·웨이브 수·방어 대상 내구도 | I38: 3 | J38: 방어 목표를 유지하며 3개 웨이브 종료 | K38: 방어 대상 내구도 0 또는 플레이어 체력 0 시 웨이브 재시작 | L38: 0.0039351852 | M38: 재도전 시 방어 대상 내구도 증가·첫 웨이브 적 수 감소 | N38: =N37+L38 -> 0.088888889 | O38: 2-B | 대피소 공성전 | P38: 212 | Q38: =P38 -> 212 | R38: =ROUND(60+0.8*Q38+0.0012*Q38^2,0) -> 284 | S38: 40 | T38: 30 | U38: =IF(S38="","",ROUNDUP(R38/S38,0)*T38) -> 240 | V38: =IF(S38="","",ROUNDUP(R38/S38,0)) -> 8
A39: 2 | 대피소 방어 | B39: 38 | C39: 5 | D39: 9 | E39: 시민 대피 시간을 확보하기 | F39: 호위 대상이 공격에 취약하고 이동을 멈추는 구간마다 적 증원이 발생함 | G39: 호위 대상보다 앞서 이동해 적을 끌어내고 위험 구간에서는 방어 스킬로 이동 시간을 확보함 | H39: 5/10 – 주요 난이도 요인: 호위 거리·적 증원 수·호위 대상 생존력 | I39: 3 | J39: 호위 대상과 함께 3개 안전 지점 통과 | K39: 호위 대상 체력 0 또는 플레이어와 거리 초과 시 마지막 지점부터 재시작 | L39: 0.0034722222 | M39: 호위 대상 방어력 증가·위험 구간 이동 속도 향상 | N39: =N38+L39 -> 0.092361111 | O39: 2-B | 대피소 공성전 | P39: 219 | Q39: =P39 -> 219 | R39: =ROUND(60+0.8*Q39+0.0012*Q39^2,0) -> 293 | S39: 45 | T39: 35 | U39: =IF(S39="","",ROUNDUP(R39/S39,0)*T39) -> 245 | V39: =IF(S39="","",ROUNDUP(R39/S39,0)) -> 7
A40: 2 | 대피소 방어 | B40: 39 | C40: 9 | D40: 10 | E40: 공성형 괴물 처치하기 | F40: 체력 구간마다 패턴과 전장 구조가 바뀌며 회피·약점 공격·자원 관리가 동시에 요구됨 | G40: 패턴 예고와 체력 단계 전환을 관찰해 회피 자원을 남기고 약점 노출 구간에 궁극기를 사용함 | H40: 9/10 – 주요 난이도 요인: 페이즈 수·패턴 복합도·자원 관리 압박 | I40: 1 | J40: 보스의 모든 페이즈를 돌파하고 최종 체력을 0으로 만듦 | K40: 체력 0 시 현재 보스 페이즈 시작 지점에서 재시작 | L40: 0.0064814815 | M40: 페이즈 체크포인트·패턴 예고 강화·회복 아이템 보충 | N40: =N39+L40 -> 0.098842593 | O40: 2-B | 대피소 공성전 | P40: 235 | Q40: =P40 -> 235 | R40: =ROUND(60+0.8*Q40+0.0012*Q40^2,0) -> 314 | S40: 380 | T40: 410 | U40: =IF(S40="","",ROUNDUP(R40/S40,0)*T40) -> 410 | V40: =IF(S40="","",ROUNDUP(R40/S40,0)) -> 1
...

Sheet 밸런스 팩터
B2: 밸런스 팩터
B4: 전투 중심 버전 「넌 착해!」의 성장·전투·난이도에 영향을 주는 주요 조정 요소를 원형으로 정리
B70: 큰 원은 전투 전반의 핵심 팩터이며, 작은 원은 몬스터·스킬·스테이지 단위에서 조정하는 세부 팩터임

Sheet 작성 기준
A1: 전투 중심 밸런스 문서 작성 기준
A3: 항목 | B3: 작성 방식 | C3: 값/형식 | D3: 우리 게임 적용 기준
A4: 플레이 난이도 | B4: 플레이어가 이동·공격·회피·스킬 연계를 수행할 때 느끼는 조작 난이도 | C4: 1~10 숫자 | D4: 1은 단순 확인·설정, 10은 다단계 보스 패턴과 복합 입력
A5: 플레이 흥미도 | B5: 기획자가 전투·성장·연출·성취를 통해 기대하는 재미 목표값 | C5: 1~10 숫자 | D5: 일반 전투는 6~8, 정예·보스·결정적 연출은 9~10을 목표
A6: 콘텐츠 진행 순서 | B6: 게임 시작부터 엔딩까지 해금되는 모든 플레이 내용을 순서대로 기록 | C6: 1부터 연속 넘버링 | D6: 이동·훈련·일반전·방어전·호위·정예전·보스전·성장 설정을 모두 포함
A7: 플레이 목표 | B7: 제목만 읽어도 플레이어가 무엇을 해야 하는지 보이도록 작성 | C7: 행동형 제목 | D7: 예: 승강장 변이체 무리 처치하기, 플랫폼을 3분간 방어하기
A8: 플레이 난관 | B8: 목표 달성을 방해하는 적 패턴·지형·시간·자원·호위 대상 요소 | C8: 구체적 서술 | D8: 동시 적 수, 공격 예고 시간, 강인도, 웨이브 수, 방어 대상 내구도 등
A9: 공략 방법 | B9: 방해 요소를 해결하기 위해 플레이어가 관찰·판단·조작해야 하는 내용 | C9: 구체적 플레이 절차 | D9: 표적 우선순위, 회피 타이밍, 약점 공격, 스킬 자원 관리 등을 작성
A10: 체감 난이도 | B10: 조작과 판단의 어려움 및 난이도를 만드는 원인을 함께 기록 | C10: 숫자/10 + 원인 설명 | D10: 패턴 수, 동시 적 수, 약점 노출 시간, 제한시간, 체크포인트 간격 등
A11: 수행 과제 수 | B11: 해당 행을 완료하기 위해 필요한 적·웨이브·장치·단계의 수 | C11: 정수 | D11: 일반 적 6마리, 방어 3웨이브, 장치 4개, 보스 2페이즈 등
A12: 목표 달성 조건 | B12: 시스템이 완료를 판정할 수 있는 명확한 조건 | C12: 구체적 판정 조건 | D12: 적 체력 0, 웨이브 종료, 호위 대상 도착, 장치 입력 완료 등
A13: 실패 결과 | B13: 실패가 발생하는 조건과 재시작 범위를 기록 | C13: 구체적 판정 조건 또는 실패 없음 | D13: 플레이어 체력 0, 방어 대상 파괴, 호위 대상 이탈, 오답 누적 등
A14: 예상 소요 시간 | B14: 초회 플레이어가 해당 콘텐츠를 완료하는 데 걸리는 예상 시간 | C14: Excel 시간값 | D14: 전투 패턴 학습·적 수·이동거리·재도전 가능성을 함께 고려
... A18: 문서 범위 | B18: 게임 시작부터 엔딩까지 모든 콘텐츠를 작성 | C18: 총 123개 | D18: 5개 챕터, 전투·훈련·방어·호위·정예·보스 중심으로 구성

Sheet 밸런스 곡선
A1: 전투 중심 버전 전체 밸런스 곡선 요약
A3: 총 콘텐츠 수 | B3: =COUNTA('밸런스 문서'!B2:B124) -> 123 | C3: 평균 플레이 난이도 | D3: =AVERAGE('밸런스 문서'!C2:C124) -> 4.8699187 | E3: 평균 플레이 흥미도 | F3: =AVERAGE('밸런스 문서'!D2:D124) -> 8.6747967 | G3: 최고 플레이 난이도 | H3: =MAX('밸런스 문서'!C2:C124) -> 10 | I3: 최고 플레이 흥미도 | J3: =MAX('밸런스 문서'!D2:D124) -> 10
A5: 구간 | B5: 콘텐츠 수 | C5: 평균 플레이 난이도 | D5: 평균 플레이 흥미도 | E5: 최고 플레이 난이도
A6: Q1 첫 각성 | B6: 22 | C6: =AVERAGE('밸런스 문서'!C2:C23) -> 2.7727273 | D6: =AVERAGE('밸런스 문서'!D2:D23) -> 7.1363636 | E6: =MAX('밸런스 문서'!C2:C23) -> 8
A7: Q2 대피소 방어 | B7: 24 | C7: =AVERAGE('밸런스 문서'!C24:C47) -> 4.875 | D7: =AVERAGE('밸런스 문서'!D24:D47) -> 8.5833333 | E7: =MAX('밸런스 문서'!C24:C47) -> 9
A8: Q3 고등급자 토벌대 | B8: 26 | C8: =AVERAGE('밸런스 문서'!C48:C73) -> 4.8461538 | D8: =AVERAGE('밸런스 문서'!D48:D73) -> 8.5 | E8: =MAX('밸런스 문서'!C48:C73) -> 10
A9: Q4 폐교 던전 | B9: 28 | C9: =AVERAGE('밸런스 문서'!C74:C101) -> 5.7857143 | D9: =AVERAGE('밸런스 문서'!D74:D101) -> 9.3571429 | E9: =MAX('밸런스 문서'!C74:C101) -> 10
A10: Q5 균열 최종전 | B10: 23 | C10: =AVERAGE('밸런스 문서'!C102:C124) -> 5.7826087 | D10: =AVERAGE('밸런스 문서'!D102:D124) -> 9.6086957 | E10: =MAX('밸런스 문서'!C102:C124) -> 10
A14: 콘텐츠 진행 순서 | B14: 플레이 난이도 | C14: 플레이 흥미도 | E14: X 콘텐츠 진행 포인트 | F14: Y 레벨업을 위한 필요 경험치
A15: 1 | B15: ='밸런스 문서'!C2 -> 1 | C15: ='밸런스 문서'!D2 -> 5 | E15: ='밸런스 문서'!Q2 -> 2 | F15: ='밸런스 문서'!R2 -> 62
A16: 2 | B16: ='밸런스 문서'!C3 -> 2 | C16: ='밸런스 문서'!D3 -> 7 | E16: ='밸런스 문서'!Q3 -> 6 | F16: ='밸런스 문서'!R3 -> 65
A17: 3 | B17: ='밸런스 문서'!C4 -> 1 | C17: ='밸런스 문서'!D4 -> 5 | E17: ='밸런스 문서'!Q4 -> 8 | F17: ='밸런스 문서'!R4 -> 66
A18: 4 | B18: ='밸런스 문서'!C5 -> 2 | C18: ='밸런스 문서'!D5 -> 7 | E18: ='밸런스 문서'!Q5 -> 12 | F18: ='밸런스 문서'!R5 -> 70
A19: 5 | B19: ='밸런스 문서'!C6 -> 4 | C19: ='밸런스 문서'!D6 -> 7 | E19: ='밸런스 문서'!Q6 -> 17 | F19: ='밸런스 문서'!R6 -> 74
A20: 6 | B20: ='밸런스 문서'!C7 -> 2 | C20: ='밸런스 문서'!D7 -> 6 | E20: ='밸런스 문서'!Q7 -> 20 | F20: ='밸런스 문서'!R7 -> 76
A21: 7 | B21: ='밸런스 문서'!C8 -> 4 | C21: ='밸런스 문서'!D8 -> 8 | E21: ='밸런스 문서'!Q8 -> 26 | F21: ='밸런스 문서'!R8 -> 82
A22: 8 | B22: ='밸런스 문서'!C9 -> 1 | C22: ='밸런스 문서'!D9 -> 9 | E22: ='밸런스 문서'!Q9 -> 29 | F22: ='밸런스 문서'!R9 -> 84
A23: 9 | B23: ='밸런스 문서'!C10 -> 2 | C23: ='밸런스 문서'!D10 -> 6 | E23: ='밸런스 문서'!Q10 -> 32 | F23: ='밸런스 문서'!R10 -> 87
A24: 10 | B24: ='밸런스 문서'!C11 -> 1 | C24: ='밸런스 문서'!D11 -> 6 | E24: ='밸런스 문서'!Q11 -> 34 | F24: ='밸런스 문서'!R11 -> 89
A25: 11 | B25: ='밸런스 문서'!C12 -> 2 | C25: ='밸런스 문서'!D12 -> 7 | E25: ='밸런스 문서'!Q12 -> 38 | F25: ='밸런스 문서'!R12 -> 92
A26: 12 | B26: ='밸런스 문서'!C13 -> 2 | C26: ='밸런스 문서'!D13 -> 7 | E26: ='밸런스 문서'!Q13 -> 42 | F26: ='밸런스 문서'!R13 -> 96
... A137: 123 | B137: ='밸런스 문서'!C124 -> 2 | C137: ='밸런스 문서'!D124 -> 9 | E137: ='밸런스 문서'!Q124 -> 1000 | F137: ='밸런스 문서'!R124 -> 2060
