Workbook

Sheet 밸런스 문서
Q1: a | R1: b
M2: 경험치 그래프 | Q2: 5 | R2: 15
Q3: =Q2/100 -> 0.05 | R3: =R2/100 -> 0.15
A4: 챕터 | B4: 콘텐츠 진행 순서 | C4: 플레이 난이도 | D4: 플레이 흥미도 | E4: 플레이 목표 | F4: 플레이 난관 | G4: 공략 방법 | H4: 체감 난이도 | I4: 수행 과제 수 | J4: 목표 달성 조건 | K4: 실패 결과 | L4: 예상 소요 시간 | M4: 난이도 조절 요소 | N4: 누적 플레이 시간 | O4: 스테이지 | P4: 콘텐츠 진행 포인트 누적 | Q4: X 콘텐츠 진행 포인트 | R4: Y 진행 요구 숙련도 | S4: 전투 콘텐츠 분류 | T4: 권장 전투 숙련도 | U4: 전투 예상 시간 (초) | V4: 핵심 전투 기믹 | W4: 라이트 유저 (예상 시간 기준) | X4: 미들 유저 | Y4: 헤비 유저 | Z4: 보스가 주는 경험치 | AA4: 해당 레벨의 보스 분포 수 | AB4: 보스 잡는 데 걸리는 시간(초) 보스타입 (근거리) | AC4: 보스 잡는 데 걸리는 시간(초) 보스타입 (원거리) | AD4: 자아마모도(%) | AE4: 인연 시스템 (추가 경험치 획득률%) | AF4: Kill 이벤트 (관문)
A5: 1 | 동생 심부름 | B5: 1 | C5: 1 | D5: 8 | E5: 차한해의 과거 오프닝 감상 | F5: 입양 이후 가족 안에서 희생을 요구받아 온 과거를 보여주는 연출이 길게 이어져 플레이어가 핵심 정보를 놓칠 수 있음 | G5: 핵심 장면의 시선 유도와 짧은 자막을 통해 관계와 감정 변화를 이해함 | H5: 1/10 – 연출 길이와 정보량이 난이도를 결정함 | I5: 1 | J5: 오프닝 재생이 끝나면 자동 완료 | K5: - | L5: 1분 30초 | M5: 스킵·다시 보기 기능 제공 | N5: =(IFERROR(VALUE(LEFT(L5,FIND("분",L5)-1))*60,0)+IFERROR(VALUE(TRIM(MID(L5,IFERROR(FIND("분",L5),0)+1,IFERROR(FIND("초",L5),LEN(L5)+1)-IFERROR(FIND("분",L5),0)-1))),0))/86400 -> 0.0010416667 | O5: 1-A | 집·튜토리얼 | P5: =Q5 -> 4 | Q5: 4 | R5: =ROUND($Q$3*P5*P5+$R$3*P5,2) -> 1.4 | S5: 비전투 | T5: — | U5: — | V5: — | W5: 0.0012152778 | X5: 0.001099537 | Y5: 0.0010416667 | AD5: -
A6: 1 | 동생 심부름 | B6: 2 | C6: 1 | D6: 3 | E6: 빨래 개기 | F6: 조사 가능한 가구가 많아 조작 가능한 대상을 바로 알아보기 어려움 | G6: 주인공 주변의 상호작용 표시를 확인하고 조사 키를 누름 | H6: 1/10 – 상호작용 표시의 가시성과 조사 범위가 난이도를 결정함 | I6: 1 | J6: 소파 옆 주인공에서 조사 입력 1회 완료 | K6: - | L6: 20초 | M6: 첫 상호작용 대상에 반짝임 표시 | N6: =N5+(IFERROR(VALUE(LEFT(L6,FIND("분",L6)-1))*60,0)+IFERROR(VALUE(TRIM(MID(L6,IFERROR(FIND("분",L6),0)+1,IFERROR(FIND("초",L6),LEN(L6)+1)-IFERROR(FIND("분",L6),0)-1))),0))/86400 -> 0.0012731481 | O6: 1-A | 집·튜토리얼 | P6: =P5+Q6 -> 6 | Q6: 2 | R6: =ROUND($Q$3*P6*P6+$R$3*P6,2) -> 2.7 | S6: 비전투 | T6: — | U6: — | V6: — | W6: 0.00028935185 | X6: 0.00028935185 | Y6: 0.00023148148 | AD6: -
A7: 1 | 동생 심부름 | B7: 3 | C7: 1 | D7: 5 | E7: 동생에게 심부름 지시 받기 | F7: 대화 속에 다음 목적지와 필요한 물품 정보가 섞여 있음 | G7: 강조되는 핵심 단어와 NPC의 요구를 확인하며 대화를 끝까지 진행함 | H7: 1/10 – 대사 길이·핵심 정보의 명확성·선택지 수가 난이도를 결정함 | I7: 1 | J7: 신상 과자·헤어롤·팝콘 심부름에 관한 대화를 마지막 문장까지 진행 | K7: - | L7: 1분 | M7: 대화 종료 후 핵심 내용을 화면 한쪽에 요약 표시 | N7: =N6+(IFERROR(VALUE(LEFT(L7,FIND("분",L7)-1))*60,0)+IFERROR(VALUE(TRIM(MID(L7,IFERROR(FIND("분",L7),0)+1,IFERROR(FIND("초",L7),LEN(L7)+1)-IFERROR(FIND("분",L7),0)-1))),0))/86400 -> 0.0019675926 | O7: 1-A | 집·튜토리얼 | P7: =P6+Q7 -> 9 | Q7: 3 | R7: =ROUND($Q$3*P7*P7+$R$3*P7,2) -> 5.4 | S7: 비전투 | T7: — | U7: — | V7: — | W7: 0.00081018519 | X7: 0.00075231481 | Y7: 0.00069444444 | AD7: -
A8: 1 | 동생 심부름 | B8: 4 | C8: 1 | D8: 3 | E8: 이동 조작 안내 확인 | F8: 여러 조작을 한 번에 제시하면 입력 방법을 혼동할 수 있음 | G8: 화면에 표시되는 키를 순서대로 입력하고 각 동작의 결과를 확인함 | H8: 1/10 – 동시에 제시되는 조작 수와 입력 허용 시간이 난이도를 결정함 | I8: 4 | J8: 상하좌우 이동과 조사 키를 안내 순서대로 모두 수행 | K8: - | L8: 40초 | M8: 입력하지 않은 키 안내를 계속 유지 | N8: =N7+(IFERROR(VALUE(LEFT(L8,FIND("분",L8)-1))*60,0)+IFERROR(VALUE(TRIM(MID(L8,IFERROR(FIND("분",L8),0)+1,IFERROR(FIND("초",L8),LEN(L8)+1)-IFERROR(FIND("분",L8),0)-1))),0))/86400 -> 0.0024305556 | O8: 1-A | 집·튜토리얼 | P8: =P7+Q8 -> 11 | Q8: 2 | R8: =ROUND($Q$3*P8*P8+$R$3*P8,2) -> 7.7 | S8: 비전투 | T8: — | U8: — | V8: — | W8: 0.0005787037 | X8: 0.00052083333 | Y8: 0.00046296296 | AD8: -
A9: 1 | 동생 심부름 | B9: 5 | C9: 1 | D9: 3 | E9: 현관으로 이동하기 | F9: 갈림길과 주변 상호작용 오브젝트 때문에 목적지 방향을 놓칠 수 있음 | G9: 표지판·미니맵·NPC 이동 방향을 확인하며 거실에서 현관문까지 이동함 | H9: 1/10 – 맵 크기·갈림길 수·목적지 표식의 가시성이 난이도를 결정함 | I9: 1 | J9: 거실에서 현관문의 도착 트리거에 진입 | K9: - | L9: 30초 | M9: 일정 시간 정체 시 목적지 방향 화살표 표시 | N9: =N8+(IFERROR(VALUE(LEFT(L9,FIND("분",L9)-1))*60,0)+IFERROR(VALUE(TRIM(MID(L9,IFERROR(FIND("분",L9),0)+1,IFERROR(FIND("초",L9),LEN(L9)+1)-IFERROR(FIND("분",L9),0)-1))),0))/86400 -> 0.0027777778 | O9: 1-A | 집·튜토리얼 | P9: =P8+Q9 -> 13 | Q9: 2 | R9: =ROUND($Q$3*P9*P9+$R$3*P9,2) -> 10.4 | S9: 비전투 | T9: — | U9: — | V9: — | W9: 0.00040509259 | X9: 0.00040509259 | Y9: 0.00034722222 | AD9: -
A10: 1 | 동생 심부름 | B10: 6 | C10: 1 | D10: 5 | E10: 집 밖으로 나가기 | F10: 조사 대상이 배경 오브젝트와 비슷해 상호작용 가능 여부를 놓칠 수 있음 | G10: 현관문 가까이 이동한 뒤 상호작용 아이콘이 나타날 때 조사함 | H10: 1/10 – 조사 대상의 크기·배경과의 대비·상호작용 범위가 난이도를 결정함 | I10: 1 | J10: 현관문 조사 완료 | K10: - | L10: 20초 | M10: 상호작용 가능 범위를 넓히고 아이콘 표시 | N10: =N9+(IFERROR(VALUE(LEFT(L10,FIND("분",L10)-1))*60,0)+IFERROR(VALUE(TRIM(MID(L10,IFERROR(FIND("분",L10),0)+1,IFERROR(FIND("초",L10),LEN(L10)+1)-IFERROR(FIND("분",L10),0)-1))),0))/86400 -> 0.0030092593 | O10: 1-A | 집·튜토리얼 | P10: =P9+Q10 -> 16 | Q10: 3 | R10: =ROUND($Q$3*P10*P10+$R$3*P10,2) -> 15.2 | S10: 비전투 | T10: — | U10: — | V10: — | W10: 0.00028935185 | X10: 0.00028935185 | Y10: 0.00023148148 | AD10: -
A11: 1 | 동생 심부름 | B11: 7 | C11: 2 | D11: 5 | E11: 편의점으로 이동하기 | F11: 갈림길과 주변 상호작용 오브젝트 때문에 목적지 방향을 놓칠 수 있음 | G11: 표지판·미니맵·NPC 이동 방향을 확인하며 아파트에서 편의점까지 이동함 | H11: 2/10 – 맵 크기·갈림길 수·목적지 표식의 가시성이 난이도를 결정함 | I11: 1 | J11: 아파트에서 편의점의 도착 트리거에 진입 | K11: - | L11: 1분 15초 | M11: 일정 시간 정체 시 목적지 방향 화살표 표시 | N11: =N10+(IFERROR(VALUE(LEFT(L11,FIND("분",L11)-1))*60,0)+IFERROR(VALUE(TRIM(MID(L11,IFERROR(FIND("분",L11),0)+1,IFERROR(FIND("초",L11),LEN(L11)+1)-IFERROR(FIND("분",L11),0)-1))),0))/86400 -> 0.0038773148 | O11: 1-B | 편의점 | P11: =P10+Q11 -> 19 | Q11: 3 | R11: =ROUND($Q$3*P11*P11+$R$3*P11,2) -> 20.9 | S11: 비전투 | T11: — | U11: — | V11: — | W11: 0.0010416667 | X11: 0.00092592593 | Y11: 0.00086805556 | AD11: -
A12: 1 | 동생 심부름 | B12: 8 | C12: 2 | D12: 6 | E12: 신상 과자 진열대 찾기 | F12: 비슷한 오브젝트와 진열대가 많아 목표 대상을 한 번에 찾기 어려움 | G12: 구역별 표지와 상품 외형을 비교하며 편의점 안 신상 과자 진열대를 조사함 | H12: 3/10 – 후보 오브젝트 수·외형 유사도·탐색 범위가 난이도를 결정함 | I12: 4 | J12: 편의점 안 신상 과자 진열대 발견 및 조사 완료 | K12: - | L12: 1분 30초 | M12: 30초 이상 미발견 시 목표 구역에 약한 반짝임 표시 | N12: =N11+(IFERROR(VALUE(LEFT(L12,FIND("분",L12)-1))*60,0)+IFERROR(VALUE(TRIM(MID(L12,IFERROR(FIND("분",L12),0)+1,IFERROR(FIND("초",L12),LEN(L12)+1)-IFERROR(FIND("분",L12),0)-1))),0))/86400 -> 0.0049189815 | O12: 1-B | 편의점 | P12: =P11+Q12 -> 23 | Q12: 4 | R12: =ROUND($Q$3*P12*P12+$R$3*P12,2) -> 29.9 | S12: 비전투 | T12: — | U12: — | V12: — | W12: 0.0012152778 | X12: 0.001099537 | Y12: 0.0010416667 | AD12: -
A13: 1 | 동생 심부름 | B13: 9 | C13: 1 | D13: 5 | E13: 품절 안내 조사하기 | F13: 조사 대상이 배경 오브젝트와 비슷해 상호작용 가능 여부를 놓칠 수 있음 | G13: 비어 있는 진열칸과 손글씨 품절 안내 가까이 이동한 뒤 상호작용 아이콘이 나타날 때 조사함 | H13: 2/10 – 조사 대상의 크기·배경과의 대비·상호작용 범위가 난이도를 결정함 | I13: 2 | J13: 비어 있는 진열칸과 손글씨 품절 안내 조사 완료 | K13: - | L13: 35초 | M13: 상호작용 가능 범위를 넓히고 아이콘 표시 | N13: =N12+(IFERROR(VALUE(LEFT(L13,FIND("분",L13)-1))*60,0)+IFERROR(VALUE(TRIM(MID(L13,IFERROR(FIND("분",L13),0)+1,IFERROR(FIND("초",L13),LEN(L13)+1)-IFERROR(FIND("분",L13),0)-1))),0))/86400 -> 0.0053240741 | O13: 1-B | 편의점 | P13: =P12+Q13 -> 25 | Q13: 2 | R13: =ROUND($Q$3*P13*P13+$R$3*P13,2) -> 35 | S13: 비전투 | T13: — | U13: — | V13: — | W13: 0.00052083333 | X13: 0.00046296296 | Y13: 0.00040509259 | AD13: -
A14: 1 | 동생 심부름 | B14: 10 | C14: 1 | D14: 6 | E14: 알바생 NPC와 대화하기 | F14: 대화 속에 다음 목적지와 필요한 물품 정보가 섞여 있음 | G14: 강조되는 핵심 단어와 NPC의 요구를 확인하며 대화를 끝까지 진행함 | H14: 2/10 – 대사 길이·핵심 정보의 명확성·선택지 수가 난이도를 결정함 | I14: 1 | J14: 재입고 시간과 물류 트럭 정보에 관한 대화를 마지막 문장까지 진행 | K14: - | L14: 1분 15초 | M14: 대화 종료 후 핵심 내용을 화면 한쪽에 요약 표시 | N14: =N13+(IFERROR(VALUE(LEFT(L14,FIND("분",L14)-1))*60,0)+IFERROR(VALUE(TRIM(MID(L14,IFERROR(FIND("분",L14),0)+1,IFERROR(FIND("초",L14),LEN(L14)+1)-IFERROR(FIND("분",L14),0)-1))),0))/86400 -> 0.0061921296 | O14: 1-B | 편의점 | P14: =P13+Q14 -> 28 | Q14: 3 | R14: =ROUND($Q$3*P14*P14+$R$3*P14,2) -> 43.4 | S14: 비전투 | T14: — | U14: — | V14: — | W14: 0.0010416667 | X14: 0.00092592593 | Y14: 0.00086805556 | AD14: -
A15: 1 | 동생 심부름 | B15: 11 | C15: 2 | D15: 5 | E15: 다이소로 이동하기 | F15: 갈림길과 주변 상호작용 오브젝트 때문에 목적지 방향을 놓칠 수 있음 | G15: 표지판·미니맵·NPC 이동 방향을 확인하며 편의점에서 다이소까지 이동함 | H15: 2/10 – 맵 크기·갈림길 수·목적지 표식의 가시성이 난이도를 결정함 | I15: 1 | J15: 편의점에서 다이소의 도착 트리거에 진입 | K15: - | L15: 1분 30초 | M15: 일정 시간 정체 시 목적지 방향 화살표 표시 | N15: =N14+(IFERROR(VALUE(LEFT(L15,FIND("분",L15)-1))*60,0)+IFERROR(VALUE(TRIM(MID(L15,IFERROR(FIND("분",L15),0)+1,IFERROR(FIND("초",L15),LEN(L15)+1)-IFERROR(FIND("분",L15),0)-1))),0))/86400 -> 0.0072337963 | O15: 1-C | 다이소 | P15: =P14+Q15 -> 31 | Q15: 3 | R15: =ROUND($Q$3*P15*P15+$R$3*P15,2) -> 52.7 | S15: 비전투 | T15: — | U15: — | V15: — | W15: 0.0012152778 | X15: 0.001099537 | Y15: 0.0010416667 | AD15: -
A16: 1 | 동생 심부름 | B16: 12 | C16: 2 | D16: 6 | E16: 헤어롤 진열대 찾기 | F16: 비슷한 오브젝트와 진열대가 많아 목표 대상을 한 번에 찾기 어려움 | G16: 구역별 표지와 상품 외형을 비교하며 생활용품 코너의 헤어롤을 조사함 | H16: 3/10 – 후보 오브젝트 수·외형 유사도·탐색 범위가 난이도를 결정함 | I16: 5 | J16: 생활용품 코너의 헤어롤 발견 및 조사 완료 | K16: - | L16: 1분 50초 | M16: 30초 이상 미발견 시 목표 구역에 약한 반짝임 표시 | N16: =N15+(IFERROR(VALUE(LEFT(L16,FIND("분",L16)-1))*60,0)+IFERROR(VALUE(TRIM(MID(L16,IFERROR(FIND("분",L16),0)+1,IFERROR(FIND("초",L16),LEN(L16)+1)-IFERROR(FIND("분",L16),0)-1))),0))/86400 -> 0.0085069444 | O16: 1-C | 다이소 | P16: =P15+Q16 -> 35 | Q16: 4 | R16: =ROUND($Q$3*P16*P16+$R$3*P16,2) -> 66.5 | S16: 비전투 | T16: — | U16: — | V16: — | W16: 0.0015046296 | X16: 0.0013888889 | Y16: 0.0012731481 | AD16: -
A17: 1 | 동생 심부름 | B17: 13 | C17: 1 | D17: 5 | E17: 헤어롤 구매하기 | F17: 구매 대상·수량·결제 순서를 잘못 선택할 수 있음 | G17: 요청받은 품목을 확인하고 상품 선택→계산대 상호작용→결제를 순서대로 진행함 | H17: 2/10 – 상품 후보 수·품목 유사도·구매 단계 수가 난이도를 결정함 | I17: 3 | J17: 헤어롤 1개 구매 후 인벤토리에 등록 | K17: 잘못된 품목 구매 시 다시 선택해야 함 | L17: 50초 | M17: 요청 품목에 작은 임무 아이콘 표시 | N17: =N16+(IFERROR(VALUE(LEFT(L17,FIND("분",L17)-1))*60,0)+IFERROR(VALUE(TRIM(MID(L17,IFERROR(FIND("분",L17),0)+1,IFERROR(FIND("초",L17),LEN(L17)+1)-IFERROR(FIND("분",L17),0)-1))),0))/86400 -> 0.0090856481 | O17: 1-C | 다이소 | P17: =P16+Q17 -> 37 | Q17: 2 | R17: =ROUND($Q$3*P17*P17+$R$3*P17,2) -> 74 | S17: 비전투 | T17: — | U17: — | V17: — | W17: 0.00069444444 | X17: 0.00063657407 | Y17: 0.0005787037 | AD17: -
... A40: 2 | 공원 청소 | B40: 36 | C40: 3 | D40: 6 | E40: 벤치 주변 쓰레기 수거하기 | F40: 쓰레기가 넓은 구역과 가려진 틈에 흩어져 있어 남은 대상을 찾기 어려움 | G40: 구역을 일정한 방향으로 순회하고 반짝임·잔여 개수 UI를 확인하며 벤치와 가려진 틈의 쓰레기 6개를 수거함 | H40: 5/10 – 목표 수량·배치 밀도·가림 오브젝트·탐색 범위가 난이도를 결정함 | I40: 6 | J40: 벤치와 가려진 틈의 쓰레기 6개 전부 수거 | K40: 필수 수량을 채우지 못하면 다음 구역 진행 불가 | L40: 2분 30초 | M40: 60초 이상 미발견 시 가장 가까운 미수거 대상 방향 표시 | N40: =N39+(IFERROR(VALUE(LEFT(L40,FIND("분",L40)-1))*60,0)+IFERROR(VALUE(TRIM(MID(L40,IFERROR(FIND("분",L40),0)+1,IFERROR(FIND("초",L40),LEN(L40)+1)-IFERROR(FIND("분",L40),0)-1))),0))/86400 -> 0.033622685 | O40: 2-A | 공원 축제·청소 | P40: =P39+Q40 -> 126 | Q40: 5 | R40: =ROUND($Q$3*P40*P40+$R$3*P40,2) -> 812.7 | S40: 비전투 | T40: — | U40: — | V40: — | W40: 0.0023726852 | X40: 0.002025463 | Y40: 0.0017361111 | AD40: -
A41: 2 | 공원 청소 | B41: 37 | C41: 1 | D41: 5 | E41: 한도윤과 대화하기 | F41: 대화 속에 다음 목적지와 필요한 물품 정보가 섞여 있음 | G41: 강조되는 핵심 단어와 NPC의 요구를 확인하며 대화를 끝까지 진행함 | H41: 2/10 – 대사 길이·핵심 정보의 명확성·선택지 수가 난이도를 결정함 | I41: 1 | J41: 혼자 청소하는 이유와 도움 제안에 관한 대화를 마지막 문장까지 진행 | K41: - | L41: 1분 30초 | M41: 대화 종료 후 핵심 내용을 화면 한쪽에 요약 표시 | N41: =N40+(IFERROR(VALUE(LEFT(L41,FIND("분",L41)-1))*60,0)+IFERROR(VALUE(TRIM(MID(L41,IFERROR(FIND("분",L41),0)+1,IFERROR(FIND("초",L41),LEN(L41)+1)-IFERROR(FIND("분",L41),0)-1))),0))/86400 -> 0.034664352 | O41: 2-A | 공원 축제·청소 | P41: =P40+Q41 -> 128 | Q41: 2 | R41: =ROUND($Q$3*P41*P41+$R$3*P41,2) -> 838.4 | S41: 비전투 | T41: — | U41: — | V41: — | W41: 0.0012152778 | X41: 0.001099537 | Y41: 0.0010416667 | AD41: - | AE41: [한도윤] +5%
A42: 2 | 공원 청소 | B42: 38 | C42: 2 | D42: 5 | E42: 한도윤과 구역 분담하기 | F42: 동료가 담당하는 구역과 플레이어 구역이 겹치면 불필요한 이동이 발생함 | G42: 대화에서 정한 담당 구역을 확인하고 서로 다른 공원 구역를 순서대로 처리함 | H42: 4/10 – 구역 수·동료 행동 예측 가능성·이동 동선이 난이도를 결정함 | I42: 4 | J42: 플레이어 담당 구역의 목표 수량 달성 | K42: - | L42: 2분 20초 | M42: 미니맵에 담당 구역을 서로 다른 테두리로 표시 | N42: =N41+(IFERROR(VALUE(LEFT(L42,FIND("분",L42)-1))*60,0)+IFERROR(VALUE(TRIM(MID(L42,IFERROR(FIND("분",L42),0)+1,IFERROR(FIND("초",L42),LEN(L42)+1)-IFERROR(FIND("분",L42),0)-1))),0))/86400 -> 0.036284722 | O42: 2-A | 공원 축제·청소 | P42: =P41+Q42 -> 131 | Q42: 3 | R42: =ROUND($Q$3*P42*P42+$R$3*P42,2) -> 877.7 | S42: 비전투 | T42: — | U42: — | V42: — | W42: 0.0019097222 | X42: 0.0017361111 | Y42: 0.0016203704 | AD42: -
A43: 2 | 공원 청소 | B43: 39 | C43: 4 | D43: 8 | E43: 청소 콤보 유지하기 | F43: 서로 다른 쓰레기를 연속으로 정확히 주워야 콤보가 유지되며 잘못 집으면 게이지가 초기화됨 | G43: 가까운 쓰레기의 종류와 다음 분리수거 위치를 미리 확인해 이동 동선을 끊지 않고 수거함 | H43: 4/10 – 콤보 유지 시간·쓰레기 간 거리·오분류 페널티가 난이도를 결정함 | I43: 12 | J43: 정확 수거 콤보 12회를 달성 | K43: 오분류 시 콤보만 초기화되고 수거 진행도는 유지 | L43: 2분 | M43: 콤보 실패 후 다음 3개 쓰레기의 분류 아이콘을 미리 표시 | N43: =N42+(IFERROR(VALUE(LEFT(L43,FIND("분",L43)-1))*60,0)+IFERROR(VALUE(TRIM(MID(L43,IFERROR(FIND("분",L43),0)+1,IFERROR(FIND("초",L43),LEN(L43)+1)-IFERROR(FIND("분",L43),0)-1))),0))/86400 -> 0.037673611 | O43: 2-A | 공원 축제·청소 | P43: =P42+Q43 -> 138 | Q43: 7 | R43: =ROUND($Q$3*P43*P43+$R$3*P43,2) -> 972.9 | S43: 비전투 | T43: — | U43: — | V43: — | W43: 0.0019097222 | X43: 0.0016203704 | Y43: 0.0013888889 | AD43: -
A44: 2 | 공원 청소 | B44: 40 | C44: 2 | D44: 6 | E44: 우정 반지 단서 발견하기 | F44: 작은 단서가 쓰레기와 배경에 섞여 있어 일반 수거물로 오인할 수 있음 | G44: 중학생이 잃어버린 반지의 흔적의 형태와 주변 대사를 확인하고 별도 조사함 | H44: 4/10 – 단서 크기·배경 대비·오인 가능성이 난이도를 결정함 | I44: 3 | J44: 필수 단서 모두 조사 | K44: 단서를 버리려 하면 경고 후 행동 취소 | L44: 1분 15초 | M44: 단서에 일반 쓰레기와 다른 약한 빛 효과 적용 | N44: =N43+(IFERROR(VALUE(LEFT(L44,FIND("분",L44)-1))*60,0)+IFERROR(VALUE(TRIM(MID(L44,IFERROR(FIND("분",L44),0)+1,IFERROR(FIND("초",L44),LEN(L44)+1)-IFERROR(FIND("분",L44),0)-1))),0))/86400 -> 0.038541667 | O44: 2-A | 공원 축제·청소 | P44: =P43+Q44 -> 142 | Q44: 4 | R44: =ROUND($Q$3*P44*P44+$R$3*P44,2) -> 1029.5 | S44: 비전투 | T44: — | U44: — | V44: — | W44: 0.0010416667 | X44: 0.00092592593 | Y44: 0.00086805556 | AD44: -
A45: 2 | 공원 청소 | B45: 41 | C45: 4 | D45: 8 | E45: 발자국과 스티커 단서 대조하기 | F45: 비슷한 운동화 자국과 축제 스티커가 여러 방향으로 이어져 잘못된 동선을 선택하기 쉬움 | G45: 반지에 묻은 흙·신발 자국·가방 스티커를 비교해 중학생이 지나간 경로를 좁힘 | H45: 4/10 – 후보 경로 수·단서 유사도·비교 단계 수가 난이도를 결정함 | I45: 4 | J45: 세 단서를 연결해 올바른 탐색 구역 선택 | K45: 오답 경로 선택 시 불필요한 탐색 시간이 추가됨 | L45: 2분 | M45: 오답 후 일치하지 않는 단서 하나에 취소 표시 | N45: =N44+(IFERROR(VALUE(LEFT(L45,FIND("분",L45)-1))*60,0)+IFERROR(VALUE(TRIM(MID(L45,IFERROR(FIND("분",L45),0)+1,IFERROR(FIND("초",L45),LEN(L45)+1)-IFERROR(FIND("분",L45),0)-1))),0))/86400 -> 0.039930556 | O45: 2-A | 공원 축제·청소 | P45: =P44+Q45 -> 149 | Q45: 7 | R45: =ROUND($Q$3*P45*P45+$R$3*P45,2) -> 1132.4 | S45: 비전투 | T45: — | U45: — | V45: — | W45: 0.0019097222 | X45: 0.0016203704 | Y45: 0.0013888889 | AD45: -
A46: 2 | 공원 청소 | B46: 42 | C46: 3 | D46: 7 | E46: 우정 반지 찾기 | F46: 목표물이 작고 수거 가능한 쓰레기 사이에 섞여 있어 탐색 부담이 큼 | G46: 마지막 목격 위치와 반짝임 주기를 이용해 쓰레기 사이에 섞인 작은 반지를 찾음 | H46: 6/10 – 목표물 크기·탐색 범위·가짜 후보 수가 난이도를 결정함 | I46: 5 | J46: 쓰레기 사이에 섞인 작은 반지 발견 후 획득 | K46: - | L46: 2분 50초 | M46: 90초 이상 미발견 시 탐색 범위를 단계적으로 축소 | N46: =N45+(IFERROR(VALUE(LEFT(L46,FIND("분",L46)-1))*60,0)+IFERROR(VALUE(TRIM(MID(L46,IFERROR(FIND("분",L46),0)+1,IFERROR(FIND("초",L46),LEN(L46)+1)-IFERROR(FIND("분",L46),0)-1))),0))/86400 -> 0.041898148 | O46: 2-A | 공원 축제·청소 | P46: =P45+Q46 -> 154 | Q46: 5 | R46: =ROUND($Q$3*P46*P46+$R$3*P46,2) -> 1208.9 | S46: 비전투 | T46: — | U46: — | V46: — | W46: 0.002662037 | X46: 0.0023148148 | Y46: 0.0019675926 | AD46: -
A47: 2 | 공원 청소 | B47: 43 | C47: 1 | D47: 8 | E47: 중학생에게 반지 전달하기 | F47: 비슷한 복장의 NPC가 있어 물건의 주인을 잘못 선택할 수 있음 | G47: 의뢰 대사와 위치를 확인한 뒤 반지의 주인에게 전달함 | H47: 2/10 – NPC 후보 수·위치 이동 여부·의뢰 단서 명확성이 난이도를 결정함 | I47: 2 | J47: 올바른 NPC에게 물품 전달 | K47: 오답 NPC 선택 시 전달이 취소되고 다시 선택 | L47: 1분 10초 | M47: 의뢰 NPC 머리 위에 약한 대화 아이콘 표시 | N47: =N46+(IFERROR(VALUE(LEFT(L47,FIND("분",L47)-1))*60,0)+IFERROR(VALUE(TRIM(MID(L47,IFERROR(FIND("분",L47),0)+1,IFERROR(FIND("초",L47),LEN(L47)+1)-IFERROR(FIND("분",L47),0)-1))),0))/86400 -> 0.042708333 | O47: 2-A | 공원 축제·청소 | P47: =P46+Q47 -> 158 | Q47: 4 | R47: =ROUND($Q$3*P47*P47+$R$3*P47,2) -> 1271.9 | S47: 비전투 | T47: — | U47: — | V47: — | W47: 0.0009837963 | X47: 0.00086805556 | Y47: 0.00081018519 | AD47: - | AE47: [도시] +5%
A48: 2 | 공원 청소 | B48: 44 | C48: 1 | D48: 5 | E48: 남은 쓰레기 확인하기 | F48: 완료한 것처럼 보여도 남은 대상이나 오분류 항목이 존재할 수 있음 | G48: 잔여 수량과 각 구역 상태를 확인해 공원 미수거 구역과 남은 수량의 미완료 항목을 점검함 | H48: 4/10 – 검사 항목 수·오류 위치의 분산 정도가 난이도를 결정함 | I48: 4 | J48: 잔여 수량 0 및 오류 항목 0 | K48: 조건 미달 시 완료 상호작용이 비활성화됨 | L48: 1분 30초 | M48: 미완료 구역과 오류 수량을 별도 UI로 표시 | N48: =N47+(IFERROR(VALUE(LEFT(L48,FIND("분",L48)-1))*60,0)+IFERROR(VALUE(TRIM(MID(L48,IFERROR(FIND("분",L48),0)+1,IFERROR(FIND("초",L48),LEN(L48)+1)-IFERROR(FIND("분",L48),0)-1))),0))/86400 -> 0.04375 | O48: 2-A | 공원 축제·청소 | P48: =P47+Q48 -> 160 | Q48: 2 | R48: =ROUND($Q$3*P48*P48+$R$3*P48,2) -> 1304 | S48: 비전투 | T48: — | U48: — | V48: — | W48: 0.0012152778 | X48: 0.001099537 | Y48: 0.0010416667 | AD48: -
A49: 2 | 공원 청소 | B49: 45 | C49: 2 | D49: 6 | E49: 분리수거장으로 이동하기 | F49: 갈림길과 주변 상호작용 오브젝트 때문에 목적지 방향을 놓칠 수 있음 | G49: 표지판·미니맵·NPC 이동 방향을 확인하며 공원에서 분리수거장까지 이동함 | H49: 2/10 – 맵 크기·갈림길 수·목적지 표식의 가시성이 난이도를 결정함 | I49: 1 | J49: 공원에서 분리수거장의 도착 트리거에 진입 | K49: - | L49: 1분 15초 | M49: 일정 시간 정체 시 목적지 방향 화살표 표시 | N49: =N48+(IFERROR(VALUE(LEFT(L49,FIND("분",L49)-1))*60,0)+IFERROR(VALUE(TRIM(MID(L49,IFERROR(FIND("분",L49),0)+1,IFERROR(FIND("초",L49),LEN(L49)+1)-IFERROR(FIND("분",L49),0)-1))),0))/86400 -> 0.044618056 | O49: 2-B | 분리수거장 | P49: =P48+Q49 -> 164 | Q49: 4 | R49: =ROUND($Q$3*P49*P49+$R$3*P49,2) -> 1369.4 | S49: 비전투 | T49: — | U49: — | V49: — | W49: 0.0010416667 | X49: 0.00092592593 | Y49: 0.00086805556 | AD49: -
A50: 2 | 공원 청소 | B50: 46 | C50: 2 | D50: 6 | E50: 일반쓰레기 분류하기 | F50: 외형이 비슷하거나 내용물이 남은 쓰레기는 분류 기준을 혼동하기 쉬움 | G50: 재질·오염 여부·남은 내용물을 확인하고 일반쓰레기 8개를 올바른 수거함에 넣음 | H50: 4/10 – 분류 종류 수·외형 유사도·오답 허용 횟수가 난이도를 결정함 | I50: 8 | J50: 일반쓰레기 8개 전부 올바르게 분류 | K50: 오분류 5회 누적 시 해당 분류 단계 재시작 | L50: 2분 20초 | M50: 오답 2회 후 분류 기준 그림 표시 | N50: =N49+(IFERROR(VALUE(LEFT(L50,FIND("분",L50)-1))*60,0)+IFERROR(VALUE(TRIM(MID(L50,IFERROR(FIND("분",L50),0)+1,IFERROR(FIND("초",L50),LEN(L50)+1)-IFERROR(FIND("분",L50),0)-1))),0))/86400 -> 0.046238426 | O50: 2-B | 분리수거장 | P50: =P49+Q50 -> 168 | Q50: 4 | R50: =ROUND($Q$3*P50*P50+$R$3*P50,2) -> 1436.4 | S50: 비전투 | T50: — | U50: — | V50: — | W50: 0.0019097222 | X50: 0.0017361111 | Y50: 0.0016203704 | AD50: -
A51: 2 | 공원 청소 | B51: 47 | C51: 3 | D51: 7 | E51: 재활용품 분류하기 | F51: 외형이 비슷하거나 내용물이 남은 쓰레기는 분류 기준을 혼동하기 쉬움 | G51: 재질·오염 여부·남은 내용물을 확인하고 플라스틱·캔·종이 10개를 올바른 수거함에 넣음 | H51: 6/10 – 분류 종류 수·외형 유사도·오답 허용 횟수가 난이도를 결정함 | I51: 10 | J51: 플라스틱·캔·종이 10개 전부 올바르게 분류 | K51: 오분류 5회 누적 시 해당 분류 단계 재시작 | L51: 3분 | M51: 오답 2회 후 분류 기준 그림 표시 | N51: =N50+(IFERROR(VALUE(LEFT(L51,FIND("분",L51)-1))*60,0)+IFERROR(VALUE(TRIM(MID(L51,IFERROR(FIND("분",L51),0)+1,IFERROR(FIND("초",L51),LEN(L51)+1)-IFERROR(FIND("분",L51),0)-1))),0))/86400 -> 0.048321759 | O51: 2-B | 분리수거장 | P51: =P50+Q51 -> 173 | Q51: 5 | R51: =ROUND($Q$3*P51*P51+$R$3*P51,2) -> 1522.4 | S51: 비전투 | T51: — | U51: — | V51: — | W51: 0.0028356481 | X51: 0.0024305556 | Y51: 0.0020833333 | AD51: -
A52: 2 | 공원 청소 | B52: 48 | C52: 3 | D52: 7 | E52: 오염된 쓰레기 분류하기 | F52: 외형이 비슷하거나 내용물이 남은 쓰레기는 분류 기준을 혼동하기 쉬움 | G52: 재질·오염 여부·남은 내용물을 확인하고 내용물이 남거나 오염된 쓰레기 6개를 올바른 수거함에 넣음 | H52: 7/10 – 분류 종류 수·외형 유사도·오답 허용 횟수가 난이도를 결정함 | I52: 6 | J52: 내용물이 남거나 오염된 쓰레기 6개 전부 올바르게 분류 | K52: 오분류 5회 누적 시 해당 분류 단계 재시작 | L52: 2분 40초 | M52: 오답 2회 후 분류 기준 그림 표시 | N52: =N51+(IFERROR(VALUE(LEFT(L52,FIND("분",L52)-1))*60,0)+IFERROR(VALUE(TRIM(MID(L52,IFERROR(FIND("분",L52),0)+1,IFERROR(FIND("초",L52),LEN(L52)+1)-IFERROR(FIND("분",L52),0)-1))),0))/86400 -> 0.050173611 | O52: 2-B | 분리수거장 | P52: =P51+Q52 -> 178 | Q52: 5 | R52: =ROUND($Q$3*P52*P52+$R$3*P52,2) -> 1610.9 | S52: 비전투 | T52: — | U52: — | V52: — | W52: 0.0025462963 | X52: 0.0021412037 | Y52: 0.0018518519 | AD52: -
A53: 2 | 공원 청소 | B53: 49 | C53: 5 | D53: 8 | E53: 분리수거 라인 막힘 해소하기 | F53: 한꺼번에 들어온 쓰레기로 컨베이어가 막히고 오염물이 다른 분류함으로 번짐 | G53: 막힘 원인을 먼저 제거한 뒤 제한 시간 동안 재활용·일반·세척 대상을 우선순위대로 분류함 | H53: 5/10 – 동시 등장 수·오염 확산 속도·우선순위 판단이 난이도를 결정함 | I53: 10 | J53: 막힘 제거 후 쓰레기 10개를 오분류 없이 처리 | K53: 오염도 게이지가 최대가 되면 구간 시작부터 재시작 | L53: 1분 40초 | M53: 재시도 시 컨베이어 속도를 낮추고 오염 확산 대상에 경고 테두리 표시 | N53: =N52+(IFERROR(VALUE(LEFT(L53,FIND("분",L53)-1))*60,0)+IFERROR(VALUE(TRIM(MID(L53,IFERROR(FIND("분",L53),0)+1,IFERROR(FIND("초",L53),LEN(L53)+1)-IFERROR(FIND("분",L53),0)-1))),0))/86400 -> 0.051331019 | O53: 2-B | 분리수거장 | P53: =P52+Q53 -> 185 | Q53: 7 | R53: =ROUND($Q$3*P53*P53+$R$3*P53,2) -> 1739 | S53: 비전투 | T53: — | U53: — | V53: — | W53: 0.0018518519 | X53: 0.0015046296 | Y53: 0.0011574074 | AD53: -
A54: 2 | 공원 청소 | B54: 50 | C54: 2 | D54: 7 | E54: 분리수거 완료하기 | F54: 완료한 것처럼 보여도 남은 대상이나 오분류 항목이 존재할 수 있음 | G54: 잔여 수량과 각 구역 상태를 확인해 모든 분류함과 오분류 여부의 미완료 항목을 점검함 | H54: 4/10 – 검사 항목 수·오류 위치의 분산 정도가 난이도를 결정함 | I54: 3 | J54: 잔여 수량 0 및 오류 항목 0 | K54: 조건 미달 시 완료 상호작용이 비활성화됨 | L54: 1분 10초 | M54: 미완료 구역과 오류 수량을 별도 UI로 표시 | N54: =N53+(IFERROR(VALUE(LEFT(L54,FIND("분",L54)-1))*60,0)+IFERROR(VALUE(TRIM(MID(L54,IFERROR(FIND("분",L54),0)+1,IFERROR(FIND("초",L54),LEN(L54)+1)-IFERROR(FIND("분",L54),0)-1))),0))/86400 -> 0.052141204 | O54: 2-B | 분리수거장 | P54: =P53+Q54 -> 189 | Q54: 4 | R54: =ROUND($Q$3*P54*P54+$R$3*P54,2) -> 1814.4 | S54: 비전투 | T54: — | U54: — | V54: — | W54: 0.0009837963 | X54: 0.00086805556 | Y54: 0.00081018519 | AD54: -
A55: 2 | 공원 청소 | B55: 51 | C55: 1 | D55: 9 | E55: 균열 발생을 목격하기 | F55: 짧은 연출 안에서 사건의 원인과 인물의 태도를 동시에 이해해야 함 | G55: 카메라가 강조하는 인물과 오브젝트를 보며 분리수거장 바닥에서 열리는 도덕 균열를 확인함 | H55: 1/10 – 연출 속도·동시에 제시되는 정보량이 난이도를 결정함 | I55: 1 | J55: 사건 연출 종료 | K55: - | L55: 50초 | M55: 핵심 오브젝트에 카메라 줌과 효과음 적용 | N55: =N54+(IFERROR(VALUE(LEFT(L55,FIND("분",L55)-1))*60,0)+IFERROR(VALUE(TRIM(MID(L55,IFERROR(FIND("분",L55),0)+1,IFERROR(FIND("초",L55),LEN(L55)+1)-IFERROR(FIND("분",L55),0)-1))),0))/86400 -> 0.052719907 | O55: 2-C | 균열 발생 | P55: =P54+Q55 -> 193 | Q55: 4 | R55: =ROUND($Q$3*P55*P55+$R$3*P55,2) -> 1891.4 | S55: 비전투 | T55: — | U55: — | V55: — | W55: 0.00069444444 | X55: 0.00063657407 | Y55: 0.0005787037 | AD55: -
A56: 2 | 공원 청소 | B56: 52 | C56: 2 | D56: 9 | E56: 균열 구경하기 | F56: 중요한 단서가 여러 인물과 배경 오브젝트 사이에 분산되어 있음 | G56: 시선·행동·복장·주변 오브젝트를 순서대로 확인해 균열의 빛·소리·주변 반응의 특징을 파악함 | H56: 4/10 – 관찰 대상 수·단서의 명확성·외형 유사도가 난이도를 결정함 | I56: 3 | J56: 필수 관찰 대상 모두 조사 | K56: - | L56: 1분 35초 | M56: 필수 대상 위에 짧은 시선 유도 아이콘 표시 | N56: =N55+(IFERROR(VALUE(LEFT(L56,FIND("분",L56)-1))*60,0)+IFERROR(VALUE(TRIM(MID(L56,IFERROR(FIND("분",L56),0)+1,IFERROR(FIND("초",L56),LEN(L56)+1)-IFERROR(FIND("분",L56),0)-1))),0))/86400 -> 0.053819444 | O56: 2-C | 균열 발생 | P56: =P55+Q56 -> 198 | Q56: 5 | R56: =ROUND($Q$3*P56*P56+$R$3*P56,2) -> 1989.9 | S56: 비전투 | T56: — | U56: — | V56: — | W56: 0.0012731481 | X56: 0.0011574074 | Y56: 0.001099537 | AD56: -
A57: 2 | 공원 청소 | B57: 53 | C57: 2 | D57: 5 | E57: 집으로 귀가하기 | F57: 갈림길과 주변 상호작용 오브젝트 때문에 목적지 방향을 놓칠 수 있음 | G57: 표지판·미니맵·NPC 이동 방향을 확인하며 공원에서 집까지 이동함 | H57: 2/10 – 맵 크기·갈림길 수·목적지 표식의 가시성이 난이도를 결정함 | I57: 1 | J57: 공원에서 집의 도착 트리거에 진입 | K57: - | L57: 2분 | M57: 일정 시간 정체 시 목적지 방향 화살표 표시 | N57: =N56+(IFERROR(VALUE(LEFT(L57,FIND("분",L57)-1))*60,0)+IFERROR(VALUE(TRIM(MID(L57,IFERROR(FIND("분",L57),0)+1,IFERROR(FIND("초",L57),LEN(L57)+1)-IFERROR(FIND("분",L57),0)-1))),0))/86400 -> 0.055208333 | O57: 2-D | 귀가·밤 | P57: =P56+Q57 -> 201 | Q57: 3 | R57: =ROUND($Q$3*P57*P57+$R$3*P57,2) -> 2050.2 | S57: 비전투 | T57: — | U57: — | V57: — | W57: 0.0016203704 | X57: 0.0015046296 | Y57: 0.0013888889 | AD57: -
A58: 2 | 공원 청소 | B58: 54 | C58: 1 | D58: 5 | E58: 잠자기 | F58: 다음 날로 넘어가는 상호작용임을 알아차리지 못할 수 있음 | G58: 침대를 조사하고 휴식 확인 선택지를 선택함 | H58: 1/10 – 상호작용 대상의 명확성이 난이도를 결정함 | I58: 1 | J58: 잠자기 확인 후 다음 장면 전환 | K58: - | L58: 35초 | M58: 침대에 임무 아이콘 표시 | N58: =N57+(IFERROR(VALUE(LEFT(L58,FIND("분",L58)-1))*60,0)+IFERROR(VALUE(TRIM(MID(L58,IFERROR(FIND("분",L58),0)+1,IFERROR(FIND("초",L58),LEN(L58)+1)-IFERROR(FIND("분",L58),0)-1))),0))/86400 -> 0.055613426 | O58: 2-D | 귀가·밤 | P58: =P57+Q58 -> 203 | Q58: 2 | R58: =ROUND($Q$3*P58*P58+$R$3*P58,2) -> 2090.9 | S58: 비전투 | T58: — | U58: — | V58: — | W58: 0.00052083333 | X58: 0.00046296296 | Y58: 0.00040509259 | AD58: -
A59: 3 | 재난 대응 | B59: 55 | C59: 1 | D59: 6 | E59: 새벽 재난 문자 확인하기 | F59: 재난 문자와 주변 효과음이 동시에 출력되어 핵심 행동을 놓칠 수 있음 | G59: 균열 인근 대피 안내의 대피 위치와 위험 지역을 먼저 확인함 | H59: 2/10 – 동시 정보량·경고 문구의 명확성이 난이도를 결정함 | I59: 2 | J59: 재난 문자 핵심 항목 확인 | K59: - | L59: 40초 | M59: 문자를 닫은 뒤 화면에 대피 목표를 고정 표시 | N59: =N58+(IFERROR(VALUE(LEFT(L59,FIND("분",L59)-1))*60,0)+IFERROR(VALUE(TRIM(MID(L59,IFERROR(FIND("분",L59),0)+1,IFERROR(FIND("초",L59),LEN(L59)+1)-IFERROR(FIND("분",L59),0)-1))),0))/86400 -> 0.056076389 | O59: 3-A | 아파트 재난 | P59: =P58+Q59 -> 206 | Q59: 3 | R59: =ROUND($Q$3*P59*P59+$R$3*P59,2) -> 2152.7 | S59: 비전투 | T59: — | U59: — | V59: — | W59: 0.0005787037 | X59: 0.00052083333 | Y59: 0.00046296296 | AD59: -
... A63: 3 | 재난 대응 | B63: 59 | C63: 4 | D63: 8 | E63: 아파트 계단으로 이동하기 | F63: 좁은 통로·어두운 조명·장애물로 이동 경로가 제한됨 | G63: 손전등과 안전한 발판을 확인하며 정전된 계단을 통과함 | H63: 5/10 – 통로 폭·시야 범위·장애물 간격이 난이도를 결정함 | I63: 1 | J63: 다음 층 도착 트리거 진입 | K63: 낙하 또는 장애물 피격 3회 시 구간 재시작 | L63: 1분 35초 | M63: 안전 발판 테두리와 체크포인트 제공 | N63: =N62+(IFERROR(VALUE(LEFT(L63,FIND("분",L63)-1))*60,0)+IFERROR(VALUE(TRIM(MID(L63,IFERROR(FIND("분",L63),0)+1,IFERROR(FIND("초",L63),LEN(L63)+1)-IFERROR(FIND("분",L63),0)-1))),0))/86400 -> 0.061226852 | O63: 3-B | 대피 경로 | P63: =P62+Q63 -> 230 | Q63: 7 | R63: =ROUND($Q$3*P63*P63+$R$3*P63,2) -> 2679.5 | S63: 비전투 | T63: — | U63: — | V63: — | W63: 0.0015046296 | X63: 0.0012731481 | Y63: 0.001099537 | AD63: -
A64: 3 | 재난 대응 | B64: 60 | C64: 5 | D64: 9 | E64: 이웃 주민 구조하기 | F64: 위험이 지속되는 동안 대상 상태를 확인하고 구조 행동을 여러 번 수행해야 함 | G64: 위험 패턴이 멈춘 순간에 접근해 계단에 쓰러진 이웃 주민를 안전 지점으로 옮김 | H64: 7/10 – 위험 주기·대상 체력·이동 거리·구조 단계 수가 난이도를 결정함 | I64: 3 | J64: 구조 대상이 안전 지점 도착 | K64: 구조 대상 체력이 0이 되면 체크포인트 재시작 | L64: 3분 | M64: 대상 체력 경고와 안전 경로 표시 | N64: =N63+(IFERROR(VALUE(LEFT(L64,FIND("분",L64)-1))*60,0)+IFERROR(VALUE(TRIM(MID(L64,IFERROR(FIND("분",L64),0)+1,IFERROR(FIND("초",L64),LEN(L64)+1)-IFERROR(FIND("분",L64),0)-1))),0))/86400 -> 0.063310185 | O64: 3-B | 대피 경로 | P64: =P63+Q64 -> 237 | Q64: 7 | R64: =ROUND($Q$3*P64*P64+$R$3*P64,2) -> 2844 | S64: 비전투 | T64: — | U64: — | V64: — | W64: 0.0033564815 | X64: 0.0027199074 | Y64: 0.0020833333 | AD64: - | AE64: [도시] +5%
A65: 3 | 재난 대응 | B65: 61 | C65: 5 | D65: 9 | E65: 아파트 밖으로 탈출하기 | F65: 출구가 무너지고 안전 경로가 짧은 시간마다 바뀜 | G65: 붕괴 경고 표시를 보고 붕괴되는 출입구의 열린 통로로 빠르게 이동함 | H65: 7/10 – 제한시간·안전 경로 폭·장애물 발생 주기가 난이도를 결정함 | I65: 1 | J65: 제한시간 안에 탈출 지점 도착 | K65: 제한시간 종료 또는 3회 피격 시 재시작 | L65: 2분 20초 | M65: 실패 후 제한시간 10초 증가 | N65: =N64+(IFERROR(VALUE(LEFT(L65,FIND("분",L65)-1))*60,0)+IFERROR(VALUE(TRIM(MID(L65,IFERROR(FIND("분",L65),0)+1,IFERROR(FIND("초",L65),LEN(L65)+1)-IFERROR(FIND("분",L65),0)-1))),0))/86400 -> 0.064930556 | O65: 3-B | 대피 경로 | P65: =P64+Q65 -> 244 | Q65: 7 | R65: =ROUND($Q$3*P65*P65+$R$3*P65,2) -> 3013.4 | S65: 비전투 | T65: — | U65: — | V65: — | W65: 0.0026041667 | X65: 0.0021412037 | Y65: 0.0016203704 | AD65: -
...

Sheet 밸런스 팩터
B2: 밸런스 팩터
B4: 게임 「넌 착해!」의 플레이 경험에 영향을 주는 주요 조정 요소를 원형으로 정리
B70: 큰 원은 플레이 전반에 미치는 영향이 큰 핵심 팩터이며, 작은 원은 장면·미션 단위에서 조정하는 세부 팩터임

Sheet 작성 기준
A1: 밸런스 문서 작성 기준
A3: 항목 | B3: 작성 방식 | C3: 값/형식 | D3: 우리 게임 적용 기준
A4: 조작난이도 | B4: 플레이어가 실제 입력을 수행할 때 느끼는 손 조작의 어려움 | C4: 1~10 숫자 | D4: 1은 단순 확인·대화, 10은 빠른 보스 패턴과 복합 입력
A5: 재미율 | B5: 기획자가 해당 구간이 이 정도로 재미있기를 기대하며 정하는 정성적 목표값 | C5: 1~10 숫자 | D5: 탐색·긴장·감정·반전·성취를 모두 포함하며 실제 테스트값이 아님
A6: 컨텐츠 제시순서 | B6: 게임 시작부터 엔딩까지 해금되는 모든 플레이 내용을 순서대로 기록 | C6: 1부터 연속 넘버링 | D6: UI 미션뿐 아니라 이동·조사·대화·전투·업적성 행동·연출 확인까지 포함
A7: 미션 | B7: 제목만 읽어도 플레이어가 무엇을 해야 하는지 보이도록 작성 | C7: 행동형 제목 | D7: 예: 신상 과자 진열대 찾기, 균열 괴물과 첫 전투 치르기
A8: 방해요소 | B8: 목표를 바로 달성하지 못하게 만드는 맵·NPC·시간·정보·전투 요소 | C8: 구체적 서술 | D8: 비슷한 후보, 넓은 탐색 범위, 제한시간, 시야 차단, 감정적 압박 등
A9: 방해요소 공략 | B9: 방해요소를 해결하기 위해 플레이어가 관찰·판단·조작해야 하는 내용 | C9: 구체적 플레이 절차 | D9: 이 표에서 가장 핵심적인 항목으로 작성
A10: 방해요인의 난이도 | B10: 관찰·판단·공략의 어려움과 그 난이도를 만드는 요인을 함께 기록 | C10: 숫자/10 + 원인 설명 | D10: 후보 수, 맵 크기, 속도 차이, 제한시간, 패턴 수 등
A11: 미션개수 | B11: 해당 행의 목표를 완료하기 위해 필요한 행동·대상·단계의 수 | C11: 정수 | D11: 수거 8개, 단서 5개, 대화 1회, 보스 패턴 6회 등
A12: 성공 미션조건 | B12: 시스템이 완료를 판정할 수 있는 명확한 조건 | C12: 구체적 판정 조건 | D12: 목표 수량 달성, 트리거 진입, 보스 체력 0 등
A13: 실패 미션조건 | B13: 실패가 존재하는 경우 재시작·페널티가 발생하는 조건 | C13: 구체적 판정 조건 또는 실패 없음 | D13: 추격 거리 초과, 체력 0, 제한시간 종료, 오답 누적 등
A14: 예상 플레이타임 | B14: 초회 플레이어가 해당 콘텐츠를 완료하는 데 걸릴 것으로 예상하는 시간 | C14: 초/분 | D14: L열 예상 소요 시간은 헤비 유저의 1회 성공 기준으로 작성함. W~Y열은 조작난이도와 전투 여부에 따라 라이트·미들·헤비 유저의 탐색·판단·재시도 시간을 반영함. 보스전은 대표 행에 전체 보스전 합산 시간을 표시하고 세부 패턴 행은 중복 집계하지 않음
... A17: 이동속도 B | B17: 추격 대상·동행 NPC·위협체 등 상대 캐릭터의 이동속도 | C17: 1~5 상대값 | D17: A와 B의 속도 차이가 추격·호위·회피 난이도를 결정
A18: 문서 범위 | B18: 게임 시작부터 엔딩까지 모든 콘텐츠를 작성 | C18: 최소 50개 이상 | D18: ="현재 문서에는 총 "&COUNTA('밸런스 문서'!B5:B178)&"개 콘텐츠를 기록" -> 현재 문서에는 총 174개 콘텐츠를 기록
A19: 진행 요구 숙련도 | B19: 콘텐츠 진행 포인트가 누적될수록 플레이어에게 요구되는 조작·판단·시스템 이해 수준 | C19: Y=ax²+bx / 0~10000 | D19: X는 콘텐츠 진행 포인트 누적, Y는 진행 요구 숙련도. Q3의 a와 R3의 b를 사용하며 마지막 값은 10000
A20: 전투 콘텐츠 분류 | B20: 해당 행이 비전투·튜토리얼·일반 몬스터·정예 몬스터·보스 중 무엇인지 구분 | C20: 텍스트 분류 | D20: 보스전의 준비·전투·결말 행을 구분하고 균열 수호체는 정예 몬스터로 별도 분류
A21: 권장 전투 숙련도 | B21: 해당 전투를 안정적으로 공략하기 위해 요구되는 회피·조준·기믹 이해 수준 | C21: 1~10 숫자 또는 — | D21: 일반 전투는 2~7, 보스전은 5~10 범위. 비전투 콘텐츠는 —
A22: 전투 예상 시간(초) | B22: 해당 행에서 실제 전투 조작에 사용되는 예상 시간 | C22: 초 단위 정수 또는 — | D22: 스토리 연출과 전투 후 대화는 제외하고 순수 전투·기믹 수행 시간만 기록
A23: 핵심 전투 기믹 | B23: 전투를 단순 체력 감소가 아닌 해당 콘텐츠만의 공략 규칙으로 요약 | C23: 행동 순서형 짧은 문장 | D23: 예: 돌진 유도→철문 파괴, 시민 대신 공격 받아내기, 등급 표식 해제
A24: 보스가 주는 경험치 | B24: 해당 구간 일반 몬스터 30체분의 환산 경험치를 보스 처치 보상으로 산정 | C24: 숫자 | D24: 25×30=750에서 시작해 후반 보스는 50×30=1500까지 증가
A25: 해당 레벨의 보스 분포 수 | B25: 해당 챕터에 배치된 보스 스테이지 수를 기록하며 페이즈·분열 개체 수는 중복 계산하지 않음 | C25: 정수 | D25: 재난 대응 3개, 폐교 탐색 1개, 균열의 진실 1개
A26: 보스타입 A/B 시간 | B26: AB는 근거리형 패턴 시간, AC는 원거리형 패턴 시간으로 기록하고 합계를 보스 총 전투시간으로 사용 | C26: 초 단위 정수 | D26: AB+AC는 헤비 유저 기준 보스 총 전투시간과 일치함. W·X·Y는 보스 대표 행에서 라이트·미들·헤비 유저의 전체 보스전 예상시간을 표시하며, 세부 패턴 행은 중복을 방지하기 위해 공란 처리함

Sheet 밸런스 곡선
A1: 전체 밸런스 곡선 요약
A3: 총 콘텐츠 수 | B3: =COUNTA('밸런스 문서'!B5:B178) -> 174 | C3: 평균 플레이 난이도 | D3: =AVERAGE('밸런스 문서'!C5:C178) -> 3.5689655 | E3: 평균 플레이 흥미도 | F3: =AVERAGE('밸런스 문서'!D5:D178) -> 7.8103448 | G3: 보스 스테이지 수 | H3: =COUNT('밸런스 문서'!Z5:Z178) -> 4 | I3: 총 예상 플레이 시간(헤비 기준) | J3: ='밸런스 문서'!N178 -> 0.23072917
A4: 콘텐츠 진행 순서 | B4: 콘텐츠 진행 포인트 누적 | C4: 진행 요구 숙련도 | D4: 누적 플레이 시간
A5: ='밸런스 문서'!B5 -> 1 | B5: ='밸런스 문서'!P5 -> 4 | C5: ='밸런스 문서'!R5 -> 1.4 | D5: ='밸런스 문서'!N5 -> 0.0010416667
A6: ='밸런스 문서'!B6 -> 2 | B6: ='밸런스 문서'!P6 -> 6 | C6: ='밸런스 문서'!R6 -> 2.7 | D6: ='밸런스 문서'!N6 -> 0.0012731481
A7: ='밸런스 문서'!B7 -> 3 | B7: ='밸런스 문서'!P7 -> 9 | C7: ='밸런스 문서'!R7 -> 5.4 | D7: ='밸런스 문서'!N7 -> 0.0019675926
A8: ='밸런스 문서'!B8 -> 4 | B8: ='밸런스 문서'!P8 -> 11 | C8: ='밸런스 문서'!R8 -> 7.7 | D8: ='밸런스 문서'!N8 -> 0.0024305556
A9: ='밸런스 문서'!B9 -> 5 | B9: ='밸런스 문서'!P9 -> 13 | C9: ='밸런스 문서'!R9 -> 10.4 | D9: ='밸런스 문서'!N9 -> 0.0027777778
A10: ='밸런스 문서'!B10 -> 6 | B10: ='밸런스 문서'!P10 -> 16 | C10: ='밸런스 문서'!R10 -> 15.2 | D10: ='밸런스 문서'!N10 -> 0.0030092593
A11: ='밸런스 문서'!B11 -> 7 | B11: ='밸런스 문서'!P11 -> 19 | C11: ='밸런스 문서'!R11 -> 20.9 | D11: ='밸런스 문서'!N11 -> 0.0038773148
A12: ='밸런스 문서'!B12 -> 8 | B12: ='밸런스 문서'!P12 -> 23 | C12: ='밸런스 문서'!R12 -> 29.9 | D12: ='밸런스 문서'!N12 -> 0.0049189815
A13: ='밸런스 문서'!B13 -> 9 | B13: ='밸런스 문서'!P13 -> 25 | C13: ='밸런스 문서'!R13 -> 35 | D13: ='밸런스 문서'!N13 -> 0.0053240741
A14: ='밸런스 문서'!B14 -> 10 | B14: ='밸런스 문서'!P14 -> 28 | C14: ='밸런스 문서'!R14 -> 43.4 | D14: ='밸런스 문서'!N14 -> 0.0061921296
A15: ='밸런스 문서'!B15 -> 11 | B15: ='밸런스 문서'!P15 -> 31 | C15: ='밸런스 문서'!R15 -> 52.7 | D15: ='밸런스 문서'!N15 -> 0.0072337963
A16: ='밸런스 문서'!B16 -> 12 | B16: ='밸런스 문서'!P16 -> 35 | C16: ='밸런스 문서'!R16 -> 66.5 | D16: ='밸런스 문서'!N16 -> 0.0085069444
... A178: ='밸런스 문서'!B178 -> 174 | B178: ='밸런스 문서'!P178 -> 1000 | C178: ='밸런스 문서'!R178 -> 50150 | D178: ='밸런스 문서'!N178 -> 0.23072917

Sheet 보스 설계 요약
A1: 보스 밸런스 설계 요약
A2: 보스 경험치는 해당 구간 일반 몬스터 30체분으로 산정함. 보스 총시간은 헤비 유저의 1회 성공 기준이며, 밸런스 문서 W·X·Y열의 보스 대표 행에는 라이트·미들·헤비 유저의 재시도와 판단 시간을 반영한 전체 보스전 시간을 한 번만 기록함
A4: 순서 | B4: 챕터·스테이지 | C4: 보스명 | D4: 인간 시절 핵심 서사 | E4: 선의 0 도달 원인 | F4: 전투 구조 | G4: 핵심 공략 | H4: 일반 몬스터 1체 경험치 | I4: 보스 경험치 | J4: 일반 몬스터 1체 시간(초) | K4: 30체 총시간(초) | L4: 보스 총시간(초) | M4: 근거리형 시간(초) | N4: 원거리형 시간(초) | O4: 시간 효율 | P4: 해당 챕터 보스 수 | Q4: 서사적 승리 조건 | R4: 효율 검증
A5: 1 | B5: 3-F | 첫 보스·봉쇄 대피소 | C5: 닫힌 문지기 | D5: 대피소를 지키려 문을 열었던 관리인이 사고 이후 문밖의 사람을 위험 요소로 보기 시작함 | E5: 문을 열어도 되는 상황에서 구조 요청을 외면하고 안도감을 느끼는 순간 타인을 돕고자 하는 마음이 소진됨 | F5: 단일 페이즈·환경 파괴형 | G5: 돌진으로 철문 파괴→시민 이동→노출 핵 공격 | H5: 25 | I5: =H5*30 -> 750 | J5: 20 | K5: =J5*30 -> 600 | L5: 330 | M5: 210 | N5: 120 | O5: =L5/K5 -> 0.55 | P5: 3 | Q5: 닫힌 문을 모두 열고 문밖 시민을 구조한 뒤 방어 핵 파괴 | R5: =IF(AND(L5<K5,L5=M5+N5),"적정","재검토") -> 적정
A6: 2 | B6: 3-I | 융합 보스·폭력의 순환 | C6: 폭력의 순환체 | D6: 아이 대신 폭력을 받아낸 엄마와 후임 대신 폭력을 행사하도록 강요받은 군인의 기억이 하나의 외피에 갇힘 | E6: 엄마는 희생이 아이를 지키지 못했다고 믿고, 군인은 자신이 폭력을 줄인 것이 아니라 지속시켰다고 깨달으며 인간에 대한 신뢰를 잃음 | F6: 1체 시작→2체 분열·2페이즈형 | G6: 받아내야 하는 공격과 피해야 하는 공격을 구분하고 시민을 대피시킨 뒤 연결 핵 동시 파괴 | H6: 30 | I6: =H6*30 -> 900 | J6: 25 | K6: =J6*30 -> 750 | L6: 420 | M6: 210 | N6: 210 | O6: =L6/K6 -> 0.56 | P6: 3 | Q6: 때리는 자와 맞는 자를 연결한 폭력 순환 구조 자체를 파괴 | R6: =IF(AND(L6<K6,L6=M6+N6),"적정","재검토") -> 적정
A7: 3 | B7: 3-K | 보스전·갈채를 먹는 자 | C7: 갈채를 먹는 자 | D7: 순수한 구조자였으나 고등급자 특혜와 영웅 대접에 익숙해지며 선행을 생활 유지 수단으로 바꿈 | E7: 긴급 구조 알림을 끄고 '다른 고등급자를 보내라'고 선택한 평범한 순간 선의 수치가 0에 도달함 | F7: 환경 제어·무대 전환형 | G7: 카메라 사각지대 이동→중계 장치 차단→실제 시민 판별→비공개 구조 | H7: 35 | I7: =H7*30 -> 1050 | J7: 26 | K7: =J7*30 -> 780 | L7: 450 | M7: 120 | N7: 330 | O7: =L7/K7 -> 0.57692308 | P7: 3 | Q7: 아무도 보지 않는 곳에서 시민을 구조해 갈채 보호막을 제거 | R7: =IF(AND(L7<K7,L7=M7+N7),"적정","재검토") -> 적정
A8: 4 | B8: 4-F | 폐교 강당·보스전 | C8: 남겨진 친구 | D8: 학교폭력과 체벌을 호소했지만 주변이 문제 학생으로 취급하거나 외면한 차한해의 친구 | E8: 참는 것이 착한 행동이라는 믿음이 무너지고 아무도 자신을 구하지 않는다고 확신하며 선의가 고갈됨 | F8: 괴물형→인간형·비처치 결말형 | G8: 사랑의 매로 외피 파괴→농구공으로 기억 핵 개입→공격 중지→접근·포옹 | H8: 40 | I8: =H8*30 -> 1200 | J8: 28 | K8: =J8*30 -> 840 | L8: 510 | M8: 300 | N8: 210 | O8: =L8/K8 -> 0.60714286 | P8: 1 | Q8: 체력 0이 아니라 공격을 멈추고 친구를 포옹해 인간으로 복원 | R8: =IF(AND(L8<K8,L8=M8+N8),"적정","재검토") -> 적정
A9: 5 | B9: 5-C | 선의 계량자 보스전 | C9: 선의 계량자 | D9: 선의 측정 체계를 설계해 책임을 공정하게 나누려 했으나 사람을 등급과 자원으로만 판단하게 된 연구자 | E9: 차한해 한 명의 희생을 예상 손실 1명이라는 최적해로 결정하며 타인을 사람으로 보는 마지막 선의를 잃음 | F9: 전장 규칙 변경·지적 보스형 | G9: 등급 발생 장치 파괴→표식 해제→무한대 부담 분산→다인 협력으로 계산식 붕괴 | H9: 50 | I9: =H9*30 -> 1500 | J9: 32 | K9: =J9*30 -> 960 | L9: 570 | M9: 180 | N9: 390 | O9: =L9/K9 -> 0.59375 | P9: 1 | Q9: 한 사람의 무한한 희생이 아니라 여러 사람의 유한한 선택으로 부담을 분담 | R9: =IF(AND(L9<K9,L9=M9+N9),"적정","재검토") -> 적정
A11: 정예 몬스터 분류: 균열 수호체는 보스가 아니며, 전투시간 200초·안전 구역/약점 노출 기믹을 가진 후반 정예 몬스터로 보스 분포 수와 보스 경험치 산정에서 제외
