Workbook

Sheet 밸런스 문서
S1: 예상 플레이 시간
A2: 챕터 | B2: 콘텐츠 진행 순서 | C2: 플레이 난이도 | D2: 플레이 흥미도 | E2: 플레이 목표 | F2: 플레이 난관 | G2: 공략 방법 | H2: 체감 난이도 | I2: 수행 과제 수 | J2: 목표 달성 조건 | K2: 실패 결과 | L2: 예상 소요 시간 | M2: 난이도 조절 요소 | N2: 누적 플레이 시간 | O2: 스테이지 | P2: 콘텐츠 진행 포인트 (획득량) | Q2: 콘텐츠 진행 포인트 누적 | R2: 핵심 전투 기믹 | S2: 라이트 유저 (예상 시간 기준) | T2: 미들 유저 | U2: 헤비 유저 | V2: 자아마모도 변화(%) | W2: 인연 변화(%) | X2: 진행 관문 조건 | Y2: 선택·추가 콘텐츠 해금
A3: 1 | 평범한 하루 | B3: 1 | C3: 1 | D3: 8 | E3: 차한해의 과거 오프닝 감상 | F3: 입양 뒤 가족의 몫까지 당연히 떠맡아 온 시간을 짧은 장면으로 이해해야 함 | G3: 가족의 요구와 차한해가 먼저 움직이는 습관을 확인함 | H3: 1/10 – 목표 식별·선택·입력 부담을 종합한 체감 난이도 | I3: 1 | J3: 오프닝 재생 완료 | K3: - | L3: 45초 | M3: 핵심 대상 강조·정체 시 단계별 힌트 제공 | N3: 0.00052083333 | O3: 1-A | 집·가족의 몫 | P3: 3 | Q3: =P3 -> 3 | S3: 45초 | T3: 40초 | U3: 35초
A4: 1 | 평범한 하루 | B4: 2 | C4: 1 | D4: 6 | E4: 아버지 회사 서류를 챙겨 식탁에 올려두기 | F4: 흩어진 서류 중 회사 문서만 골라야 함 | G4: 봉투 표식과 아버지의 메모를 보고 서류를 모아 식탁 지정 칸에 둠 | H4: 1/10 – 목표 식별·선택·입력 부담을 종합한 체감 난이도 | I4: 4 | J4: 회사 서류 4묶음 정리 완료 | K4: - | L4: 25초 | M4: 핵심 대상 강조·정체 시 단계별 힌트 제공 | N4: 0.00081018519 | O4: 1-A | 집·가족의 몫 | P4: 2 | Q4: =Q3+P4 -> 5 | S4: 25초 | T4: 20초 | U4: 15초
A5: 1 | 평범한 하루 | B5: 3 | C5: 1 | D5: 6 | E5: 빨래를 분류해 세탁기에 넣고 작동하기 | F5: 색상과 세탁 표시가 다른 옷이 섞여 있음 | G5: 일반 빨래만 세탁기에 넣고 세제 투입 뒤 표준 코스를 시작함 | H5: 1/10 – 목표 식별·선택·입력 부담을 종합한 체감 난이도 | I5: 3 | J5: 일반 빨래 분류·투입·세탁 시작 | K5: 비싼 블라우스를 넣으면 경고 후 분류 단계로 복귀 | L5: 40초 | M5: 핵심 대상 강조·정체 시 단계별 힌트 제공 | N5: 0.0012731481 | O5: 1-A | 집·가족의 몫 | P5: 3 | Q5: 8 | S5: 40초 | T5: 35초 | U5: 30초
A6: 1 | 평범한 하루 | B6: 4 | C6: 2 | D6: 7 | E6: 어머니의 비싼 블라우스를 손세탁하기 | F6: 강하게 문지르면 옷감 손상 게이지가 오름 | G6: 미지근한 물·중성세제·누르기 세탁 순서를 지킴 | H6: 2/10 – 목표 식별·선택·입력 부담을 종합한 체감 난이도 | I6: 4 | J6: 블라우스 손상 없이 손세탁 완료 | K6: 손상 게이지 최대 시 현재 단계 재시작 | L6: 50초 | M6: 핵심 대상 강조·정체 시 단계별 힌트 제공 | N6: 0.0018518519 | O6: 1-A | 집·가족의 몫 | P6: 3 | Q6: 11 | S6: 50초 | T6: 45초 | U6: 40초
A7: 1 | 평범한 하루 | B7: 5 | C7: 1 | D7: 6 | E7: 건조기 완료음을 듣고 빨래를 꺼내 거실에서 개기 | F7: 건조 완료 시점과 옷별 접는 방향을 확인해야 함 | G7: 완료음 뒤 빨래를 거실로 옮기고 종류별 실루엣에 맞춰 갬 | H7: 1/10 – 목표 식별·선택·입력 부담을 종합한 체감 난이도 | I7: 8 | J7: 빨래 8개를 모두 개어 바구니에 정리 | K7: - | L7: 45초 | M7: 핵심 대상 강조·정체 시 단계별 힌트 제공 | N7: 0.0023726852 | O7: 1-A | 집·가족의 몫 | P7: 2 | Q7: 13 | S7: 45초 | T7: 40초 | U7: 35초
A8: 1 | 평범한 하루 | B8: 6 | C8: 1 | D8: 7 | E8: 동생에게 신상 과자·헤어롤·팝콘 심부름 받기 | F8: 대화에 품목과 목적지가 섞여 있음 | G8: 강조된 품목과 동선을 확인하고 심부름 목록을 등록함 | H8: 1/10 – 목표 식별·선택·입력 부담을 종합한 체감 난이도 | I8: 3 | J8: 심부름 3종 등록 | K8: - | L8: 35초 | M8: 핵심 대상 강조·정체 시 단계별 힌트 제공 | N8: 0.0027777778 | O8: 1-A | 집·가족의 몫 | P8: 2 | Q8: 15 | S8: 35초 | T8: 30초 | U8: 25초 | W8: [차우선] 기준 45%
A9: 1 | 평범한 하루 | B9: 7 | C9: 1 | D9: 7 | E9: 엘리베이터에서 주민 모두에게 인사하며 밖으로 나가기 | F9: 어른·아이·택배기사 등 서로 다른 위치의 주민을 발견해야 함 | G9: 이동·조사 입력으로 만나는 주민에게 자연스럽게 인사함 | H9: 1/10 – 목표 식별·선택·입력 부담을 종합한 체감 난이도 | I9: 5 | J9: 엘리베이터와 로비의 주민 5명에게 인사 후 외출 | K9: - | L9: 35초 | M9: 핵심 대상 강조·정체 시 단계별 힌트 제공 | N9: 0.0031828704 | O9: 1-A | 아파트·인사 튜토리얼 | P9: 3 | Q9: 18 | S9: 35초 | T9: 30초 | U9: 25초 | Y9: 이동·조사 튜토리얼 완료
A10: 1 | 평범한 하루 | B10: 8 | C10: 2 | D10: 7 | E10: 편의점에서 신상 과자가 아직 입고되지 않았음을 확인하기 | F10: 빈 진열대와 입고 안내를 찾아야 함 | G10: 신상 코너와 알바생 대화를 통해 물류 트럭 도착 시간을 확인함 | H10: 2/10 – 목표 식별·선택·입력 부담을 종합한 체감 난이도 | I10: 2 | J10: 신상 과자 입고 전 상태·트럭 시간 확인 | K10: - | L10: 35초 | M10: 핵심 대상 강조·정체 시 단계별 힌트 제공 | N10: 0.003587963 | O10: 1-B | 편의점·첫 방문 | P10: 4 | Q10: 22 | S10: 35초 | T10: 30초 | U10: 25초
A11: 1 | 평범한 하루 | B11: 9 | C11: 2 | D11: 8 | E11: 알바생의 무거운 음료 박스 진열 부탁을 수락할지 선택하기 | F11: 동생 심부름과 짧은 도움 사이에서 선택해야 함 | G11: 수락하거나 [싫어요.]를 사용해 거절함. 거절해도 메인 진행은 유지되지만 해당 서브 퀘스트의 인연·보상 획득 기회는 사라짐 | H11: 2/10 – 목표 식별·선택·입력 부담을 종합한 체감 난이도 | I11: 1 | J11: 부탁 수락 또는 [싫어요.] 사용 | K11: - | L11: 30초 | M11: 핵심 대상 강조·정체 시 단계별 힌트 제공 | N11: 0.0039351852 | O11: 1-B | 편의점 알바생 부탁 | P11: 3 | Q11: 25 | S11: 30초 | T11: 25초 | U11: 20초 | Y11: 선택 서브 퀘스트 : 편의점 음료 진열
A12: 1 | 평범한 하루 | B12: 10 | C12: 3 | D12: 8 | E12: 음료 박스를 가격표에 맞춰 진열하기 | F12: 비슷한 포장과 무게 때문에 위치를 헷갈릴 수 있음 | G12: 상표·용량·가격표를 대조해 무거운 박스부터 아래 칸에 배치함 | H12: 3/10 – 목표 식별·선택·입력 부담을 종합한 체감 난이도 | I12: 6 | J12: 음료 6박스 진열 완료 | K12: 오배치 3회 시 틀린 가격표를 강조 | L12: 1분 10초 | M12: 핵심 대상 강조·정체 시 단계별 힌트 제공 | N12: 0.0047453704 | O12: 1-B | 편의점 알바생 부탁 | P12: 3 | Q12: 28 | S12: 1분 10초 | T12: 1분 | U12: 50초 | Y12: 완료 시 알바생이 신상 과자 1개를 맡아두는 약속
A13: 1 | 평범한 하루 | B13: 11 | C13: 2 | D13: 8 | E13: 골목에서 들리는 예쁜 고양이 울음소리 확인하기 | F13: 심부름 목적지가 따로 있어 작은 울음소리를 무시하고 지나칠 수 있음 | G13: 편의점 주변에서 반복되는 울음소리와 골목 그림자를 확인하되 조사하지 않고 진행할 수도 있음 | H13: 2/10 – 발견 여부와 선택에 따라 진행이 달라짐 | I13: 2 | J13: 울음소리가 들리는 골목 위치 확인 또는 선택적으로 지나침 | K13: - | L13: 45초 | M13: 자동 등록하지 않고 소리·행동·오브젝트로만 암시 | N13: 0.0052662037 | O13: 1-B | 편의점·고양이 선택 | P13: 3 | Q13: 31 | S13: 45초 | T13: 40초 | U13: 35초 | Y13: 서브 퀘스트 : 예쁜 고양이 인연 1단계 발견
A14: 1 | 평범한 하루 | B14: 12 | C14: 2 | D14: 8 | E14: 편의점에서 츄르 4개입 세트 구매하기 | F14: 구매 메뉴에는 심부름 물품 외에도 여러 상품이 있어 츄르를 직접 찾아야 함 | G14: 알바생 대화 후 ‘물건 구매하기’를 선택하고 반려동물 간식 칸에서 츄르 4개입을 구매함 | H14: 2/10 – 발견 여부와 선택에 따라 진행이 달라짐 | I14: 2 | J14: 츄르 4개입 세트 구매 완료 | K14: - | L14: 45초 | M14: 자동 등록하지 않고 소리·행동·오브젝트로만 암시 | N14: 0.005787037 | O14: 1-B | 편의점·고양이 선택 | P14: 3 | Q14: 34 | S14: 45초 | T14: 40초 | U14: 35초 | Y14: 서브 퀘스트 : 이후 예쁜 고양이 인연 콘텐츠 4회 수행 가능
A15: 1 | 평범한 하루 | B15: 13 | C15: 2 | D15: 8 | E15: 예쁜 고양이에게 첫 번째 츄르 건네기 | F15: 예쁜 고양이는 처음 만난 차한해를 경계해 바로 가까이 오지 않음 | G15: 일정 거리에 츄르를 내려놓고 뒤로 물러난 뒤 고양이가 스스로 다가올 때까지 기다림 | H15: 2/10 – 발견 여부와 선택에 따라 진행이 달라짐 | I15: 2 | J15: 예쁜 고양이가 츄르를 먹고 도망가지 않은 채 차한해를 바라봄 | K15: - | L15: 45초 | M15: 자동 등록하지 않고 소리·행동·오브젝트로만 암시 | N15: 0.0063078704 | O15: 1-B | 편의점·고양이 선택 | P15: 3 | Q15: 37 | S15: 45초 | T15: 40초 | U15: 35초 | W15: [예쁜 고양이] +25% 선택 (최대 누적 25%) | Y15: 츄르 보유 시 수행 예쁜 고양이 인연 +25%
A16: 1 | 평범한 하루 | B16: 14 | C16: 2 | D16: 5 | E16: 다이소로 이동하기 | F16: 갈림길과 주변 상호작용 오브젝트 때문에 목적지 방향을 놓칠 수 있음 | G16: 표지판·미니맵·NPC 이동 방향을 확인하며 편의점에서 다이소까지 이동함 | H16: 2/10 – 맵 크기·갈림길 수·목적지 표식의 가시성이 난이도를 결정함 | I16: 1 | J16: 편의점에서 다이소의 도착 트리거에 진입 | K16: - | L16: 25초 | M16: 일정 시간 정체 시 목적지 방향 화살표 표시 | N16: 0.0065972222 | O16: 1-C | 다이소 | P16: 3 | Q16: 40 | S16: 25초 | T16: 20초 | U16: 20초
A17: 1 | 평범한 하루 | B17: 15 | C17: 2 | D17: 6 | E17: 헤어롤 진열대 찾기 | F17: 비슷한 오브젝트와 진열대가 많아 목표 대상을 한 번에 찾기 어려움 | G17: 구역별 표지와 상품 외형을 비교하며 생활용품 코너의 헤어롤을 조사함 | H17: 2/10 – 후보 오브젝트 수·외형 유사도·탐색 범위가 난이도를 결정함 | I17: 5 | J17: 생활용품 코너의 헤어롤 발견 및 조사 완료 | K17: - | L17: 35초 | M17: 30초 이상 미발견 시 목표 구역에 약한 반짝임 표시 | N17: 0.0070023148 | O17: 1-C | 다이소 | P17: 4 | Q17: 44 | S17: 35초 | T17: 30초 | U17: 25초
A18: 1 | 평범한 하루 | B18: 16 | C18: 1 | D18: 5 | E18: 헤어롤 구매하기 | F18: 구매 대상·수량·결제 순서를 잘못 선택할 수 있음 | G18: 요청받은 품목을 확인하고 상품 선택→계산대 상호작용→결제를 순서대로 진행함 | H18: 1/10 – 상품 후보 수·품목 유사도·구매 단계 수가 난이도를 결정함 | I18: 3 | J18: 헤어롤 1개 구매 후 인벤토리에 등록 | K18: 잘못된 품목 구매 시 다시 선택해야 함 | L18: 20초 | M18: 요청 품목에 작은 임무 아이콘 표시 | N18: 0.0072337963 | O18: 1-C | 다이소 | P18: 3 | Q18: 47 | S18: 20초 | T18: 15초 | U18: 15초
A19: 1 | 평범한 하루 | B19: 17 | C19: 1 | D19: 8 | E19: 다이소를 나오자 편의점 물류 트럭이 지나가는 장면 확인하기 | F19: 신상 과자 재입고 기회를 즉시 알아차려야 함 | G19: 트럭 표식과 편의점 방향을 확인함 | H19: 1/10 – 목표 식별·선택·입력 부담을 종합한 체감 난이도 | I19: 1 | J19: 물류 트럭과 편의점 재입고 방향 확인 | K19: - | L19: 20초 | M19: 핵심 대상 강조·정체 시 단계별 힌트 제공 | N19: 0.0074652778 | O19: 1-D | 어르신과 신상 과자 | P19: 3 | Q19: 50 | S19: 20초 | T19: 15초 | U19: 15초
A20: 1 | 평범한 하루 | B20: 18 | C20: 2 | D20: 10 | E20: 짐이 많은 어르신을 도울지 신상 과자를 사러 갈지 선택하기 | F20: 도움이 늦어지면 신상 과자가 품절될 수 있음 | G20: 어르신의 구조 요청과 동생의 심부름을 비교해 행동을 선택함 | H20: 2/10 – 목표 식별·선택·입력 부담을 종합한 체감 난이도 | I20: 1 | J20: 어르신 돕기 또는 편의점으로 바로 달리기 | K20: - | L20: 30초 | M20: 핵심 대상 강조·정체 시 단계별 힌트 제공 | N20: 0.0078125 | O20: 1-D | 어르신과 신상 과자 | P20: 3 | Q20: 53 | S20: 30초 | T20: 25초 | U20: 25초 | Y20: 핵심 선택 : 자발적 선행과 개인 손실
A21: 1 | 평범한 하루 | B21: 19 | C21: 2 | D21: 10 | E21: 어르신의 무거운 짐을 목적지까지 옮기기 | F21: 짐 때문에 이동이 느리고 보행자와 턱을 피해 가야 함 | G21: 무게 중심을 유지하며 안전한 길로 짐을 나누어 운반함 | H21: 2/10 – 목표 식별·선택·입력 부담을 종합한 체감 난이도 | I21: 4 | J21: 짐 4개 운반·어르신 귀가 확인 | K21: - | L21: 1분 10초 | M21: 핵심 대상 강조·정체 시 단계별 힌트 제공 | N21: 0.0086226852 | O21: 1-D | 어르신과 신상 과자 | P21: 3 | Q21: 56 | S21: 1분 10초 | T21: 1분 | U21: 50초 | W21: [도시] +5% 선택 (기본 0% · 최대 5%) | Y21: 어르신을 도운 경우 수행·신상 과자 분기 변화
A22: 1 | 평범한 하루 | B22: 20 | C22: 2 | D22: 8 | E22: 치킨집 앞 두 손님의 주문 대화 듣기 | F22: 서로 다른 주문과 번복 대사에서 확정 내용을 골라야 함 | G22: 치킨·소스·음료·추가 요청을 구분해 기억함 | H22: 2/10 – 목표 식별·선택·입력 부담을 종합한 체감 난이도 | I22: 4 | J22: 두 손님의 최종 주문 확인 | K22: - | L22: 40초 | M22: 핵심 대상 강조·정체 시 단계별 힌트 제공 | N22: 0.0090856481 | O22: 1-E | 치킨집 알바 서브 | P22: 3 | Q22: 59 | S22: 40초 | T22: 35초 | U22: 30초 | Y22: 서브 퀘스트 : 치킨집 알바
A23: 1 | 평범한 하루 | B23: 21 | C23: 2 | D23: 8 | E23: 바쁜 직원의 도움 요청을 확인하기 | F23: 밀린 주문과 손님 대화가 겹침 | G23: 직원의 호출을 확인하고 잠시 도울지 선택함 | H23: 2/10 – 목표 식별·선택·입력 부담을 종합한 체감 난이도 | I23: 1 | J23: 도움 요청 확인 | K23: - | L23: 40초 | M23: 핵심 대상 강조·정체 시 단계별 힌트 제공 | N23: 0.0095486111 | O23: 1-E | 치킨집 알바 서브 | P23: 4 | Q23: 63 | S23: 40초 | T23: 35초 | U23: 30초 | Y23: 거절 시 서브 퀘스트 종료
A24: 1 | 평범한 하루 | B24: 22 | C24: 2 | D24: 8 | E24: 치킨집 알바를 도울지 선택하기 | F24: 심부름 일정과 직원의 부탁 사이에서 선택해야 함 | G24: 돕기를 선택하거나 [싫어요.]를 사용해 알바 부탁을 거절하고 기존 심부름을 계속함 | H24: 2/10 – 목표 식별·선택·입력 부담을 종합한 체감 난이도 | I24: 1 | J24: 알바 수락 또는 [싫어요.] 사용 | K24: - | L24: 35초 | M24: 핵심 대상 강조·정체 시 단계별 힌트 제공 | N24: 0.0099537037 | O24: 1-E | 치킨집 알바 서브 | P24: 6 | Q24: 69 | S24: 35초 | T24: 30초 | U24: 25초 | Y24: 수락 시 포장 미니게임 해금
A25: 1 | 평범한 하루 | B25: 23 | C25: 4 | D25: 8 | E25: 주문표의 치킨·소스·음료 확인하기 | F25: 여러 주문표의 번호와 구성품을 혼동하기 쉬움 | G25: 주문 번호별 필수 항목을 순서대로 확인함 | H25: 4/10 – 목표 식별·선택·입력 부담을 종합한 체감 난이도 | I25: 5 | J25: 주문표 필수 항목 5개 확인 | K25: 오답 누적 시 현재 단계 재시작 | L25: 1분 10초 | M25: 핵심 대상 강조·정체 시 단계별 힌트 제공 | N25: 0.010763889 | O25: 1-E | 치킨집 알바 서브 | P25: 6 | Q25: 75 | S25: 1분 10초 | T25: 1분 | U25: 50초
A26: 1 | 평범한 하루 | B26: 24 | C26: 4 | D26: 8 | E26: 주문에 맞게 치킨 포장하기 | F26: 번복된 대사와 확정 주문을 구분해야 함 | G26: 확정 주문표만 보고 상자·무·소스·음료를 넣음 | H26: 4/10 – 목표 식별·선택·입력 부담을 종합한 체감 난이도 | I26: 5 | J26: 구성품 5종 올바르게 포장 | K26: 오답 누적 시 현재 단계 재시작 | L26: 1분 10초 | M26: 핵심 대상 강조·정체 시 단계별 힌트 제공 | N26: 0.011574074 | O26: 1-E | 치킨집 알바 서브 | P26: 6 | Q26: 81 | S26: 1분 10초 | T26: 1분 | U26: 50초
A27: 1 | 평범한 하루 | B27: 25 | C27: 4 | D27: 8 | E27: 잘못 포장된 주문 수정하기 | F27: 다른 주문의 소스와 음료가 섞여 있음 | G27: 주문표와 포장을 대조해 오류 항목만 교체함 | H27: 4/10 – 목표 식별·선택·입력 부담을 종합한 체감 난이도 | I27: 4 | J27: 오포장 항목 전부 수정 | K27: 오답 누적 시 현재 단계 재시작 | L27: 55초 | M27: 핵심 대상 강조·정체 시 단계별 힌트 제공 | N27: 0.012210648 | O27: 1-E | 치킨집 알바 서브 | P27: 3 | Q27: 84 | S27: 55초 | T27: 45초 | U27: 40초
A28: 1 | 평범한 하루 | B28: 26 | C28: 2 | D28: 8 | E28: 손님에게 주문을 전달하고 보상 받기 | F28: 비슷한 두 손님 중 올바른 주문자를 찾아야 함 | G28: 대화 특징과 주문 번호를 대조해 전달함 | H28: 2/10 – 목표 식별·선택·입력 부담을 종합한 체감 난이도 | I28: 2 | J28: 올바른 손님에게 전달·알바비 획득 | K28: - | L28: 40초 | M28: 핵심 대상 강조·정체 시 단계별 힌트 제공 | N28: 0.012673611 | O28: 1-E | 치킨집 알바 서브 | P28: 3 | Q28: 87 | S28: 40초 | T28: 35초 | U28: 30초 | Y28: 치킨집 알바 서브 퀘스트 완료
A29: 1 | 평범한 하루 | B29: 27 | C29: 2 | D29: 8 | E29: 편의점으로 돌아가 신상 과자 재고 확인하기 | F29: 어르신·알바생 부탁 선택에 따라 결과가 달라짐 | G29: 진열대와 알바생 반응을 확인함 | H29: 2/10 – 목표 식별·선택·입력 부담을 종합한 체감 난이도 | I29: 2 | J29: 재고·예약 여부 확인 | K29: - | L29: 25초 | M29: 핵심 대상 강조·정체 시 단계별 힌트 제공 | N29: 0.012962963 | O29: 1-F | 편의점 결과 분기 | P29: 4 | Q29: 91 | S29: 25초 | T29: 20초 | U29: 20초
A30: 1 | 평범한 하루 | B30: 28 | C30: 2 | D30: 10 | E30: 선택 결과에 따라 신상 과자 확보 여부 확정하기 | F30: 도움을 선택했을 때 앞선 알바생 부탁 수행 여부가 보상을 바꿈 | G30: 어르신 무시 시 구매, 어르신 도움+부탁 완료 시 예약품 수령, 도움+부탁에 [싫어요.] 사용 시 품절 결과를 확인함 | H30: 2/10 – 목표 식별·선택·입력 부담을 종합한 체감 난이도 | I30: 3 | J30: 신상 과자 구매·예약 수령 또는 품절 확정 | K30: - | L30: 50초 | M30: 핵심 대상 강조·정체 시 단계별 힌트 제공 | N30: 0.013541667 | O30: 1-F | 편의점 결과 분기 | P30: 5 | Q30: 96 | S30: 50초 | T30: 40초 | U30: 35초 | Y30: 선택 연쇄 결과 저장
A31: 1 | 평범한 하루 | B31: 29 | C31: 1 | D31: 9 | E31: 동생에게 과자 결과를 알리고 지하철 중고거래 심부름 받기 | F31: 품절 분기에서는 동생의 짜증 섞인 추가 요구를 감정적으로 받아들여야 함 | G31: 결과 대화를 확인하고 거래 상대 단서를 등록함 | H31: 1/10 – 목표 식별·선택·입력 부담을 종합한 체감 난이도 | I31: 2 | J31: 중고거래 장소·상대 특징 등록 | K31: - | L31: 35초 | M31: 핵심 대상 강조·정체 시 단계별 힌트 제공 | N31: 0.013946759 | O31: 1-F | 동생의 추가 심부름 | P31: 6 | Q31: 102 | S31: 35초 | T31: 30초 | U31: 25초 | W31: 과자 확보: [차우선] +5% (50%) / 품절: -5% (40%)
A32: 1 | 평범한 하루 | B32: 30 | C32: 1 | D32: 6 | E32: 영화관으로 이동하기 | F32: 상가 갈림길에서 목적지를 찾아야 함 | G32: 표지판과 심부름 목록을 보고 영화관으로 이동함 | H32: 1/10 – 목표 식별·선택·입력 부담을 종합한 체감 난이도 | I32: 1 | J32: 영화관 도착 | K32: - | L32: 30초 | M32: 핵심 대상 강조·정체 시 단계별 힌트 제공 | N32: 0.014293981 | O32: 1-F | 영화관·지하철 | P32: 5 | Q32: 107 | S32: 30초 | T32: 25초 | U32: 25초
A33: 1 | 평범한 하루 | B33: 31 | C33: 1 | D33: 6 | E33: 동생이 부탁한 팝콘 구매하기 | F33: 맛과 크기를 잘못 고를 수 있음 | G33: 심부름 목록과 메뉴를 대조해 구매함 | H33: 1/10 – 목표 식별·선택·입력 부담을 종합한 체감 난이도 | I33: 3 | J33: 지정 팝콘 구매 | K33: - | L33: 25초 | M33: 핵심 대상 강조·정체 시 단계별 힌트 제공 | N33: 0.014583333 | O33: 1-F | 영화관·지하철 | P33: 3 | Q33: 110 | S33: 25초 | T33: 20초 | U33: 20초
A34: 1 | 평범한 하루 | B34: 32 | C34: 2 | D34: 6 | E34: 지하철 중고거래 장소로 이동하기 | F34: 출구 번호와 약속 위치가 다름 | G34: 역 안내판과 채팅의 출구 번호를 확인함 | H34: 2/10 – 목표 식별·선택·입력 부담을 종합한 체감 난이도 | I34: 2 | J34: 약속 장소 도착 | K34: - | L34: 35초 | M34: 핵심 대상 강조·정체 시 단계별 힌트 제공 | N34: 0.014988426 | O34: 1-F | 영화관·지하철 | P34: 3 | Q34: 113 | S34: 35초 | T34: 30초 | U34: 25초
A35: 1 | 평범한 하루 | B35: 33 | C35: 2 | D35: 7 | E35: 거래 후보 세 명의 특징 관찰하기 | F35: 복장 일부가 비슷해 판매자를 혼동하기 쉬움 | G35: 채팅의 가방·신발·손에 든 물건을 대조함 | H35: 2/10 – 목표 식별·선택·입력 부담을 종합한 체감 난이도 | I35: 3 | J35: 후보 3명 관찰 | K35: - | L35: 30초 | M35: 핵심 대상 강조·정체 시 단계별 힌트 제공 | N35: 0.015335648 | O35: 1-F | 영화관·지하철 | P35: 3 | Q35: 116 | S35: 30초 | T35: 25초 | U35: 20초
A36: 1 | 평범한 하루 | B36: 34 | C36: 3 | D36: 7 | E36: 올바른 중고거래 상대 찾기 | F36: 가짜 후보에게 말을 걸면 시간이 추가됨 | G36: 세 단서가 모두 맞는 사람에게 암구호를 말함 | H36: 3/10 – 목표 식별·선택·입력 부담을 종합한 체감 난이도 | I36: 3 | J36: 정확한 거래 상대 선택 | K36: 오답 후보 선택 시 대화 후 다시 탐색 | L36: 40초 | M36: 핵심 대상 강조·정체 시 단계별 힌트 제공 | N36: 0.015798611 | O36: 1-F | 영화관·지하철 | P36: 4 | Q36: 120 | S36: 40초 | T36: 35초 | U36: 30초
A37: 1 | 평범한 하루 | B37: 35 | C37: 1 | D37: 8 | E37: 중고거래를 마치고 동생에게 완료 연락하기 | F37: 과자 분기와 거래 결과에 따라 동생의 반응이 달라짐 | G37: 물품 상태를 확인하고 송금·완료 메시지를 보냄 | H37: 1/10 – 목표 식별·선택·입력 부담을 종합한 체감 난이도 | I37: 3 | J37: 거래·완료 연락 | K37: - | L37: 25초 | M37: 핵심 대상 강조·정체 시 단계별 힌트 제공 | N37: 0.016087963 | O37: 1-F | 영화관·지하철 | P37: 5 | Q37: 125 | S37: 25초 | T37: 20초 | U37: 20초 | W37: [차우선] +5% (과자 확보 55% / 품절 45%)
A38: 1 | 평범한 하루 | B38: 36 | C38: 2 | D38: 8 | E38: 횡단보도에서 아이가 떨어뜨린 학용품을 주워주기 | F38: 신호가 바뀌기 전 안전한 순서로 물건을 모아야 함 | G38: 차도 가까운 물건부터 회수하고 아이를 인도로 유도함 | H38: 2/10 – 목표 식별·선택·입력 부담을 종합한 체감 난이도 | I38: 5 | J38: 학용품 5개 회수·아이 안전 확인 | K38: 신호 종료 시 남은 물건이 인도 쪽으로 이동 | L38: 55초 | M38: 핵심 대상 강조·정체 시 단계별 힌트 제공 | N38: 0.016724537 | O38: 1-F | 동네의 작은 선행 | P38: 3 | Q38: 128 | S38: 55초 | T38: 45초 | U38: 40초 | Y38: 선택 서브 퀘스트·동네 목격자 스티커 플래그
A39: 1 | 평범한 하루 | B39: 37 | C39: 1 | D39: 9 | E39: 공원에서 모든 심부름 완료와 섬광 이상 현상 확인하기 | F39: 평범한 귀가 직전 소리 없는 번개와 미세 진동이 짧게 겹침 | G39: 세 심부름 물품을 확인하고 하늘의 섬광·땅의 떨림을 기억함 | H39: 1/10 – 목표 식별·선택·입력 부담을 종합한 체감 난이도 | I39: 4 | J39: 심부름 3종 완료·첫 이상 현상 확인 | K39: - | L39: 30초 | M39: 핵심 대상 강조·정체 시 단계별 힌트 제공 | N39: 0.017071759 | O39: 1-G | 공원·첫 전조 | P39: 4 | Q39: 132 | S39: 30초 | T39: 25초 | U39: 25초 | X39: 1챕터 메인 심부름 완료
A40: 2 | 금이 간 일상 | B40: 38 | C40: 1 | D40: 7 | E40: 축제 종료 현장과 남은 이상 징후 관찰하기 | F40: 떠나는 시민·쌓인 쓰레기·간헐적으로 깜빡이는 조명 사이에 섬광의 원인을 추정할 단서가 분산되어 있음 | G40: 시민의 행동과 쓰레기 상태를 살펴본 뒤 조명 깜빡임과 바닥의 미세한 떨림을 차례로 확인함 | H40: 1/10 – 관찰 대상 수·이상 징후의 미세함·단서 분산 정도가 난이도를 결정함 | I40: 5 | J40: 시민·쓰레기·조명·바닥 진동에 관한 필수 관찰 대상 확인 | K40: - | L40: 20초 | M40: 이상 징후가 발생할 때 효과음과 짧은 시선 유도 아이콘 표시 | N40: 0.017303241 | O40: 2-A | 공원 축제·청소 | P40: 3 | Q40: 135 | S40: 20초 | T40: 20초 | U40: 20초
...

Sheet PC DATA(대차대조표)
A1: 콘텐츠 진행 순서 | B1: 콘텐츠명 | C1: 캐릭터 이름 | D1: 전투 상태 | E1: 기본 공격력 | F1: 공격력 변화(최초·일회성) | G1: 기본 방어력 | H1: 방어력 변화(획득·손상·파손) | I1: 스킬(최초 해금) | J1: 변경 근거·현재 상태
A2: ※ 밸런스 문서의 콘텐츠 진행 순서 1~306에서 현재 기본 공격력·기본 방어력과 전투 상태를 확인할 수 있음. 장비와 지속 해금 PC 스킬은 처음 획득·교체·손상·해금되는 시점에만 기록함. 아이템 고유 행동·UI 기능·엔딩 전용 강제 이벤트 스킬([눈물] 등)은 아이템·스킬 DATA·밸런스 문서의 동일 콘텐츠 번호로 검증함. 일반인 상태는 공격력 10·방어력 10이며, 첫 힘 발현은 해당 콘텐츠에만 적용되는 +990 일회성 보정임.
A3: 1 | B3: 차한해의 과거 오프닝 감상 | C3: 차한해 | D3: 전투 시스템 미개방 | E3: 10 | G3: 10 | I3: 싫어요. | J3: 기본 공격력 10 / 기본 방어력 10
A4: 2 | B4: 아버지 회사 서류를 챙겨 식탁에 올려두기 | C4: 차한해 | D4: 전투 시스템 미개방 | E4: 10 | G4: 10 | J4: 일반인 신체 능력 유지
A5: 3 | B5: 빨래를 분류해 세탁기에 넣고 작동하기 | C5: 차한해 | D5: 전투 시스템 미개방 | E5: 10 | G5: 10
A6: 4 | B6: 어머니의 비싼 블라우스를 손세탁하기 | C6: 차한해 | D6: 전투 시스템 미개방 | E6: 10 | G6: 10
A7: 5 | B7: 건조기 완료음을 듣고 빨래를 꺼내 거실에서 개기 | C7: 차한해 | D7: 전투 시스템 미개방 | E7: 10 | G7: 10
A8: 6 | B8: 동생에게 신상 과자·헤어롤·팝콘 심부름 받기 | C8: 차한해 | D8: 전투 시스템 미개방 | E8: 10 | G8: 10
A9: 7 | B9: 엘리베이터에서 주민 모두에게 인사하며 밖으로 나가기 | C9: 차한해 | D9: 전투 시스템 미개방 | E9: 10 | G9: 10
A10: 8 | B10: 편의점에서 신상 과자가 아직 입고되지 않았음을 확인하기 | C10: 차한해 | D10: 전투 시스템 미개방 | E10: 10 | G10: 10
A11: 9 | B11: 알바생의 무거운 음료 박스 진열 부탁을 수락할지 선택하기 | C11: 차한해 | D11: 전투 시스템 미개방 | E11: 10 | G11: 10
A12: 10 | B12: 음료 박스를 가격표에 맞춰 진열하기 | C12: 차한해 | D12: 전투 시스템 미개방 | E12: 10 | G12: 10
A13: 11 | B13: 골목에서 들리는 예쁜 고양이 울음소리 확인하기 | C13: 차한해 | D13: 전투 시스템 미개방 | E13: 10 | G13: 10
A14: 12 | B14: 편의점에서 츄르 4개입 세트 구매하기 | C14: 차한해 | D14: 전투 시스템 미개방 | E14: 10 | G14: 10
A15: 13 | B15: 예쁜 고양이에게 첫 번째 츄르 건네기 | C15: 차한해 | D15: 전투 시스템 미개방 | E15: 10 | G15: 10
A16: 14 | B16: 다이소로 이동하기 | C16: 차한해 | D16: 전투 시스템 미개방 | E16: 10 | G16: 10
... A80: 78 | B80: 문틈젤리와 정면으로 마주치기 | C80: 차한해 | D80: 전투 시스템 미개방 | E80: 10 | G80: 10
A81: 79 | B81: 두 눈을 감고 양손으로 괴물을 막기 | C81: 차한해 | D81: 무의식적 일회성 발현 | E81: 10 | F81: [펑!] 연계 : 무의식적 선의 폭발 +990 순간 출력 1000 | G81: 10 | I81: 펑! | J81: 기본 공격력 10 / 무의식적 선의 폭발 +990 · 순간 출력 1000 / 기본 방어력 10
A82: 80 | B82: 먼지처럼 사라진 괴물의 흔적 확인하기 | C82: 차한해 | D82: 미개방·힘 재현 불가 | E82: 10 | F82: [펑!] 연계 종료 : +990 → 0 | G82: 10 | J82: 무의식적 선의 폭발 종료 : +990 → 0
A83: 81 | B83: 어린아이를 공주님 안기로 구출하기 | C83: 차한해 | D83: 미개방·힘 재현 불가 | E83: 10 | G83: 10 | J83: 첫 힘의 존재와 발동 방법을 인식하지 못함
A84: 82 | B84: 아이의 ‘괴물 펑’ 목격담 듣기 | C84: 차한해 | D84: 미개방·힘 재현 불가 | E84: 10 | G84: 10
A85: 83 | B85: 질질핵를 우회해 안전 구역으로 이동하기 | C85: 차한해 | D85: 미개방·힘 재현 불가 | E85: 10 | G85: 10
A86: 84 | B86: 울음주머니의 울음 파동을 피해 새벽 괴물 습격 구간 벗어나기 | C86: 차한해 | D86: 미개방·힘 재현 불가 | E86: 10 | G86: 10
A87: 85 | B87: 길치섬모의 배회 경로를 피해 한도윤과 합류하기 | C87: 차한해 | D87: 미개방·힘 재현 불가 | E87: 10 | G87: 10
A88: 86 | B88: 임시 대피소 도착하기 | C88: 차한해 | D88: 미개방·힘 재현 불가 | E88: 10 | G88: 10
A89: 87 | B89: 맨몸으로 할머니를 구해 유명해진 청년의 뉴스 확인하기 | C89: 차한해 | D89: 미개방·힘 재현 불가 | E89: 10 | G89: 10
A90: 88 | B90: 선행으로 유명해진 청년의 인터뷰와 밈 확인하기 | C90: 차한해 | D90: 미개방·힘 재현 불가 | E90: 10 | G90: 10
A91: 89 | B91: 악질 채널 ‘클릭헌터’의 균열 접근 생방송 시청하기 | C91: 차한해 | D91: 미개방·힘 재현 불가 | E91: 10 | G91: 10
A92: 90 | B92: 클릭헌터에게 나타난 선의 수치 96 확인하기 | C92: 차한해 | D92: 미개방·힘 재현 불가 | E92: 10 | G92: 10
A93: 91 | B93: 기계가 정상 작동하는 균열 연구 현장 확인하기 | C93: 차한해 | D93: 미개방·힘 재현 불가 | E93: 10 | G93: 10
A94: 92 | B94: 유명 청년의 선의 수치 836 측정하기 | C94: 차한해 | D94: 미개방·힘 재현 불가 | E94: 10 | G94: 10
A95: 93 | B95: 새로운 수치를 ‘선의 수치’라고 부르는 과정 확인하기 | C95: 차한해 | D95: 미개방·힘 재현 불가 | E95: 10 | G95: 10
... A119: 117 | B119: 선의 수치 836 청년의 초기 구조 원칙 듣기 | C119: 차한해 | D119: 미개방·힘 재현 불가 | E119: 10 | G119: 10
A120: 118 | B120: 관리국 표준 대응 장비 8종·응급품 2종을 수령하고 상태 UI 확인하기 | C120: 차한해 | D120: 전투 가능·비전투 콘텐츠 | E120: 80 | F120: 관리국 지급 권총 +20 관리국 대응 장갑 +3 비살상 충격탄 사용 시 +6 | G120: 100 | H120: 기본 보호 조끼 +30 관리국 방진 고글 +4 관리국 대응 장갑 +5 관리국 전술화 +6 관리국 방진 마스크 +3 | I120: 탕! 앗, 피해! 잠깐만! | J120: 관리국 표준 대응 세트 8종·응급 주사·비살상 충격탄 획득
A121: 119 | B121: 관리국 지급 권총·비살상 충격탄·관리국 전술화를 이용해 사격과 회피 연습하기 | C121: 차한해 | D121: 전투 가능 | E121: 100 | G121: 100 | J121: 기본 공격력 100 / 스킬 : 조준 사격 · 긴급 회피
A122: 120 | B122: 출동 차량을 향해 환호하는 시민들 지나가기 | C122: 차한해 | D122: 전투 가능·비전투 콘텐츠 | E122: 100 | G122: 100 | J122: 전투 수치 변화 없이 탐색·대화·이동 진행
A123: 121 | B123: 도심 잔해 구역으로 이동하며 관리국 보급 상자에서 소형 방진 필터 챙기기 | C123: 차한해 | D123: 전투 가능·비전투 콘텐츠 | E123: 100 | G123: 100 | J123: 소형 방진 필터 1개 획득
A124: 122 | B124: 고립 시민 찾기 | C124: 차한해 | D124: 전투 가능·비전투 콘텐츠 | E124: 100 | G124: 100
A125: 123 | B125: 관리국 대응 장갑을 착용하고 잔해 제거하기 | C125: 차한해 | D125: 전투 가능·비전투 콘텐츠 | E125: 100 | G125: 100
A126: 124 | B126: 시민 대피 유도하기 | C126: 차한해 | D126: 전투 가능·비전투 콘텐츠 | E126: 100 | G126: 100
...

Sheet PC DATA
A1: 플레이어 고유명(CLASS) | B1: 콘텐츠 진행 순서 | C1: 기본 공격력 | D1: 공격력 합산 요소(최초·일회성 변화) | E1: 기본 방어력 | F1: 방어력 합산 요소(획득·손상·파손) | G1: 스킬(최초 해금)
A2: ※ 일반인 상태의 기본 공격력·기본 방어력은 각각 10으로 시작함. 79번 콘텐츠에서 [펑!]으로 무의식적 선의 폭발 +990이 한 번만 적용되어 순간 출력 1000이 되지만 다음 콘텐츠에서 보정이 0으로 돌아감. 정식 전투 능력과 관리국 표준 대응 장비는 118번부터 개방됨. 스킬 열에는 지속 해금되는 PC 조작·판단 스킬만 기록하고, 아이템 고유 행동·UI 기능·엔딩 전용 강제 이벤트 스킬([눈물] 등)은 아이템 시트·스킬 DATA·밸런스 문서에서 관리함.
A3: 차한해 | B3: 1 | C3: 10 | E3: 10 | G3: 싫어요.
B4: 79 | C4: 10 | D4: [펑!] 연계 : 무의식적 선의 폭발 +990 순간 출력 1000 | E4: 10 | G4: 펑!
B5: 80 | D5: [펑!] 연계 종료 : +990 → 0
B6: 118 | C6: 80 | D6: 관리국 지급 권총 +20 관리국 대응 장갑 +3 비살상 충격탄 사용 시 +6 | E6: 100 | F6: 기본 보호 조끼 +30 관리국 방진 고글 +4 관리국 대응 장갑 +5 관리국 전술화 +6 관리국 방진 마스크 +3 | G6: 탕! 앗, 피해! 잠깐만!
B7: 119 | C7: 100
B8: 125 | G8: 먼저 들었어
B9: 126 | C9: 120 | G9: 피했으면 내 차례
B10: 129 | D10: 보랏빛 철봉 +80
B11: 130 | C11: 160 | G11: 보라색, 여기!
B12: 131 | E12: 110 | F12: 기본 보호 조끼 손상: +30 → +15
B13: 134 | F13: 깨진 경찰 방패 +20 | G13: 앞은 내가 막아 저기 봐!
B14: 140 | D14: 차단기 막대 +90
B15: 141 | G15: 이쪽이야!
B16: 142 | C16: 180
B17: 145 | F17: 나무판 보호대 +10
B18: 148 | C18: 220 | E18: 120 | F18: 나무판 보호대 파손: 사용 불가 | G18: 핵부터!
B19: 153 | D19: 고등급자 공명 증폭기 +15 | F19: 충격 보호대 +20 관리국 대응 장갑 해제 : +5 → 0 공명 보호 장갑 +15 | G19: 증폭기, 켠다!
B20: 159 | D20: 전광판 쇠막대 +100
B21: 160 | C21: 250 | G21: 한 줄로 서!
B22: 163 | G22: 둘 중 하나!
B23: 166 | F23: 깨진 경찰 방패 파손: 사용 불가
B24: 168 | C24: 300 | E24: 135 | G24: 하나, 둘—지금!
B25: 169 | F25: 군용 방탄판 +35 | G25: 버텨!
B26: 179 | G26: 안 찍히면 돼
B27: 181 | C27: 340 | E27: 150 | F27: 군용 방탄판 균열: +35 → +15 | G27: 아무도 안 봐도
B28: 185 | D28: 소방용 진압 도끼 +75 구조용 로프 발사기 +12 | F28: 구조대 안전모 +8 | G28: 도와줘! 길 하나 만들게!
B29: 187 | F29: 소방 방열복 +22 화염 보호복 +20
B30: 188 | C30: 380 | D30: 소방용 진압 도끼·구조용 로프 발사기 반납 : +87 → 0 | E30: 165 | F30: 구조대 안전모·소방 방열복 반납 : +30 → 0 기본 보호 조끼 완전 파손 : 사용 불가 화염 보호복 손상 : +20 → +10
B31: 192 | F31: 관리국 방진 고글 해제 : +4 → 0 관리국 방진 마스크 해제 : +3 → 0 먼지 보호 안경 +10 균열 보호 마스크 +15
B32: 194 | F32: 철판 보호대 +25
B33: 196 | F33: 오염 차단 전신복 +35 심층 균열 탐사 헬멧 +12 관리국 전술화 해제 : +6 → 0 고밀도 충격 흡수 장화 +10 | G33: 괜찮아, 아직.
B34: 215 | G34: 쉿.
B35: 237 | D35: 사랑의 매 +140
B36: 238 | C36: 430 | G36: 껍데기부터
B37: 242 | F37: 매트 보호대 +15
B38: 243 | D38: 보랏빛 농구공 +120
B39: 244 | G39: 한 번 튕겨!
B40: 249 | C40: 470 | G40: 바꿔가며!
...

Sheet 아이템
A1: 이름 | B1: 타입 | C1: 참고 이미지 | D1: 사용 권한 | 획득 방식 | 획득 조건 | G1: 거래 제한 | H1: 사용 조건 | I1: 공격 수치 | 공격 보정 | K1: 방어 수치 | 방어 보정 | M1: 기타 수치 | N1: 세트 이름 | 효과 | 내용 | Q1: 수치 | R1: 최소 공격력 | S1: 최대 공격력
A2: 관리국 지급 권총 | B2: 무기 | D2: 선의관리국 요원 | E2: 퀘스트 | F2: 118번 | 관리국 표준 대응 장비 8종·응급품 2종을 수령하고 상태 UI 확인하기 | G2: 획득 시 귀속 | H2: 119번 이후 | 균열 대응 원거리 전투에서 사용 | I2: 20 | J2: 원거리 공격 보정 +5 | K2: 0 | N2: 관리국 표준 대응 세트 | O2: 2세트: 장비 교체 시간 -10% 5세트: 균열 오염 저항 +10 8세트: 자아 마모 누적량 -15% | P2: 물리·관통 | Q2: 100 | R2: 18 | S2: 22
A3: 기본 보호 조끼 | B3: 상의 | D3: 선의관리국 요원 | E3: 퀘스트 | F3: 118번 | 관리국 표준 대응 장비 8종·응급품 2종을 수령하고 상태 UI 확인하기 | G3: 획득 시 귀속 | H3: 130번 사용·131번 손상·188번 완전 파손 | I3: 0 | K3: 30 | L3: 충격 저항 +8 | N3: 관리국 표준 대응 세트 | P3: 충격 저항 | Q3: 100 | R3: 0 | S3: 0
A4: 관리국 방진 고글 | B4: 얼굴 | D4: 선의관리국 요원 | E4: 퀘스트 | F4: 118번 | 관리국 표준 대응 장비 8종·응급품 2종을 수령하고 상태 UI 확인하기 | G4: 획득 시 귀속 | H4: 128번 공명 흔적 추적·192번 먼지 보호 안경으로 교체 | I4: 0 | K4: 4 | L4: 분진·시야 방해 저항 +10 | M4: 균열 감지 범위 +2m | N4: 관리국 표준 대응 세트 | P4: 균열 감지 패시브 | Q4: +2m | R4: 0 | S4: 0
A5: 관리국 대응 장갑 | B5: 손 | D5: 선의관리국 요원 | E5: 퀘스트 | F5: 118번 | 관리국 표준 대응 장비 8종·응급품 2종을 수령하고 상태 UI 확인하기 | G5: 획득 시 귀속 | H5: 123번 잔해 제거·153번 공명 보호 장갑으로 교체 | I5: 3 | J5: 근접 공격 보정 +2 | K5: 5 | L5: 접촉 피해 감소 +5% | M5: 상호작용 속도 +5% | N5: 관리국 표준 대응 세트 | P5: 접촉 안정 패시브 | Q5: 피해 -5% | R5: 2 | S5: 4
A6: 관리국 전술화 | B6: 신발 | D6: 선의관리국 요원 | E6: 퀘스트 | F6: 118번 | 관리국 표준 대응 장비 8종·응급품 2종을 수령하고 상태 UI 확인하기 | G6: 획득 시 귀속 | H6: 119·126번 회피 훈련·196번 고밀도 충격 흡수 장화로 교체 | I6: 0 | K6: 6 | L6: 넘어짐 저항 +10% | M6: 회피 이동 거리 +5% | N6: 관리국 표준 대응 세트 | P6: 기동 보정 | Q6: +5% | R6: 0 | S6: 0
A7: 관리국 방진 마스크 | B7: 얼굴 | D7: 선의관리국 요원 | E7: 퀘스트 | F7: 118번 | 관리국 표준 대응 장비 8종·응급품 2종을 수령하고 상태 UI 확인하기 | G7: 획득 시 귀속 | H7: 128번 필터 교체 후 공명 흔적 추적·192번 균열 보호 마스크로 교체 | I7: 0 | K7: 3 | L7: 균열 오염 저항 +8 | M7: 자아 마모 저항 +3% | N7: 관리국 표준 대응 세트 | P7: 오염 저항 | Q7: 108 | R7: 0 | S7: 0
A8: 관리국 무전 이어피스 | B8: 액세서리 | D8: 선의관리국 요원 | E8: 퀘스트 | F8: 118번 | 관리국 표준 대응 장비 8종·응급품 2종을 수령하고 상태 UI 확인하기 | G8: 획득 시 귀속 | H8: 125번 공격 예고 판독에 사용 | I8: 0 | K8: 0 | M8: 공격 예고 판독 시간 +0.3초 | N8: 관리국 표준 대응 세트 | P8: 전술 정보 패시브 | Q8: +0.3초 | R8: 0 | S8: 0
A9: 관리국 상태 측정기 | B9: 액세서리 | D9: 선의관리국 요원 | E9: 퀘스트 | F9: 118번 | 관리국 표준 대응 장비 8종·응급품 2종을 수령하고 상태 UI 확인하기 | G9: 획득 시 귀속 | H9: 131번 장비 손상 확인·임무 종료 시 자동 동기화 | I9: 0 | K9: 0 | M9: 장비 내구도·자아 마모도 표시 | N9: 관리국 표준 대응 세트 | P9: 상태 확인 패시브 | Q9: UI 표시 | R9: 0 | S9: 0
A10: 보랏빛 철봉 | B10: 무기 | D10: 일반인 / 모든 선의 등급자 | E10: 콘텐츠 | F10: 129번 | 차한해에게만 보이는 보랏빛 아우라가 흐르는 철봉 회수 | H10: 130번 밖으로 나가재 제압 후 132번 소멸 | I10: 80 | J10: 근접 강공격 보정 +10 | K10: 0 | M10: 경직 유발 +12% | P10: 충격 | Q10: 115 | R10: 72 | S10: 88
A11: 깨진 경찰 방패 | B11: 보조 장비 | D11: 일반인 / 모든 선의 등급자 | E11: 콘텐츠 | F11: 134번 | 구조한 경찰에게 깨진 경찰 방패와 휴대용 섬광 신호기 받기 | H11: 146번 나만 살아서 다행 보스전·166번 파손 | I11: 0 | K11: 20 | L11: 전방 피해 감소 +12% | M11: 전방 방어 해금 | P11: 물리 저항 | Q11: 112 | R11: 0 | S11: 0
A12: 차단기 막대 | B12: 무기 | D12: 일반인 / 모든 선의 등급자 | E12: 콘텐츠 | F12: 140번 | 차한해에게만 보이는 보랏빛 공명의 차단기 막대 회수 | H12: 141번 유인·142번 비상구대게 제압 | I12: 90 | J12: 근접 공격 보정 +12 | K12: 0 | M12: 환경 유인 효과 +10% | P12: 전기·충격 | Q12: 120 | R12: 81 | S12: 99
A13: 나무판 보호대 | B13: 팔 방어구 | D13: 일반인 / 모든 선의 등급자 | E13: 제작 | F13: 145번 | 대피소 시민과 나무판 보호대 제작 | H13: 146~148번 나만 살아서 다행 보스전 사용 후 파손 | I13: 0 | K13: 10 | L13: 근접 피해 감소 +5% | M13: 임시 장비 제작 | P13: 물리 저항 | Q13: 105 | R13: 0 | S13: 0
A14: 소방용 진압 도끼 | B14: 무기 | D14: 고등급자 / 선의관리국 요원 | E14: 콘텐츠 | F14: 185번 | 회사로 우회하며 소방 보급 상자에서 확보 | G14: 획득 시 귀속 | H14: 188번 붕괴 잔해 3개 파괴 후 반납 | I14: 75 | J14: 구조물 공격 보정 +30 | K14: 0 | M14: 구조 행동 속도 +15% | N14: 재난 구조 세트 | O14: 2세트: 구조 행동 속도 +10% 4세트: 화염·연기 피해 -15% | P14: 화염 대응 | Q14: 115 | R14: 68 | S14: 82
A15: 소방 방열복 | B15: 상의 | D15: 고등급자 / 선의관리국 요원 | E15: 퀘스트 | F15: 187번 | 부상당한 소방관 구조 후 임시 대여 | G15: 획득 시 귀속 | H15: 188번 고열·낙하물 구간 통과 후 반납 | I15: 0 | K15: 22 | L15: 화염 피해 감소 +20% | M15: 이동 속도 -5% | N15: 재난 구조 세트 | P15: 화염 저항 | Q15: 120 | R15: 0 | S15: 0
A16: 구조대 안전모 | B16: 머리 | D16: 일반인 / 모든 선의 등급자 | E16: 콘텐츠 | F16: 185번 | 회사로 우회하며 소방 보급 상자에서 확보 | H16: 186~188번 낙하물 피해 대응 후 반납 | I16: 0 | K16: 8 | L16: 낙하물 피해 감소 +15% | M16: 기절 시간 -10% | N16: 재난 구조 세트 | P16: 낙하 충격 저항 | Q16: 115 | R16: 0 | S16: 0
A17: 구조용 로프 발사기 | B17: 보조 장비 | D17: 고등급자 / 선의관리국 요원 | E17: 퀘스트 | F17: 185번 | 회사로 우회하며 소방 보급 상자에서 확보 | G17: 획득 시 귀속 | H17: 186번 1회·188번 1회 사용 후 2회분 소진 | I17: 12 | J17: 원거리 경직 보정 +5 | K17: 0 | M17: 구조 이동 경로 해금 | N17: 재난 구조 세트 | P17: 이동 보조 패시브 | Q17: 2회 | R17: 10 | S17: 14
A18: 오염 차단 전신복 | B18: 상의 | D18: 고등급자 | E18: 퀘스트 | F18: 196번 | 관리국 현장 보급함에서 수령·장착 | G18: 획득 시 귀속 | H18: 213~217번 폐교 오염 조사·270번 최종 장비로 교체 | I18: 0 | K18: 35 | L18: 균열 오염 저항 +20 | M18: 자아 마모 누적량 -8% | N18: 심층 균열 탐사 세트 | O18: 2세트: 균열 감지 범위 +3m 4세트: 자아 마모 누적량 -12% | P18: 균열 저항 | Q18: 120 | R18: 0 | S18: 0
A19: 심층 균열 탐사 헬멧 | B19: 머리 | D19: 고등급자 | E19: 퀘스트 | F19: 196번 | 관리국 현장 보급함에서 수령·장착 | G19: 획득 시 귀속 | H19: 213·217번 흔적·퍼즐 단서 탐지 | I19: 0 | K19: 12 | L19: 정신 피해 저항 +10 | M19: 균열 감지 범위 +4m | N19: 심층 균열 탐사 세트 | P19: 균열 감지 패시브 | Q19: +4m | R19: 0 | S19: 0
A20: 선의 안정 장치 | B20: 액세서리 | D20: 차한해 전용 | E20: 업적 | F20: 196번 | 시민 구조 누적 30회 달성 후 관리국 현장 보급함에서 추가 수령 | G20: 획득 시 귀속 | H20: 249번 친구 정체 확인 시 1회 자동 발동 | I20: 0 | K20: 0 | M20: 자아마모 수치 유지·입력 흔들림 10초 완화 | N20: 심층 균열 탐사 세트 | P20: 입력 안정 | Q20: 10초 | R20: 0 | S20: 0
A21: 고밀도 충격 흡수 장화 | B21: 신발 | D21: 고등급자 | E21: 퀘스트 | F21: 196번 | 관리국 현장 보급함에서 수령·장착 | G21: 획득 시 귀속 | H21: 215번 밀치기 방어·251번 친구 접근·270번 강화 전투화로 교체 | I21: 0 | K21: 10 | L21: 넘어짐·밀쳐짐 저항 +20% | M21: 회피 후 경직 시간 -10% | N21: 심층 균열 탐사 세트 | P21: 기동 안정 | Q21: 120 | R21: 0 | S21: 0
A22: 응급 압박 붕대 | B22: 소모품 | D22: 일반인 / 모든 선의 등급자 | E22: 보급 | F22: 144번 | 봉쇄 대피소 보급 상자에서 획득 | H22: 146번 나만 살아서 다행 보스전에서 1회 사용 | I22: 0 | K22: 0 | M22: 체력 20% 회복 | P22: 회복 | Q22: 20 | R22: 0 | S22: 0
A23: 관리국 응급 주사 | B23: 소모품 | D23: 선의관리국 요원 | E23: 퀘스트 | F23: 118번 | 관리국 표준 대응 장비와 함께 지급 | G23: 획득 시 귀속 | H23: 168번 합치면 강해진댔잖아 보스전에서 1회 사용 | I23: 0 | K23: 0 | M23: 체력 35% 회복, 이동 속도 5초간 -10% | P23: 회복 | Q23: 35 | R23: 0 | S23: 0
A24: 안정 앰플 | B24: 소모품 | D24: 고등급자 / 차한해 전용 | E24: 퀘스트 | F24: 192번 | 나대진에게 환경 장비와 함께 수령 | G24: 획득 시 귀속 | H24: 250번 공격 중지 생존 구간에서 1회 사용 | I24: 0 | K24: 0 | M24: 자아마모 수치 유지·UI 간섭 8초 완화 | P24: UI 안정 | Q24: 8초 | R24: 0 | S24: 0
A25: 소형 방진 필터 | B25: 소모품 | D25: 일반인 / 모든 선의 등급자 | E25: 보급 | F25: 121번 | 도심 잔해 구역 이동 중 관리국 보급 상자에서 획득 | H25: 128번 관리국 방진 마스크에 1회 사용 | I25: 0 | K25: 0 | M25: 마스크 내구도 30 회복 | P25: 장비 회복 | Q25: 30 | R25: 0 | S25: 0
A26: 휴대용 섬광 신호기 | B26: 소모품 | D26: 일반인 / 모든 선의 등급자 | E26: 콘텐츠 | F26: 134번 | 구조한 경찰에게 깨진 방패와 함께 받기 | H26: 141번 내자리산호 유인에 1회 사용 | I26: 0 | K26: 0 | M26: 일반 괴물 주의 분산 4초 | P26: 시야 교란 | Q26: 4 | R26: 0 | S26: 0
A27: 비살상 충격탄 | B27: 탄약 | D27: 선의관리국 요원 | E27: 퀘스트 | F27: 118번 | 관리국 표준 대응 장비와 함께 지급 | G27: 획득 시 귀속 | H27: 119번 사격 훈련·125번 비살상 제압에 사용 | I27: 6 | J27: 경직 피해 +20% | K27: 0 | M27: 처치 대신 제압 게이지 증가 | P27: 비살상 충격 | Q27: 120 | R27: 5 | S27: 7
A28: 고등급자 공명 증폭기 | B28: 액세서리 | D28: 고등급자 | E28: 나대진 지급 | F28: 153번 | [나대진] 75% 이상에서 장비 지원으로 수령 | G28: 획득 시 귀속 | H28: 159번 공명 탐지·160번 찰싹진드기 제압 | I28: 15 | J28: 균열 개체 대상 피해 +8% | K28: 0 | M28: 공명 피해 증가·UI 간섭 +3% | P28: 공명 증폭 | Q28: 108 | R28: 13 | S28: 17
A29: 연구실 최고 권한 키카드 | B29: 접근 도구 | D29: 연구실 최고 권한자 | E29: 나대진 안내·현장 회수 | F29: 265번 | [나대진] 85% 이상에서 암호 경로를 따라 연구시설 책임자 단말에서 회수 | G29: 획득 시 귀속 | H29: 266번 | 첫 번째 연구시설 보안문 해제 | I29: 0 | K29: 0 | M29: 최고 보안 구역 접근 | P29: 접근 권한 | Q29: 최고 | R29: 0 | S29: 0
A30: 보안 요원 생체 인증 모듈 | B30: 접근 도구 | D30: 차한해 | E30: 몬스터 제압·회수 | F30: 265번 | 권한이 없습니다 제압 후 노출된 생체 인증 모듈 회수 | G30: 획득 시 귀속 | H30: 266번 | 두 번째 연구시설 생체 인식문 1회 해제 | I30: 0 | K30: 0 | M30: 보안 구역 접근 | P30: 생체 인증 | Q30: 1회 | R30: 0 | S30: 0
A31: 충격 보호대 | B31: 보조 장비 | D31: 차한해 | E31: 나대진 지급 | F31: 153번 | 충격 보호대·공명 보호 장갑·공명 증폭기 수령 | G31: 획득 시 귀속 | H31: 164~168번 합치면 강해진댔잖아 보스전에서 사용 | I31: 0 | K31: 20 | L31: 피격 경직 감소 | P31: 충격 보호 | Q31: 20 | R31: 0 | S31: 0
A32: 공명 보호 장갑 | B32: 손 | D32: 차한해 | E32: 나대진 지급 | F32: 153번 | 충격 보호대·공명 보호 장갑·공명 증폭기 수령 | G32: 획득 시 귀속 | H32: 159~168번 공명 무기·증폭기 사용 부담 완화 | I32: 0 | K32: 15 | L32: 공명 반동 감소 | P32: 공명 보호 | Q32: 15 | R32: 0 | S32: 0
A33: 전광판 쇠막대 | B33: 무기 | D33: 차한해 | E33: 현장 획득 | F33: 159번 | 차한해에게만 보이는 보랏빛 아우라와 공명 증폭기 반응이 겹치는 쇠막대 회수 | H33: 160번 찰싹진드기 제압 | I33: 100 | J33: 다수 정렬 타격 | K33: 0 | P33: 충격 | Q33: 100 | R33: 90 | S33: 110
A34: 군용 방탄판 | B34: 상의 | D34: 차한해 | E34: 군인 지원 | F34: 169번 | 구조된 군인에게 지원받기 | G34: 획득 시 귀속 | H34: 178~181번 박수 없인 못 살아 보스전·181번 균열 | I34: 0 | K34: 35 | L34: 강한 공격 방어 | P34: 물리 저항 | Q34: 35 | R34: 0 | S34: 0
A35: 화염 보호복 | B35: 상의 | D35: 차한해 | E35: 소방관 지원 | F35: 187번 | 도시 인연 50% 이상에서 부상당한 소방관 구조 보상으로 획득 | G35: 획득 시 귀속 | H35: 188번 회사 화재 구조·손상 후 +10 유지 | I35: 0 | K35: 20 | L35: 화염 피해 대응 | P35: 화염 저항 | Q35: 20 | R35: 0 | S35: 0
A36: 먼지 보호 안경 | B36: 얼굴 | D36: 차한해 | E36: 나대진 지급 | F36: 192번 | 폐교 환경 장비 수령 | G36: 획득 시 귀속 | H36: 213~217번 폐교 분진·시야 방해 구간 | I36: 0 | K36: 10 | L36: 분진 시야 확보 | P36: 분진 저항 | Q36: 10 | R36: 0 | S36: 0
A37: 균열 보호 마스크 | B37: 얼굴 | D37: 차한해 | E37: 나대진 지급 | F37: 192번 | 폐교 환경 장비 수령 | G37: 획득 시 귀속 | H37: 213~217번 폐교 균열 오염 구간 | I37: 0 | K37: 15 | L37: 균열 오염 차단 | P37: 균열 저항 | Q37: 15 | R37: 0 | S37: 0
A38: 철판 보호대 | B38: 보조 장비 | D38: 차한해 | E38: 정비공 지원 | F38: 194번 | 구조받은 정비공에게 획득 | G38: 획득 시 귀속 | H38: 246~251번 별을 삼킨 강당전·251번 파손 | I38: 0 | K38: 25 | L38: 충격 보호 | P38: 물리 저항 | Q38: 25 | R38: 0 | S38: 0
A39: 사랑의 매 | B39: 무기 | D39: 차한해 | E39: 현장 획득 | F39: 237번 | 변혜서의 기억과 공명해 차한해에게만 보랏빛으로 보이는 사랑의 매 회수 | H39: 238번 시험·246번 별을 삼킨 강당 외피 파괴 | I39: 140 | J39: 공명 외피 파괴 | K39: 0 | P39: 공명 | Q39: 140 | R39: 126 | S39: 154
A40: 매트 보호대 | B40: 보조 장비 | D40: 차한해 | E40: 현장 제작 | F40: 242번 | 체육관 매트로 제작 | G40: 획득 시 귀속 | H40: 246~251번 별을 삼킨 강당전·251번 파손 | I40: 0 | K40: 15 | L40: 충격 완화 | P40: 물리 저항 | Q40: 15 | R40: 0 | S40: 0
...

Sheet 속성 대차대조표
A1: 1. 속성 정의 및 적용 대상
A2: 속성 | B2: 핵심 성질 | E2: 공격 속성 적용 | I2: 방어 속성 적용 | M2: 대표 표현
A3: 안정 | B3: 형태와 에너지의 상태를 고정하고 과도한 진동을 억제하는 파장 | E3: 공명 주기 고정, 흔들림 억제, 변이체의 움직임 안정화 | I3: 공명·진동 피해 완화, 밀려남과 흔들림을 억제하는 방호 상태 | M3: 청색 고정선, 입자가 한 지점으로 모이는 연출
A4: 공명 | B4: 파동을 반복·중첩하여 내부 진동과 에너지 증폭을 일으키는 파장 | E4: 반복 타격과 파동 중첩, 차단 한계 초과, 균열 확대 | I4: 외부 파장을 되울리거나 분산하여 충격을 흘려보내는 상태 | M4: 보라색 파문, 동심원과 진동 잔상
A5: 차단 | B5: 에너지·파장·오염의 전달 경로와 연결을 끊는 파장 | E5: 능력 연결 절단, 침식 확산 중단, 유지 에너지 공급 방해 | I5: 외부 에너지 유입과 상태이상 전이를 막는 방호 상태 | M5: 짙은 회색 단절선, 벽 형태의 끊김 연출
A6: 침식 | B6: 조직과 구조의 결합을 약화하고 형태를 점진적으로 붕괴시키는 파장 | E6: 고정 구조 붕괴, 방어 상태 약화, 균열 부위 확대 | I6: 공격 에너지를 분해·흡수하며 일부 피해를 약화하는 상태 | M6: 자홍색 번짐, 표면이 부식되듯 퍼지는 연출
A8: 2. 속성 대차대조표 및 피해 계산 검증
A9: 피해 매개 상수표 K | G9: 상성 순환
A10: 공격자＼방어자 | B10: 안정 | C10: 공명 | D10: 차단 | E10: 침식 | L10: 안정 → 공명 → 차단 → 침식 → 안정은 ×1.7의 강한 우위 관계이며, 반대 방향은 ×0.3의 강한 열위 관계로 적용함.
A11: 안정 | B11: 1 | C11: 1.7 | D11: 0.8 | E11: 0.3
A12: 공명 | B12: 0.3 | C12: 1 | D12: 1.7 | E12: 1.2
A13: 차단 | B13: 1.2 | C13: 0.3 | D13: 1 | E13: 1.7
A14: 침식 | B14: 1.7 | C14: 0.8 | D14: 0.3 | E14: 1
A16: 3. 수치 근거표
A17: 공격 속성 | B17: 방어 속성 | C17: 관계 유형 | E17: 매개 상수 | G17: 수치 적용 근거 | L17: 전투 표현
A18: 안정 | B18: 안정 | C18: 동일 | E18: 1 | G18: 동일한 파장끼리는 서로 우위가 없으므로 기존 피해식에 영향을 주지 않음. | L18: 기본 피해 수치와 기본 속성 이펙트 적용
A19: 안정 | B19: 공명 | C19: 강한 우위 | E19: 1.7 | G19: 안정 파장이 진동 주기를 고정하여 공명의 반복·증폭 작용을 직접 억제함. | L19: 파동이 멈추고 약점 적중 이펙트 강조
A20: 안정 | B20: 차단 | C20: 약한 열위 | E20: 0.8 | G20: 차단 상태가 안정 파장의 전달 경로를 일부 끊어 고정 효과가 충분히 도달하지 못함. | L20: 안정선이 끊기며 피해 표시를 약하게 표현
A21: 안정 | B21: 침식 | C21: 강한 열위 | E21: 0.3 | G21: 이미 침식된 구조는 고정할 원형과 기준이 약해 안정화 효과가 크게 감소함. | L21: 고정선이 번짐에 흡수되는 연출
A22: 공명 | B22: 안정 | C22: 강한 열위 | E22: 0.3 | G22: 안정된 구조가 진동의 확산과 파동 중첩을 막아 공명 증폭이 발생하기 어려움. | L22: 파문이 짧게 사라지는 연출
A23: 공명 | B23: 공명 | C23: 동일 | E23: 1 | G23: 동일한 파장끼리는 서로 우위가 없으므로 기존 피해식에 영향을 주지 않음. | L23: 기본 피해 수치와 기본 속성 이펙트 적용
A24: 공명 | B24: 차단 | C24: 강한 우위 | E24: 1.7 | G24: 반복되는 공명 파동이 차단 상태의 처리 한계를 넘어 과부하를 발생시킴. | L24: 차단벽에 균열이 번지고 파동이 관통하는 연출
A25: 공명 | B25: 침식 | C25: 약한 우위 | E25: 1.2 | G25: 침식으로 약해진 구조의 미세 균열을 진동이 확대하여 붕괴를 촉진함. | L25: 침식 부위가 파동에 따라 넓어지는 연출
A26: 차단 | B26: 안정 | C26: 약한 우위 | E26: 1.2 | G26: 안정 상태를 유지하는 에너지 공급과 연결을 끊어 구조의 유지력을 약화함. | L26: 고정선 일부가 끊기며 약점 이펙트 표시
A27: 차단 | B27: 공명 | C27: 강한 열위 | E27: 0.3 | G27: 공명은 파동이 누적된 뒤에도 영향이 남아 단일 연결 차단만으로 완전히 제거하기 어려움. | L27: 차단선 너머로 파문이 이어지는 연출
A28: 차단 | B28: 차단 | C28: 동일 | E28: 1 | G28: 동일한 파장끼리는 서로 우위가 없으므로 기존 피해식에 영향을 주지 않음. | L28: 기본 피해 수치와 기본 속성 이펙트 적용
A29: 차단 | B29: 침식 | C29: 강한 우위 | E29: 1.7 | G29: 침식 에너지의 접촉·전이·확산 경로를 끊어 핵심 작용을 직접 무력화함. | L29: 번짐이 절단되고 약점 적중 이펙트 강조
... A33: 침식 | B33: 침식 | C33: 동일 | E33: 1 | G33: 동일한 파장끼리는 서로 우위가 없으므로 기존 피해식에 영향을 주지 않음. | L33: 기본 피해 수치와 기본 속성 이펙트 적용

Sheet 몬스터
B1: 검증 항목 | C1: 값 | E1: 작성 기준
B2: 전체 콘텐츠 수 | C2: 306 | E2: [신규 몬스터 작성 기준] 1) 초기 변이체만 전신 80~100%를 짙은 보라·자주·연보라로 구성하고, 단세포·점액·세포낭처럼 얼굴·손발 없는 단순 실루엣을 사용함. 2) 일반 변이체부터는 비인간 생물·사물·군체형을 기본으로 하며 보라색은 핵·균열·관절·체액에만 20~45% 사용함. 3) 일반→강화→선도체→보스 단계가 오를수록 외피, 복합 기관, 부하 통제 기관, 공간·사물 융합이 증가해 더 강해 보이게 함. 4) 3장 세포·심해생물, 4장 갑각류·문·대피소, 5장 곤충·갈채·카메라, 6장 빈 교복·교구, 7장 기계·압류·계량으로 챕터 서사를 구분함. 5) 인간 기원은 음성·행동·소지품·기억으로 암시함. 폐교의 빈 복장 연출 외에는 사람 얼굴·손·다리·직립 인체 비례를 사용하지 않음.
B3: 몬스터 배치 콘텐츠 수 | C3: =COUNTIF(C7:C312,"<>") -> 43
B4: 몬스터 미배치 콘텐츠 수 | C4: =C2-C3 -> 263
B5: 콘텐츠 누락 개수 | C5: =C2-COUNT(A7:A312) -> 0
A6: 콘텐츠 제시 순서 | C6: 몬스터 이름 | D6: 몬스터 이미지 | E6: 몬스터 타입 | F6: 생명력 | G6: 공격력 | H6: 공격력 합산 STATUS | I6: 공격력 보정 | J6: 최종 공격력 | K6: 방어력 | L6: 방어력 합산 STATUS | M6: 방어력 보정 | N6: 최종 방어력 | O6: 스킬1 | P6: 발동률1 | Q6: 스킬2 | R6: 발동률2 | S6: 스킬3 | T6: 발동률3 | U6: 스킬4 | V6: 발동률4 | W6: 몬스터 속성 | X6: 비고
A7: 1 | J7: =IF(C7="","",G7+I7) | N7: =IF(C7="","",K7+M7)
A8: 2
A9: 3
A10: 4
A11: 5
A12: 6
A13: 7
A14: 8
A15: 9
A16: 10
A17: 11
A18: 12
A19: 13
... A70: 64
A71: 65 | J71: =IF(C71="","",G71+I71) | N71: =IF(C71="","",K71+M71)
A72: 66
A73: 67
A74: 68
A75: 69
A76: 70
A77: 71
A78: 72
A79: 73
A80: 74 | B80: 조건부 선공 | C80: 보라멍울 | E80: 초기 변이체 | F80: 30 | G80: 4 | H80: 근접 본능 | I80: 1 | J80: 5 | K80: 0 | L80: 불완전한 외피 | M80: 0 | N80: 0 | O80: 슥, 긁기 | P80: 70 | Q80: 꿈틀꿈틀 | R80: 30 | T80: 0 | V80: 0 | W80: 침식 | X80: 전신이 짙은 보라색인 아메바형 단세포. 얼굴·손발 없이 위족과 발광 핵만으로 움직이는 최초 조우 개체.
A81: 75
A82: 76
A83: 77
A84: 78 | B84: 조건부 선공 | C84: 문틈젤리 | E84: 초기 변이체 | F84: 60 | G84: 7 | H84: 기습 반응 | I84: 1 | J84: 8 | K84: 2 | L84: 웅크린 자세 | M84: 1 | N84: 3 | O84: 문 열면 나와! | P84: 45 | Q84: 여긴 내 틈 | R84: 35 | S84: 쭈욱! | T84: 20 | V84: 0 | W84: 안정 | X84: 전신 보라색의 납작한 세포막. 문틈에 붙어 있다가 꽃잎처럼 막을 펼치며 접근을 막는다.
A85: 79
A86: 80
A87: 81
A88: 82
A89: 83 | B89: 선공 | C89: 질질핵 | E89: 초기 변이체 | F89: 45 | G89: 5 | H89: 체중 충격 | I89: 1 | J89: 6 | K89: 1 | L89: 두꺼운 등 외피 | M89: 1 | N89: 2 | O89: 쿵. | P89: 60 | Q89: 질질질… | R89: 40 | T89: 0 | V89: 0 | W89: 침식 | X89: 길쭉한 보라 점액질 몸으로 밝은 핵을 끌고 다닌다. 느린 압박과 우회 학습을 담당한다.
A90: 84 | B90: 비선공 | C90: 울음주머니 | E90: 초기 변이체 | F90: 35 | G90: 4 | H90: 공포 음파 | I90: 1 | J90: 5 | K90: 0 | L90: 얇은 외피 | M90: 0 | N90: 0 | O90: 으아앙— | P90: 45 | Q90: 가까이 오지 마 | R90: 35 | S90: 숨 한번 | T90: 20 | V90: 0 | W90: 공명 | X90: 입 없는 보라색 세포낭. 몸 전체가 부풀고 수축할 때 사람과 비슷한 울음만 새어 나온다.
...

Sheet 밸런스 팩터
B2: 밸런스 팩터
B3: 게임 「넌 착해!」의 플레이 경험 조절 요소. 핵심 연결은 ① 권장 대표 경로 미들 3시간 40분·전체 선택 포함 4시간 이내, ② 선의 수치 96·836·999 ERROR와 836 청년의 특혜 상실 공포·거짓 소문·희생 선동, ③ 메인 60%·선택 최대 100% 도시 인연과 1장 어르신 선택, ④ 변혜서의 우정 반지·별 펜던트·폐교 기억, ⑤ 클릭헌터와 조회수는 못 참지의 동일 개체 연결, ⑥ 초기 변이체의 전신 보라 단세포형과 일반 이상 비인간형 실루엣, ⑦ 보스 6종+정예 균열 수호체 1종, 괴물 43종·아이템 42종, ⑧ 연구시설의 권한이 없습니다와 생체 인증 모듈 획득 흐름임
B5: 진행·콘텐츠 | J5: 서사·상태 | R5: 전투 | Z5: 가이드·편의 | AH5: 크기: 핵심(대) · 반복 조정(중) · 장면 조정(소)
B70: 큰 원은 플레이 전반에 미치는 영향이 큰 핵심 팩터이며, 작은 원은 장면·미션 단위에서 조정하는 세부 팩터임

Sheet 작성 기준
A1: 게임 「넌 착해!」 밸런스 문서 작성 기준
A2: 모든 시트가 7챕터·콘텐츠 진행 순서 1~306, 문서 전체·대표 경로 시간, 자아마모도, 도시·예쁜 고양이 인연, PC 성장·장비 변화와 다중 엔딩 조건을 동일하게 사용하도록 검증하는 기준표 | D2: 7챕터·콘텐츠 306개·권장 대표 경로 미들 3시간 40분·괴물 43종·아이템 42종·보스 6종+정예 1종을 모든 시트가 동일하게 사용. 스킬 DATA는 PC·NPC 지원·상태/시스템·몬스터/보스 총 211개 데이터를 하나의 표에서 관리
A3: 1. 밸런스 문서 핵심 항목
A4: 항목 | B4: 작성 방식 | C4: 값/형식 | D4: 우리 게임 적용 기준
A5: 플레이 난이도 | B5: 플레이어가 실제 입력을 수행할 때 느끼는 조작 난도 | C5: 1~10 정수 | D5: 1은 단순 확인·대화, 10은 빠른 보스 패턴과 복합 입력
A6: 플레이 흥미도 | B6: 기획자가 해당 구간에서 기대하는 재미의 목표값 | C6: 1~10 정수 | D6: 탐색·긴장·감정·반전·성취를 포함하며 실제 테스트값과 구분
A7: 콘텐츠 진행 순서 | B7: 게임 시작부터 엔딩까지 해금되는 모든 플레이 내용을 순서대로 기록 | C7: 1부터 연속 넘버링 | D7: 이동·조사·대화·전투·연출·선택 콘텐츠·장비 변화를 포함한 총 306개·7챕터. 연구시설 보안 전투는 265번에 편입
A8: 플레이 목표 | B8: 제목만 읽어도 플레이어가 해야 할 행동이 보이도록 작성 | C8: 행동형 제목 | D8: 예: 신상 과자 진열대 찾기, 아파트 계단에서 괴물을 피해 숨기
A9: 플레이 난관 | B9: 목표를 바로 달성하지 못하게 만드는 맵·NPC·시간·정보·전투 요소 | C9: 구체적 서술 | D9: 후보 수·시야 차단·시간 압박·감정적 부담 등을 기록
A10: 공략 방법 | B10: 플레이 난관을 해결하기 위해 관찰·판단·조작해야 하는 절차 | C10: 구체적 플레이 절차 | D10: 표에서 가장 핵심적인 항목으로 작성
A11: 체감 난이도 | B11: 플레이 난관 자체의 어려움과 원인을 함께 기록 | C11: 숫자/10 + 원인 | D11: 정보량·후보 수·패턴 수·시간 압박을 함께 평가
A12: 수행 과제 수 | B12: 해당 행을 완료하기 위해 필요한 행동·대상·단계의 수 | C12: 정수 | D12: 수거 8개, 단서 5개, 보스 패턴 3회 등
A13: 목표 달성 조건 | B13: 시스템이 완료를 판정할 수 있는 명확한 조건 | C13: 구체적 판정 조건 | D13: 목표 수량·트리거·퍼즐·보스 기믹 완료 등
A14: 실패 결과 | B14: 실패 시 재시작 지점이나 보상 감소 등 결과를 기록 | C14: 구체적 결과 또는 - | D14: 체력 0·시민 피해·오답 누적·시간 초과 등을 반영
A15: 예상 소요 시간 | B15: 라이트 유저가 초회 플레이에서 완료하는 기준 시간 | C15: 분·초 텍스트 | D15: 라이트 유저 열과 동일하게 작성
... A30: 전투 숙련 단계 | B30: 해당 전투를 안정적으로 공략하기 위한 조작·판단 수준 | C30: 1~9 또는 — | D30: PC DATA 기본 공격력 상승 시점과 전투 복잡도 검증에 사용
A31: 2. PC DATA 작성 기준
A32: 항목 | B32: 작성 방식 | C32: 값/형식 | D32: 우리 게임 적용 기준
A33: 플레이어 고유명(CLASS) | B33: 주인공의 고유명 또는 클래스 정체성 | C33: 텍스트 | D33: 닉네임이 아니라 차한해를 기록
A34: 콘텐츠 진행 순서 | B34: 능력치·장비·스킬이 최초 변화하는 시점 | C34: 밸런스 문서 번호 | D34: PC DATA는 능력치·장비·스킬이 처음 변하는 시점만 기록하고, PC DATA(대차대조표)는 1~306 모든 콘텐츠의 챕터·콘텐츠명·전투 상태·현재 기본 수치와 변화 근거를 기록
A35: 기본 공격력 | B35: 장비를 제외한 차한해의 전투 숙련 공격력 | C35: 10~560 정수 | D35: 일반인 기본 공격력 10. 79번에서 일회성 +990으로 순간 출력 1000, 118번부터 정식 전투 공격력 80→560 계단형 상승
A36: 공격력 합산 요소 | B36: 무기·공명 등 공격력에 더해지는 요소 | C36: 이름 + 보정값 | D36: 무기·공명·일회성 출력 변화는 최초 획득 또는 종료 시점만 기록
A37: 기본 방어력 | B37: 장비를 제외한 차한해의 피해 대응 숙련도 | C37: 10~220 정수 | D37: 일반인 기본 방어력 10. 정식 전투 개방 시 100으로 상승하고 공격 예측·충격 흘리기 숙련에 따라 220까지 증가
A38: 방어력 합산 요소 | B38: 방어구·보호 장비의 획득·파손·보정 변화 | C38: 이름 + 보정값 또는 변화값 | D38: 방어구는 획득·손상·성능 감소·완전 파손 시점만 기록
A39: 스킬 | B39: 지속 해금되는 PC 조작·판단 스킬의 이름을 최초 해금 시점에만 기록 | C39: 이름만 기록 | D39: 수치·발동 조건·상태이상·연계는 스킬 DATA에서 관리. 아이템 고유 행동과 엔딩 전용 강제 이벤트 스킬은 PC DATA에 반복 기입하지 않고 해당 콘텐츠와 스킬 DATA에서 연결
A40: 최초 등장·변화 원칙 | B40: 무기·스킬은 최초 등장, 방어구는 획득·성능 변화 시 기록 | C40: 변화 시점만 기록 | D40: PC DATA와 대차대조표 모두 무기·방어구·스킬을 매 행 누적 반복하지 않음. 변화 열은 최초 획득·교체·손상·파손 시점만 쓰고 나머지는 공란으로 유지
A41: 3. 우리 게임에서 제외한 항목
A42: 항목 | B42: 작성 방식 | C42: 값/형식 | D42: 우리 게임 적용 기준
A43: Lv·레벨업 필요 경험치·전직 퀘스트 | B43: 레벨과 전직 시스템이 없음 | C43: 챕터·스테이지·진행 관문 | D43: 삭제
A44: 몬스터 1체 경험치·퀘스트 보상 경험치 | B44: 처치 반복으로 성장하는 구조가 아님 | C44: 콘텐츠 진행 포인트 | D44: 삭제
A45: 레벨업 전투시간·필요 처치 수 | B45: 반복 사냥과 레벨업 루프가 없음 | C45: 전투 예상 시간·전투 숙련 단계 | D45: 삭제
A46: 파티플레이 보상 경험치 비율 | B46: 파티 경험치 분배 시스템이 없음 | C46: 인연 변화·다인 협력 기믹 | D46: 삭제
A47: 아이템 구매 기준가격·필요 처치 수 | B47: 전투 파밍 상점 경제가 핵심이 아님 | C47: 필요 시 별도 경제 시트 | D47: 전투 파밍 상점 경제는 제외. 정식 명칭의 아이템 42종에 획득·사용 콘텐츠를 연결하고, 연구시설의 권한이 없습니다까지 괴물 43종의 배치 번호를 추적
A48: 보스 경험치·레벨별 보스 분포 수 | B48: 보스가 레벨업 보상을 제공하지 않음 | C48: 보스 스테이지 수·스테이지 점수 | D48: 삭제
A49: 보스 타입 A/B 공통 시간 | B49: 보스마다 서사·기믹·페이즈가 달라 평균이 부정확함 | C49: 보스별 실제 페이즈 합 | D49: 삭제
A50: 퀘스트 레벨별 분포 개수 | B50: 퀘스트 레벨 구간이 없음 | C50: 챕터별 콘텐츠 수·진행 순서 | D50: 삭제
A51: 이동속도 A/B 고정 열 | B51: 일부 추격·호위에서만 필요해 대부분 공란 | C51: 난관·난이도 조절·밸런스 팩터 | D51: 필요 시 별도 시트
A52: 4. 시트 간 통일성 검증
A53: 항목 | B53: 작성 방식 | C53: 값/형식 | D53: 우리 게임 적용 기준
A54: 누적 플레이 시간 | B54: 예상 소요 시간 합계와 일치하는지 확인 | C54: 오차 0초 | D54: 문서 전체 라이트 4시간 15분 40초 · 미들 3시간 53분 35초 · 헤비 3시간 32분 20초 / 권장 대표 진엔딩 경로 라이트 4시간 · 미들 3시간 40분 · 헤비 3시간 20분
...

Sheet 밸런스 곡선
A1: 전체 밸런스 곡선 요약
A2: 문서 전체 라이트 4시간 15분 40초 · 미들 3시간 53분 35초 · 헤비 3시간 32분 20초 / 권장 대표 진엔딩 경로 라이트 4시간 · 미들 3시간 40분 · 헤비 3시간 20분 — 1장 자발적 선행 선택, 836 청년의 변질, 변혜서·클릭헌터, 연구시설 보안 전투, 괴물 43종·아이템 42종을 통합함
A3: 총 콘텐츠 수 | B3: 306 | C3: 평균 플레이 난이도 | D3: 2.88 | E3: 평균 플레이 흥미도 | F3: 8.29 | G3: 보스 스테이지 수 | H3: 6 | I3: 대표 진엔딩 예상 시간(미들 기준) | J3: 0.15277778
A4: 콘텐츠 진행 순서 | B4: 콘텐츠 진행 포인트 누적 | C4: 상위 스테이지 해금 요구 포인트 | D4: 누적 플레이 시간(라이트)
A5: 1 | B5: 3 | C5: 0 | D5: 0.00052083333
A6: 2 | B6: 5 | C6: 0 | D6: 0.00081018519
A7: 3 | B7: 8 | C7: 0 | D7: 0.0012731481
A8: 4 | B8: 11 | C8: 0 | D8: 0.0018518519
A9: 5 | B9: 13 | C9: 0 | D9: 0.0023726852
A10: 6 | B10: 15 | C10: 0 | D10: 0.0027777778
A11: 7 | B11: 18 | C11: 15 | D11: 0.0031828704
A12: 8 | B12: 22 | C12: 15 | D12: 0.003587963
A13: 9 | B13: 25 | C13: 15 | D13: 0.0039351852
A14: 10 | B14: 28 | C14: 15 | D14: 0.0047453704
A15: 11 | B15: 31 | C15: 28 | D15: 0.0052662037
A16: 12 | B16: 34 | C16: 28 | D16: 0.005787037
... A27: 23 | B27: 75 | C27: 53 | D27: 0.010763889
A28: 24 | B28: 81 | C28: 53 | D28: 0.011574074 | F28: 챕터 | G28: 콘텐츠 수 | H28: 라이트 | I28: 미들 | J28: 헤비
A29: 25 | B29: 84 | C29: 53 | D29: 0.012210648 | F29: 1 | 평범한 하루 | G29: 37 | H29: 0.017071759 | I29: 0.014525463 | J29: 0.012673611
A30: 26 | B30: 87 | C30: 84 | D30: 0.012673611 | F30: 2 | 금이 간 일상 | G30: 32 | H30: 0.0097800926 | I30: 0.0089699074 | J30: 0.0087384259
A31: 27 | B31: 91 | C31: 87 | D31: 0.012962963 | F31: 3 | 선택된 선의 | G31: 45 | H31: 0.017766204 | I31: 0.016608796 | J31: 0.014583333
A32: 28 | B32: 96 | C32: 87 | D32: 0.013541667 | F32: 4 | 영웅의 시작 | G32: 39 | H32: 0.018518519 | I32: 0.016782407 | J32: 0.01568287
A33: 29 | B33: 102 | C33: 87 | D33: 0.013946759 | F33: 5 | 영웅의 대가 | G33: 41 | H33: 0.028587963 | I33: 0.026099537 | J33: 0.024537037
A34: 30 | B34: 107 | C34: 87 | D34: 0.014293981 | F34: 6 | 남겨진 친구 | G34: 63 | H34: 0.039409722 | I34: 0.036168981 | J34: 0.032465278
A35: 31 | B35: 110 | C35: 87 | D35: 0.014583333 | F35: 7 | 강요된 희생 | G35: 49 | H35: 0.046412037 | I35: 0.043055556 | J35: 0.038773148
A36: 32 | B36: 113 | C36: 87 | D36: 0.014988426
A37: 33 | B37: 116 | C37: 113 | D37: 0.015335648
A38: 34 | B38: 120 | C38: 113 | D38: 0.015798611 | F38: 인연 대상 | G38: 초기값 | H38: 최종/범위 | I38: 설계 방향 | J38: 엔딩 조건
A39: 35 | B39: 125 | C39: 113 | D39: 0.016087963 | F39: 도시 | G39: 0 | H39: 기본 60%·최대 100% | I39: 메인 구조로 기본 인연을 보장하고 1장 어르신 돕기를 포함한 선택 콘텐츠 8개로 최대치 달성 | J39: 75%: 진실 은폐 공동 진입 신뢰 / 100%: 진실 공개 진엔딩
A40: 36 | B40: 128 | C40: 113 | D40: 0.016724537 | F40: 예쁜 고양이 | G40: 0 | H40: 0~100% | I40: 츄르 4개입과 선택 만남 4회로 25%씩 상승 | J40: 0~49% 두 고양이 간식 / 50~69% 대장 고양이 간식 / 70~99% 헤드번팅 없음 / 100% 전용 애교
A41: 37 | B41: 132 | C41: 128 | D41: 0.017071759 | F41: 차우선 | G41: 45 | H41: 엔딩별 변동 | I41: 심부름·대피·질투·원망·마지막 대면을 거쳐 관계 결산 | J41: 생존·희생 엔딩 후일담 분기
A42: 38 | B42: 135 | C42: 132 | D42: 0.017303241 | F42: 한도윤 | G42: 75 | H42: 100% 고정 | I42: 공원 협력·회사 구조 후 사망, 예약 음성으로 후반 감정 축 유지 | J42: 100%: 예약 음성·후일담 강화
A43: 39 | B43: 138 | C43: 132 | D43: 0.017418981 | F43: 이용익 | G43: 50 | H43: 0% | I43: 영웅화·고등급자 특혜·여론 조작·균열 진입 명령으로 하락 | J43: 비리 공개 선택 시 도시 인연 +5%
A44: 40 | B44: 140 | C44: 132 | D44: 0.017534722 | F44: 강재한 | G44: 45 | H44: 0% | I44: 정부 비판에서 폭력시위·희생 선동으로 적대화 | J44: 진엔딩에서 시민 증언으로 최종 설득 가능
A45: 41 | B45: 143 | C45: 132 | D45: 0.017766204 | F45: 나대진 | G45: 50 | H45: 100% | I45: 측정 안전·장비 지원·비상 계획·개인 기록 보존 | J45: 차한해를 자원이 아닌 사람으로 대하는 고정 조력자
A46: 42 | B46: 148 | C46: 132 | D46: 0.017939815
A47: 43 | B47: 151 | C47: 132 | D47: 0.018113426
A48: 44 | B48: 156 | C48: 132 | D48: 0.018576389
A49: 45 | B49: 160 | C49: 132 | D49: 0.018981481
A50: 46 | B50: 163 | C50: 132 | D50: 0.019386574
...

Sheet 보스 설계 요약
A1: 보스 밸런스 설계 요약
A2: 보스전은 개별 페이즈 합으로 계산하며 권장 대표 경로 미들 3시간 40분 안에서 6종 보스와 정예 수호체 1종의 규칙이 겹치지 않게 배치함. 보스 스킬명은 각 존재의 상황·목표·서사가 읽히도록 대사형·행동형으로 구성하고 실제 효과는 스킬 DATA의 상태·연계 값으로 공용화함. 변혜서는 포옹 뒤 잠깐 인간 모습으로 돌아와 감사한 후 완전히 소멸하며, 너만 무한이잖아는 차한해와 같은 균열 태생 존재임.
A4: 순서 | B4: 챕터·스테이지 | C4: 보스명 | D4: 인간 시절 핵심 서사 | E4: 선의 0 도달 원인 | F4: 전투 구조 | G4: 핵심 공략 | H4: 권장 전투 숙련도 | I4: 보스전 예상 시간(라이트) | J4: 보스전 예상 시간(미들) | K4: 보스전 예상 시간(헤비) | L4: 핵심 패턴 수 | M4: 실패·재시작 기준 | N4: 난이도 보정 | O4: 자아마모도 변화 | P4: 스테이지 점수 S | Q4: 서사적 승리 조건 | R4: 전후 완급 조절 | S4: 콘텐츠 소모율 조절 | T4: 검증
A5: 1 | B5: 4-E | 첫 보스·봉쇄 대피소 | C5: 나만 살아서 다행 | D5: 문밖 구조 요청이 진짜 사람임을 알았지만 괴물 소리와 자기보존 욕망 때문에 문을 닫은 대피소 관리자 | E5: 사람들이 사라진 뒤 ‘난 살아서 다행’이라고 안도한 순간 선의 0, 곧바로 균열에 들어가 변이 | F5: 연속 폐문·존재 무시·통로 봉쇄·잠금 핵 노출형 [문 닫습니다! / 밖에 있어. / 너도 밖으로. / 잠금 해제? 잠깐.] | G5: 방화문 재개방→문밖 시민 전원 구조→전 문 개방 유지→잠금 핵 무력화. 필요 시 PC [잠깐만!] 1회로 1초 경직 | H5: 6 | I5: 6분 | J5: 5분 30초 | K5: 5분 | L5: 4 | M5: 주인공 또는 시민 체력 0·시민 소멸·문 2개 이상 재폐쇄 시 현재 페이즈 재시작 | N5: 잠금 순서·시민 음성 방향·재폐쇄 예고·핵 노출 시간 표시 | O5: 0% (누적 0%) | P5: 4200 | Q5: 닫힌 문을 모두 열고 문밖 시민까지 구조한 뒤 잠금 핵을 무력화 | R5: 전: 경찰 방패·시민 제작 나무판 보호대 / 후: 장비 파손·구조 지연 비난 | S5: 3페이즈 체크포인트·실패한 페이즈부터 재시작 | T5: 일치 (146~148번, 6분·5분30초·5분, 자아마모 0%)
A6: 2 | B6: 5-C | 융합 보스·폭력의 순환 | C6: 합치면 강해진댔잖아 | D6: 폭력을 대신 받아낸 자와 살아남기 위해 폭력을 행사한 자의 기억이 하나의 외피에 갇힘 | E6: 희생과 복종이 폭력을 끝내지 못했다는 절망으로 인간에 대한 신뢰를 잃음 | F6: 융합 부위 교대·흡수·재생·폭주형 [한꺼번에 쾅! / 너도 붙어! / 하나 더 붙이면 돼 / 왜 더 약해져?!] | G6: 받아낼 공격·피할 공격 구분→시민 대피→연결 핵 동시 파괴 | H6: 8 | I6: 7분 | J6: 6분 30초 | K6: 6분 | L6: 6 | M6: 시민 체력 0·공격 규칙 오판 누적·시간 초과 시 현재 페이즈 재시작 | N6: 공격 전조·안전 방향·시민 이동 예상선 강화 | O6: +5% (누적 12%) | P6: 7600 | Q6: 때리는 자와 맞는 자를 연결한 폭력 순환 구조 자체 파괴 | R6: 전: 836 청년의 거짓 소문·차한해 단독 출동 / 후: 군용 방탄판 지원 | S6: 공격 규칙 교대와 시민 보호를 결합하고 전조만 단계 강화 | T6: 일치 (163~168번, 7분·6분30초·6분, 자아마모 +5%)
A7: 3 | B7: 5-F | 보스전·박수 없인 못 살아 | C7: 박수 없인 못 살아 | D7: 고등급자 특혜를 잃기 싫어 긴급 구조 알림을 끈 인물. 다른 고등급자도 출동하지 않아 대규모 사상자가 발생 | E7: 참사 뉴스를 보면서도 ‘내 수치를 지키려면 어쩔 수 없었다’고 합리화해 선의 0 | F7: 갈채 보호막·카메라 시야·실제 시민 판별형 [나 찍고 있지? / 박수 더! / 진짜 시민 맞아? / 박수 먹기] | G7: 카메라 사각 이동→중계 차단→실제 시민 판별→카메라 없는 구조 | H7: 8 | I7: 8분 | J7: 7분 30초 | K7: 7분 | L7: 4 | M7: 갈채 수치 최대·가짜 구조 오답 누적·시민 또는 주인공 체력 0 시 재시작 | N7: 카메라 시야·전원선·실제 시민 행동 단서 강화 | O7: +8% (누적 24%) | P7: 4800 | Q7: 아무도 보지 않는 곳에서 시민을 구조해 갈채 보호막 제거 | R7: 전: 긴급 알림 차단·연쇄 불출동 / 후: 구조 영상 부재로 여론 악화 | S7: 판별·환경 제어 중심, 오답만 체크포인트화 | T7: 일치 (178~181번, 8분·7분30초·7분, 자아마모 +8%)
A8: 4 | B8: 6-F | 폐교 본관 3층·환영전 | C8: 그날의 오답노트 | D8: 인간 출신이 아니라 변혜서의 기억 조각과 차한해의 죄책감을 재료로 균열이 만든 군체 | E8: 해당 없음 — 책상·칠판·보랏빛 세포막이 엉킨 비인간형 균열 구성체 | F8: 왜곡 장면·거짓 단서·죄책감 증폭·진실 닻 교체형 [그날은 이랬어. / 교실 다시 쓰기 / 네가 틀렸잖아. / 정답 바꾸기] | G8: 수집 증거로 왜곡 장면 판별→포위 해체→별 문양·보랏빛 진실 닻 확인→거짓 닻 3개 파괴 | H8: 8 | I8: 8분 30초 | J8: 8분 | K8: 7분 30초 | L8: 4 | M8: 왜곡 선택 3회·죄책감 최대·주인공 체력 0 시 현재 페이즈 재시작 | N8: 증거 바로 보기·거짓 닻 제거·진실 닻 잔광 강화 | O8: 0% (누적 53%) | P8: 5200 | Q8: 환영을 죽이는 것이 아니라 왜곡을 해체해 강당 열쇠와 진짜 기억 확보 | R8: 전: 졸업앨범·연락 기록 / 후: 강당 장비 준비·변혜서 대면 | S8: 2페이즈 증거 판별과 환경 파괴를 분리 | T8: 일치 (239~240번, 8분30초·8분·7분30초)
A9: 5 | B9: 6-G | 폐교 강당·보스전 | C9: 별을 삼킨 강당 | D9: 변혜서. 어린 시절 선하고 자존감 높아 차한해를 도왔지만 학교폭력으로 무너지고 타인의 고통까지 외면함 | E9: 과거의 자신처럼 괴롭힘당하는 아이를 ‘나도 도움받지 못했다’며 외면한 마지막 선택 | F9: 괴물 외피→기억 개입→별 목걸이 심장→공격 중지·포옹·소멸형 [아직 안 끝났어 / 공은 돌아온다 / 왜 이제 왔어? / 때리지 마.] | G9: 사랑의 매 외피 파괴→농구공 기억 핵 차단→변혜서 확인→[손 내려.]로 공격 중지→포옹 | H9: 9 | I9: 10분 | J9: 9분 30초 | K9: 9분 | L9: 6 | M9: 죄책감 최대·접근 피격 누적·공격 중지 실패 시 해당 페이즈 재시작 | N9: 우정 반지 완료 시 펜던트 식별·약점 경고 강화, 접근 체크포인트 제공 | O9: +27% (누적 80%) | P9: 8900 | Q9: 변혜서를 생존 복원하지 않고 포옹으로 고통에서 해방해 마지막 감사 뒤 완전히 보내 줌 | R9: 전: 우정 반지·졸업앨범·학교폭력 기억 / 후: 변혜서 소멸·인간 기원 공식 확인 | S9: 근·원거리 교대 뒤 공격 중지로 승리 규칙 전환 | T9: 일치 (246~251번, 10분·9분30초·9분, 변혜서 완전 소멸)
A10: 6 | B10: 7-H | 너만 무한이잖아 보스전 | C10: 너만 무한이잖아 | D10: 인간 출신이 아닌 차한해와 같은 균열 근원에서 태어난 존재로, 차한해와 둘이면서 하나임 | E10: 해당 없음 — 인간 변이체가 아니라 균열 태생 존재 | F10: 계량 규칙 변경·무한대 부담 장치·마지막 일격 동기화형 [등급부터 매길게. / 한 명이면 충분해. / 측정합니다. / 마지막은 같이.] | G10: [등급? 됐거든.]→표식 해제→[이번엔 같이.]로 무한대 부담 장치 파괴→핵 노출→마지막 일격 동기화 | H10: 9 | I10: 12분 30초 | J10: 12분 | K10: 11분 30초 | L10: 5 | M10: 차한해 체력 0·계량 장치 재가동 시 현재 페이즈 재시작 | N10: 등급 위험 순서·해제 연결선·핵 공명 주기 강화 | O10: +3% (진실 확인 포함·누적 100%) | P10: 6400 | Q10: 단순 처치가 아니라 마지막 일격으로 동기화해 태생과 두 해결 방법을 체험 | R10: 전: 거울 미로·껍데기의 바다·정예 수호체 / 후: 진실 공개·도시 인연 엔딩 판정 | S10: 전투 뒤 기억 체험으로 진실 전달·최종 선택 재시작 지점 분리 | T10: 일치 (285~288번, 12분30초·12분·11분30초, 기원 진실 290번)
A11: 정예 몬스터인 균열 수호체 ‘선의 압류관’는 인간 변이체가 아니라 균열에서 태어난 존재이며 보스 수에 포함하지 않음. 정예전 시간은 라이트 10분 30초·미들 10분·헤비 9분 30초로 별도 집계함.
A13: 보스명 | B13: 라이트(분) | C13: 미들(분) | D13: 헤비(분)
A14: 나만 살아서 다행 | B14: 6 | C14: 5.5 | D14: 5
A15: 합치면 강해진댔잖아 | B15: 7 | C15: 6.5 | D15: 6
A16: 박수 없인 못 살아 | B16: 8 | C16: 7.5 | D16: 7
A17: 그날의 오답노트 | B17: 8.5 | C17: 8 | D17: 7.5
A18: 별을 삼킨 강당 | B18: 10 | C18: 9.5 | D18: 9
A19: 너만 무한이잖아 | B19: 12.5 | C19: 12 | D19: 11.5

Sheet 스킬 DATA
A1: 넌 착해! — 스킬 DATA
A2: 스킬을 ‘약속 + UI + Data’로 정의한 시스템 연동용 표 · 총 211개 스킬/상태 데이터 · 피해 계수 1.00 = 해당 시점 기본/최종 공격력 100% · 몬스터 발동 확률은 몬스터 시트의 발동률과 동기화 · 이벤트 전용 스킬도 별도 시트로 분리하지 않고 본 표에서 통합 관리
A3: 관리 정보 | E3: UI 기재 내용 | K3: 발동 조건 | M3: 피해 | Q3: AI 제어 | S3: 조작·시간 | V3: 버프·디버프 | Z3: 연계·운영
A4: 스킬 ID | B4: 구간 | C4: 최초 사용 콘텐츠 | D4: 사용 주체 | E4: 스킬명 | F4: 스킬 추가 설명 | G4: 스킬 아이콘 | H4: 스킬 타입 | I4: 지정 사용자 | J4: 상태 이상 값 | K4: 발동 조건 타입 | L4: 발동 필요 값 | M4: 피해 적용 타입 | N4: 피해 계수 | O4: 고정 피해 | P4: 피해 산정식 | Q4: AI 발동 주기(초) | R4: AI 발동 확률 | S4: 쿨타임 타입 | T4: 쿨타임(초) | U4: 시전 필요 시간(초) | V4: 능력 변동 종류 | W4: 능력 변동 수치 | X4: 단위 | Y4: 지속 시간(초) | Z4: 종료·취소 조건 | AA4: 연계 스킬 ID | AB4: 비고
A5: SKL-PC-001 | B5: 기본 상호작용 | C5: 9번 | 알바생의 무거운 음료 박스 진열 부탁을 수락할지 선택하기 | D5: PC | E5: 싫어요. | F5: 거절 가능한 부탁·요청에서 수락 대신 사용해 해당 요청을 종료하는 기본 상호작용 스킬. 거절한 콘텐츠의 인연·보상 획득 기회는 포기함. | H5: 액티브 | I5: 차한해 | K5: 입력 | L5: 수락 전 [싫어요.] 선택 | M5: 없음 | N5: 0 | O5: 0 | P5: 피해 없음 | S5: 없음 | T5: 0 | U5: 0 | V5: 없음 | W5: 0 | X5: 없음 | Y5: 0 | Z5: 선택 확정 | AA5: 없음 | AB5: 게임 시작부터 해금·첫 사용 가능 콘텐츠 9번
A6: SKL-PC-002 | B6: 3장·첫 힘 발현 | C6: 79번 | 두 눈을 감고 양손으로 괴물을 막기 | D6: PC | E6: 펑! | F6: 괴물이 덮치기 직전 전용 UI에서 1회 발동하는 사건형 액티브. 무의식적 선의 폭발을 호출해 순간 출력 1000을 만들고 접촉 소멸까지 연쇄함. | H6: 연출용+액티브 | I6: 차한해 | K6: 1회 강제 발동 | L6: 문틈젤리 접촉 직전 | M6: 없음 | N6: 0 | O6: 0 | P6: 피해 없음 | S6: 없음 | T6: 0 | U6: 0.6 | V6: 공격력 | W6: 990 | X6: + | Y6: 0 | Z6: 접촉 소멸 완료 | AA6: SKL-STS-011 → SKL-STS-012 | AB6: 스토리 필수 사용·해당 콘텐츠에만 적용
A7: SKL-PC-003 | B7: 정식 전투 | C7: 119번 | 관리국 지급 권총·비살상 충격탄·관리국 전술화를 이용해 사격과 회피 연습하기 | D7: PC | E7: 탕! | F7: 장착한 총기·원거리 무기의 공격 수치를 포함해 정면 표적 1체를 공격하는 기본 사격. | H7: 액티브 | I7: 차한해 | J7: 경직 0.20초 | K7: 입력 | L7: 공격 입력 1회 | M7: 기본 공격력 비율 | N7: 1 | O7: 0 | P7: 기본 공격력 × 100% | S7: 개별 | T7: 0.45 | U7: 0.2 | V7: 없음 | W7: 0 | X7: 없음 | Y7: 0 | Z7: 시전 종료 | AA7: SKL-STS-001 | AB7: 관리국 지급 권총을 기준으로 최초 훈련
A8: SKL-PC-004 | B8: 정식 전투 | C8: 119번 | 관리국 지급 권총·비살상 충격탄·관리국 전술화를 이용해 사격과 회피 연습하기 | D8: PC | E8: 앗, 피해! | F8: 입력 방향으로 짧게 이동하며 공격 판정을 피하는 기본 회피. 성공 시 일부 반격 스킬의 조건을 열어 줌. | H8: 액티브 | I8: 차한해 | K8: 입력 | L8: 회피 입력 1회 | M8: 없음 | N8: 0 | O8: 0 | P8: 피해 없음 | S8: 개별 | T8: 1.8 | U8: 0.1 | V8: 이동 속도 | W8: 80 | X8: % | Y8: 0.25 | Z8: 이동 종료 | AA8: 없음 | AB8: 훈련 이후 상시 사용
A9: SKL-PC-005 | B9: 보스 공통 | C9: 146번 | 나만 살아서 다행이 연속으로 닫는 방화문 다시 열기 | D9: PC | E9: 잠깐만! | F9: 보스전에서 딱 1번 사용할 수 있는 보조 스킬. 보스의 현재 행동을 1초간 멈춰 위험 패턴을 끊을 틈을 만듦. | H9: 액티브 | I9: 보스 | J9: 경직 1.00초 | K9: 전투당 1회 | L9: 보스전·미사용 상태 | M9: 없음 | N9: 0 | O9: 0 | P9: 피해 없음 | S9: 전투당 1회 | T9: 0 | U9: 0.15 | V9: 없음 | W9: 0 | X9: 없음 | Y9: 1 | Z9: 1초 종료 | AA9: SKL-STS-001 | AB9: 118번에서 해금·146번 첫 보스부터 실제 사용 가능
A10: SKL-PC-006 | B10: 전투 정보 | C10: 125번 | 관리국 무전 이어피스로 똑똑소라의 공격 예고 신호 파악하기 | D10: PC | E10: 먼저 들었어 | F10: 관리국 무전 이어피스의 공격 예고 신호를 판독해 적의 전조를 기본보다 0.3초 먼저 표시하는 패시브. | H10: 패시브 | I10: 차한해 | K10: 장비 착용 | L10: 관리국 무전 이어피스 장착 | M10: 없음 | N10: 0 | O10: 0 | P10: 피해 없음 | S10: 없음 | T10: 0 | U10: 0 | V10: 전조 표시 시간 | W10: 0.3 | X10: 초 | Y10: 0 | Z10: 장비 해제 | AA10: 없음 | AB10: 장비 효과를 스킬 형태로 표현
A11: SKL-PC-007 | B11: 정식 전투 | C11: 126번 | 문틈새우의 후방 기습을 피하고 반격 타이밍 맞추기 | D11: PC | E11: 피했으면 내 차례 | F11: 직전 공격을 회피한 직후 짧은 반격 창에서 사용하는 대응 사격·타격. | H11: 액티브 | I11: 차한해 | J11: 경직 0.30초 | K11: 조건부 입력 | L11: 회피 성공 후 0.8초 이내 | M11: 기본 공격력 비율 | N11: 1.15 | O11: 0 | P11: 기본 공격력 × 115% | S11: 개별 | T11: 2 | U11: 0.25 | V11: 없음 | W11: 0 | X11: 없음 | Y11: 0 | Z11: 반격 창 종료 | AA11: SKL-STS-001 | AB11: 회피 성공을 공격 기회로 전환
A12: SKL-PC-008 | B12: 공명 전투 | C12: 130번 | 보랏빛 철봉으로 밖으로 나가재 제압하기 | D12: PC | E12: 보라색, 여기! | F12: 차한해에게만 보이는 보랏빛 공명 반응 부위를 노려 타격해 일반 공격보다 큰 약점 피해를 줌. | H12: 액티브 | I12: 차한해 | K12: 약점 노출 | L12: 보랏빛 약점 표식 활성 | M12: 기본 공격력 비율 | N12: 1.35 | O12: 0 | P12: 기본 공격력 × 135% | S12: 개별 | T12: 2.5 | U12: 0.35 | V12: 없음 | W12: 0 | X12: 없음 | Y12: 0 | Z12: 약점 타격 종료 | AA12: 없음 | AB12: 공명 약점이 없는 대상에는 사용 불가
A13: SKL-PC-009 | B13: 방어 전투 | C13: 134번 | 구조한 경찰에게 깨진 경찰 방패와 휴대용 섬광 신호기 받기 | D13: PC | E13: 앞은 내가 막아 | F13: 깨진 경찰 방패 등 전방 방어 장비를 들어 정면 피해와 밀려남을 줄이는 유지형 방어. | H13: 액티브 | I13: 차한해 | K13: 입력 유지 | L13: 방어 장비 장착·방어 입력 유지 | M13: 없음 | N13: 0 | O13: 0 | P13: 피해 없음 | S13: 유지형 | T13: 0 | U13: 0.15 | V13: 받는 정면 피해 | W13: -50 | X13: % | Y13: 0 | Z13: 입력 해제·방패 파손 | AA13: 없음 | AB13: 보스·강한 공격에는 감소량이 낮아질 수 있음
A14: SKL-PC-010 | B14: 환경 유인 | C14: 141번 | 휴대용 섬광 신호기와 차단기 막대로 내자리산호 유인하기 | D14: PC | E14: 저기 봐! | F14: 휴대용 섬광 신호기 1개를 소비해 일반 변이체의 주의를 설치 지점으로 4초간 돌리는 비전투·전투 겸용 스킬. | H14: 연출용+액티브 | I14: 일반 변이체 | J14: 주의 분산 4초 | K14: 아이템 사용 | L14: 휴대용 섬광 신호기 1회 소모 | M14: 없음 | N14: 0 | O14: 0 | P14: 피해 없음 | S14: 아이템 횟수 | T14: 0 | U14: 0.4 | V14: 표적 인식 | W14: -1 | X14: 대상 | Y14: 4 | Z14: 지속 종료·보스 면역 | AA14: SKL-STS-010 | AB14: PPT의 폭죽형 유틸리티 스킬과 같은 구조
A15: SKL-PC-011 | B15: 환경 유인 | C15: 141번 | 휴대용 섬광 신호기와 차단기 막대로 내자리산호 유인하기 | D15: PC | E15: 이쪽이야! | F15: 차단기 막대나 주변 소음 오브젝트를 이용해 주의가 분산된 적의 이동 목표를 열린 공간으로 유도함. | H15: 액티브 | I15: 차한해 | K15: 환경 상호작용 | L15: 유인 가능한 오브젝트 활성 | M15: 없음 | N15: 0 | O15: 0 | P15: 피해 없음 | S15: 개별 | T15: 3 | U15: 0.3 | V15: 이동 목표 | W15: 1 | X15: 지점 | Y15: 3 | Z15: 대상 도달·지속 종료 | AA15: SKL-STS-007 | AB15: 환경 지형과 함께 사용하는 전술형 스킬
A16: SKL-PC-012 | B16: 첫 보스 | C16: 148번 | 모든 문을 열린 채 고정하고 잠금 핵 무력화하기 | D16: PC | E16: 핵부터! | F16: 보스의 노출된 핵에 공격을 집중해 외피보다 큰 파괴 효율을 내는 상황형 집중 공격. | H16: 액티브 | I16: 차한해 | K16: 약점 노출 | L16: 보스 핵 노출 상태 | M16: 기본 공격력 비율 | N16: 1.4 | O16: 0 | P16: 기본 공격력 × 140% | S16: 개별 | T16: 1.5 | U16: 0.3 | V16: 핵 피해 | W16: 40 | X16: % | Y16: 0 | Z16: 핵 은폐 | AA16: 없음 | AB16: 노출 약점 전용
A17: SKL-PC-013 | B17: 공명 장비 | C17: 153번 | 나대진에게 충격 보호대·공명 보호 장갑·고등급자 공명 증폭기 수령하기 | D17: PC | E17: 증폭기, 켠다! | F17: 고등급자 공명 증폭기를 켜 공명 대상 공격력을 높이는 대신 화면 간섭을 함께 발생시키는 장비 액티브. | H17: 액티브 | I17: 차한해 | J17: UI 간섭 | K17: 장비 사용 | L17: 고등급자 공명 증폭기 장착 | M17: 없음 | N17: 0 | O17: 0 | P17: 피해 없음 | S17: 개별 | T17: 8 | U17: 0.35 | V17: 공격력 | W17: 15 | X17: + | Y17: 8 | Z17: 장비 해제·지속 종료 | AA17: 없음 | AB17: 공명 대상 피해 +8%·UI 간섭 +3%는 아이템 시트 값 적용
A18: SKL-PC-014 | B18: 다수 전투 | C18: 160번 | 공명 증폭기와 전광판 쇠막대로 승강장의 찰싹진드기 제압하기 | D18: PC | E18: 한 줄로 서! | F18: 전광판 쇠막대의 넓은 궤적으로 일렬에 겹친 여러 적을 한 번에 타격하는 정렬 공격. | H18: 액티브 | I18: 차한해 | K18: 입력 | L18: 2체 이상 일렬 정렬 | M18: 기본 공격력 비율 | N18: 1.1 | O18: 0 | P18: 기본 공격력 × 110% | S18: 개별 | T18: 3.2 | U18: 0.5 | V18: 최대 타격 수 | W18: 3 | X18: 체 | Y18: 0 | Z18: 시전 종료 | AA18: 없음 | AB18: 대상별 피해 동일
A19: SKL-PC-015 | B19: 융합 보스 | C19: 163번 | 합치면 강해진댔잖아의 단일 외피 공략하기 | D19: PC | E19: 둘 중 하나! | F19: 상반된 공격 전조를 읽고 이번 공격을 받아낼지 피할지 판별하는 판단형 패시브. | H19: 패시브 | I19: 차한해 | K19: 패턴 판독 | L19: 상반 전조 발생 | M19: 없음 | N19: 0 | O19: 0 | P19: 피해 없음 | S19: 없음 | T19: 0 | U19: 0 | V19: 판독 표시 | W19: 1 | X19: 회 | Y19: 0 | Z19: 해당 공격 종료 | AA19: 없음 | AB19: 잘못 판독하면 보스 패턴 페널티 적용
A20: SKL-PC-016 | B20: 융합 보스 | C20: 168번 | 관리국 응급 주사를 사용하고 폭력의 순환 핵 파괴하기 | D20: PC | E20: 하나, 둘—지금! | F20: 동시에 노출된 2개의 연결 핵을 짧은 허용 시간 안에 맞혀 폭력의 순환 연결을 끊는 동시 타격. | H20: 액티브 | I20: 차한해 | K20: 동시 조건 | L20: 연결 핵 2개 동시 노출 | M20: 기본 공격력 비율 | N20: 1.2 | O20: 0 | P20: 기본 공격력 × 120% | S20: 개별 | T20: 5 | U20: 0.45 | V20: 동시 판정 시간 | W20: 0.6 | X20: 초 | Y20: 0 | Z20: 핵 파괴·허용 시간 초과 | AA20: 없음 | AB20: 2개 핵 모두 적중해야 성공
A21: SKL-PC-017 | B21: 중장비 방어 | C21: 169번 | 구조된 군인에게 군용 방탄판 받기 | D21: PC | E21: 버텨! | F21: 군용 방탄판 등 중량 방어구를 이용해 강한 단발 공격을 정면에서 받아내고 밀려남을 크게 줄임. | H21: 액티브 | I21: 차한해 | K21: 조건부 입력 | L21: 강공격 전조 중 방어 입력 | M21: 없음 | N21: 0 | O21: 0 | P21: 피해 없음 | S21: 개별 | T21: 4 | U21: 0.2 | V21: 받는 피해 | W21: -35 | X21: % | Y21: 1 | Z21: 강공격 종료 | AA21: SKL-STS-002 | AB21: 방어구 내구도 소모
A22: SKL-PC-018 | B22: 갈채 보스 | C22: 179번 | 추앙풍뎅이의 보호막 부여를 차단하고 중계 카메라 끄기 | D22: PC | E22: 안 찍히면 돼 | F22: 카메라 시야와 스포트라이트를 피해 사각지대에서 이동하면 갈채 계열 적의 추적·강화 조건을 끊음. | H22: 패시브 | I22: 차한해 | K22: 위치 조건 | L22: 카메라 시야 밖 | M22: 없음 | N22: 0 | O22: 0 | P22: 피해 없음 | S22: 없음 | T22: 0 | U22: 0 | V22: 갈채 획득 | W22: 0 | X22: 고정 | Y22: 0 | Z22: 카메라 시야 진입 | AA22: SKL-STS-016 | AB22: 카메라 없는 행동이 보스 기믹을 약화
A23: SKL-PC-019 | B23: 갈채 보스 | C23: 181번 | 아무도 보지 않는 곳에서 시민을 구하고 박수 없인 못 살아 제압하기 | D23: PC | E23: 아무도 안 봐도 | F23: 카메라가 없는 위치에서 실제 시민을 구조해 갈채와 무관한 선행을 증명하고 보스 보호막을 제거하는 사건형 행동. | H23: 연출용+액티브 | I23: 차한해 | K23: 사건 조건 | L23: 실제 시민 판별·카메라 비노출 | M23: 없음 | N23: 0 | O23: 0 | P23: 피해 없음 | S23: 없음 | T23: 0 | U23: 1 | V23: 보호막 | W23: 0 | X23: 고정 | Y23: 0 | Z23: 구조 완료 | AA23: SKL-STS-016 | AB23: 서사와 보스 공략을 직접 연결
A24: SKL-PC-020 | B24: 회사 구조 | C24: 186번 | 구조용 로프 발사기로 한도윤과 회사 직원 대피시키기 | D24: PC | E24: 도와줘! | F24: 현재 콘텐츠에 사전 정의된 지원 행동이 있고 해당 NPC의 인연·위치 조건을 만족할 때만 지원을 호출하는 제한형 스킬. | H24: 액티브 | I24: 지원 가능 NPC | K24: 상황 조건 | L24: 지원 가능 NPC·인연·콘텐츠 플래그 충족 | M24: 없음 | N24: 0 | O24: 0 | P24: 피해 없음 | S24: 상황당 1회 | T24: 0 | U24: 0.3 | V24: 없음 | W24: 0 | X24: 없음 | Y24: 0 | Z24: 지원 행동 완료 | AA24: SKL-NPC-001 / SKL-NPC-002 | AB24: 범용 동료 AI가 아니라 콘텐츠별 고정 지원 행동 호출
A25: SKL-PC-021 | B25: 회사 구조 | C25: 186번 | 구조용 로프 발사기로 한도윤과 회사 직원 대피시키기 | D25: PC | E25: 길 하나 만들게! | F25: 구조용 로프 발사기 1회를 소비해 끊어진 계단·붕괴 통로에 임시 이동 경로를 생성함. | H25: 연출용+액티브 | I25: 차한해 | K25: 아이템 사용 | L25: 구조용 로프 발사기 1회 소모 | M25: 없음 | N25: 0 | O25: 0 | P25: 피해 없음 | S25: 아이템 횟수 | T25: 0 | U25: 0.8 | V25: 이동 경로 | W25: 1 | X25: 개 | Y25: 0 | Z25: 경로 생성 완료 | AA25: 없음 | AB25: 186번·188번 총 2회 사용
A26: SKL-PC-022 | B26: 심층 탐사 | C26: 249번 | 별을 삼킨 강당가 변혜서임을 확정하고 선의 안정 장치 발동 견디기 | D26: PC | E26: 괜찮아, 아직. | F26: 선의 안정 장치가 큰 심리 충격으로 입력 흔들림이 발생할 때 1회 자동 발동해 자아마모 수치는 유지한 채 조작 흔들림만 완화함. | H26: 패시브+자동 | I26: 차한해 | K26: 사건 플래그 | L26: 선의 안정 장치 장착·친구 정체 확정 | M26: 없음 | N26: 0 | O26: 0 | P26: 피해 없음 | S26: 1회 자동 | T26: 0 | U26: 0 | V26: 입력 흔들림 | W26: -100 | X26: % | Y26: 10 | Z26: 10초 종료 | AA26: SKL-STS-013 | AB26: 196번에서 장치 획득·249번 첫 자동 발동
A27: SKL-PC-023 | B27: 폐교 은폐 | C27: 215번 | 고밀도 충격 흡수 장화로 등 뒤 한 칸의 기습을 버티며 복도 통과하기 | D27: PC | E27: 쉿. | F27: 이동을 잠시 멈추고 소리 발생 행동을 제한해 청각 추적형 변이체의 추적 게이지를 끊음. | H27: 액티브 | I27: 차한해 | K27: 입력 유지 | L27: 1초간 이동·공격 입력 없음 | M27: 없음 | N27: 0 | O27: 0 | P27: 피해 없음 | S27: 개별 | T27: 2.5 | U27: 1 | V27: 소음 발생량 | W27: -100 | X27: % | Y27: 1.5 | Z27: 이동·공격 입력 | AA27: 없음 | AB27: 은폐 전용
A28: SKL-PC-024 | B28: 폐교 공명 | C28: 238번 | 보랏빛 사랑의 매로 기억 외피 공명 타격 시험하기 | D28: PC | E28: 껍데기부터 | F28: 사랑의 매로 보랏빛 공명 외피만 골라 때려 외피 방어를 먼저 제거하는 전용 공략 스킬. | H28: 액티브 | I28: 차한해 | K28: 약점 노출 | L28: 공명 외피 활성 | M28: 기본 공격력 비율 | N28: 1.3 | O28: 0 | P28: 기본 공격력 × 130% | S28: 개별 | T28: 2.8 | U28: 0.45 | V28: 외피 피해 | W28: 50 | X28: % | Y28: 0 | Z28: 외피 파괴 | AA28: 없음 | AB28: 본체 피해보다 외피 제거에 특화
A29: SKL-PC-025 | B29: 폐교 투척 | C29: 244번 | 농구공의 투척 궤적 익히기 | D29: PC | E29: 한 번 튕겨! | F29: 보랏빛 농구공을 벽·골대에 반사시켜 직선으로 닿지 않는 기억 핵을 타격함. | H29: 액티브 | I29: 차한해 | K29: 입력 | L29: 반사 경로 조준 완료 | M29: 기본 공격력 비율 | N29: 1.1 | O29: 0 | P29: 기본 공격력 × 110% | S29: 개별 | T29: 2 | U29: 0.55 | V29: 반사 횟수 | W29: 1 | X29: 회 | Y29: 0 | Z29: 공 회수·화면 밖 이탈 | AA29: 없음 | AB29: 반사 성공 시 기억 핵 판정 가능
... A34: SKL-PC-030 | B34: 최종 보스 | C34: 287번 | 차한해에게 연결된 무한대 부담 장치 파괴하기 | D34: PC | E34: 이번엔 같이. | F34: 차한해 혼자 무한대 부담을 받아내지 않고 전장에 분산된 연결 장치를 동료와 동시 작동시키는 협력형 사건 스킬. | H34: 연출용+액티브 | I34: 차한해·동료 | K34: 동시 입력 | L34: 부담 연결 장치 4개 활성 | M34: 없음 | N34: 0 | O34: 0 | P34: 피해 없음 | S34: 페이즈 1회 | T34: 0 | U34: 0.6 | V34: 부담 연결 | W34: -4 | X34: 개 | Y34: 0 | Z34: 장치 4개 동시 파괴 | AA34: 없음 | AB34: 최종부 주제인 책임 분담을 전투 기믹으로 표현
