Workbook
Name PC_DATA_콘텐츠_번호: 'PC DATA(대차대조표)'!$B$3:$B$308
Name 기타_가져오기: INDEX(아이템_이미지,MATCH('전투 시뮬레이터'!$L$4,아이템_이름,0))
Name 몬스터_가져오기: INDEX('속성 대차대조표 (2)'!몬스터_이미지,MATCH('[C:/Users/82103/OneDrive/바탕 화면/Gihoek_7/넌착해 밸런스 기획 문서.xlsx]시뮬레이터'!$B$2,'속성 대차대조표 (2)'!몬스터_이름,0))
Name 몬스터_가져오기: INDEX(몬스터_이미지,MATCH('전투 시뮬레이터'!$B$2:$C$2,몬스터_이름,0))
Name 몬스터_스킬1_이름: '[C:/Users/82103/OneDrive/바탕 화면/Gihoek_7/넌착해 밸런스 기획 문서.xlsx]몬스터'!$O$7:$O$290
Name 몬스터_이름: '[C:/Users/82103/OneDrive/바탕 화면/Gihoek_7/넌착해 밸런스 기획 문서.xlsx]몬스터'!$C$7:$C$290
Name 몬스터_이름: 몬스터!$C$7:$C$312
Name 몬스터_이미지: '[C:/Users/82103/OneDrive/바탕 화면/Gihoek_7/넌착해 밸런스 기획 문서.xlsx]몬스터'!$D$7:$D$290
Name 몬스터_이미지: 몬스터!$D$7:$D$312
Name 무기_가져오기: INDEX(아이템_이미지,MATCH('전투 시뮬레이터'!$L$2,아이템_이름,0))
Name 방어구_가져오기: INDEX(아이템_이미지,MATCH('전투 시뮬레이터'!$K$2,아이템_이름,0))
Name 스킬_콘텐츠_번호: '스킬 DATA'!$D$5:$D$215
Name 아이템_이름: 아이템!$A$2:$A$43
Name 아이템_이미지: 아이템!$C$2:$C$43
Name 아이템_콘텐츠_번호: 아이템!$H$2:$H$43
Name 액세서리_가져오기: INDEX(아이템_이미지,MATCH('전투 시뮬레이터'!$K$4,아이템_이름,0))
Name 캐릭터_가져오기: INDEX('속성 대차대조표 (2)'!캐릭터_이미지,MATCH('[C:/Users/82103/OneDrive/바탕 화면/Gihoek_7/넌착해 밸런스 기획 문서.xlsx]시뮬레이터'!$F$2,캐릭터_이름,0))
Name 캐릭터_가져오기: INDEX(캐릭터_이미지,MATCH('전투 시뮬레이터'!$I$2:$J$2,캐릭터_이름,0))
Name 캐릭터_이름: 'PC DATA(대차대조표)'!$A$3:$A$308
Name 캐릭터_이미지: '[C:/Users/82103/OneDrive/바탕 화면/Gihoek_7/넌착해 밸런스 기획 문서.xlsx]PC DATA(대차대조표)'!$D$3:$D$308
Name 캐릭터_이미지: 'PC DATA(대차대조표)'!$E$3:$E$308
Name 콘텐츠진행순서: 'PC DATA(대차대조표)'!$B$3:$B$308

Sheet 밸런스 문서
S1: 예상 플레이 시간
A2: 챕터 | B2: 콘텐츠 진행 순서 | C2: 플레이 난이도 | D2: 플레이 흥미도 | E2: 플레이 목표 | F2: 플레이 난관 | G2: 공략 방법 | H2: 체감 난이도 | I2: 수행 과제 수 | J2: 목표 달성 조건 | K2: 실패 결과 | L2: 예상 소요 시간 | M2: 난이도 조절 요소 | N2: 누적 플레이 시간 | O2: 스테이지 | P2: 콘텐츠 진행 포인트 (획득량) | Q2: 콘텐츠 진행 포인트 누적 | R2: 핵심 전투 기믹 | S2: 라이트 유저 (예상 시간 기준) | T2: 미들 유저 | U2: 헤비 유저 | V2: 자아마모도 변화(%) | W2: 인연 변화(%) | X2: 진행 관문 조건 | Y2: 선택·추가 콘텐츠 해금
A3: 1 | 평범한 하루 | B3: 1 | C3: 1 | D3: 8 | E3: 차한해의 과거 오프닝 감상 | F3: 입양 뒤 가족의 몫까지 당연히 떠맡아 온 시간을 짧은 장면으로 이해해야 함 | G3: 가족의 요구와 차한해가 먼저 움직이는 습관을 확인함 | H3: 1/10 – 목표 식별·선택·입력 부담을 종합한 체감 난이도 | I3: 1 | J3: 오프닝 재생 완료 | K3: - | L3: 45초 | M3: 핵심 대상 강조·정체 시 단계별 힌트 제공 | N3: 0.00052083333 | O3: 1-A | 집·가족의 몫 | P3: 3 | Q3: =P3 -> 3 | S3: 45초 | T3: 40초 | U3: 35초
A4: 1 | 평범한 하루 | B4: 2 | C4: 1 | D4: 6 | E4: 아버지 회사 서류를 챙겨 식탁에 올려두기 | F4: 흩어진 서류 중 회사 문서만 골라야 함 | G4: 봉투 표식과 아버지의 메모를 보고 서류를 모아 식탁 지정 칸에 둠 | H4: 1/10 – 목표 식별·선택·입력 부담을 종합한 체감 난이도 | I4: 4 | J4: 회사 서류 4묶음 정리 완료 | K4: - | L4: 25초 | M4: 핵심 대상 강조·정체 시 단계별 힌트 제공 | N4: 0.00081018519 | O4: 1-A | 집·가족의 몫 | P4: 2 | Q4: =Q3+P4 -> 5 | S4: 25초 | T4: 20초 | U4: 15초
A5: 1 | 평범한 하루 | B5: 3 | C5: 1 | D5: 6 | E5: 빨래를 분류해 세탁기에 넣고 작동하기 | F5: 색상과 세탁 표시가 다른 옷이 섞여 있음 | G5: 일반 빨래만 세탁기에 넣고 세제 투입 뒤 표준 코스를 시작함 | H5: 1/10 – 목표 식별·선택·입력 부담을 종합한 체감 난이도 | I5: 3 | J5: 일반 빨래 분류·투입·세탁 시작 | K5: 비싼 블라우스를 넣으면 경고 후 분류 단계로 복귀 | L5: 40초 | M5: 핵심 대상 강조·정체 시 단계별 힌트 제공 | N5: 0.0012731481 | O5: 1-A | 집·가족의 몫 | P5: 3 | Q5: 8 | S5: 40초 | T5: 35초 | U5: 30초
A6: 1 | 평범한 하루 | B6: 4 | C6: 2 | D6: 7 | E6: 어머니의 비싼 블라우스를 손세탁하기 | F6: 강하게 문지르면 옷감 손상 게이지가 오름 | G6: 미지근한 물·중성세제·누르기 세탁 순서를 지킴 | H6: 2/10 – 목표 식별·선택·입력 부담을 종합한 체감 난이도 | I6: 4 | J6: 블라우스 손상 없이 손세탁 완료 | K6: 손상 게이지 최대 시 현재 단계 재시작 | L6: 50초 | M6: 핵심 대상 강조·정체 시 단계별 힌트 제공 | N6: 0.0018518519 | O6: 1-A | 집·가족의 몫 | P6: 3 | Q6: 11 | S6: 50초 | T6: 45초 | U6: 40초
A7: 1 | 평범한 하루 | B7: 5 | C7: 1 | D7: 6 | E7: 건조기 완료음을 듣고 빨래를 꺼내 거실에서 개기 | F7: 건조 완료 시점과 옷별 접는 방향을 확인해야 함 | G7: 완료음 뒤 빨래를 거실로 옮기고 종류별 실루엣에 맞춰 갬 | H7: 1/10 – 목표 식별·선택·입력 부담을 종합한 체감 난이도 | I7: 8 | J7: 빨래 8개를 모두 개어 바구니에 정리 | K7: - | L7: 45초 | M7: 핵심 대상 강조·정체 시 단계별 힌트 제공 | N7: 0.0023726852 | O7: 1-A | 집·가족의 몫 | P7: 2 | Q7: 13 | S7: 45초 | T7: 40초 | U7: 35초
A8: 1 | 평범한 하루 | B8: 6 | C8: 1 | D8: 7 | E8: 동생에게 신상 과자·헤어롤·팝콘 심부름 받기 | F8: 대화에 품목과 목적지가 섞여 있음 | G8: 강조된 품목과 동선을 확인하고 심부름 목록을 등록함 | H8: 1/10 – 목표 식별·선택·입력 부담을 종합한 체감 난이도 | I8: 3 | J8: 심부름 3종 등록 | K8: - | L8: 35초 | M8: 핵심 대상 강조·정체 시 단계별 힌트 제공 | N8: 0.0027777778 | O8: 1-A | 집·가족의 몫 | P8: 2 | Q8: 15 | S8: 35초 | T8: 30초 | U8: 25초 | W8: [차우선] 기준 45%
A9: 1 | 평범한 하루 | B9: 7 | C9: 1 | D9: 7 | E9: 엘리베이터에서 주민 모두에게 인사하며 밖으로 나가기 | F9: 어른·아이·택배기사 등 서로 다른 위치의 주민을 발견해야 함 | G9: 이동·조사 입력으로 만나는 주민에게 자연스럽게 인사함 | H9: 1/10 – 목표 식별·선택·입력 부담을 종합한 체감 난이도 | I9: 5 | J9: 엘리베이터와 로비의 주민 5명에게 인사 후 외출 | K9: - | L9: 35초 | M9: 핵심 대상 강조·정체 시 단계별 힌트 제공 | N9: 0.0031828704 | O9: 1-A | 아파트·인사 튜토리얼 | P9: 3 | Q9: 18 | S9: 35초 | T9: 30초 | U9: 25초 | Y9: 이동·조사 튜토리얼 완료
A10: 1 | 평범한 하루 | B10: 8 | C10: 2 | D10: 7 | E10: 편의점에서 신상 과자가 아직 입고되지 않았음을 확인하기 | F10: 빈 진열대와 입고 안내를 찾아야 함 | G10: 신상 코너와 알바생 대화를 통해 물류 트럭 도착 시간을 확인함 | H10: 2/10 – 목표 식별·선택·입력 부담을 종합한 체감 난이도 | I10: 2 | J10: 신상 과자 입고 전 상태·트럭 시간 확인 | K10: - | L10: 35초 | M10: 핵심 대상 강조·정체 시 단계별 힌트 제공 | N10: 0.003587963 | O10: 1-B | 편의점·첫 방문 | P10: 4 | Q10: 22 | S10: 35초 | T10: 30초 | U10: 25초
A11: 1 | 평범한 하루 | B11: 9 | C11: 2 | D11: 8 | E11: 알바생의 무거운 음료 박스 진열 부탁을 수락할지 선택하기 | F11: 동생 심부름과 짧은 도움 사이에서 선택해야 함 | G11: 수락하거나 [싫어요.]를 사용해 거절함. 거절해도 메인 진행은 유지되지만 해당 서브 퀘스트의 인연·보상 획득 기회는 사라짐 | H11: 2/10 – 목표 식별·선택·입력 부담을 종합한 체감 난이도 | I11: 1 | J11: 부탁 수락 또는 [싫어요.] 사용 | K11: - | L11: 30초 | M11: 핵심 대상 강조·정체 시 단계별 힌트 제공 | N11: 0.0039351852 | O11: 1-B | 편의점 알바생 부탁 | P11: 3 | Q11: 25 | S11: 30초 | T11: 25초 | U11: 20초 | Y11: 선택 서브 퀘스트 : 편의점 음료 진열
A12: 1 | 평범한 하루 | B12: 10 | C12: 3 | D12: 8 | E12: 음료 박스를 가격표에 맞춰 진열하기 | F12: 비슷한 포장과 무게 때문에 위치를 헷갈릴 수 있음 | G12: 상표·용량·가격표를 대조해 무거운 박스부터 아래 칸에 배치함 | H12: 3/10 – 목표 식별·선택·입력 부담을 종합한 체감 난이도 | I12: 6 | J12: 음료 6박스 진열 완료 | K12: 오배치 3회 시 틀린 가격표를 강조 | L12: 1분 10초 | M12: 핵심 대상 강조·정체 시 단계별 힌트 제공 | N12: 0.0047453704 | O12: 1-B | 편의점 알바생 부탁 | P12: 3 | Q12: 28 | S12: 1분 10초 | T12: 1분 | U12: 50초 | Y12: 완료 시 알바생이 신상 과자 1개를 맡아두는 약속
A13: 1 | 평범한 하루 | B13: 11 | C13: 2 | D13: 8 | E13: 골목에서 들리는 예쁜 고양이 울음소리 확인하기 | F13: 심부름 목적지가 따로 있어 작은 울음소리를 무시하고 지나칠 수 있음 | G13: 편의점 주변에서 반복되는 울음소리와 골목 그림자를 확인하되 조사하지 않고 진행할 수도 있음 | H13: 2/10 – 발견 여부와 선택에 따라 진행이 달라짐 | I13: 2 | J13: 울음소리가 들리는 골목 위치 확인 또는 선택적으로 지나침 | K13: - | L13: 45초 | M13: 자동 등록하지 않고 소리·행동·오브젝트로만 암시 | N13: 0.0052662037 | O13: 1-B | 편의점·고양이 선택 | P13: 3 | Q13: 31 | S13: 45초 | T13: 40초 | U13: 35초 | Y13: 서브 퀘스트 : 예쁜 고양이 인연 1단계 발견
A14: 1 | 평범한 하루 | B14: 12 | C14: 2 | D14: 8 | E14: 편의점에서 츄르 4개입 세트 구매하기 | F14: 구매 메뉴에는 심부름 물품 외에도 여러 상품이 있어 츄르를 직접 찾아야 함 | G14: 알바생 대화 후 ‘물건 구매하기’를 선택하고 반려동물 간식 칸에서 츄르 4개입을 구매함 | H14: 2/10 – 발견 여부와 선택에 따라 진행이 달라짐 | I14: 2 | J14: 츄르 4개입 세트 구매 완료 | K14: - | L14: 45초 | M14: 자동 등록하지 않고 소리·행동·오브젝트로만 암시 | N14: 0.005787037 | O14: 1-B | 편의점·고양이 선택 | P14: 3 | Q14: 34 | S14: 45초 | T14: 40초 | U14: 35초 | Y14: 서브 퀘스트 : 이후 예쁜 고양이 인연 콘텐츠 4회 수행 가능
A15: 1 | 평범한 하루 | B15: 13 | C15: 2 | D15: 8 | E15: 예쁜 고양이에게 첫 번째 츄르 건네기 | F15: 예쁜 고양이는 처음 만난 차한해를 경계해 바로 가까이 오지 않음 | G15: 일정 거리에 츄르를 내려놓고 뒤로 물러난 뒤 고양이가 스스로 다가올 때까지 기다림 | H15: 2/10 – 발견 여부와 선택에 따라 진행이 달라짐 | I15: 2 | J15: 예쁜 고양이가 츄르를 먹고 도망가지 않은 채 차한해를 바라봄 | K15: - | L15: 45초 | M15: 자동 등록하지 않고 소리·행동·오브젝트로만 암시 | N15: 0.0063078704 | O15: 1-B | 편의점·고양이 선택 | P15: 3 | Q15: 37 | S15: 45초 | T15: 40초 | U15: 35초 | W15: [예쁜 고양이] +25% 선택 (최대 누적 25%) | Y15: 츄르 보유 시 수행 예쁜 고양이 인연 +25%
A16: 1 | 평범한 하루 | B16: 14 | C16: 2 | D16: 5 | E16: 다이소로 이동하기 | F16: 갈림길과 주변 상호작용 오브젝트 때문에 목적지 방향을 놓칠 수 있음 | G16: 표지판·미니맵·NPC 이동 방향을 확인하며 편의점에서 다이소까지 이동함 | H16: 2/10 – 맵 크기·갈림길 수·목적지 표식의 가시성이 난이도를 결정함 | I16: 1 | J16: 편의점에서 다이소의 도착 트리거에 진입 | K16: - | L16: 25초 | M16: 일정 시간 정체 시 목적지 방향 화살표 표시 | N16: 0.0065972222 | O16: 1-C | 다이소 | P16: 3 | Q16: 40 | S16: 25초 | T16: 20초 | U16: 20초
A17: 1 | 평범한 하루 | B17: 15 | C17: 2 | D17: 6 | E17: 헤어롤 진열대 찾기 | F17: 비슷한 오브젝트와 진열대가 많아 목표 대상을 한 번에 찾기 어려움 | G17: 구역별 표지와 상품 외형을 비교하며 생활용품 코너의 헤어롤을 조사함 | H17: 2/10 – 후보 오브젝트 수·외형 유사도·탐색 범위가 난이도를 결정함 | I17: 5 | J17: 생활용품 코너의 헤어롤 발견 및 조사 완료 | K17: - | L17: 35초 | M17: 30초 이상 미발견 시 목표 구역에 약한 반짝임 표시 | N17: 0.0070023148 | O17: 1-C | 다이소 | P17: 4 | Q17: 44 | S17: 35초 | T17: 30초 | U17: 25초
A18: 1 | 평범한 하루 | B18: 16 | C18: 1 | D18: 5 | E18: 헤어롤 구매하기 | F18: 구매 대상·수량·결제 순서를 잘못 선택할 수 있음 | G18: 요청받은 품목을 확인하고 상품 선택→계산대 상호작용→결제를 순서대로 진행함 | H18: 1/10 – 상품 후보 수·품목 유사도·구매 단계 수가 난이도를 결정함 | I18: 3 | J18: 헤어롤 1개 구매 후 인벤토리에 등록 | K18: 잘못된 품목 구매 시 다시 선택해야 함 | L18: 20초 | M18: 요청 품목에 작은 임무 아이콘 표시 | N18: 0.0072337963 | O18: 1-C | 다이소 | P18: 3 | Q18: 47 | S18: 20초 | T18: 15초 | U18: 15초
A19: 1 | 평범한 하루 | B19: 17 | C19: 1 | D19: 8 | E19: 다이소를 나오자 편의점 물류 트럭이 지나가는 장면 확인하기 | F19: 신상 과자 재입고 기회를 즉시 알아차려야 함 | G19: 트럭 표식과 편의점 방향을 확인함 | H19: 1/10 – 목표 식별·선택·입력 부담을 종합한 체감 난이도 | I19: 1 | J19: 물류 트럭과 편의점 재입고 방향 확인 | K19: - | L19: 20초 | M19: 핵심 대상 강조·정체 시 단계별 힌트 제공 | N19: 0.0074652778 | O19: 1-D | 어르신과 신상 과자 | P19: 3 | Q19: 50 | S19: 20초 | T19: 15초 | U19: 15초
A20: 1 | 평범한 하루 | B20: 18 | C20: 2 | D20: 10 | E20: 짐이 많은 어르신을 도울지 신상 과자를 사러 갈지 선택하기 | F20: 도움이 늦어지면 신상 과자가 품절될 수 있음 | G20: 어르신의 구조 요청과 동생의 심부름을 비교해 행동을 선택함 | H20: 2/10 – 목표 식별·선택·입력 부담을 종합한 체감 난이도 | I20: 1 | J20: 어르신 돕기 또는 편의점으로 바로 달리기 | K20: - | L20: 30초 | M20: 핵심 대상 강조·정체 시 단계별 힌트 제공 | N20: 0.0078125 | O20: 1-D | 어르신과 신상 과자 | P20: 3 | Q20: 53 | S20: 30초 | T20: 25초 | U20: 25초 | Y20: 핵심 선택 : 자발적 선행과 개인 손실
A21: 1 | 평범한 하루 | B21: 19 | C21: 2 | D21: 10 | E21: 어르신의 무거운 짐을 목적지까지 옮기기 | F21: 짐 때문에 이동이 느리고 보행자와 턱을 피해 가야 함 | G21: 무게 중심을 유지하며 안전한 길로 짐을 나누어 운반함 | H21: 2/10 – 목표 식별·선택·입력 부담을 종합한 체감 난이도 | I21: 4 | J21: 짐 4개 운반·어르신 귀가 확인 | K21: - | L21: 1분 10초 | M21: 핵심 대상 강조·정체 시 단계별 힌트 제공 | N21: 0.0086226852 | O21: 1-D | 어르신과 신상 과자 | P21: 3 | Q21: 56 | S21: 1분 10초 | T21: 1분 | U21: 50초 | W21: [도시] +5% 선택 (기본 0% · 최대 5%) | Y21: 어르신을 도운 경우 수행·신상 과자 분기 변화
A22: 1 | 평범한 하루 | B22: 20 | C22: 2 | D22: 8 | E22: 치킨집 앞 두 손님의 주문 대화 듣기 | F22: 서로 다른 주문과 번복 대사에서 확정 내용을 골라야 함 | G22: 치킨·소스·음료·추가 요청을 구분해 기억함 | H22: 2/10 – 목표 식별·선택·입력 부담을 종합한 체감 난이도 | I22: 4 | J22: 두 손님의 최종 주문 확인 | K22: - | L22: 40초 | M22: 핵심 대상 강조·정체 시 단계별 힌트 제공 | N22: 0.0090856481 | O22: 1-E | 치킨집 알바 서브 | P22: 3 | Q22: 59 | S22: 40초 | T22: 35초 | U22: 30초 | Y22: 서브 퀘스트 : 치킨집 알바
A23: 1 | 평범한 하루 | B23: 21 | C23: 2 | D23: 8 | E23: 바쁜 직원의 도움 요청을 확인하기 | F23: 밀린 주문과 손님 대화가 겹침 | G23: 직원의 호출을 확인하고 잠시 도울지 선택함 | H23: 2/10 – 목표 식별·선택·입력 부담을 종합한 체감 난이도 | I23: 1 | J23: 도움 요청 확인 | K23: - | L23: 40초 | M23: 핵심 대상 강조·정체 시 단계별 힌트 제공 | N23: 0.0095486111 | O23: 1-E | 치킨집 알바 서브 | P23: 4 | Q23: 63 | S23: 40초 | T23: 35초 | U23: 30초 | Y23: 거절 시 서브 퀘스트 종료
A24: 1 | 평범한 하루 | B24: 22 | C24: 2 | D24: 8 | E24: 치킨집 알바를 도울지 선택하기 | F24: 심부름 일정과 직원의 부탁 사이에서 선택해야 함 | G24: 돕기를 선택하거나 [싫어요.]를 사용해 알바 부탁을 거절하고 기존 심부름을 계속함 | H24: 2/10 – 목표 식별·선택·입력 부담을 종합한 체감 난이도 | I24: 1 | J24: 알바 수락 또는 [싫어요.] 사용 | K24: - | L24: 35초 | M24: 핵심 대상 강조·정체 시 단계별 힌트 제공 | N24: 0.0099537037 | O24: 1-E | 치킨집 알바 서브 | P24: 6 | Q24: 69 | S24: 35초 | T24: 30초 | U24: 25초 | Y24: 수락 시 포장 미니게임 해금
A25: 1 | 평범한 하루 | B25: 23 | C25: 4 | D25: 8 | E25: 주문표의 치킨·소스·음료 확인하기 | F25: 여러 주문표의 번호와 구성품을 혼동하기 쉬움 | G25: 주문 번호별 필수 항목을 순서대로 확인함 | H25: 4/10 – 목표 식별·선택·입력 부담을 종합한 체감 난이도 | I25: 5 | J25: 주문표 필수 항목 5개 확인 | K25: 오답 누적 시 현재 단계 재시작 | L25: 1분 10초 | M25: 핵심 대상 강조·정체 시 단계별 힌트 제공 | N25: 0.010763889 | O25: 1-E | 치킨집 알바 서브 | P25: 6 | Q25: 75 | S25: 1분 10초 | T25: 1분 | U25: 50초
A26: 1 | 평범한 하루 | B26: 24 | C26: 4 | D26: 8 | E26: 주문에 맞게 치킨 포장하기 | F26: 번복된 대사와 확정 주문을 구분해야 함 | G26: 확정 주문표만 보고 상자·무·소스·음료를 넣음 | H26: 4/10 – 목표 식별·선택·입력 부담을 종합한 체감 난이도 | I26: 5 | J26: 구성품 5종 올바르게 포장 | K26: 오답 누적 시 현재 단계 재시작 | L26: 1분 10초 | M26: 핵심 대상 강조·정체 시 단계별 힌트 제공 | N26: 0.011574074 | O26: 1-E | 치킨집 알바 서브 | P26: 6 | Q26: 81 | S26: 1분 10초 | T26: 1분 | U26: 50초
A27: 1 | 평범한 하루 | B27: 25 | C27: 4 | D27: 8 | E27: 잘못 포장된 주문 수정하기 | F27: 다른 주문의 소스와 음료가 섞여 있음 | G27: 주문표와 포장을 대조해 오류 항목만 교체함 | H27: 4/10 – 목표 식별·선택·입력 부담을 종합한 체감 난이도 | I27: 4 | J27: 오포장 항목 전부 수정 | K27: 오답 누적 시 현재 단계 재시작 | L27: 55초 | M27: 핵심 대상 강조·정체 시 단계별 힌트 제공 | N27: 0.012210648 | O27: 1-E | 치킨집 알바 서브 | P27: 3 | Q27: 84 | S27: 55초 | T27: 45초 | U27: 40초
A28: 1 | 평범한 하루 | B28: 26 | C28: 2 | D28: 8 | E28: 손님에게 주문을 전달하고 보상 받기 | F28: 비슷한 두 손님 중 올바른 주문자를 찾아야 함 | G28: 대화 특징과 주문 번호를 대조해 전달함 | H28: 2/10 – 목표 식별·선택·입력 부담을 종합한 체감 난이도 | I28: 2 | J28: 올바른 손님에게 전달·알바비 획득 | K28: - | L28: 40초 | M28: 핵심 대상 강조·정체 시 단계별 힌트 제공 | N28: 0.012673611 | O28: 1-E | 치킨집 알바 서브 | P28: 3 | Q28: 87 | S28: 40초 | T28: 35초 | U28: 30초 | Y28: 치킨집 알바 서브 퀘스트 완료
A29: 1 | 평범한 하루 | B29: 27 | C29: 2 | D29: 8 | E29: 편의점으로 돌아가 신상 과자 재고 확인하기 | F29: 어르신·알바생 부탁 선택에 따라 결과가 달라짐 | G29: 진열대와 알바생 반응을 확인함 | H29: 2/10 – 목표 식별·선택·입력 부담을 종합한 체감 난이도 | I29: 2 | J29: 재고·예약 여부 확인 | K29: - | L29: 25초 | M29: 핵심 대상 강조·정체 시 단계별 힌트 제공 | N29: 0.012962963 | O29: 1-F | 편의점 결과 분기 | P29: 4 | Q29: 91 | S29: 25초 | T29: 20초 | U29: 20초
A30: 1 | 평범한 하루 | B30: 28 | C30: 2 | D30: 10 | E30: 선택 결과에 따라 신상 과자 확보 여부 확정하기 | F30: 도움을 선택했을 때 앞선 알바생 부탁 수행 여부가 보상을 바꿈 | G30: 어르신 무시 시 구매, 어르신 도움+부탁 완료 시 예약품 수령, 도움+부탁에 [싫어요.] 사용 시 품절 결과를 확인함 | H30: 2/10 – 목표 식별·선택·입력 부담을 종합한 체감 난이도 | I30: 3 | J30: 신상 과자 구매·예약 수령 또는 품절 확정 | K30: - | L30: 50초 | M30: 핵심 대상 강조·정체 시 단계별 힌트 제공 | N30: 0.013541667 | O30: 1-F | 편의점 결과 분기 | P30: 5 | Q30: 96 | S30: 50초 | T30: 40초 | U30: 35초 | Y30: 선택 연쇄 결과 저장
A31: 1 | 평범한 하루 | B31: 29 | C31: 1 | D31: 9 | E31: 동생에게 과자 결과를 알리고 지하철 중고거래 심부름 받기 | F31: 품절 분기에서는 동생의 짜증 섞인 추가 요구를 감정적으로 받아들여야 함 | G31: 결과 대화를 확인하고 거래 상대 단서를 등록함 | H31: 1/10 – 목표 식별·선택·입력 부담을 종합한 체감 난이도 | I31: 2 | J31: 중고거래 장소·상대 특징 등록 | K31: - | L31: 35초 | M31: 핵심 대상 강조·정체 시 단계별 힌트 제공 | N31: 0.013946759 | O31: 1-F | 동생의 추가 심부름 | P31: 6 | Q31: 102 | S31: 35초 | T31: 30초 | U31: 25초 | W31: 과자 확보: [차우선] +5% (50%) / 품절: -5% (40%)
A32: 1 | 평범한 하루 | B32: 30 | C32: 1 | D32: 6 | E32: 영화관으로 이동하기 | F32: 상가 갈림길에서 목적지를 찾아야 함 | G32: 표지판과 심부름 목록을 보고 영화관으로 이동함 | H32: 1/10 – 목표 식별·선택·입력 부담을 종합한 체감 난이도 | I32: 1 | J32: 영화관 도착 | K32: - | L32: 30초 | M32: 핵심 대상 강조·정체 시 단계별 힌트 제공 | N32: 0.014293981 | O32: 1-F | 영화관·지하철 | P32: 5 | Q32: 107 | S32: 30초 | T32: 25초 | U32: 25초
A33: 1 | 평범한 하루 | B33: 31 | C33: 1 | D33: 6 | E33: 동생이 부탁한 팝콘 구매하기 | F33: 맛과 크기를 잘못 고를 수 있음 | G33: 심부름 목록과 메뉴를 대조해 구매함 | H33: 1/10 – 목표 식별·선택·입력 부담을 종합한 체감 난이도 | I33: 3 | J33: 지정 팝콘 구매 | K33: - | L33: 25초 | M33: 핵심 대상 강조·정체 시 단계별 힌트 제공 | N33: 0.014583333 | O33: 1-F | 영화관·지하철 | P33: 3 | Q33: 110 | S33: 25초 | T33: 20초 | U33: 20초
A34: 1 | 평범한 하루 | B34: 32 | C34: 2 | D34: 6 | E34: 지하철 중고거래 장소로 이동하기 | F34: 출구 번호와 약속 위치가 다름 | G34: 역 안내판과 채팅의 출구 번호를 확인함 | H34: 2/10 – 목표 식별·선택·입력 부담을 종합한 체감 난이도 | I34: 2 | J34: 약속 장소 도착 | K34: - | L34: 35초 | M34: 핵심 대상 강조·정체 시 단계별 힌트 제공 | N34: 0.014988426 | O34: 1-F | 영화관·지하철 | P34: 3 | Q34: 113 | S34: 35초 | T34: 30초 | U34: 25초
A35: 1 | 평범한 하루 | B35: 33 | C35: 2 | D35: 7 | E35: 거래 후보 세 명의 특징 관찰하기 | F35: 복장 일부가 비슷해 판매자를 혼동하기 쉬움 | G35: 채팅의 가방·신발·손에 든 물건을 대조함 | H35: 2/10 – 목표 식별·선택·입력 부담을 종합한 체감 난이도 | I35: 3 | J35: 후보 3명 관찰 | K35: - | L35: 30초 | M35: 핵심 대상 강조·정체 시 단계별 힌트 제공 | N35: 0.015335648 | O35: 1-F | 영화관·지하철 | P35: 3 | Q35: 116 | S35: 30초 | T35: 25초 | U35: 20초
A36: 1 | 평범한 하루 | B36: 34 | C36: 3 | D36: 7 | E36: 올바른 중고거래 상대 찾기 | F36: 가짜 후보에게 말을 걸면 시간이 추가됨 | G36: 세 단서가 모두 맞는 사람에게 암구호를 말함 | H36: 3/10 – 목표 식별·선택·입력 부담을 종합한 체감 난이도 | I36: 3 | J36: 정확한 거래 상대 선택 | K36: 오답 후보 선택 시 대화 후 다시 탐색 | L36: 40초 | M36: 핵심 대상 강조·정체 시 단계별 힌트 제공 | N36: 0.015798611 | O36: 1-F | 영화관·지하철 | P36: 4 | Q36: 120 | S36: 40초 | T36: 35초 | U36: 30초
A37: 1 | 평범한 하루 | B37: 35 | C37: 1 | D37: 8 | E37: 중고거래를 마치고 동생에게 완료 연락하기 | F37: 과자 분기와 거래 결과에 따라 동생의 반응이 달라짐 | G37: 물품 상태를 확인하고 송금·완료 메시지를 보냄 | H37: 1/10 – 목표 식별·선택·입력 부담을 종합한 체감 난이도 | I37: 3 | J37: 거래·완료 연락 | K37: - | L37: 25초 | M37: 핵심 대상 강조·정체 시 단계별 힌트 제공 | N37: 0.016087963 | O37: 1-F | 영화관·지하철 | P37: 5 | Q37: 125 | S37: 25초 | T37: 20초 | U37: 20초 | W37: [차우선] +5% (과자 확보 55% / 품절 45%)
A38: 1 | 평범한 하루 | B38: 36 | C38: 2 | D38: 8 | E38: 횡단보도에서 아이가 떨어뜨린 학용품을 주워주기 | F38: 신호가 바뀌기 전 안전한 순서로 물건을 모아야 함 | G38: 차도 가까운 물건부터 회수하고 아이를 인도로 유도함 | H38: 2/10 – 목표 식별·선택·입력 부담을 종합한 체감 난이도 | I38: 5 | J38: 학용품 5개 회수·아이 안전 확인 | K38: 신호 종료 시 남은 물건이 인도 쪽으로 이동 | L38: 55초 | M38: 핵심 대상 강조·정체 시 단계별 힌트 제공 | N38: 0.016724537 | O38: 1-F | 동네의 작은 선행 | P38: 3 | Q38: 128 | S38: 55초 | T38: 45초 | U38: 40초 | Y38: 선택 서브 퀘스트·동네 목격자 스티커 플래그
A39: 1 | 평범한 하루 | B39: 37 | C39: 1 | D39: 9 | E39: 공원에서 모든 심부름 완료와 섬광 이상 현상 확인하기 | F39: 평범한 귀가 직전 소리 없는 번개와 미세 진동이 짧게 겹침 | G39: 세 심부름 물품을 확인하고 하늘의 섬광·땅의 떨림을 기억함 | H39: 1/10 – 목표 식별·선택·입력 부담을 종합한 체감 난이도 | I39: 4 | J39: 심부름 3종 완료·첫 이상 현상 확인 | K39: - | L39: 30초 | M39: 핵심 대상 강조·정체 시 단계별 힌트 제공 | N39: 0.017071759 | O39: 1-G | 공원·첫 전조 | P39: 4 | Q39: 132 | S39: 30초 | T39: 25초 | U39: 25초 | X39: 1챕터 메인 심부름 완료
A40: 2 | 금이 간 일상 | B40: 38 | C40: 1 | D40: 7 | E40: 축제 종료 현장과 남은 이상 징후 관찰하기 | F40: 떠나는 시민·쌓인 쓰레기·간헐적으로 깜빡이는 조명 사이에 섬광의 원인을 추정할 단서가 분산되어 있음 | G40: 시민의 행동과 쓰레기 상태를 살펴본 뒤 조명 깜빡임과 바닥의 미세한 떨림을 차례로 확인함 | H40: 1/10 – 관찰 대상 수·이상 징후의 미세함·단서 분산 정도가 난이도를 결정함 | I40: 5 | J40: 시민·쓰레기·조명·바닥 진동에 관한 필수 관찰 대상 확인 | K40: - | L40: 20초 | M40: 이상 징후가 발생할 때 효과음과 짧은 시선 유도 아이콘 표시 | N40: 0.017303241 | O40: 2-A | 공원 축제·청소 | P40: 3 | Q40: 135 | S40: 20초 | T40: 20초 | U40: 20초
...

Sheet PC DATA(대차대조표)
A1: 이름 | B1: 콘텐츠 진행 순서 | C1: 콘텐츠명 | D1: 이름 | E1: 이미지 | F1: 전투 상태 | G1: 기본 공격력 | H1: 공격력 변화(최초·일회성) | I1: 기본 방어력 | J1: 방어력 변화(획득·손상·파손) | K1: 스킬(최초 해금) | L1: 변경 근거·현재 상태
B2: ※ 밸런스 문서의 콘텐츠 진행 순서 1~306에서 현재 기본 공격력·기본 방어력과 전투 상태를 확인할 수 있음. 장비와 지속 해금 PC 스킬은 처음 획득·교체·손상·해금되는 시점에만 기록함. 아이템 고유 행동·UI 기능·엔딩 전용 강제 이벤트 스킬([눈물] 등)은 아이템·스킬 DATA·밸런스 문서의 동일 콘텐츠 번호로 검증함. 일반인 상태는 공격력 10·방어력 10이며, 첫 힘 발현은 해당 콘텐츠에만 적용되는 +990 일회성 보정임.
A3: 차한해 | B3: 1 | C3: 차한해의 과거 오프닝 감상 | D3: 차한해 | F3: 전투 시스템 미개방 | G3: 10 | I3: 10 | K3: 싫어요. | L3: 기본 공격력 10 / 기본 방어력 10
A4: 차한해 | B4: 2 | C4: 아버지 회사 서류를 챙겨 식탁에 올려두기 | D4: 차한해 | F4: 전투 시스템 미개방 | G4: 10 | I4: 10 | L4: 일반인 신체 능력 유지
A5: 차한해 | B5: 3 | C5: 빨래를 분류해 세탁기에 넣고 작동하기 | D5: 차한해 | F5: 전투 시스템 미개방 | G5: 10 | I5: 10
A6: 차한해 | B6: 4 | C6: 어머니의 비싼 블라우스를 손세탁하기 | D6: 차한해 | F6: 전투 시스템 미개방 | G6: 10 | I6: 10
A7: 차한해 | B7: 5 | C7: 건조기 완료음을 듣고 빨래를 꺼내 거실에서 개기 | D7: 차한해 | F7: 전투 시스템 미개방 | G7: 10 | I7: 10
A8: 차한해 | B8: 6 | C8: 동생에게 신상 과자·헤어롤·팝콘 심부름 받기 | D8: 차한해 | F8: 전투 시스템 미개방 | G8: 10 | I8: 10
A9: 차한해 | B9: 7 | C9: 엘리베이터에서 주민 모두에게 인사하며 밖으로 나가기 | D9: 차한해 | F9: 전투 시스템 미개방 | G9: 10 | I9: 10
A10: 차한해 | B10: 8 | C10: 편의점에서 신상 과자가 아직 입고되지 않았음을 확인하기 | D10: 차한해 | F10: 전투 시스템 미개방 | G10: 10 | I10: 10
A11: 차한해 | B11: 9 | C11: 알바생의 무거운 음료 박스 진열 부탁을 수락할지 선택하기 | D11: 차한해 | F11: 전투 시스템 미개방 | G11: 10 | I11: 10
A12: 차한해 | B12: 10 | C12: 음료 박스를 가격표에 맞춰 진열하기 | D12: 차한해 | F12: 전투 시스템 미개방 | G12: 10 | I12: 10
A13: 차한해 | B13: 11 | C13: 골목에서 들리는 예쁜 고양이 울음소리 확인하기 | D13: 차한해 | F13: 전투 시스템 미개방 | G13: 10 | I13: 10
A14: 차한해 | B14: 12 | C14: 편의점에서 츄르 4개입 세트 구매하기 | D14: 차한해 | F14: 전투 시스템 미개방 | G14: 10 | I14: 10
A15: 차한해 | B15: 13 | C15: 예쁜 고양이에게 첫 번째 츄르 건네기 | D15: 차한해 | F15: 전투 시스템 미개방 | G15: 10 | I15: 10
A16: 차한해 | B16: 14 | C16: 다이소로 이동하기 | D16: 차한해 | F16: 전투 시스템 미개방 | G16: 10 | I16: 10
... A80: 차한해 | B80: 78 | C80: 문틈젤리와 정면으로 마주치기 | D80: 차한해 | F80: 전투 시스템 미개방 | G80: 10 | I80: 10
A81: 차한해 | B81: 79 | C81: 두 눈을 감고 양손으로 괴물을 막기 | D81: 차한해 | F81: 무의식적 일회성 발현 | G81: 10 | H81: [펑!] 연계 : 무의식적 선의 폭발 +990 순간 출력 1000 | I81: 10 | K81: 펑! | L81: 기본 공격력 10 / 무의식적 선의 폭발 +990 · 순간 출력 1000 / 기본 방어력 10
A82: 차한해 | B82: 80 | C82: 먼지처럼 사라진 괴물의 흔적 확인하기 | D82: 차한해 | F82: 미개방·힘 재현 불가 | G82: 10 | H82: [펑!] 연계 종료 : +990 → 0 | I82: 10 | L82: 무의식적 선의 폭발 종료 : +990 → 0
A83: 차한해 | B83: 81 | C83: 어린아이를 공주님 안기로 구출하기 | D83: 차한해 | F83: 미개방·힘 재현 불가 | G83: 10 | I83: 10 | L83: 첫 힘의 존재와 발동 방법을 인식하지 못함
A84: 차한해 | B84: 82 | C84: 아이의 ‘괴물 펑’ 목격담 듣기 | D84: 차한해 | F84: 미개방·힘 재현 불가 | G84: 10 | I84: 10
A85: 차한해 | B85: 83 | C85: 질질핵를 우회해 안전 구역으로 이동하기 | D85: 차한해 | F85: 미개방·힘 재현 불가 | G85: 10 | I85: 10
A86: 차한해 | B86: 84 | C86: 울음주머니의 울음 파동을 피해 새벽 괴물 습격 구간 벗어나기 | D86: 차한해 | F86: 미개방·힘 재현 불가 | G86: 10 | I86: 10
A87: 차한해 | B87: 85 | C87: 길치섬모의 배회 경로를 피해 한도윤과 합류하기 | D87: 차한해 | F87: 미개방·힘 재현 불가 | G87: 10 | I87: 10
A88: 차한해 | B88: 86 | C88: 임시 대피소 도착하기 | D88: 차한해 | F88: 미개방·힘 재현 불가 | G88: 10 | I88: 10
A89: 차한해 | B89: 87 | C89: 맨몸으로 할머니를 구해 유명해진 청년의 뉴스 확인하기 | D89: 차한해 | F89: 미개방·힘 재현 불가 | G89: 10 | I89: 10
A90: 차한해 | B90: 88 | C90: 선행으로 유명해진 청년의 인터뷰와 밈 확인하기 | D90: 차한해 | F90: 미개방·힘 재현 불가 | G90: 10 | I90: 10
A91: 차한해 | B91: 89 | C91: 악질 채널 ‘클릭헌터’의 균열 접근 생방송 시청하기 | D91: 차한해 | F91: 미개방·힘 재현 불가 | G91: 10 | I91: 10
A92: 차한해 | B92: 90 | C92: 클릭헌터에게 나타난 선의 수치 96 확인하기 | D92: 차한해 | F92: 미개방·힘 재현 불가 | G92: 10 | I92: 10
A93: 차한해 | B93: 91 | C93: 기계가 정상 작동하는 균열 연구 현장 확인하기 | D93: 차한해 | F93: 미개방·힘 재현 불가 | G93: 10 | I93: 10
A94: 차한해 | B94: 92 | C94: 유명 청년의 선의 수치 836 측정하기 | D94: 차한해 | F94: 미개방·힘 재현 불가 | G94: 10 | I94: 10
A95: 차한해 | B95: 93 | C95: 새로운 수치를 ‘선의 수치’라고 부르는 과정 확인하기 | D95: 차한해 | F95: 미개방·힘 재현 불가 | G95: 10 | I95: 10
... A119: 차한해 | B119: 117 | C119: 선의 수치 836 청년의 초기 구조 원칙 듣기 | D119: 차한해 | F119: 미개방·힘 재현 불가 | G119: 10 | I119: 10
A120: 차한해 | B120: 118 | C120: 관리국 표준 대응 장비 8종·응급품 2종을 수령하고 상태 UI 확인하기 | D120: 차한해 | F120: 전투 가능·비전투 콘텐츠 | G120: 80 | H120: 관리국 지급 권총 +20 관리국 대응 장갑 +3 비살상 충격탄 사용 시 +6 | I120: 100 | J120: 기본 보호 조끼 +30 관리국 방진 고글 +4 관리국 대응 장갑 +5 관리국 전술화 +6 관리국 방진 마스크 +3 | K120: 탕! 앗, 피해! 잠깐만! | L120: 관리국 표준 대응 세트 8종·응급 주사·비살상 충격탄 획득
A121: 차한해 | B121: 119 | C121: 관리국 지급 권총·비살상 충격탄·관리국 전술화를 이용해 사격과 회피 연습하기 | D121: 차한해 | F121: 전투 가능 | G121: 100 | I121: 100 | L121: 기본 공격력 100 / 스킬 : 조준 사격 · 긴급 회피
A122: 차한해 | B122: 120 | C122: 출동 차량을 향해 환호하는 시민들 지나가기 | D122: 차한해 | F122: 전투 가능·비전투 콘텐츠 | G122: 100 | I122: 100 | L122: 전투 수치 변화 없이 탐색·대화·이동 진행
A123: 차한해 | B123: 121 | C123: 도심 잔해 구역으로 이동하며 관리국 보급 상자에서 소형 방진 필터 챙기기 | D123: 차한해 | F123: 전투 가능·비전투 콘텐츠 | G123: 100 | I123: 100 | L123: 소형 방진 필터 1개 획득
A124: 차한해 | B124: 122 | C124: 고립 시민 찾기 | D124: 차한해 | F124: 전투 가능·비전투 콘텐츠 | G124: 100 | I124: 100
A125: 차한해 | B125: 123 | C125: 관리국 대응 장갑을 착용하고 잔해 제거하기 | D125: 차한해 | F125: 전투 가능·비전투 콘텐츠 | G125: 100 | I125: 100
A126: 차한해 | B126: 124 | C126: 시민 대피 유도하기 | D126: 차한해 | F126: 전투 가능·비전투 콘텐츠 | G126: 100 | I126: 100
...

Sheet PC DATA
A1: 플레이어 고유명(CLASS) | B1: 콘텐츠 진행 순서 | C1: 기본 공격력 | D1: 공격력 합산 요소(최초·일회성 변화) | E1: 기본 방어력 | F1: 방어력 합산 요소(획득·손상·파손) | G1: 스킬(최초 해금)
A2: ※ 일반인 상태의 기본 공격력·기본 방어력은 각각 10으로 시작함. 79번 콘텐츠에서 [펑!]으로 무의식적 선의 폭발 +990이 한 번만 적용되어 순간 출력 1000이 되지만 다음 콘텐츠에서 보정이 0으로 돌아감. 정식 전투 능력과 관리국 표준 대응 장비는 118번부터 개방됨. 스킬 열에는 지속 해금되는 PC 조작·판단 스킬만 기록하고, 아이템 고유 행동·UI 기능·엔딩 전용 강제 이벤트 스킬([눈물] 등)은 아이템 시트·스킬 DATA·밸런스 문서에서 관리함.
A3: 차한해 | B3: 1 | C3: 10 | E3: 10 | G3: 싫어요.
B4: 79 | C4: 10 | D4: [펑!] 연계 : 무의식적 선의 폭발 +990 순간 출력 1000 | E4: 10 | G4: 펑!
B5: 80 | D5: [펑!] 연계 종료 : +990 → 0
B6: 118 | C6: 80 | D6: 관리국 지급 권총 +20 관리국 대응 장갑 +3 비살상 충격탄 사용 시 +6 | E6: 100 | F6: 기본 보호 조끼 +30 관리국 방진 고글 +4 관리국 대응 장갑 +5 관리국 전술화 +6 관리국 방진 마스크 +3 | G6: 탕! 앗, 피해! 잠깐만!
B7: 119 | C7: 100
B8: 125 | G8: 먼저 들었어
B9: 126 | C9: 120 | G9: 피했으면 내 차례
B10: 129 | D10: 보랏빛 철봉 +80
B11: 130 | C11: 160 | G11: 보라색, 여기!
B12: 131 | E12: 110 | F12: 기본 보호 조끼 손상: +30 → +15
B13: 134 | F13: 깨진 경찰 방패 +20 | G13: 앞은 내가 막아 저기 봐!
B14: 140 | D14: 차단기 막대 +90
B15: 141 | G15: 이쪽이야!
B16: 142 | C16: 180
B17: 145 | F17: 나무판 보호대 +10
B18: 148 | C18: 220 | E18: 120 | F18: 나무판 보호대 파손: 사용 불가 | G18: 핵부터!
B19: 153 | D19: 고등급자 공명 증폭기 +15 | F19: 충격 보호대 +20 관리국 대응 장갑 해제 : +5 → 0 공명 보호 장갑 +15 | G19: 증폭기, 켠다!
B20: 159 | D20: 전광판 쇠막대 +100
B21: 160 | C21: 250 | G21: 한 줄로 서!
B22: 163 | G22: 둘 중 하나!
B23: 166 | F23: 깨진 경찰 방패 파손: 사용 불가
B24: 168 | C24: 300 | E24: 135 | G24: 하나, 둘—지금!
B25: 169 | F25: 군용 방탄판 +35 | G25: 버텨!
B26: 179 | G26: 안 찍히면 돼
B27: 181 | C27: 340 | E27: 150 | F27: 군용 방탄판 균열: +35 → +15 | G27: 아무도 안 봐도
B28: 185 | D28: 소방용 진압 도끼 +75 구조용 로프 발사기 +12 | F28: 구조대 안전모 +8 | G28: 도와줘! 길 하나 만들게!
B29: 187 | F29: 소방 방열복 +22 화염 보호복 +20
B30: 188 | C30: 380 | D30: 소방용 진압 도끼·구조용 로프 발사기 반납 : +87 → 0 | E30: 165 | F30: 구조대 안전모·소방 방열복 반납 : +30 → 0 기본 보호 조끼 완전 파손 : 사용 불가 화염 보호복 손상 : +20 → +10
B31: 192 | F31: 관리국 방진 고글 해제 : +4 → 0 관리국 방진 마스크 해제 : +3 → 0 먼지 보호 안경 +10 균열 보호 마스크 +15
B32: 194 | F32: 철판 보호대 +25
B33: 196 | F33: 오염 차단 전신복 +35 심층 균열 탐사 헬멧 +12 관리국 전술화 해제 : +6 → 0 고밀도 충격 흡수 장화 +10 | G33: 괜찮아, 아직.
B34: 215 | G34: 쉿.
B35: 237 | D35: 사랑의 매 +140
B36: 238 | C36: 430 | G36: 껍데기부터
B37: 242 | F37: 매트 보호대 +15
B38: 243 | D38: 보랏빛 농구공 +120
B39: 244 | G39: 한 번 튕겨!
B40: 249 | C40: 470 | G40: 바꿔가며!
...

Sheet 아이템
A1: 이름 | B1: 타입 | C1: 참고 이미지 | D1: 사용 권한 | 획득 방식 | 획득 조건 | G1: 거래 제한 | H1: 사용 조건 | I1: 공격 수치 | 공격 보정 | K1: 방어 수치 | 방어 보정 | M1: 기타 수치 | N1: 세트 이름 | 효과 | 내용 | Q1: 수치 | R1: 최소 공격력 | S1: 최대 공격력
A2: 관리국 지급 권총 | B2: 무기 | D2: 선의관리국 요원 | E2: 퀘스트 | F2: 118번 | 관리국 표준 대응 장비 8종·응급품 2종을 수령하고 상태 UI 확인하기 | G2: 획득 시 귀속 | H2: 119번 이후 | 균열 대응 원거리 전투에서 사용 | I2: 20 | J2: 원거리 공격 보정 +5 | K2: 0 | N2: 관리국 표준 대응 세트 | O2: 2세트: 장비 교체 시간 -10% 5세트: 균열 오염 저항 +10 8세트: 자아 마모 누적량 -15% | P2: 물리·관통 | Q2: 100 | R2: 18 | S2: 22
A3: 기본 보호 조끼 | B3: 상의 | D3: 선의관리국 요원 | E3: 퀘스트 | F3: 118번 | 관리국 표준 대응 장비 8종·응급품 2종을 수령하고 상태 UI 확인하기 | G3: 획득 시 귀속 | H3: 130번 사용·131번 손상·188번 완전 파손 | I3: 0 | K3: 30 | L3: 충격 저항 +8 | N3: 관리국 표준 대응 세트 | P3: 충격 저항 | Q3: 100 | R3: 0 | S3: 0
A4: 관리국 방진 고글 | B4: 얼굴 | D4: 선의관리국 요원 | E4: 퀘스트 | F4: 118번 | 관리국 표준 대응 장비 8종·응급품 2종을 수령하고 상태 UI 확인하기 | G4: 획득 시 귀속 | H4: 128번 공명 흔적 추적·192번 먼지 보호 안경으로 교체 | I4: 0 | K4: 4 | L4: 분진·시야 방해 저항 +10 | M4: 균열 감지 범위 +2m | N4: 관리국 표준 대응 세트 | P4: 균열 감지 패시브 | Q4: +2m | R4: 0 | S4: 0
A5: 관리국 대응 장갑 | B5: 손 | D5: 선의관리국 요원 | E5: 퀘스트 | F5: 118번 | 관리국 표준 대응 장비 8종·응급품 2종을 수령하고 상태 UI 확인하기 | G5: 획득 시 귀속 | H5: 123번 잔해 제거·153번 공명 보호 장갑으로 교체 | I5: 3 | J5: 근접 공격 보정 +2 | K5: 5 | L5: 접촉 피해 감소 +5% | M5: 상호작용 속도 +5% | N5: 관리국 표준 대응 세트 | P5: 접촉 안정 패시브 | Q5: 피해 -5% | R5: 2 | S5: 4
A6: 관리국 전술화 | B6: 신발 | D6: 선의관리국 요원 | E6: 퀘스트 | F6: 118번 | 관리국 표준 대응 장비 8종·응급품 2종을 수령하고 상태 UI 확인하기 | G6: 획득 시 귀속 | H6: 119·126번 회피 훈련·196번 고밀도 충격 흡수 장화로 교체 | I6: 0 | K6: 6 | L6: 넘어짐 저항 +10% | M6: 회피 이동 거리 +5% | N6: 관리국 표준 대응 세트 | P6: 기동 보정 | Q6: +5% | R6: 0 | S6: 0
A7: 관리국 방진 마스크 | B7: 얼굴 | D7: 선의관리국 요원 | E7: 퀘스트 | F7: 118번 | 관리국 표준 대응 장비 8종·응급품 2종을 수령하고 상태 UI 확인하기 | G7: 획득 시 귀속 | H7: 128번 필터 교체 후 공명 흔적 추적·192번 균열 보호 마스크로 교체 | I7: 0 | K7: 3 | L7: 균열 오염 저항 +8 | M7: 자아 마모 저항 +3% | N7: 관리국 표준 대응 세트 | P7: 오염 저항 | Q7: 108 | R7: 0 | S7: 0
A8: 관리국 무전 이어피스 | B8: 액세서리 | D8: 선의관리국 요원 | E8: 퀘스트 | F8: 118번 | 관리국 표준 대응 장비 8종·응급품 2종을 수령하고 상태 UI 확인하기 | G8: 획득 시 귀속 | H8: 125번 공격 예고 판독에 사용 | I8: 0 | K8: 0 | M8: 공격 예고 판독 시간 +0.3초 | N8: 관리국 표준 대응 세트 | P8: 전술 정보 패시브 | Q8: +0.3초 | R8: 0 | S8: 0
A9: 관리국 상태 측정기 | B9: 액세서리 | D9: 선의관리국 요원 | E9: 퀘스트 | F9: 118번 | 관리국 표준 대응 장비 8종·응급품 2종을 수령하고 상태 UI 확인하기 | G9: 획득 시 귀속 | H9: 131번 장비 손상 확인·임무 종료 시 자동 동기화 | I9: 0 | K9: 0 | M9: 장비 내구도·자아 마모도 표시 | N9: 관리국 표준 대응 세트 | P9: 상태 확인 패시브 | Q9: UI 표시 | R9: 0 | S9: 0
A10: 보랏빛 철봉 | B10: 무기 | D10: 일반인 / 모든 선의 등급자 | E10: 콘텐츠 | F10: 129번 | 차한해에게만 보이는 보랏빛 아우라가 흐르는 철봉 회수 | H10: 130번 밖으로 나가재 제압 후 132번 소멸 | I10: 80 | J10: 근접 강공격 보정 +10 | K10: 0 | M10: 경직 유발 +12% | P10: 충격 | Q10: 115 | R10: 72 | S10: 88
A11: 깨진 경찰 방패 | B11: 보조 장비 | D11: 일반인 / 모든 선의 등급자 | E11: 콘텐츠 | F11: 134번 | 구조한 경찰에게 깨진 경찰 방패와 휴대용 섬광 신호기 받기 | H11: 146번 나만 살아서 다행 보스전·166번 파손 | I11: 0 | K11: 20 | L11: 전방 피해 감소 +12% | M11: 전방 방어 해금 | P11: 물리 저항 | Q11: 112 | R11: 0 | S11: 0
A12: 차단기 막대 | B12: 무기 | D12: 일반인 / 모든 선의 등급자 | E12: 콘텐츠 | F12: 140번 | 차한해에게만 보이는 보랏빛 공명의 차단기 막대 회수 | H12: 141번 유인·142번 비상구대게 제압 | I12: 90 | J12: 근접 공격 보정 +12 | K12: 0 | M12: 환경 유인 효과 +10% | P12: 전기·충격 | Q12: 120 | R12: 81 | S12: 99
A13: 나무판 보호대 | B13: 팔 방어구 | D13: 일반인 / 모든 선의 등급자 | E13: 제작 | F13: 145번 | 대피소 시민과 나무판 보호대 제작 | H13: 146~148번 나만 살아서 다행 보스전 사용 후 파손 | I13: 0 | K13: 10 | L13: 근접 피해 감소 +5% | M13: 임시 장비 제작 | P13: 물리 저항 | Q13: 105 | R13: 0 | S13: 0
A14: 소방용 진압 도끼 | B14: 무기 | D14: 고등급자 / 선의관리국 요원 | E14: 콘텐츠 | F14: 185번 | 회사로 우회하며 소방 보급 상자에서 확보 | G14: 획득 시 귀속 | H14: 188번 붕괴 잔해 3개 파괴 후 반납 | I14: 75 | J14: 구조물 공격 보정 +30 | K14: 0 | M14: 구조 행동 속도 +15% | N14: 재난 구조 세트 | O14: 2세트: 구조 행동 속도 +10% 4세트: 화염·연기 피해 -15% | P14: 화염 대응 | Q14: 115 | R14: 68 | S14: 82
A15: 소방 방열복 | B15: 상의 | D15: 고등급자 / 선의관리국 요원 | E15: 퀘스트 | F15: 187번 | 부상당한 소방관 구조 후 임시 대여 | G15: 획득 시 귀속 | H15: 188번 고열·낙하물 구간 통과 후 반납 | I15: 0 | K15: 22 | L15: 화염 피해 감소 +20% | M15: 이동 속도 -5% | N15: 재난 구조 세트 | P15: 화염 저항 | Q15: 120 | R15: 0 | S15: 0
A16: 구조대 안전모 | B16: 머리 | D16: 일반인 / 모든 선의 등급자 | E16: 콘텐츠 | F16: 185번 | 회사로 우회하며 소방 보급 상자에서 확보 | H16: 186~188번 낙하물 피해 대응 후 반납 | I16: 0 | K16: 8 | L16: 낙하물 피해 감소 +15% | M16: 기절 시간 -10% | N16: 재난 구조 세트 | P16: 낙하 충격 저항 | Q16: 115 | R16: 0 | S16: 0
A17: 구조용 로프 발사기 | B17: 보조 장비 | D17: 고등급자 / 선의관리국 요원 | E17: 퀘스트 | F17: 185번 | 회사로 우회하며 소방 보급 상자에서 확보 | G17: 획득 시 귀속 | H17: 186번 1회·188번 1회 사용 후 2회분 소진 | I17: 12 | J17: 원거리 경직 보정 +5 | K17: 0 | M17: 구조 이동 경로 해금 | N17: 재난 구조 세트 | P17: 이동 보조 패시브 | Q17: 2회 | R17: 10 | S17: 14
A18: 오염 차단 전신복 | B18: 상의 | D18: 고등급자 | E18: 퀘스트 | F18: 196번 | 관리국 현장 보급함에서 수령·장착 | G18: 획득 시 귀속 | H18: 213~217번 폐교 오염 조사·270번 최종 장비로 교체 | I18: 0 | K18: 35 | L18: 균열 오염 저항 +20 | M18: 자아 마모 누적량 -8% | N18: 심층 균열 탐사 세트 | O18: 2세트: 균열 감지 범위 +3m 4세트: 자아 마모 누적량 -12% | P18: 균열 저항 | Q18: 120 | R18: 0 | S18: 0
A19: 심층 균열 탐사 헬멧 | B19: 머리 | D19: 고등급자 | E19: 퀘스트 | F19: 196번 | 관리국 현장 보급함에서 수령·장착 | G19: 획득 시 귀속 | H19: 213·217번 흔적·퍼즐 단서 탐지 | I19: 0 | K19: 12 | L19: 정신 피해 저항 +10 | M19: 균열 감지 범위 +4m | N19: 심층 균열 탐사 세트 | P19: 균열 감지 패시브 | Q19: +4m | R19: 0 | S19: 0
A20: 선의 안정 장치 | B20: 액세서리 | D20: 차한해 전용 | E20: 업적 | F20: 196번 | 시민 구조 누적 30회 달성 후 관리국 현장 보급함에서 추가 수령 | G20: 획득 시 귀속 | H20: 249번 친구 정체 확인 시 1회 자동 발동 | I20: 0 | K20: 0 | M20: 자아마모 수치 유지·입력 흔들림 10초 완화 | N20: 심층 균열 탐사 세트 | P20: 입력 안정 | Q20: 10초 | R20: 0 | S20: 0
A21: 고밀도 충격 흡수 장화 | B21: 신발 | D21: 고등급자 | E21: 퀘스트 | F21: 196번 | 관리국 현장 보급함에서 수령·장착 | G21: 획득 시 귀속 | H21: 215번 밀치기 방어·251번 친구 접근·270번 강화 전투화로 교체 | I21: 0 | K21: 10 | L21: 넘어짐·밀쳐짐 저항 +20% | M21: 회피 후 경직 시간 -10% | N21: 심층 균열 탐사 세트 | P21: 기동 안정 | Q21: 120 | R21: 0 | S21: 0
A22: 응급 압박 붕대 | B22: 소모품 | D22: 일반인 / 모든 선의 등급자 | E22: 보급 | F22: 144번 | 봉쇄 대피소 보급 상자에서 획득 | H22: 146번 나만 살아서 다행 보스전에서 1회 사용 | I22: 0 | K22: 0 | M22: 체력 20% 회복 | P22: 회복 | Q22: 20 | R22: 0 | S22: 0
A23: 관리국 응급 주사 | B23: 소모품 | D23: 선의관리국 요원 | E23: 퀘스트 | F23: 118번 | 관리국 표준 대응 장비와 함께 지급 | G23: 획득 시 귀속 | H23: 168번 합치면 강해진댔잖아 보스전에서 1회 사용 | I23: 0 | K23: 0 | M23: 체력 35% 회복, 이동 속도 5초간 -10% | P23: 회복 | Q23: 35 | R23: 0 | S23: 0
A24: 안정 앰플 | B24: 소모품 | D24: 고등급자 / 차한해 전용 | E24: 퀘스트 | F24: 192번 | 나대진에게 환경 장비와 함께 수령 | G24: 획득 시 귀속 | H24: 250번 공격 중지 생존 구간에서 1회 사용 | I24: 0 | K24: 0 | M24: 자아마모 수치 유지·UI 간섭 8초 완화 | P24: UI 안정 | Q24: 8초 | R24: 0 | S24: 0
A25: 소형 방진 필터 | B25: 소모품 | D25: 일반인 / 모든 선의 등급자 | E25: 보급 | F25: 121번 | 도심 잔해 구역 이동 중 관리국 보급 상자에서 획득 | H25: 128번 관리국 방진 마스크에 1회 사용 | I25: 0 | K25: 0 | M25: 마스크 내구도 30 회복 | P25: 장비 회복 | Q25: 30 | R25: 0 | S25: 0
A26: 휴대용 섬광 신호기 | B26: 소모품 | D26: 일반인 / 모든 선의 등급자 | E26: 콘텐츠 | F26: 134번 | 구조한 경찰에게 깨진 방패와 함께 받기 | H26: 141번 내자리산호 유인에 1회 사용 | I26: 0 | K26: 0 | M26: 일반 괴물 주의 분산 4초 | P26: 시야 교란 | Q26: 4 | R26: 0 | S26: 0
A27: 비살상 충격탄 | B27: 탄약 | D27: 선의관리국 요원 | E27: 퀘스트 | F27: 118번 | 관리국 표준 대응 장비와 함께 지급 | G27: 획득 시 귀속 | H27: 119번 사격 훈련·125번 비살상 제압에 사용 | I27: 6 | J27: 경직 피해 +20% | K27: 0 | M27: 처치 대신 제압 게이지 증가 | P27: 비살상 충격 | Q27: 120 | R27: 5 | S27: 7
A28: 고등급자 공명 증폭기 | B28: 액세서리 | D28: 고등급자 | E28: 나대진 지급 | F28: 153번 | [나대진] 75% 이상에서 장비 지원으로 수령 | G28: 획득 시 귀속 | H28: 159번 공명 탐지·160번 찰싹진드기 제압 | I28: 15 | J28: 균열 개체 대상 피해 +8% | K28: 0 | M28: 공명 피해 증가·UI 간섭 +3% | P28: 공명 증폭 | Q28: 108 | R28: 13 | S28: 17
A29: 연구실 최고 권한 키카드 | B29: 접근 도구 | D29: 연구실 최고 권한자 | E29: 나대진 안내·현장 회수 | F29: 265번 | [나대진] 85% 이상에서 암호 경로를 따라 연구시설 책임자 단말에서 회수 | G29: 획득 시 귀속 | H29: 266번 | 첫 번째 연구시설 보안문 해제 | I29: 0 | K29: 0 | M29: 최고 보안 구역 접근 | P29: 접근 권한 | Q29: 최고 | R29: 0 | S29: 0
A30: 보안 요원 생체 인증 모듈 | B30: 접근 도구 | D30: 차한해 | E30: 몬스터 제압·회수 | F30: 265번 | 권한이 없습니다 제압 후 노출된 생체 인증 모듈 회수 | G30: 획득 시 귀속 | H30: 266번 | 두 번째 연구시설 생체 인식문 1회 해제 | I30: 0 | K30: 0 | M30: 보안 구역 접근 | P30: 생체 인증 | Q30: 1회 | R30: 0 | S30: 0
A31: 충격 보호대 | B31: 보조 장비 | D31: 차한해 | E31: 나대진 지급 | F31: 153번 | 충격 보호대·공명 보호 장갑·공명 증폭기 수령 | G31: 획득 시 귀속 | H31: 164~168번 합치면 강해진댔잖아 보스전에서 사용 | I31: 0 | K31: 20 | L31: 피격 경직 감소 | P31: 충격 보호 | Q31: 20 | R31: 0 | S31: 0
A32: 공명 보호 장갑 | B32: 손 | D32: 차한해 | E32: 나대진 지급 | F32: 153번 | 충격 보호대·공명 보호 장갑·공명 증폭기 수령 | G32: 획득 시 귀속 | H32: 159~168번 공명 무기·증폭기 사용 부담 완화 | I32: 0 | K32: 15 | L32: 공명 반동 감소 | P32: 공명 보호 | Q32: 15 | R32: 0 | S32: 0
A33: 전광판 쇠막대 | B33: 무기 | D33: 차한해 | E33: 현장 획득 | F33: 159번 | 차한해에게만 보이는 보랏빛 아우라와 공명 증폭기 반응이 겹치는 쇠막대 회수 | H33: 160번 찰싹진드기 제압 | I33: 100 | J33: 다수 정렬 타격 | K33: 0 | P33: 충격 | Q33: 100 | R33: 90 | S33: 110
A34: 군용 방탄판 | B34: 상의 | D34: 차한해 | E34: 군인 지원 | F34: 169번 | 구조된 군인에게 지원받기 | G34: 획득 시 귀속 | H34: 178~181번 박수 없인 못 살아 보스전·181번 균열 | I34: 0 | K34: 35 | L34: 강한 공격 방어 | P34: 물리 저항 | Q34: 35 | R34: 0 | S34: 0
A35: 화염 보호복 | B35: 상의 | D35: 차한해 | E35: 소방관 지원 | F35: 187번 | 도시 인연 50% 이상에서 부상당한 소방관 구조 보상으로 획득 | G35: 획득 시 귀속 | H35: 188번 회사 화재 구조·손상 후 +10 유지 | I35: 0 | K35: 20 | L35: 화염 피해 대응 | P35: 화염 저항 | Q35: 20 | R35: 0 | S35: 0
A36: 먼지 보호 안경 | B36: 얼굴 | D36: 차한해 | E36: 나대진 지급 | F36: 192번 | 폐교 환경 장비 수령 | G36: 획득 시 귀속 | H36: 213~217번 폐교 분진·시야 방해 구간 | I36: 0 | K36: 10 | L36: 분진 시야 확보 | P36: 분진 저항 | Q36: 10 | R36: 0 | S36: 0
A37: 균열 보호 마스크 | B37: 얼굴 | D37: 차한해 | E37: 나대진 지급 | F37: 192번 | 폐교 환경 장비 수령 | G37: 획득 시 귀속 | H37: 213~217번 폐교 균열 오염 구간 | I37: 0 | K37: 15 | L37: 균열 오염 차단 | P37: 균열 저항 | Q37: 15 | R37: 0 | S37: 0
A38: 철판 보호대 | B38: 보조 장비 | D38: 차한해 | E38: 정비공 지원 | F38: 194번 | 구조받은 정비공에게 획득 | G38: 획득 시 귀속 | H38: 246~251번 별을 삼킨 강당전·251번 파손 | I38: 0 | K38: 25 | L38: 충격 보호 | P38: 물리 저항 | Q38: 25 | R38: 0 | S38: 0
A39: 사랑의 매 | B39: 무기 | D39: 차한해 | E39: 현장 획득 | F39: 237번 | 변혜서의 기억과 공명해 차한해에게만 보랏빛으로 보이는 사랑의 매 회수 | H39: 238번 시험·246번 별을 삼킨 강당 외피 파괴 | I39: 140 | J39: 공명 외피 파괴 | K39: 0 | P39: 공명 | Q39: 140 | R39: 126 | S39: 154
A40: 매트 보호대 | B40: 보조 장비 | D40: 차한해 | E40: 현장 제작 | F40: 242번 | 체육관 매트로 제작 | G40: 획득 시 귀속 | H40: 246~251번 별을 삼킨 강당전·251번 파손 | I40: 0 | K40: 15 | L40: 충격 완화 | P40: 물리 저항 | Q40: 15 | R40: 0 | S40: 0
...

Sheet 속성 대차대조표 (2)
A1: 1. 속성 정의 및 적용 대상
A2: 속성 | B2: 핵심 성질 | E2: 공격 속성 적용 | I2: 방어 속성 적용 | M2: 대표 표현
A3: 안정 | B3: 형태와 에너지의 상태를 고정하고 과도한 진동을 억제하는 파장 | E3: 공명 주기 고정, 흔들림 억제, 변이체의 움직임 안정화 | I3: 공명·진동 피해 완화, 밀려남과 흔들림을 억제하는 방호 상태 | M3: 청색 고정선, 입자가 한 지점으로 모이는 연출
A4: 공명 | B4: 파동을 반복·중첩하여 내부 진동과 에너지 증폭을 일으키는 파장 | E4: 반복 타격과 파동 중첩, 차단 한계 초과, 균열 확대 | I4: 외부 파장을 되울리거나 분산하여 충격을 흘려보내는 상태 | M4: 보라색 파문, 동심원과 진동 잔상
A5: 차단 | B5: 에너지·파장·오염의 전달 경로와 연결을 끊는 파장 | E5: 능력 연결 절단, 침식 확산 중단, 유지 에너지 공급 방해 | I5: 외부 에너지 유입과 상태이상 전이를 막는 방호 상태 | M5: 짙은 회색 단절선, 벽 형태의 끊김 연출
A6: 침식 | B6: 조직과 구조의 결합을 약화하고 형태를 점진적으로 붕괴시키는 파장 | E6: 고정 구조 붕괴, 방어 상태 약화, 균열 부위 확대 | I6: 공격 에너지를 분해·흡수하며 일부 피해를 약화하는 상태 | M6: 자홍색 번짐, 표면이 부식되듯 퍼지는 연출
A8: 2. 속성 대차대조표 및 피해 계산 검증
A9: 피해 매개 상수표 K | G9: 상성 순환
A10: 공격자＼방어자 | B10: 안정 | C10: 공명 | D10: 차단 | E10: 침식 | L10: 안정 → 공명 → 차단 → 침식 → 안정은 ×1.7의 강한 우위 관계이며, 반대 방향은 ×0.3의 강한 열위 관계로 적용함.
A11: 안정 | B11: 1 | C11: 1.7 | D11: 0.8 | E11: 0.3
A12: 공명 | B12: 0.3 | C12: 1 | D12: 1.7 | E12: 1.2
A13: 차단 | B13: 1.2 | C13: 0.3 | D13: 1 | E13: 1.7
A14: 침식 | B14: 1.7 | C14: 0.8 | D14: 0.3 | E14: 1
A16: 3. 수치 근거표
A17: 공격 속성 | B17: 방어 속성 | C17: 관계 유형 | E17: 매개 상수 | G17: 수치 적용 근거 | L17: 전투 표현
A18: 안정 | B18: 안정 | C18: 동일 | E18: 1 | G18: 동일한 파장끼리는 서로 우위가 없으므로 기존 피해식에 영향을 주지 않음. | L18: 기본 피해 수치와 기본 속성 이펙트 적용
A19: 안정 | B19: 공명 | C19: 강한 우위 | E19: 1.7 | G19: 안정 파장이 진동 주기를 고정하여 공명의 반복·증폭 작용을 직접 억제함. | L19: 파동이 멈추고 약점 적중 이펙트 강조
A20: 안정 | B20: 차단 | C20: 약한 열위 | E20: 0.8 | G20: 차단 상태가 안정 파장의 전달 경로를 일부 끊어 고정 효과가 충분히 도달하지 못함. | L20: 안정선이 끊기며 피해 표시를 약하게 표현
A21: 안정 | B21: 침식 | C21: 강한 열위 | E21: 0.3 | G21: 이미 침식된 구조는 고정할 원형과 기준이 약해 안정화 효과가 크게 감소함. | L21: 고정선이 번짐에 흡수되는 연출
A22: 공명 | B22: 안정 | C22: 강한 열위 | E22: 0.3 | G22: 안정된 구조가 진동의 확산과 파동 중첩을 막아 공명 증폭이 발생하기 어려움. | L22: 파문이 짧게 사라지는 연출
A23: 공명 | B23: 공명 | C23: 동일 | E23: 1 | G23: 동일한 파장끼리는 서로 우위가 없으므로 기존 피해식에 영향을 주지 않음. | L23: 기본 피해 수치와 기본 속성 이펙트 적용
A24: 공명 | B24: 차단 | C24: 강한 우위 | E24: 1.7 | G24: 반복되는 공명 파동이 차단 상태의 처리 한계를 넘어 과부하를 발생시킴. | L24: 차단벽에 균열이 번지고 파동이 관통하는 연출
A25: 공명 | B25: 침식 | C25: 약한 우위 | E25: 1.2 | G25: 침식으로 약해진 구조의 미세 균열을 진동이 확대하여 붕괴를 촉진함. | L25: 침식 부위가 파동에 따라 넓어지는 연출
A26: 차단 | B26: 안정 | C26: 약한 우위 | E26: 1.2 | G26: 안정 상태를 유지하는 에너지 공급과 연결을 끊어 구조의 유지력을 약화함. | L26: 고정선 일부가 끊기며 약점 이펙트 표시
A27: 차단 | B27: 공명 | C27: 강한 열위 | E27: 0.3 | G27: 공명은 파동이 누적된 뒤에도 영향이 남아 단일 연결 차단만으로 완전히 제거하기 어려움. | L27: 차단선 너머로 파문이 이어지는 연출
A28: 차단 | B28: 차단 | C28: 동일 | E28: 1 | G28: 동일한 파장끼리는 서로 우위가 없으므로 기존 피해식에 영향을 주지 않음. | L28: 기본 피해 수치와 기본 속성 이펙트 적용
A29: 차단 | B29: 침식 | C29: 강한 우위 | E29: 1.7 | G29: 침식 에너지의 접촉·전이·확산 경로를 끊어 핵심 작용을 직접 무력화함. | L29: 번짐이 절단되고 약점 적중 이펙트 강조
... A33: 침식 | B33: 침식 | C33: 동일 | E33: 1 | G33: 동일한 파장끼리는 서로 우위가 없으므로 기존 피해식에 영향을 주지 않음. | L33: 기본 피해 수치와 기본 속성 이펙트 적용

Sheet 스킬 DATA
A1: 넌 착해! — 스킬 DATA
A2: 스킬을 ‘약속 + UI + Data’로 정의한 시스템 연동용 표 · 총 211개 스킬/상태 데이터 · 피해 계수 1.00 = 해당 시점 기본/최종 공격력 100% · 몬스터 발동 확률은 몬스터 시트의 발동률과 동기화 · 이벤트 전용 스킬도 별도 시트로 분리하지 않고 본 표에서 통합 관리
A3: 관리 정보 | G3: UI 기재 내용 | M3: 발동 조건 | O3: 피해 | S3: AI 제어 | U3: 조작·시간 | X3: 버프·디버프 | AB3: 연계·운영
A4: 스킬 ID | B4: 지정 사용자 | C4: 구간 | D4: 콘텐츠 번호 | E4: 최초 사용 콘텐츠 | F4: 사용 주체 | G4: 스킬명 | H4: 스킬 추가 설명 | I4: 스킬 아이콘 | J4: 스킬 타입 | K4: 지정 사용자 | L4: 상태 이상 값 | M4: 발동 조건 타입 | N4: 발동 필요 값 | O4: 피해 적용 타입 | P4: 피해 계수 | Q4: 고정 피해 | R4: 피해 산정식 | S4: AI 발동 주기(초) | T4: AI 발동 확률 | U4: 쿨타임 타입 | V4: 쿨타임(초) | W4: 시전 필요 시간(초) | X4: 능력 변동 종류 | Y4: 능력 변동 수치 | Z4: 단위 | AA4: 지속 시간(초) | AB4: 종료·취소 조건 | AC4: 연계 스킬 ID | AD4: 비고
A5: SKL-PC-001 | B5: 차한해 | C5: 기본 상호작용 | D5: 9 | E5: 9번 | 알바생의 무거운 음료 박스 진열 부탁을 수락할지 선택하기 | F5: PC | G5: 싫어요. | H5: 거절 가능한 부탁·요청에서 수락 대신 사용해 해당 요청을 종료하는 기본 상호작용 스킬. 거절한 콘텐츠의 인연·보상 획득 기회는 포기함. | J5: 액티브 | K5: 차한해 | M5: 입력 | N5: 수락 전 [싫어요.] 선택 | O5: 없음 | P5: 0 | Q5: 0 | R5: 피해 없음 | U5: 없음 | V5: 0 | W5: 0 | X5: 없음 | Y5: 0 | Z5: 없음 | AA5: 0 | AB5: 선택 확정 | AC5: 없음 | AD5: 게임 시작부터 해금·첫 사용 가능 콘텐츠 9번
A6: SKL-PC-002 | B6: 차한해 | C6: 3장·첫 힘 발현 | D6: 79 | E6: 79번 | 두 눈을 감고 양손으로 괴물을 막기 | F6: PC | G6: 펑! | H6: 괴물이 덮치기 직전 전용 UI에서 1회 발동하는 사건형 액티브. 무의식적 선의 폭발을 호출해 순간 출력 1000을 만들고 접촉 소멸까지 연쇄함. | J6: 연출용+액티브 | K6: 차한해 | M6: 1회 강제 발동 | N6: 문틈젤리 접촉 직전 | O6: 없음 | P6: 0 | Q6: 0 | R6: 피해 없음 | U6: 없음 | V6: 0 | W6: 0.6 | X6: 공격력 | Y6: 990 | Z6: + | AA6: 0 | AB6: 접촉 소멸 완료 | AC6: SKL-STS-011 → SKL-STS-012 | AD6: 스토리 필수 사용·해당 콘텐츠에만 적용
A7: SKL-PC-003 | B7: 차한해 | C7: 정식 전투 | D7: 119 | E7: 119번 | 관리국 지급 권총·비살상 충격탄·관리국 전술화를 이용해 사격과 회피 연습하기 | F7: PC | G7: 탕! | H7: 장착한 총기·원거리 무기의 공격 수치를 포함해 정면 표적 1체를 공격하는 기본 사격. | J7: 액티브 | K7: 차한해 | L7: 경직 0.20초 | M7: 입력 | N7: 공격 입력 1회 | O7: 기본 공격력 비율 | P7: 1 | Q7: 0 | R7: 기본 공격력 × 100% | U7: 개별 | V7: 0.45 | W7: 0.2 | X7: 없음 | Y7: 0 | Z7: 없음 | AA7: 0 | AB7: 시전 종료 | AC7: SKL-STS-001 | AD7: 관리국 지급 권총을 기준으로 최초 훈련
A8: SKL-PC-004 | B8: 차한해 | C8: 정식 전투 | D8: 119 | E8: 119번 | 관리국 지급 권총·비살상 충격탄·관리국 전술화를 이용해 사격과 회피 연습하기 | F8: PC | G8: 앗, 피해! | H8: 입력 방향으로 짧게 이동하며 공격 판정을 피하는 기본 회피. 성공 시 일부 반격 스킬의 조건을 열어 줌. | J8: 액티브 | K8: 차한해 | M8: 입력 | N8: 회피 입력 1회 | O8: 없음 | P8: 0 | Q8: 0 | R8: 피해 없음 | U8: 개별 | V8: 1.8 | W8: 0.1 | X8: 이동 속도 | Y8: 80 | Z8: % | AA8: 0.25 | AB8: 이동 종료 | AC8: 없음 | AD8: 훈련 이후 상시 사용
A9: SKL-PC-005 | B9: 보스 | C9: 보스 공통 | D9: 146 | E9: 146번 | 나만 살아서 다행이 연속으로 닫는 방화문 다시 열기 | F9: PC | G9: 잠깐만! | H9: 보스전에서 딱 1번 사용할 수 있는 보조 스킬. 보스의 현재 행동을 1초간 멈춰 위험 패턴을 끊을 틈을 만듦. | J9: 액티브 | K9: 보스 | L9: 경직 1.00초 | M9: 전투당 1회 | N9: 보스전·미사용 상태 | O9: 없음 | P9: 0 | Q9: 0 | R9: 피해 없음 | U9: 전투당 1회 | V9: 0 | W9: 0.15 | X9: 없음 | Y9: 0 | Z9: 없음 | AA9: 1 | AB9: 1초 종료 | AC9: SKL-STS-001 | AD9: 118번에서 해금·146번 첫 보스부터 실제 사용 가능
A10: SKL-PC-006 | B10: 차한해 | C10: 전투 정보 | D10: 125 | E10: 125번 | 관리국 무전 이어피스로 똑똑소라의 공격 예고 신호 파악하기 | F10: PC | G10: 먼저 들었어 | H10: 관리국 무전 이어피스의 공격 예고 신호를 판독해 적의 전조를 기본보다 0.3초 먼저 표시하는 패시브. | J10: 패시브 | K10: 차한해 | M10: 장비 착용 | N10: 관리국 무전 이어피스 장착 | O10: 없음 | P10: 0 | Q10: 0 | R10: 피해 없음 | U10: 없음 | V10: 0 | W10: 0 | X10: 전조 표시 시간 | Y10: 0.3 | Z10: 초 | AA10: 0 | AB10: 장비 해제 | AC10: 없음 | AD10: 장비 효과를 스킬 형태로 표현
A11: SKL-PC-007 | B11: 차한해 | C11: 정식 전투 | D11: 126 | E11: 126번 | 문틈새우의 후방 기습을 피하고 반격 타이밍 맞추기 | F11: PC | G11: 피했으면 내 차례 | H11: 직전 공격을 회피한 직후 짧은 반격 창에서 사용하는 대응 사격·타격. | J11: 액티브 | K11: 차한해 | L11: 경직 0.30초 | M11: 조건부 입력 | N11: 회피 성공 후 0.8초 이내 | O11: 기본 공격력 비율 | P11: 1.15 | Q11: 0 | R11: 기본 공격력 × 115% | U11: 개별 | V11: 2 | W11: 0.25 | X11: 없음 | Y11: 0 | Z11: 없음 | AA11: 0 | AB11: 반격 창 종료 | AC11: SKL-STS-001 | AD11: 회피 성공을 공격 기회로 전환
A12: SKL-PC-008 | B12: 차한해 | C12: 공명 전투 | D12: 130 | E12: 130번 | 보랏빛 철봉으로 밖으로 나가재 제압하기 | F12: PC | G12: 보라색, 여기! | H12: 차한해에게만 보이는 보랏빛 공명 반응 부위를 노려 타격해 일반 공격보다 큰 약점 피해를 줌. | J12: 액티브 | K12: 차한해 | M12: 약점 노출 | N12: 보랏빛 약점 표식 활성 | O12: 기본 공격력 비율 | P12: 1.35 | Q12: 0 | R12: 기본 공격력 × 135% | U12: 개별 | V12: 2.5 | W12: 0.35 | X12: 없음 | Y12: 0 | Z12: 없음 | AA12: 0 | AB12: 약점 타격 종료 | AC12: 없음 | AD12: 공명 약점이 없는 대상에는 사용 불가
A13: SKL-PC-009 | B13: 차한해 | C13: 방어 전투 | D13: 134 | E13: 134번 | 구조한 경찰에게 깨진 경찰 방패와 휴대용 섬광 신호기 받기 | F13: PC | G13: 앞은 내가 막아 | H13: 깨진 경찰 방패 등 전방 방어 장비를 들어 정면 피해와 밀려남을 줄이는 유지형 방어. | J13: 액티브 | K13: 차한해 | M13: 입력 유지 | N13: 방어 장비 장착·방어 입력 유지 | O13: 없음 | P13: 0 | Q13: 0 | R13: 피해 없음 | U13: 유지형 | V13: 0 | W13: 0.15 | X13: 받는 정면 피해 | Y13: -50 | Z13: % | AA13: 0 | AB13: 입력 해제·방패 파손 | AC13: 없음 | AD13: 보스·강한 공격에는 감소량이 낮아질 수 있음
A14: SKL-PC-010 | B14: 일반 변이체 | C14: 환경 유인 | D14: 141 | E14: 141번 | 휴대용 섬광 신호기와 차단기 막대로 내자리산호 유인하기 | F14: PC | G14: 저기 봐! | H14: 휴대용 섬광 신호기 1개를 소비해 일반 변이체의 주의를 설치 지점으로 4초간 돌리는 비전투·전투 겸용 스킬. | J14: 연출용+액티브 | K14: 일반 변이체 | L14: 주의 분산 4초 | M14: 아이템 사용 | N14: 휴대용 섬광 신호기 1회 소모 | O14: 없음 | P14: 0 | Q14: 0 | R14: 피해 없음 | U14: 아이템 횟수 | V14: 0 | W14: 0.4 | X14: 표적 인식 | Y14: -1 | Z14: 대상 | AA14: 4 | AB14: 지속 종료·보스 면역 | AC14: SKL-STS-010 | AD14: PPT의 폭죽형 유틸리티 스킬과 같은 구조
A15: SKL-PC-011 | B15: 차한해 | C15: 환경 유인 | D15: 141 | E15: 141번 | 휴대용 섬광 신호기와 차단기 막대로 내자리산호 유인하기 | F15: PC | G15: 이쪽이야! | H15: 차단기 막대나 주변 소음 오브젝트를 이용해 주의가 분산된 적의 이동 목표를 열린 공간으로 유도함. | J15: 액티브 | K15: 차한해 | M15: 환경 상호작용 | N15: 유인 가능한 오브젝트 활성 | O15: 없음 | P15: 0 | Q15: 0 | R15: 피해 없음 | U15: 개별 | V15: 3 | W15: 0.3 | X15: 이동 목표 | Y15: 1 | Z15: 지점 | AA15: 3 | AB15: 대상 도달·지속 종료 | AC15: SKL-STS-007 | AD15: 환경 지형과 함께 사용하는 전술형 스킬
A16: SKL-PC-012 | B16: 차한해 | C16: 첫 보스 | D16: 148 | E16: 148번 | 모든 문을 열린 채 고정하고 잠금 핵 무력화하기 | F16: PC | G16: 핵부터! | H16: 보스의 노출된 핵에 공격을 집중해 외피보다 큰 파괴 효율을 내는 상황형 집중 공격. | J16: 액티브 | K16: 차한해 | M16: 약점 노출 | N16: 보스 핵 노출 상태 | O16: 기본 공격력 비율 | P16: 1.4 | Q16: 0 | R16: 기본 공격력 × 140% | U16: 개별 | V16: 1.5 | W16: 0.3 | X16: 핵 피해 | Y16: 40 | Z16: % | AA16: 0 | AB16: 핵 은폐 | AC16: 없음 | AD16: 노출 약점 전용
A17: SKL-PC-013 | B17: 차한해 | C17: 공명 장비 | D17: 153 | E17: 153번 | 나대진에게 충격 보호대·공명 보호 장갑·고등급자 공명 증폭기 수령하기 | F17: PC | G17: 증폭기, 켠다! | H17: 고등급자 공명 증폭기를 켜 공명 대상 공격력을 높이는 대신 화면 간섭을 함께 발생시키는 장비 액티브. | J17: 액티브 | K17: 차한해 | L17: UI 간섭 | M17: 장비 사용 | N17: 고등급자 공명 증폭기 장착 | O17: 없음 | P17: 0 | Q17: 0 | R17: 피해 없음 | U17: 개별 | V17: 8 | W17: 0.35 | X17: 공격력 | Y17: 15 | Z17: + | AA17: 8 | AB17: 장비 해제·지속 종료 | AC17: 없음 | AD17: 공명 대상 피해 +8%·UI 간섭 +3%는 아이템 시트 값 적용
A18: SKL-PC-014 | B18: 차한해 | C18: 다수 전투 | D18: 160 | E18: 160번 | 공명 증폭기와 전광판 쇠막대로 승강장의 찰싹진드기 제압하기 | F18: PC | G18: 한 줄로 서! | H18: 전광판 쇠막대의 넓은 궤적으로 일렬에 겹친 여러 적을 한 번에 타격하는 정렬 공격. | J18: 액티브 | K18: 차한해 | M18: 입력 | N18: 2체 이상 일렬 정렬 | O18: 기본 공격력 비율 | P18: 1.1 | Q18: 0 | R18: 기본 공격력 × 110% | U18: 개별 | V18: 3.2 | W18: 0.5 | X18: 최대 타격 수 | Y18: 3 | Z18: 체 | AA18: 0 | AB18: 시전 종료 | AC18: 없음 | AD18: 대상별 피해 동일
A19: SKL-PC-015 | B19: 차한해 | C19: 융합 보스 | D19: 163 | E19: 163번 | 합치면 강해진댔잖아의 단일 외피 공략하기 | F19: PC | G19: 둘 중 하나! | H19: 상반된 공격 전조를 읽고 이번 공격을 받아낼지 피할지 판별하는 판단형 패시브. | J19: 패시브 | K19: 차한해 | M19: 패턴 판독 | N19: 상반 전조 발생 | O19: 없음 | P19: 0 | Q19: 0 | R19: 피해 없음 | U19: 없음 | V19: 0 | W19: 0 | X19: 판독 표시 | Y19: 1 | Z19: 회 | AA19: 0 | AB19: 해당 공격 종료 | AC19: 없음 | AD19: 잘못 판독하면 보스 패턴 페널티 적용
A20: SKL-PC-016 | B20: 차한해 | C20: 융합 보스 | D20: 168 | E20: 168번 | 관리국 응급 주사를 사용하고 폭력의 순환 핵 파괴하기 | F20: PC | G20: 하나, 둘—지금! | H20: 동시에 노출된 2개의 연결 핵을 짧은 허용 시간 안에 맞혀 폭력의 순환 연결을 끊는 동시 타격. | J20: 액티브 | K20: 차한해 | M20: 동시 조건 | N20: 연결 핵 2개 동시 노출 | O20: 기본 공격력 비율 | P20: 1.2 | Q20: 0 | R20: 기본 공격력 × 120% | U20: 개별 | V20: 5 | W20: 0.45 | X20: 동시 판정 시간 | Y20: 0.6 | Z20: 초 | AA20: 0 | AB20: 핵 파괴·허용 시간 초과 | AC20: 없음 | AD20: 2개 핵 모두 적중해야 성공
A21: SKL-PC-017 | B21: 차한해 | C21: 중장비 방어 | D21: 169 | E21: 169번 | 구조된 군인에게 군용 방탄판 받기 | F21: PC | G21: 버텨! | H21: 군용 방탄판 등 중량 방어구를 이용해 강한 단발 공격을 정면에서 받아내고 밀려남을 크게 줄임. | J21: 액티브 | K21: 차한해 | M21: 조건부 입력 | N21: 강공격 전조 중 방어 입력 | O21: 없음 | P21: 0 | Q21: 0 | R21: 피해 없음 | U21: 개별 | V21: 4 | W21: 0.2 | X21: 받는 피해 | Y21: -35 | Z21: % | AA21: 1 | AB21: 강공격 종료 | AC21: SKL-STS-002 | AD21: 방어구 내구도 소모
A22: SKL-PC-018 | B22: 차한해 | C22: 갈채 보스 | D22: 179 | E22: 179번 | 추앙풍뎅이의 보호막 부여를 차단하고 중계 카메라 끄기 | F22: PC | G22: 안 찍히면 돼 | H22: 카메라 시야와 스포트라이트를 피해 사각지대에서 이동하면 갈채 계열 적의 추적·강화 조건을 끊음. | J22: 패시브 | K22: 차한해 | M22: 위치 조건 | N22: 카메라 시야 밖 | O22: 없음 | P22: 0 | Q22: 0 | R22: 피해 없음 | U22: 없음 | V22: 0 | W22: 0 | X22: 갈채 획득 | Y22: 0 | Z22: 고정 | AA22: 0 | AB22: 카메라 시야 진입 | AC22: SKL-STS-016 | AD22: 카메라 없는 행동이 보스 기믹을 약화
A23: SKL-PC-019 | B23: 차한해 | C23: 갈채 보스 | D23: 181 | E23: 181번 | 아무도 보지 않는 곳에서 시민을 구하고 박수 없인 못 살아 제압하기 | F23: PC | G23: 아무도 안 봐도 | H23: 카메라가 없는 위치에서 실제 시민을 구조해 갈채와 무관한 선행을 증명하고 보스 보호막을 제거하는 사건형 행동. | J23: 연출용+액티브 | K23: 차한해 | M23: 사건 조건 | N23: 실제 시민 판별·카메라 비노출 | O23: 없음 | P23: 0 | Q23: 0 | R23: 피해 없음 | U23: 없음 | V23: 0 | W23: 1 | X23: 보호막 | Y23: 0 | Z23: 고정 | AA23: 0 | AB23: 구조 완료 | AC23: SKL-STS-016 | AD23: 서사와 보스 공략을 직접 연결
A24: SKL-PC-020 | B24: 지원 가능 NPC | C24: 회사 구조 | D24: 186 | E24: 186번 | 구조용 로프 발사기로 한도윤과 회사 직원 대피시키기 | F24: PC | G24: 도와줘! | H24: 현재 콘텐츠에 사전 정의된 지원 행동이 있고 해당 NPC의 인연·위치 조건을 만족할 때만 지원을 호출하는 제한형 스킬. | J24: 액티브 | K24: 지원 가능 NPC | M24: 상황 조건 | N24: 지원 가능 NPC·인연·콘텐츠 플래그 충족 | O24: 없음 | P24: 0 | Q24: 0 | R24: 피해 없음 | U24: 상황당 1회 | V24: 0 | W24: 0.3 | X24: 없음 | Y24: 0 | Z24: 없음 | AA24: 0 | AB24: 지원 행동 완료 | AC24: SKL-NPC-001 / SKL-NPC-002 | AD24: 범용 동료 AI가 아니라 콘텐츠별 고정 지원 행동 호출
A25: SKL-PC-021 | B25: 차한해 | C25: 회사 구조 | D25: 186 | E25: 186번 | 구조용 로프 발사기로 한도윤과 회사 직원 대피시키기 | F25: PC | G25: 길 하나 만들게! | H25: 구조용 로프 발사기 1회를 소비해 끊어진 계단·붕괴 통로에 임시 이동 경로를 생성함. | J25: 연출용+액티브 | K25: 차한해 | M25: 아이템 사용 | N25: 구조용 로프 발사기 1회 소모 | O25: 없음 | P25: 0 | Q25: 0 | R25: 피해 없음 | U25: 아이템 횟수 | V25: 0 | W25: 0.8 | X25: 이동 경로 | Y25: 1 | Z25: 개 | AA25: 0 | AB25: 경로 생성 완료 | AC25: 없음 | AD25: 186번·188번 총 2회 사용
A26: SKL-PC-022 | B26: 차한해 | C26: 심층 탐사 | D26: 249 | E26: 249번 | 별을 삼킨 강당가 변혜서임을 확정하고 선의 안정 장치 발동 견디기 | F26: PC | G26: 괜찮아, 아직. | H26: 선의 안정 장치가 큰 심리 충격으로 입력 흔들림이 발생할 때 1회 자동 발동해 자아마모 수치는 유지한 채 조작 흔들림만 완화함. | J26: 패시브+자동 | K26: 차한해 | M26: 사건 플래그 | N26: 선의 안정 장치 장착·친구 정체 확정 | O26: 없음 | P26: 0 | Q26: 0 | R26: 피해 없음 | U26: 1회 자동 | V26: 0 | W26: 0 | X26: 입력 흔들림 | Y26: -100 | Z26: % | AA26: 10 | AB26: 10초 종료 | AC26: SKL-STS-013 | AD26: 196번에서 장치 획득·249번 첫 자동 발동
A27: SKL-PC-023 | B27: 차한해 | C27: 폐교 은폐 | D27: 215 | E27: 215번 | 고밀도 충격 흡수 장화로 등 뒤 한 칸의 기습을 버티며 복도 통과하기 | F27: PC | G27: 쉿. | H27: 이동을 잠시 멈추고 소리 발생 행동을 제한해 청각 추적형 변이체의 추적 게이지를 끊음. | J27: 액티브 | K27: 차한해 | M27: 입력 유지 | N27: 1초간 이동·공격 입력 없음 | O27: 없음 | P27: 0 | Q27: 0 | R27: 피해 없음 | U27: 개별 | V27: 2.5 | W27: 1 | X27: 소음 발생량 | Y27: -100 | Z27: % | AA27: 1.5 | AB27: 이동·공격 입력 | AC27: 없음 | AD27: 은폐 전용
A28: SKL-PC-024 | B28: 차한해 | C28: 폐교 공명 | D28: 238 | E28: 238번 | 보랏빛 사랑의 매로 기억 외피 공명 타격 시험하기 | F28: PC | G28: 껍데기부터 | H28: 사랑의 매로 보랏빛 공명 외피만 골라 때려 외피 방어를 먼저 제거하는 전용 공략 스킬. | J28: 액티브 | K28: 차한해 | M28: 약점 노출 | N28: 공명 외피 활성 | O28: 기본 공격력 비율 | P28: 1.3 | Q28: 0 | R28: 기본 공격력 × 130% | U28: 개별 | V28: 2.8 | W28: 0.45 | X28: 외피 피해 | Y28: 50 | Z28: % | AA28: 0 | AB28: 외피 파괴 | AC28: 없음 | AD28: 본체 피해보다 외피 제거에 특화
A29: SKL-PC-025 | B29: 차한해 | C29: 폐교 투척 | D29: 244 | E29: 244번 | 농구공의 투척 궤적 익히기 | F29: PC | G29: 한 번 튕겨! | H29: 보랏빛 농구공을 벽·골대에 반사시켜 직선으로 닿지 않는 기억 핵을 타격함. | J29: 액티브 | K29: 차한해 | M29: 입력 | N29: 반사 경로 조준 완료 | O29: 기본 공격력 비율 | P29: 1.1 | Q29: 0 | R29: 기본 공격력 × 110% | U29: 개별 | V29: 2 | W29: 0.55 | X29: 반사 횟수 | Y29: 1 | Z29: 회 | AA29: 0 | AB29: 공 회수·화면 밖 이탈 | AC29: 없음 | AD29: 반사 성공 시 기억 핵 판정 가능
... A34: SKL-PC-030 | B34: 차한해·동료 | C34: 최종 보스 | D34: 287 | E34: 287번 | 차한해에게 연결된 무한대 부담 장치 파괴하기 | F34: PC | G34: 이번엔 같이. | H34: 차한해 혼자 무한대 부담을 받아내지 않고 전장에 분산된 연결 장치를 동료와 동시 작동시키는 협력형 사건 스킬. | J34: 연출용+액티브 | K34: 차한해·동료 | M34: 동시 입력 | N34: 부담 연결 장치 4개 활성 | O34: 없음 | P34: 0 | Q34: 0 | R34: 피해 없음 | U34: 페이즈 1회 | V34: 0 | W34: 0.6 | X34: 부담 연결 | Y34: -4 | Z34: 개 | AA34: 0 | AB34: 장치 4개 동시 파괴 | AC34: 없음 | AD34: 최종부 주제인 책임 분담을 전투 기믹으로 표현
A35: SKL-PC-031 | B35: 도시 전체 시민 | C35: 희생 엔딩 | D35: 296 | E35: 296번 | 모두가 각자 가까운 균열로 함께 들어가기 | F35: PC | G35: 눈물 | H35: 차한해가 혼자 균열로 들어가는 희생 경로에서 진입 직전 UI로 반드시 사용하는 마지막 스킬. 눈물 한 방울과 함께 기억·감정이 도시 전체로 공명됨. | J35: 연출용+액티브 | K35: 도시 전체 시민 | L35: 죄책감 | M35: 1회 강제 발동 | N35: 단독 희생 엔딩 확정·균열 진입 직전 | O35: 없음 | P35: 0 | Q35: 0 | R35: 피해 없음 | U35: 엔딩 1회 | V35: 0 | W35: 2 | X35: 없음 | Y35: 0 | Z35: 없음 | AA35: 0 | AB35: 눈물 연출 종료·균열 진입 | AC35: SKL-STS-015 | AD35: 공동 진입 엔딩에서는 UI 자체가 나타나지 않음
A36: SKL-PC-032 | B36: 차한해 | C36: 고유 특성 | D36: 112 | E36: 112번 | 다른 측정기로 재측정하고 같은 오류 확인하기 | F36: PC | G36: 무한 선의 | H36: 차한해의 선의 감소 연산을 0으로 고정하고 측정 상한을 반복 초과시키는 태생적 패시브. 전투 행위 자체는 선의 감소 조건이 아님. | J36: 패시브 | K36: 차한해 | M36: 상시 | N36: 차한해 활성 상태 | O36: 없음 | P36: 0 | Q36: 0 | R36: 피해 없음 | U36: 없음 | V36: 0 | W36: 0 | X36: 선의 감소량 | Y36: 0 | Z36: 고정값 | AA36: 0 | AB36: 해제 불가 | AC36: 없음 | AD36: 112번 재측정에서 시스템적으로 확정
A37: SKL-NPC-001 | B37: 한도윤 | C37: 회사 구조 | D37: 186 | E37: 186번 | 구조용 로프 발사기로 한도윤과 회사 직원 대피시키기 | F37: NPC | G37: 찾았어, 여기야! | H37: 한도윤 인연 100%에서 [도와줘!]로 호출되는 지원 행동. 마지막 직원의 위치를 무전과 표식으로 즉시 알려 줌. | J37: 지원+이벤트 | K37: 한도윤 | M37: 연계 호출 | N37: SKL-PC-020 사용·한도윤 인연 100% | O37: 없음 | P37: 0 | Q37: 0 | R37: 피해 없음 | U37: 상황당 1회 | V37: 0 | W37: 0.5 | X37: 탐색 후보 | Y37: -1 | Z37: 구역 | AA37: 0 | AB37: 위치 표식 확인 | AC37: 없음 | AD37: 범용 AI 이동이 아니라 정보 지원
A38: SKL-NPC-002 | B38: 나대진 | C38: 최종 보스 | D38: 287 | E38: 287번 | 차한해에게 연결된 무한대 부담 장치 파괴하기 | F38: NPC | G38: 여기서 받쳐줄게 | H38: 나대진 인연 100%에서 [도와줘!]로 호출되는 원격 지원. 치명 피해 1회를 막고 가장 가까운 부담 장치 1개를 안정화함. | J38: 지원+이벤트 | K38: 나대진 | M38: 연계 호출 | N38: SKL-PC-020 사용·나대진 인연 100% | O38: 없음 | P38: 0 | Q38: 0 | R38: 피해 없음 | U38: 전투당 1회 | V38: 0 | W38: 0.4 | X38: 치명 피해 | Y38: -100 | Z38: % | AA38: 0 | AB38: 지원 1회 소모 | AC38: 없음 | AD38: 270번에서 지원 조건 해금
A39: SKL-STS-001 | B39: 피격 대상 | C39: 공용 상태 | D39: 119 | E39: 최초 호출 | 119번 | F39: 상태/시스템 | G39: 경직 | H39: 일정 시간 대상의 이동·공격 입력 또는 AI 행동을 중단시키는 공용 상태. | J39: 상태이상 | K39: 피격 대상 | L39: 행동 불가 | M39: 연계 호출 | N39: 경직을 부여하는 스킬 적중 | O39: 없음 | P39: 0 | Q39: 0 | R39: 피해 없음 | U39: 없음 | V39: 0 | W39: 0 | X39: 행동 가능 여부 | Y39: -1 | Z39: 상태 | AA39: 1 | AB39: 지속 종료 | AC39: 없음 | AD39: 호출 스킬이 지속 시간을 덮어씀
A40: SKL-STS-002 | B40: 피격 대상 | C40: 공용 상태 | D40: 130 | E40: 최초 호출 | 130번 | F40: 상태/시스템 | G40: 밀려남 | H40: 대상을 공격 방향 반대로 강제 이동시키는 공용 위치 제어 상태. | J40: 상태이상 | K40: 피격 대상 | L40: 강제 이동 | M40: 연계 호출 | N40: 밀치기·돌진·충격파 적중 | O40: 없음 | P40: 0 | Q40: 0 | R40: 피해 없음 | U40: 없음 | V40: 0 | W40: 0 | X40: 위치 이동 | Y40: 1.5 | Z40: 칸 | AA40: 0 | AB40: 이동 완료 | AC40: 없음 | AD40: 보스·고정형 개체는 거리 감소
A41: SKL-STS-003 | B41: 피격 대상 | C41: 공용 상태 | D41: 160 | E41: 최초 호출 | 160번 | F41: 상태/시스템 | G41: 이동 둔화 | H41: 대상의 이동 속도를 일정 시간 낮추는 공용 상태. | J41: 상태이상 | K41: 피격 대상 | L41: 이동 속도 감소 | M41: 연계 호출 | N41: 이동 방해 계열 스킬 적중 | O41: 없음 | P41: 0 | Q41: 0 | R41: 피해 없음 | U41: 없음 | V41: 0 | W41: 0 | X41: 이동 속도 | Y41: -40 | Z41: % | AA41: 3 | AB41: 지속 종료 | AC41: 없음 | AD41: 중첩 시 높은 값 우선
A42: SKL-STS-004 | B42: 시전자·아군 | C42: 공용 상태 | D42: 103 | E42: 최초 호출 | 103번 | F42: 상태/시스템 | G42: 공격 강화 | H42: 몬스터 또는 무리의 공격력을 일정 시간 높이는 공용 강화 상태. | J42: 버프 | K42: 시전자·아군 | M42: 연계 호출 | N42: 강화·가속·구호 계열 스킬 성공 | O42: 없음 | P42: 0 | Q42: 0 | R42: 피해 없음 | U42: 없음 | V42: 0 | W42: 0 | X42: 공격력 | Y42: 20 | Z42: % | AA42: 6 | AB42: 지속 종료 | AC42: 없음 | AD42: 선도체·갈채 계열 공용
A43: SKL-STS-005 | B43: 시전자·아군 | C43: 공용 상태 | D43: 179 | E43: 최초 호출 | 179번 | F43: 상태/시스템 | G43: 보호막 | H43: 일정량의 피해를 본체보다 먼저 흡수하는 공용 방어 상태. | J43: 버프 | K43: 시전자·아군 | M43: 연계 호출 | N43: 보호막·외피 계열 스킬 성공 | O43: 없음 | P43: 0 | Q43: 0 | R43: 피해 없음 | U43: 없음 | V43: 0 | W43: 0 | X43: 보호막 | Y43: 20 | Z43: % | AA43: 6 | AB43: 보호막 소진·지속 종료 | AC43: 없음 | AD43: 최대 HP 비율 기준
A44: SKL-STS-006 | B44: 차한해 | C44: 공용 상태 | D44: 222 | E44: 최초 호출 | 222번 | F44: 상태/시스템 | G44: 방향 혼란 | H44: 플레이어의 이동·전조 방향 정보를 짧게 뒤틀어 판단을 방해하는 상태. | J44: 디버프 | K44: 차한해 | L44: 방향 정보 왜곡 | M44: 연계 호출 | N44: 환각·혼란 계열 스킬 적중 | O44: 없음 | P44: 0 | Q44: 0 | R44: 피해 없음 | U44: 없음 | V44: 0 | W44: 0 | X44: 방향 판독 | Y44: -1 | Z44: 단계 | AA44: 2.5 | AB44: 지속 종료 | AC44: 없음 | AD44: 접근성 설정에서 시각 왜곡 완화 가능
...

Sheet 몬스터
B1: 검증 항목 | C1: 값 | E1: 작성 기준
B2: 전체 콘텐츠 수 | C2: 306 | E2: [신규 몬스터 작성 기준] 1) 초기 변이체만 전신 80~100%를 짙은 보라·자주·연보라로 구성하고, 단세포·점액·세포낭처럼 얼굴·손발 없는 단순 실루엣을 사용함. 2) 일반 변이체부터는 비인간 생물·사물·군체형을 기본으로 하며 보라색은 핵·균열·관절·체액에만 20~45% 사용함. 3) 일반→강화→선도체→보스 단계가 오를수록 외피, 복합 기관, 부하 통제 기관, 공간·사물 융합이 증가해 더 강해 보이게 함. 4) 3장 세포·심해생물, 4장 갑각류·문·대피소, 5장 곤충·갈채·카메라, 6장 빈 교복·교구, 7장 기계·압류·계량으로 챕터 서사를 구분함. 5) 인간 기원은 음성·행동·소지품·기억으로 암시함. 폐교의 빈 복장 연출 외에는 사람 얼굴·손·다리·직립 인체 비례를 사용하지 않음.
B3: 몬스터 배치 콘텐츠 수 | C3: =COUNTIF(C7:C312,"<>") -> 43
B4: 몬스터 미배치 콘텐츠 수 | C4: =C2-C3 -> 263
B5: 콘텐츠 누락 개수 | C5: =C2-COUNT(A7:A312) -> 0
A6: 콘텐츠 제시 순서 | C6: 몬스터 이름 | D6: 몬스터 이미지 | E6: 몬스터 타입 | F6: 생명력 | G6: 공격력 | H6: 공격력 합산 STATUS | I6: 공격력 보정 | J6: 최종 공격력 | K6: 방어력 | L6: 방어력 합산 STATUS | M6: 방어력 보정 | N6: 최종 방어력 | O6: 스킬1 | P6: 발동률1 | Q6: 스킬2 | R6: 발동률2 | S6: 스킬3 | T6: 발동률3 | U6: 스킬4 | V6: 발동률4 | W6: 몬스터 속성 | X6: 비고
A7: 1 | J7: =IF(C7="","",G7+I7) | N7: =IF(C7="","",K7+M7)
A8: 2
A9: 3
A10: 4
A11: 5
A12: 6
A13: 7
A14: 8
A15: 9
A16: 10
A17: 11
A18: 12
A19: 13
... A70: 64
A71: 65 | J71: =IF(C71="","",G71+I71) | N71: =IF(C71="","",K71+M71)
A72: 66
A73: 67
A74: 68
A75: 69
A76: 70
A77: 71
A78: 72
A79: 73
A80: 74 | B80: 조건부 선공 | C80: 보라멍울 | E80: 초기 변이체 | F80: 30 | G80: 4 | H80: 근접 본능 | I80: 1 | J80: 5 | K80: 0 | L80: 불완전한 외피 | M80: 0 | N80: 0 | O80: 슥, 긁기 | P80: 70 | Q80: 꿈틀꿈틀 | R80: 30 | T80: 0 | V80: 0 | W80: 침식 | X80: 전신이 짙은 보라색인 아메바형 단세포. 얼굴·손발 없이 위족과 발광 핵만으로 움직이는 최초 조우 개체.
A81: 75
A82: 76
A83: 77
A84: 78 | B84: 조건부 선공 | C84: 문틈젤리 | E84: 초기 변이체 | F84: 60 | G84: 7 | H84: 기습 반응 | I84: 1 | J84: 8 | K84: 2 | L84: 웅크린 자세 | M84: 1 | N84: 3 | O84: 문 열면 나와! | P84: 45 | Q84: 여긴 내 틈 | R84: 35 | S84: 쭈욱! | T84: 20 | V84: 0 | W84: 안정 | X84: 전신 보라색의 납작한 세포막. 문틈에 붙어 있다가 꽃잎처럼 막을 펼치며 접근을 막는다.
A85: 79
A86: 80
A87: 81
A88: 82
A89: 83 | B89: 선공 | C89: 질질핵 | E89: 초기 변이체 | F89: 45 | G89: 5 | H89: 체중 충격 | I89: 1 | J89: 6 | K89: 1 | L89: 두꺼운 등 외피 | M89: 1 | N89: 2 | O89: 쿵. | P89: 60 | Q89: 질질질… | R89: 40 | T89: 0 | V89: 0 | W89: 침식 | X89: 길쭉한 보라 점액질 몸으로 밝은 핵을 끌고 다닌다. 느린 압박과 우회 학습을 담당한다.
A90: 84 | B90: 비선공 | C90: 울음주머니 | E90: 초기 변이체 | F90: 35 | G90: 4 | H90: 공포 음파 | I90: 1 | J90: 5 | K90: 0 | L90: 얇은 외피 | M90: 0 | N90: 0 | O90: 으아앙— | P90: 45 | Q90: 가까이 오지 마 | R90: 35 | S90: 숨 한번 | T90: 20 | V90: 0 | W90: 공명 | X90: 입 없는 보라색 세포낭. 몸 전체가 부풀고 수축할 때 사람과 비슷한 울음만 새어 나온다.
...

Sheet 전투 시뮬레이터
B2: 똑똑소라 | I2: 3 | K2: 기본 보호 조끼 | L2: 관리국 지급 권총
E3: =VLOOKUP($B$2,몬스터!C7:X312,21,0) -> 공명 | F3: VS | G3: =VLOOKUP($I$2,'PC DATA(대차대조표)'!D3:L308,4,0) -> #N/A
K4: 관리국 대응 장갑 | L4: 관리국 방진 마스크
B6: 타입 | C6: =VLOOKUP($B$2,몬스터!C7:X312,3,0) -> 일반 변이체 | I6: 캐릭터 | J6: =VLOOKUP($I$2,'PC DATA(대차대조표)'!B3:L308,3,0) -> 차한해
B7: 속성 | C7: =VLOOKUP($B$2,몬스터!C8:X313,21,0) -> 공명 | I7: 전투 상태
A9: 전투 능력치
B11: 생명력 | C11: =VLOOKUP($B$2,몬스터!C7:X312,4,0) -> 130 | I11: 현재 공격력 | J11: =VLOOKUP($I$2,'PC DATA(대차대조표)'!D3:L308,4,0) -> #N/A
B12: 기본 공격력 | C12: =VLOOKUP($B$2,몬스터!C8:X313,5,0) -> 18 | I12: 공격 변화 | J12: =VLOOKUP($I$2,'PC DATA(대차대조표)'!D4:L309,5,0) -> #N/A
B13: 공격 보정 | C13: =VLOOKUP($B$2,몬스터!C9:X314,7,0) -> 3 | E13: 몬스터 | F13: STAT | G13: 플레이어 | I13: 현재 방어력 | J13: =VLOOKUP($I$2,'PC DATA(대차대조표)'!D5:L310,6,0) -> #N/A
B14: 최종 공격력 | C14: =VLOOKUP($B$2,몬스터!C10:X315,8,0) -> 21 | E14: =C14 -> 21 | F14: 최종 공격력 | G14: =J11 -> #N/A | I14: 방어 변화 | J14: =VLOOKUP($I$2,'PC DATA(대차대조표)'!D6:L311,7,0) -> #N/A
B15: 기본 방어력 | C15: =VLOOKUP($B$2,몬스터!C11:X316,9,0) -> 8 | E15: =C17 -> 10 | F15: 최종 방어력 | G15: =J13 -> #N/A
B16: 방어 보정 | C16: =VLOOKUP($B$2,몬스터!C12:X317,11,0) -> 2
B17: 최종 방어력 | C17: =VLOOKUP($B$2,몬스터!C13:X318,12,0) -> 10
A19: 속성 대차대조표 연동
A20: 몬스터 속성 | I20: 플레이어 무기 속성
E21: 공격 상성
A22: 상성 매개 상수 K | E22: =VLOOKUP($B$2,몬스터!C7:X312,21,0) -> 공명 | F22: VS | G22: 어떤 속성 | I22: 상성 매가 상수 K
A23: 상성 적용 공격 지표 | I23: 상성 적용 공격 지표
A24: 상대 방어력 | B24: =J13 -> #N/A | I24: 상대 방어력 | K24: =C17 -> 10
A25: 공격-방어 격차 | B25: =J11-C17 -> #N/A | I25: 공격-방어 격차 | K25: =C14-J13 -> #N/A
A26: =IF(B25>0,"열세",IF(B25<0,"우세","동등")) -> #N/A | I26: =IF(K25>0,"열세",IF(K25<0,"우세","동등")) -> #N/A
A28: 선택 개체 스킬
A29: 몬스터 스킬 | I29: 플레이어 스킬
A30: 스킬1 | B30: =VLOOKUP($B$2,몬스터!C7:X312,13,0) -> 똑똑똑! | C30: 발동 확률1 | D30: =VLOOKUP($B$2,몬스터!C7:X312,14,0) -> 40 | G30: =VLOOKUP($I$2,'PC DATA(대차대조표)'!A3:L308,2,0) -> #N/A | I30: 해당 시점 스킬 | K30: =VLOOKUP($I$2,'PC DATA(대차대조표)'!A3:L308,11,0) -> #N/A
A31: 스킬2 | B31: =VLOOKUP($B$2,몬스터!C8:X313,15,0) -> 문 좀 열어! | C31: 발동 확률2 | D31: =VLOOKUP($B$2,몬스터!C7:X312,16,0) -> 35 | I31: 공격 변화
A32: 스킬3 | B32: =VLOOKUP($B$2,몬스터!C9:X314,17,0) -> 다음 문! | C32: 발동 확률3 | D32: =VLOOKUP($B$2,몬스터!C7:X312,18,0) -> 25 | I32: 방어 변화
I33: 상태이상 | K33: =VLOOKUP($I$2,'PC DATA(대차대조표)'!D3:L308,4,0) -> #N/A
A35: 스킬 이름 | I35: 스킬 이름
A36: 타입 | I36: 타입
A37: 추가 설명 | I37: 추가 설명
A38: 발동 조건 | I38: 발동 조건
A39: 피해 계수 | I39: 피해 계수
A40: 쿨타임(초) | I40: 쿨타임(초)
A41: 시전 시간(초) | I41: 시전 시간(초)
A42: 능력 변동 | I42: 능력 변동
A43: 변동 수치 | I43: 변동 수치
A48: 우세인지 열세인지 | I48: 우세인지 열세인지
B50: 능력 분포 다각형
A64: 데미지 산정 공식
A65: 1회 공격 시간 | B65: = | C65: 1회 공격 시 필요 시간 (초 단위). 0.1초 단위로 고민
...

Sheet 속성 대차대조표
A1: 1. 속성 정의 및 적용 대상
A2: 속성 | B2: 핵심 성질 | E2: 공격 속성 적용 | I2: 방어 속성 적용 | M2: 대표 표현
A3: 안정 | B3: 형태와 에너지의 상태를 고정하고 과도한 진동을 억제하는 파장 | E3: 공명 주기 고정, 흔들림 억제, 변이체의 움직임 안정화 | I3: 공명·진동 피해 완화, 밀려남과 흔들림을 억제하는 방호 상태 | M3: 청색 고정선, 입자가 한 지점으로 모이는 연출
A4: 공명 | B4: 파동을 반복·중첩하여 내부 진동과 에너지 증폭을 일으키는 파장 | E4: 반복 타격과 파동 중첩, 차단 한계 초과, 균열 확대 | I4: 외부 파장을 되울리거나 분산하여 충격을 흘려보내는 상태 | M4: 보라색 파문, 동심원과 진동 잔상
A5: 차단 | B5: 에너지·파장·오염의 전달 경로와 연결을 끊는 파장 | E5: 능력 연결 절단, 침식 확산 중단, 유지 에너지 공급 방해 | I5: 외부 에너지 유입과 상태이상 전이를 막는 방호 상태 | M5: 짙은 회색 단절선, 벽 형태의 끊김 연출
A6: 침식 | B6: 조직과 구조의 결합을 약화하고 형태를 점진적으로 붕괴시키는 파장 | E6: 고정 구조 붕괴, 방어 상태 약화, 균열 부위 확대 | I6: 공격 에너지를 분해·흡수하며 일부 피해를 약화하는 상태 | M6: 자홍색 번짐, 표면이 부식되듯 퍼지는 연출
A8: 2. 속성 대차대조표 및 피해 계산 검증
A9: 피해 매개 상수표 K | G9: 상성 순환
A10: 공격자＼방어자 | B10: 안정 | C10: 공명 | D10: 차단 | E10: 침식 | L10: 안정 → 공명 → 차단 → 침식 → 안정은 ×1.7의 강한 우위 관계이며, 반대 방향은 ×0.3의 강한 열위 관계로 적용함.
A11: 안정 | B11: 1 | C11: 1.7 | D11: 0.8 | E11: 0.3
A12: 공명 | B12: 0.3 | C12: 1 | D12: 1.7 | E12: 1.2
A13: 차단 | B13: 1.2 | C13: 0.3 | D13: 1 | E13: 1.7
A14: 침식 | B14: 1.7 | C14: 0.8 | D14: 0.3 | E14: 1
A16: 3. 수치 근거표
A17: 공격 속성 | B17: 방어 속성 | C17: 관계 유형 | E17: 매개 상수 | G17: 수치 적용 근거 | L17: 전투 표현
A18: 안정 | B18: 안정 | C18: 동일 | E18: 1 | G18: 동일한 파장끼리는 서로 우위가 없으므로 기존 피해식에 영향을 주지 않음. | L18: 기본 피해 수치와 기본 속성 이펙트 적용
A19: 안정 | B19: 공명 | C19: 강한 우위 | E19: 1.7 | G19: 안정 파장이 진동 주기를 고정하여 공명의 반복·증폭 작용을 직접 억제함. | L19: 파동이 멈추고 약점 적중 이펙트 강조
A20: 안정 | B20: 차단 | C20: 약한 열위 | E20: 0.8 | G20: 차단 상태가 안정 파장의 전달 경로를 일부 끊어 고정 효과가 충분히 도달하지 못함. | L20: 안정선이 끊기며 피해 표시를 약하게 표현
A21: 안정 | B21: 침식 | C21: 강한 열위 | E21: 0.3 | G21: 이미 침식된 구조는 고정할 원형과 기준이 약해 안정화 효과가 크게 감소함. | L21: 고정선이 번짐에 흡수되는 연출
A22: 공명 | B22: 안정 | C22: 강한 열위 | E22: 0.3 | G22: 안정된 구조가 진동의 확산과 파동 중첩을 막아 공명 증폭이 발생하기 어려움. | L22: 파문이 짧게 사라지는 연출
A23: 공명 | B23: 공명 | C23: 동일 | E23: 1 | G23: 동일한 파장끼리는 서로 우위가 없으므로 기존 피해식에 영향을 주지 않음. | L23: 기본 피해 수치와 기본 속성 이펙트 적용
A24: 공명 | B24: 차단 | C24: 강한 우위 | E24: 1.7 | G24: 반복되는 공명 파동이 차단 상태의 처리 한계를 넘어 과부하를 발생시킴. | L24: 차단벽에 균열이 번지고 파동이 관통하는 연출
A25: 공명 | B25: 침식 | C25: 약한 우위 | E25: 1.2 | G25: 침식으로 약해진 구조의 미세 균열을 진동이 확대하여 붕괴를 촉진함. | L25: 침식 부위가 파동에 따라 넓어지는 연출
A26: 차단 | B26: 안정 | C26: 약한 우위 | E26: 1.2 | G26: 안정 상태를 유지하는 에너지 공급과 연결을 끊어 구조의 유지력을 약화함. | L26: 고정선 일부가 끊기며 약점 이펙트 표시
A27: 차단 | B27: 공명 | C27: 강한 열위 | E27: 0.3 | G27: 공명은 파동이 누적된 뒤에도 영향이 남아 단일 연결 차단만으로 완전히 제거하기 어려움. | L27: 차단선 너머로 파문이 이어지는 연출
A28: 차단 | B28: 차단 | C28: 동일 | E28: 1 | G28: 동일한 파장끼리는 서로 우위가 없으므로 기존 피해식에 영향을 주지 않음. | L28: 기본 피해 수치와 기본 속성 이펙트 적용
A29: 차단 | B29: 침식 | C29: 강한 우위 | E29: 1.7 | G29: 침식 에너지의 접촉·전이·확산 경로를 끊어 핵심 작용을 직접 무력화함. | L29: 번짐이 절단되고 약점 적중 이펙트 강조
... A33: 침식 | B33: 침식 | C33: 동일 | E33: 1 | G33: 동일한 파장끼리는 서로 우위가 없으므로 기존 피해식에 영향을 주지 않음. | L33: 기본 피해 수치와 기본 속성 이펙트 적용

Sheet 밸런스 팩터
B2: 밸런스 팩터
B3: 게임 「넌 착해!」의 플레이 경험 조절 요소. 핵심 연결은 ① 권장 대표 경로 미들 3시간 40분·전체 선택 포함 4시간 이내, ② 선의 수치 96·836·999 ERROR와 836 청년의 특혜 상실 공포·거짓 소문·희생 선동, ③ 메인 60%·선택 최대 100% 도시 인연과 1장 어르신 선택, ④ 변혜서의 우정 반지·별 펜던트·폐교 기억, ⑤ 클릭헌터와 조회수는 못 참지의 동일 개체 연결, ⑥ 초기 변이체의 전신 보라 단세포형과 일반 이상 비인간형 실루엣, ⑦ 보스 6종+정예 균열 수호체 1종, 괴물 43종·아이템 42종, ⑧ 연구시설의 권한이 없습니다와 생체 인증 모듈 획득 흐름임
B5: 진행·콘텐츠 | J5: 서사·상태 | R5: 전투 | Z5: 가이드·편의 | AH5: 크기: 핵심(대) · 반복 조정(중) · 장면 조정(소)
B70: 큰 원은 플레이 전반에 미치는 영향이 큰 핵심 팩터이며, 작은 원은 장면·미션 단위에서 조정하는 세부 팩터임

Sheet 작성 기준
A1: 게임 「넌 착해!」 밸런스 문서 작성 기준
A2: 모든 시트가 7챕터·콘텐츠 진행 순서 1~306, 문서 전체·대표 경로 시간, 자아마모도, 도시·예쁜 고양이 인연, PC 성장·장비 변화와 다중 엔딩 조건을 동일하게 사용하도록 검증하는 기준표 | D2: 7챕터·콘텐츠 306개·권장 대표 경로 미들 3시간 40분·괴물 43종·아이템 42종·보스 6종+정예 1종을 모든 시트가 동일하게 사용. 스킬 DATA는 PC·NPC 지원·상태/시스템·몬스터/보스 총 211개 데이터를 하나의 표에서 관리
A3: 1. 밸런스 문서 핵심 항목
A4: 항목 | B4: 작성 방식 | C4: 값/형식 | D4: 우리 게임 적용 기준
A5: 플레이 난이도 | B5: 플레이어가 실제 입력을 수행할 때 느끼는 조작 난도 | C5: 1~10 정수 | D5: 1은 단순 확인·대화, 10은 빠른 보스 패턴과 복합 입력
