Workbook
Name 몬스터_기본_공격_평균_시간: '[1]몬스터 공격 시간'!$E$4
Name 몬스터_생명력: 몬스터!$H$7:$H$312
Name 몬스터_생명력_가져오기: INDEX(몬스터_생명력,MATCH(시뮬레이터!$B$1,몬스터_이름,0))
Name 몬스터_선공: 몬스터!$C$7:$C$312
Name 몬스터_선공_가져오기: INDEX(몬스터_선공,MATCH(시뮬레이터!$B$1,몬스터_이름,0))
Name 몬스터_속성: 몬스터!$G$7:$G$312
Name 몬스터_속성_가져오기: INDEX(몬스터_속성,MATCH(시뮬레이터!$B$1,몬스터_이름,0))
Name 몬스터_스킬_가져오기: INDEX(몬스터_스킬_시전_시간,MATCH([1]시뮬레이터!$C$49,몬스터_스킬_목록,0))
Name 몬스터_스킬_목록: '[1]몬스터 공격 시간'!$A$1:$A$25
Name 몬스터_스킬_사용자: '스킬 DATA'!$C$56:$C$212
Name 몬스터_스킬_시전_시간: '[1]몬스터 공격 시간'!$B$1:$B$25
Name 몬스터_스킬1: 몬스터!$Q$7:$Q$312
Name 몬스터_스킬1_가져오기: IFERROR(INDEX(몬스터_스킬1,MATCH(시뮬레이터!$B$1,몬스터_이름,0)),"-")
Name 몬스터_스킬2: 몬스터!$S$7:$S$312
Name 몬스터_스킬2_가져오기: IFERROR(INDEX(몬스터_스킬2,MATCH(시뮬레이터!$B$1,몬스터_이름,0)),"-")
Name 몬스터_스킬3: 몬스터!$U$7:$U$312
Name 몬스터_스킬3_가져오기: IFERROR(INDEX(몬스터_스킬3,MATCH(시뮬레이터!$B$1,몬스터_이름,0)),"-")
Name 몬스터_스킬4: 몬스터!$W$7:$W$312
Name 몬스터_스킬4_가져오기: IFERROR(INDEX(몬스터_스킬4,MATCH(시뮬레이터!$B$1,몬스터_이름,0)),"-")
Name 몬스터_스킬목록: '스킬 DATA'!$G$56:$G$212
Name 몬스터_스킬목록_가져오기: INDEX(몬스터_스킬목록,MATCH(시뮬레이터!$B$1,몬스터_이름,0))
Name 몬스터_이름: 몬스터!$A$7:$A$312
Name 몬스터_이미지: 몬스터!$E$7:$E$312
Name 몬스터_이미지_가져오기: INDEX(몬스터_이미지,MATCH(시뮬레이터!$B$1,몬스터_이름,0))
Name 몬스터_콘텐츠번호: 몬스터!$B$7:$B$312
Name 몬스터_콘텐츠번호_가져오기: INDEX(몬스터_콘텐츠번호,MATCH(시뮬레이터!$B$1,몬스터_이름,0))
Name 몬스터_타입: 몬스터!$F$7:$F$312
Name 몬스터_타입_가져오기: INDEX(몬스터_타입,MATCH(시뮬레이터!$B$1,몬스터_이름,0))
Name 스킬_상태이상: '스킬 DATA'!$L$2:$L$55
Name 스킬_상태이상_가져오기: INDEX(스킬_상태이상,MATCH(시뮬레이터!$Q$45,스킬_이름,0))
Name 스킬_시전시간: '스킬 DATA'!$V$2:$V$55
Name 스킬_시전시간_가져오기: INDEX(스킬_시전시간,MATCH(시뮬레이터!$Q$45,스킬_이름,0))
Name 스킬_아이콘: '스킬 DATA'!$I$2:$I$55
Name 스킬_아이콘_가져오기: INDEX(스킬_아이콘,MATCH(시뮬레이터!$Q$45,스킬_이름,0))
Name 스킬_이름: '스킬 DATA'!$G$2:$G$55
Name 스킬_타입: '스킬 DATA'!$J$2:$J$55
Name 스킬_타입_가져오기: INDEX(스킬_타입,MATCH(시뮬레이터!$Q$45,스킬_이름,0))
Name 스킬_피해계수: '스킬 DATA'!$P$2:$P$55
Name 스킬_피해계수_가져오기: INDEX(스킬_피해계수,MATCH(시뮬레이터!$Q$45,스킬_이름,0))
Name 아이템_이름: 아이템!$A$2:$A$43
Name 아이템_이미지: 아이템!$C$2:$C$43
Name 아이템_이미지_가져오기: INDEX(아이템_이미지,MATCH(시뮬레이터!$Q$19,아이템_이름,0))
Name 캐릭터_이름: 'PC DATA(대차대조표)'!$B$2:$B$307
Name 캐릭터_이미지: 'PC DATA(대차대조표)'!$C$2:$C$307
Name 캐릭터_이미지_가져오기: INDEX(캐릭터_이미지,MATCH(시뮬레이터!$Q$12,캐릭터_이름,0))

Sheet 밸런스 문서
A1: 챕터 | B1: 콘텐츠 진행 순서 | C1: 플레이 난이도 | D1: 플레이 흥미도 | E1: 플레이 목표 | F1: 플레이 난관 | G1: 공략 방법 | H1: 체감 난이도 | I1: 수행 과제 수 | J1: 목표 달성 조건 | K1: 실패 결과 | L1: 예상 소요 시간 | M1: 난이도 조절 요소 | N1: 누적 플레이 시간 | O1: 스테이지 | P1: 콘텐츠 진행 포인트 (획득량) | Q1: 콘텐츠 진행 포인트 누적 | R1: 핵심 전투 기믹 | S1: 라이트 유저 (예상 시간 기준) | T1: 미들 유저 | U1: 헤비 유저 | V1: 자아마모도 변화(%) | W1: 인연 변화(%) | X1: 진행 관문 조건 | Y1: 선택·추가 콘텐츠 해금
A2: 1 | 평범한 하루 | B2: 1 | C2: 1 | D2: 8 | E2: 차한해의 과거 오프닝 감상 | F2: 입양 뒤 가족의 몫까지 당연히 떠맡아 온 시간을 짧은 장면으로 이해해야 함 | G2: 가족의 요구와 차한해가 먼저 움직이는 습관을 확인함 | H2: 1/10 – 목표 식별·선택·입력 부담을 종합한 체감 난이도 | I2: 1 | J2: 오프닝 재생 완료 | K2: - | L2: 40초 | M2: 핵심 대상 강조·정체 시 단계별 힌트 제공 | N2: 0.00046296296 | O2: 1-A | 집·가족의 몫 | P2: 3 | Q2: =P2 -> 3 | S2: 40초 | T2: 35초 | U2: 30초
A3: 1 | 평범한 하루 | B3: 2 | C3: 1 | D3: 6 | E3: 아버지 회사 서류를 챙겨 식탁에 올려두기 | F3: 흩어진 서류 중 회사 문서만 골라야 함 | G3: 봉투 표식과 아버지의 메모를 보고 서류를 모아 식탁 지정 칸에 둠 | H3: 1/10 – 목표 식별·선택·입력 부담을 종합한 체감 난이도 | I3: 4 | J3: 회사 서류 4묶음 정리 완료 | K3: - | L3: 25초 | M3: 핵심 대상 강조·정체 시 단계별 힌트 제공 | N3: 0.00075231481 | O3: 1-A | 집·가족의 몫 | P3: 2 | Q3: =Q2+P3 -> 5 | S3: 25초 | T3: 20초 | U3: 15초
A4: 1 | 평범한 하루 | B4: 3 | C4: 1 | D4: 6 | E4: 빨래를 분류해 세탁기에 넣고 작동하기 | F4: 색상과 세탁 표시가 다른 옷이 섞여 있음 | G4: 일반 빨래만 세탁기에 넣고 세제 투입 뒤 표준 코스를 시작함 | H4: 1/10 – 목표 식별·선택·입력 부담을 종합한 체감 난이도 | I4: 3 | J4: 일반 빨래 분류·투입·세탁 시작 | K4: 비싼 블라우스를 넣으면 경고 후 분류 단계로 복귀 | L4: 35초 | M4: 핵심 대상 강조·정체 시 단계별 힌트 제공 | N4: 0.0011574074 | O4: 1-A | 집·가족의 몫 | P4: 3 | Q4: 8 | S4: 35초 | T4: 30초 | U4: 25초
A5: 1 | 평범한 하루 | B5: 4 | C5: 2 | D5: 7 | E5: 어머니의 비싼 블라우스를 손세탁하기 | F5: 강하게 문지르면 옷감 손상 게이지가 오름 | G5: 미지근한 물·중성세제·누르기 세탁 순서를 지킴 | H5: 2/10 – 목표 식별·선택·입력 부담을 종합한 체감 난이도 | I5: 4 | J5: 블라우스 손상 없이 손세탁 완료 | K5: 손상 게이지 최대 시 현재 단계 재시작 | L5: 45초 | M5: 핵심 대상 강조·정체 시 단계별 힌트 제공 | N5: 0.0016782407 | O5: 1-A | 집·가족의 몫 | P5: 3 | Q5: 11 | S5: 45초 | T5: 40초 | U5: 35초
A6: 1 | 평범한 하루 | B6: 5 | C6: 1 | D6: 6 | E6: 건조기 완료음을 듣고 빨래를 꺼내 거실에서 개기 | F6: 건조 완료 시점과 옷별 접는 방향을 확인해야 함 | G6: 완료음 뒤 빨래를 거실로 옮기고 종류별 실루엣에 맞춰 갬 | H6: 1/10 – 목표 식별·선택·입력 부담을 종합한 체감 난이도 | I6: 8 | J6: 빨래 8개를 모두 개어 바구니에 정리 | K6: - | L6: 40초 | M6: 핵심 대상 강조·정체 시 단계별 힌트 제공 | N6: 0.0021412037 | O6: 1-A | 집·가족의 몫 | P6: 2 | Q6: 13 | S6: 40초 | T6: 35초 | U6: 30초
A7: 1 | 평범한 하루 | B7: 6 | C7: 1 | D7: 7 | E7: 동생에게 신상 과자·헤어롤·팝콘 심부름 받기 | F7: 대화에 품목과 목적지가 섞여 있음 | G7: 강조된 품목과 동선을 확인하고 심부름 목록을 등록함 | H7: 1/10 – 목표 식별·선택·입력 부담을 종합한 체감 난이도 | I7: 3 | J7: 심부름 3종 등록 | K7: - | L7: 30초 | M7: 핵심 대상 강조·정체 시 단계별 힌트 제공 | N7: 0.0024884259 | O7: 1-A | 집·가족의 몫 | P7: 2 | Q7: 15 | S7: 30초 | T7: 25초 | U7: 25초 | W7: [차우선] 기준 45%
A8: 1 | 평범한 하루 | B8: 7 | C8: 1 | D8: 7 | E8: 엘리베이터에서 주민 모두에게 인사하며 밖으로 나가기 | F8: 어른·아이·택배기사 등 서로 다른 위치의 주민을 발견해야 함 | G8: 이동·조사 입력으로 만나는 주민에게 자연스럽게 인사함 | H8: 1/10 – 목표 식별·선택·입력 부담을 종합한 체감 난이도 | I8: 5 | J8: 엘리베이터와 로비의 주민 5명에게 인사 후 외출 | K8: - | L8: 30초 | M8: 핵심 대상 강조·정체 시 단계별 힌트 제공 | N8: 0.0028356481 | O8: 1-A | 아파트·인사 튜토리얼 | P8: 3 | Q8: 18 | S8: 30초 | T8: 25초 | U8: 25초 | Y8: 이동·조사 튜토리얼 완료
A9: 1 | 평범한 하루 | B9: 8 | C9: 2 | D9: 7 | E9: 편의점에서 신상 과자가 아직 입고되지 않았음을 확인하기 | F9: 빈 진열대와 입고 안내를 찾아야 함 | G9: 신상 코너와 알바생 대화를 통해 물류 트럭 도착 시간을 확인함 | H9: 2/10 – 목표 식별·선택·입력 부담을 종합한 체감 난이도 | I9: 2 | J9: 신상 과자 입고 전 상태·트럭 시간 확인 | K9: - | L9: 30초 | M9: 핵심 대상 강조·정체 시 단계별 힌트 제공 | N9: 0.0031828704 | O9: 1-B | 편의점·첫 방문 | P9: 4 | Q9: 22 | S9: 30초 | T9: 25초 | U9: 25초
A10: 1 | 평범한 하루 | B10: 9 | C10: 2 | D10: 8 | E10: 알바생의 무거운 음료 박스 진열 부탁을 수락할지 선택하기 | F10: 동생 심부름과 짧은 도움 사이에서 선택해야 함 | G10: 수락하거나 [거절]를 사용해 거절함. 거절해도 메인 진행은 유지되지만 해당 서브 퀘스트의 인연·보상 획득 기회는 사라짐 | H10: 2/10 – 목표 식별·선택·입력 부담을 종합한 체감 난이도 | I10: 1 | J10: 부탁 수락 또는 [거절] 사용 | K10: - | L10: 25초 | M10: 핵심 대상 강조·정체 시 단계별 힌트 제공 | N10: 0.0034722222 | O10: 1-B | 편의점 알바생 부탁 | P10: 3 | Q10: 25 | S10: 25초 | T10: 25초 | U10: 20초 | Y10: 선택 서브 퀘스트 : 편의점 음료 진열
A11: 1 | 평범한 하루 | B11: 10 | C11: 3 | D11: 8 | E11: 음료 박스를 가격표에 맞춰 진열하기 | F11: 비슷한 포장과 무게 때문에 위치를 헷갈릴 수 있음 | G11: 상표·용량·가격표를 대조해 무거운 박스부터 아래 칸에 배치함 | H11: 3/10 – 목표 식별·선택·입력 부담을 종합한 체감 난이도 | I11: 6 | J11: 음료 6박스 진열 완료 | K11: 오배치 3회 시 틀린 가격표를 강조 | L11: 1분 5초 | M11: 핵심 대상 강조·정체 시 단계별 힌트 제공 | N11: 0.004224537 | O11: 1-B | 편의점 알바생 부탁 | P11: 3 | Q11: 28 | S11: 1분 5초 | T11: 55초 | U11: 45초 | Y11: 완료 시 알바생이 신상 과자 1개를 맡아두는 약속
A12: 1 | 평범한 하루 | B12: 11 | C12: 2 | D12: 8 | E12: 골목에서 들리는 예쁜 고양이 울음소리 확인하기 | F12: 심부름 목적지가 따로 있어 작은 울음소리를 무시하고 지나칠 수 있음 | G12: 편의점 주변에서 반복되는 울음소리와 골목 그림자를 확인하되 조사하지 않고 진행할 수도 있음 | H12: 2/10 – 발견 여부와 선택에 따라 진행이 달라짐 | I12: 2 | J12: 울음소리가 들리는 골목 위치 확인 또는 선택적으로 지나침 | K12: - | L12: 40초 | M12: 자동 등록하지 않고 소리·행동·오브젝트로만 암시 | N12: 0.0046875 | O12: 1-B | 편의점·고양이 선택 | P12: 3 | Q12: 31 | S12: 40초 | T12: 35초 | U12: 30초 | Y12: 서브 퀘스트 : 예쁜 고양이 인연 1단계 발견
A13: 1 | 평범한 하루 | B13: 12 | C13: 2 | D13: 8 | E13: 편의점에서 츄르 4개입 세트 구매하기 | F13: 구매 메뉴에는 심부름 물품 외에도 여러 상품이 있어 츄르를 직접 찾아야 함 | G13: 알바생 대화 후 ‘물건 구매하기’를 선택하고 반려동물 간식 칸에서 츄르 4개입을 구매함 | H13: 2/10 – 발견 여부와 선택에 따라 진행이 달라짐 | I13: 2 | J13: 츄르 4개입 세트 구매 완료 | K13: - | L13: 40초 | M13: 자동 등록하지 않고 소리·행동·오브젝트로만 암시 | N13: 0.005150463 | O13: 1-B | 편의점·고양이 선택 | P13: 3 | Q13: 34 | S13: 40초 | T13: 35초 | U13: 30초 | Y13: 서브 퀘스트 : 이후 예쁜 고양이 인연 콘텐츠 4회 수행 가능
A14: 1 | 평범한 하루 | B14: 13 | C14: 2 | D14: 8 | E14: 예쁜 고양이에게 첫 번째 츄르 건네기 | F14: 예쁜 고양이는 처음 만난 차한해를 경계해 바로 가까이 오지 않음 | G14: 일정 거리에 츄르를 내려놓고 뒤로 물러난 뒤 고양이가 스스로 다가올 때까지 기다림 | H14: 2/10 – 발견 여부와 선택에 따라 진행이 달라짐 | I14: 2 | J14: 예쁜 고양이가 츄르를 먹고 도망가지 않은 채 차한해를 바라봄 | K14: - | L14: 40초 | M14: 자동 등록하지 않고 소리·행동·오브젝트로만 암시 | N14: 0.0056134259 | O14: 1-B | 편의점·고양이 선택 | P14: 3 | Q14: 37 | S14: 40초 | T14: 35초 | U14: 30초 | W14: [예쁜 고양이] +25% 선택 (최대 누적 25%) | Y14: 츄르 보유 시 수행 예쁜 고양이 인연 +25%
A15: 1 | 평범한 하루 | B15: 14 | C15: 2 | D15: 5 | E15: 다이소로 이동하기 | F15: 갈림길과 주변 상호작용 오브젝트 때문에 목적지 방향을 놓칠 수 있음 | G15: 표지판·미니맵·NPC 이동 방향을 확인하며 편의점에서 다이소까지 이동함 | H15: 2/10 – 맵 크기·갈림길 수·목적지 표식의 가시성이 난이도를 결정함 | I15: 1 | J15: 편의점에서 다이소의 도착 트리거에 진입 | K15: - | L15: 25초 | M15: 일정 시간 정체 시 목적지 방향 화살표 표시 | N15: 0.0059027778 | O15: 1-C | 다이소 | P15: 3 | Q15: 40 | S15: 25초 | T15: 20초 | U15: 20초
A16: 1 | 평범한 하루 | B16: 15 | C16: 2 | D16: 6 | E16: 헤어롤 진열대 찾기 | F16: 비슷한 오브젝트와 진열대가 많아 목표 대상을 한 번에 찾기 어려움 | G16: 구역별 표지와 상품 외형을 비교하며 생활용품 코너의 헤어롤을 조사함 | H16: 2/10 – 후보 오브젝트 수·외형 유사도·탐색 범위가 난이도를 결정함 | I16: 5 | J16: 생활용품 코너의 헤어롤 발견 및 조사 완료 | K16: - | L16: 30초 | M16: 30초 이상 미발견 시 목표 구역에 약한 반짝임 표시 | N16: 0.00625 | O16: 1-C | 다이소 | P16: 4 | Q16: 44 | S16: 30초 | T16: 25초 | U16: 25초
A17: 1 | 평범한 하루 | B17: 16 | C17: 1 | D17: 5 | E17: 헤어롤 구매하기 | F17: 구매 대상·수량·결제 순서를 잘못 선택할 수 있음 | G17: 요청받은 품목을 확인하고 상품 선택→계산대 상호작용→결제를 순서대로 진행함 | H17: 1/10 – 상품 후보 수·품목 유사도·구매 단계 수가 난이도를 결정함 | I17: 3 | J17: 헤어롤 1개 구매 후 인벤토리에 등록 | K17: 잘못된 품목 구매 시 다시 선택해야 함 | L17: 20초 | M17: 요청 품목에 작은 임무 아이콘 표시 | N17: 0.0064814815 | O17: 1-C | 다이소 | P17: 3 | Q17: 47 | S17: 20초 | T17: 15초 | U17: 15초
A18: 1 | 평범한 하루 | B18: 17 | C18: 1 | D18: 8 | E18: 다이소를 나오자 편의점 물류 트럭이 지나가는 장면 확인하기 | F18: 신상 과자 재입고 기회를 즉시 알아차려야 함 | G18: 트럭 표식과 편의점 방향을 확인함 | H18: 1/10 – 목표 식별·선택·입력 부담을 종합한 체감 난이도 | I18: 1 | J18: 물류 트럭과 편의점 재입고 방향 확인 | K18: - | L18: 20초 | M18: 핵심 대상 강조·정체 시 단계별 힌트 제공 | N18: 0.006712963 | O18: 1-D | 어르신과 신상 과자 | P18: 3 | Q18: 50 | S18: 20초 | T18: 15초 | U18: 15초
A19: 1 | 평범한 하루 | B19: 18 | C19: 2 | D19: 10 | E19: 짐이 많은 어르신을 도울지 신상 과자를 사러 갈지 선택하기 | F19: 도움이 늦어지면 신상 과자가 품절될 수 있음 | G19: 어르신의 구조 요청과 동생의 심부름을 비교해 행동을 선택함 | H19: 2/10 – 목표 식별·선택·입력 부담을 종합한 체감 난이도 | I19: 1 | J19: 어르신 돕기 또는 편의점으로 바로 달리기 | K19: - | L19: 25초 | M19: 핵심 대상 강조·정체 시 단계별 힌트 제공 | N19: 0.0070023148 | O19: 1-D | 어르신과 신상 과자 | P19: 3 | Q19: 53 | S19: 25초 | T19: 25초 | U19: 25초 | Y19: 핵심 선택 : 자발적 선행과 개인 손실
A20: 1 | 평범한 하루 | B20: 19 | C20: 2 | D20: 10 | E20: 어르신의 무거운 짐을 목적지까지 옮기기 | F20: 짐 때문에 이동이 느리고 보행자와 턱을 피해 가야 함 | G20: 무게 중심을 유지하며 안전한 길로 짐을 나누어 운반함 | H20: 2/10 – 목표 식별·선택·입력 부담을 종합한 체감 난이도 | I20: 4 | J20: 짐 4개 운반·어르신 귀가 확인 | K20: - | L20: 1분 5초 | M20: 핵심 대상 강조·정체 시 단계별 힌트 제공 | N20: 0.0077546296 | O20: 1-D | 어르신과 신상 과자 | P20: 3 | Q20: 56 | S20: 1분 5초 | T20: 55초 | U20: 45초 | W20: [도시] +5% 선택 (기본 0% · 최대 5%) | Y20: 어르신을 도운 경우 수행·신상 과자 분기 변화
A21: 1 | 평범한 하루 | B21: 20 | C21: 2 | D21: 8 | E21: 치킨집 앞 두 손님의 주문 대화 듣기 | F21: 서로 다른 주문과 번복 대사에서 확정 내용을 골라야 함 | G21: 치킨·소스·음료·추가 요청을 구분해 기억함 | H21: 2/10 – 목표 식별·선택·입력 부담을 종합한 체감 난이도 | I21: 4 | J21: 두 손님의 최종 주문 확인 | K21: - | L21: 35초 | M21: 핵심 대상 강조·정체 시 단계별 힌트 제공 | N21: 0.0081597222 | O21: 1-E | 치킨집 알바 서브 | P21: 3 | Q21: 59 | S21: 35초 | T21: 30초 | U21: 25초 | Y21: 서브 퀘스트 : 치킨집 알바
A22: 1 | 평범한 하루 | B22: 21 | C22: 2 | D22: 8 | E22: 바쁜 직원의 도움 요청을 확인하기 | F22: 밀린 주문과 손님 대화가 겹침 | G22: 직원의 호출을 확인하고 잠시 도울지 선택함 | H22: 2/10 – 목표 식별·선택·입력 부담을 종합한 체감 난이도 | I22: 1 | J22: 도움 요청 확인 | K22: - | L22: 35초 | M22: 핵심 대상 강조·정체 시 단계별 힌트 제공 | N22: 0.0085648148 | O22: 1-E | 치킨집 알바 서브 | P22: 4 | Q22: 63 | S22: 35초 | T22: 30초 | U22: 25초 | Y22: 거절 시 서브 퀘스트 종료
A23: 1 | 평범한 하루 | B23: 22 | C23: 2 | D23: 8 | E23: 치킨집 알바를 도울지 선택하기 | F23: 심부름 일정과 직원의 부탁 사이에서 선택해야 함 | G23: 돕기를 선택하거나 [거절]를 사용해 알바 부탁을 거절하고 기존 심부름을 계속함 | H23: 2/10 – 목표 식별·선택·입력 부담을 종합한 체감 난이도 | I23: 1 | J23: 알바 수락 또는 [거절] 사용 | K23: - | L23: 30초 | M23: 핵심 대상 강조·정체 시 단계별 힌트 제공 | N23: 0.008912037 | O23: 1-E | 치킨집 알바 서브 | P23: 6 | Q23: 69 | S23: 30초 | T23: 25초 | U23: 25초 | Y23: 수락 시 포장 미니게임 해금
A24: 1 | 평범한 하루 | B24: 23 | C24: 4 | D24: 8 | E24: 주문표의 치킨·소스·음료 확인하기 | F24: 여러 주문표의 번호와 구성품을 혼동하기 쉬움 | G24: 주문 번호별 필수 항목을 순서대로 확인함 | H24: 4/10 – 목표 식별·선택·입력 부담을 종합한 체감 난이도 | I24: 5 | J24: 주문표 필수 항목 5개 확인 | K24: 오답 누적 시 현재 단계 재시작 | L24: 1분 5초 | M24: 핵심 대상 강조·정체 시 단계별 힌트 제공 | N24: 0.0096643519 | O24: 1-E | 치킨집 알바 서브 | P24: 6 | Q24: 75 | S24: 1분 5초 | T24: 55초 | U24: 45초
A25: 1 | 평범한 하루 | B25: 24 | C25: 4 | D25: 8 | E25: 주문에 맞게 치킨 포장하기 | F25: 번복된 대사와 확정 주문을 구분해야 함 | G25: 확정 주문표만 보고 상자·무·소스·음료를 넣음 | H25: 4/10 – 목표 식별·선택·입력 부담을 종합한 체감 난이도 | I25: 5 | J25: 구성품 5종 올바르게 포장 | K25: 오답 누적 시 현재 단계 재시작 | L25: 1분 5초 | M25: 핵심 대상 강조·정체 시 단계별 힌트 제공 | N25: 0.010416667 | O25: 1-E | 치킨집 알바 서브 | P25: 6 | Q25: 81 | S25: 1분 5초 | T25: 55초 | U25: 45초
A26: 1 | 평범한 하루 | B26: 25 | C26: 4 | D26: 8 | E26: 잘못 포장된 주문 수정하기 | F26: 다른 주문의 소스와 음료가 섞여 있음 | G26: 주문표와 포장을 대조해 오류 항목만 교체함 | H26: 4/10 – 목표 식별·선택·입력 부담을 종합한 체감 난이도 | I26: 4 | J26: 오포장 항목 전부 수정 | K26: 오답 누적 시 현재 단계 재시작 | L26: 50초 | M26: 핵심 대상 강조·정체 시 단계별 힌트 제공 | N26: 0.01099537 | O26: 1-E | 치킨집 알바 서브 | P26: 3 | Q26: 84 | S26: 50초 | T26: 40초 | U26: 35초
A27: 1 | 평범한 하루 | B27: 26 | C27: 2 | D27: 8 | E27: 손님에게 주문을 전달하고 보상 받기 | F27: 비슷한 두 손님 중 올바른 주문자를 찾아야 함 | G27: 대화 특징과 주문 번호를 대조해 전달함 | H27: 2/10 – 목표 식별·선택·입력 부담을 종합한 체감 난이도 | I27: 2 | J27: 올바른 손님에게 전달·알바비 획득 | K27: - | L27: 35초 | M27: 핵심 대상 강조·정체 시 단계별 힌트 제공 | N27: 0.011400463 | O27: 1-E | 치킨집 알바 서브 | P27: 3 | Q27: 87 | S27: 35초 | T27: 30초 | U27: 25초 | Y27: 치킨집 알바 서브 퀘스트 완료
A28: 1 | 평범한 하루 | B28: 27 | C28: 2 | D28: 8 | E28: 편의점으로 돌아가 신상 과자 재고 확인하기 | F28: 어르신·알바생 부탁 선택에 따라 결과가 달라짐 | G28: 진열대와 알바생 반응을 확인함 | H28: 2/10 – 목표 식별·선택·입력 부담을 종합한 체감 난이도 | I28: 2 | J28: 재고·예약 여부 확인 | K28: - | L28: 25초 | M28: 핵심 대상 강조·정체 시 단계별 힌트 제공 | N28: 0.011689815 | O28: 1-F | 편의점 결과 분기 | P28: 4 | Q28: 91 | S28: 25초 | T28: 20초 | U28: 20초
A29: 1 | 평범한 하루 | B29: 28 | C29: 2 | D29: 10 | E29: 선택 결과에 따라 신상 과자 확보 여부 확정하기 | F29: 도움을 선택했을 때 앞선 알바생 부탁 수행 여부가 보상을 바꿈 | G29: 어르신 무시 시 구매, 어르신 도움+부탁 완료 시 예약품 수령, 도움+부탁에 [거절] 사용 시 품절 결과를 확인함 | H29: 2/10 – 목표 식별·선택·입력 부담을 종합한 체감 난이도 | I29: 3 | J29: 신상 과자 구매·예약 수령 또는 품절 확정 | K29: - | L29: 45초 | M29: 핵심 대상 강조·정체 시 단계별 힌트 제공 | N29: 0.012210648 | O29: 1-F | 편의점 결과 분기 | P29: 5 | Q29: 96 | S29: 45초 | T29: 35초 | U29: 30초 | Y29: 선택 연쇄 결과 저장
A30: 1 | 평범한 하루 | B30: 29 | C30: 1 | D30: 9 | E30: 동생에게 과자 결과를 알리고 지하철 중고거래 심부름 받기 | F30: 품절 분기에서는 동생의 짜증 섞인 추가 요구를 감정적으로 받아들여야 함 | G30: 결과 대화를 확인하고 거래 상대 단서를 등록함 | H30: 1/10 – 목표 식별·선택·입력 부담을 종합한 체감 난이도 | I30: 2 | J30: 중고거래 장소·상대 특징 등록 | K30: - | L30: 30초 | M30: 핵심 대상 강조·정체 시 단계별 힌트 제공 | N30: 0.01255787 | O30: 1-F | 동생의 추가 심부름 | P30: 6 | Q30: 102 | S30: 30초 | T30: 25초 | U30: 25초 | W30: 과자 확보: [차우선] +5% (50%) / 품절: -5% (40%)
A31: 1 | 평범한 하루 | B31: 30 | C31: 1 | D31: 6 | E31: 영화관으로 이동하기 | F31: 상가 갈림길에서 목적지를 찾아야 함 | G31: 표지판과 심부름 목록을 보고 영화관으로 이동함 | H31: 1/10 – 목표 식별·선택·입력 부담을 종합한 체감 난이도 | I31: 1 | J31: 영화관 도착 | K31: - | L31: 25초 | M31: 핵심 대상 강조·정체 시 단계별 힌트 제공 | N31: 0.012847222 | O31: 1-F | 영화관·지하철 | P31: 5 | Q31: 107 | S31: 25초 | T31: 25초 | U31: 25초
A32: 1 | 평범한 하루 | B32: 31 | C32: 1 | D32: 6 | E32: 동생이 부탁한 팝콘 구매하기 | F32: 맛과 크기를 잘못 고를 수 있음 | G32: 심부름 목록과 메뉴를 대조해 구매함 | H32: 1/10 – 목표 식별·선택·입력 부담을 종합한 체감 난이도 | I32: 3 | J32: 지정 팝콘 구매 | K32: - | L32: 25초 | M32: 핵심 대상 강조·정체 시 단계별 힌트 제공 | N32: 0.013136574 | O32: 1-F | 영화관·지하철 | P32: 3 | Q32: 110 | S32: 25초 | T32: 20초 | U32: 20초
A33: 1 | 평범한 하루 | B33: 32 | C33: 2 | D33: 6 | E33: 지하철 중고거래 장소로 이동하기 | F33: 출구 번호와 약속 위치가 다름 | G33: 역 안내판과 채팅의 출구 번호를 확인함 | H33: 2/10 – 목표 식별·선택·입력 부담을 종합한 체감 난이도 | I33: 2 | J33: 약속 장소 도착 | K33: - | L33: 30초 | M33: 핵심 대상 강조·정체 시 단계별 힌트 제공 | N33: 0.013483796 | O33: 1-F | 영화관·지하철 | P33: 3 | Q33: 113 | S33: 30초 | T33: 25초 | U33: 25초
A34: 1 | 평범한 하루 | B34: 33 | C34: 2 | D34: 7 | E34: 거래 후보 세 명의 특징 관찰하기 | F34: 복장 일부가 비슷해 판매자를 혼동하기 쉬움 | G34: 채팅의 가방·신발·손에 든 물건을 대조함 | H34: 2/10 – 목표 식별·선택·입력 부담을 종합한 체감 난이도 | I34: 3 | J34: 후보 3명 관찰 | K34: - | L34: 25초 | M34: 핵심 대상 강조·정체 시 단계별 힌트 제공 | N34: 0.013773148 | O34: 1-F | 영화관·지하철 | P34: 3 | Q34: 116 | S34: 25초 | T34: 25초 | U34: 20초
A35: 1 | 평범한 하루 | B35: 34 | C35: 3 | D35: 7 | E35: 올바른 중고거래 상대 찾기 | F35: 가짜 후보에게 말을 걸면 시간이 추가됨 | G35: 세 단서가 모두 맞는 사람에게 암구호를 말함 | H35: 3/10 – 목표 식별·선택·입력 부담을 종합한 체감 난이도 | I35: 3 | J35: 정확한 거래 상대 선택 | K35: 오답 후보 선택 시 대화 후 다시 탐색 | L35: 35초 | M35: 핵심 대상 강조·정체 시 단계별 힌트 제공 | N35: 0.014178241 | O35: 1-F | 영화관·지하철 | P35: 4 | Q35: 120 | S35: 35초 | T35: 30초 | U35: 25초
A36: 1 | 평범한 하루 | B36: 35 | C36: 1 | D36: 8 | E36: 중고거래를 마치고 동생에게 완료 연락하기 | F36: 과자 분기와 거래 결과에 따라 동생의 반응이 달라짐 | G36: 물품 상태를 확인하고 송금·완료 메시지를 보냄 | H36: 1/10 – 목표 식별·선택·입력 부담을 종합한 체감 난이도 | I36: 3 | J36: 거래·완료 연락 | K36: - | L36: 25초 | M36: 핵심 대상 강조·정체 시 단계별 힌트 제공 | N36: 0.014467593 | O36: 1-F | 영화관·지하철 | P36: 5 | Q36: 125 | S36: 25초 | T36: 20초 | U36: 20초 | W36: [차우선] +5% (과자 확보 55% / 품절 45%)
A37: 1 | 평범한 하루 | B37: 36 | C37: 2 | D37: 8 | E37: 횡단보도에서 아이가 떨어뜨린 학용품을 주워주기 | F37: 신호가 바뀌기 전 안전한 순서로 물건을 모아야 함 | G37: 차도 가까운 물건부터 회수하고 아이를 인도로 유도함 | H37: 2/10 – 목표 식별·선택·입력 부담을 종합한 체감 난이도 | I37: 5 | J37: 학용품 5개 회수·아이 안전 확인 | K37: 신호 종료 시 남은 물건이 인도 쪽으로 이동 | L37: 50초 | M37: 핵심 대상 강조·정체 시 단계별 힌트 제공 | N37: 0.015046296 | O37: 1-F | 동네의 작은 선행 | P37: 3 | Q37: 128 | S37: 50초 | T37: 40초 | U37: 35초 | Y37: 선택 서브 퀘스트·동네 목격자 스티커 플래그
A38: 1 | 평범한 하루 | B38: 37 | C38: 1 | D38: 9 | E38: 공원에서 모든 심부름 완료와 섬광 이상 현상 확인하기 | F38: 평범한 귀가 직전 소리 없는 번개와 미세 진동이 짧게 겹침 | G38: 세 심부름 물품을 확인하고 하늘의 섬광·땅의 떨림을 기억함 | H38: 1/10 – 목표 식별·선택·입력 부담을 종합한 체감 난이도 | I38: 4 | J38: 심부름 3종 완료·첫 이상 현상 확인 | K38: - | L38: 25초 | M38: 핵심 대상 강조·정체 시 단계별 힌트 제공 | N38: 0.015335648 | O38: 1-G | 공원·첫 전조 | P38: 4 | Q38: 132 | S38: 25초 | T38: 25초 | U38: 25초 | X38: 1챕터 메인 심부름 완료
A39: 2 | 금이 간 일상 | B39: 38 | C39: 1 | D39: 7 | E39: 축제 종료 현장과 남은 이상 징후 관찰하기 | F39: 떠나는 시민·쌓인 쓰레기·간헐적으로 깜빡이는 조명 사이에 섬광의 원인을 추정할 단서가 분산되어 있음 | G39: 시민의 행동과 쓰레기 상태를 살펴본 뒤 조명 깜빡임과 바닥의 미세한 떨림을 차례로 확인함 | H39: 1/10 – 관찰 대상 수·이상 징후의 미세함·단서 분산 정도가 난이도를 결정함 | I39: 5 | J39: 시민·쓰레기·조명·바닥 진동에 관한 필수 관찰 대상 확인 | K39: - | L39: 20초 | M39: 이상 징후가 발생할 때 효과음과 짧은 시선 유도 아이콘 표시 | N39: 0.01556713 | O39: 2-A | 공원 축제·청소 | P39: 3 | Q39: 135 | S39: 20초 | T39: 20초 | U39: 20초
A40: 2 | 금이 간 일상 | B40: 39 | C40: 1 | D40: 6 | E40: 아이가 쓰레기에 걸려 넘어질 뻔한 장면 목격하기 | F40: 짧은 연출 안에서 사건의 원인과 인물의 태도를 동시에 이해해야 함 | G40: 카메라가 강조하는 인물과 오브젝트를 보며 아이와 가족의 행동을 확인함 | H40: 1/10 – 연출 속도·동시에 제시되는 정보량이 난이도를 결정함 | I40: 1 | J40: 사건 연출 종료 | K40: - | L40: 10초 | M40: 핵심 오브젝트에 카메라 줌과 효과음 적용 | N40: 0.01568287 | O40: 2-A | 공원 축제·청소 | P40: 3 | Q40: 138 | S40: 10초 | T40: 10초 | U40: 10초
...

Sheet 밸런스 팩터
B2: 밸런스 팩터
B3: 게임 「넌 착해!」의 플레이 경험 조절 요소. 핵심 연결은 ① 문서 전체 미들 3시간 53분 35초·대표 진엔딩 3시간 40분, ② 선의 수치·자아마모도·도시 인연, ③ 사람 1명→나쁜 부분 총합 1개→몬스터 1개·인간 껍데기 1개 원칙, ④ 초기 변이체만 보라 단세포형이고 일반 이상은 인간 서사·행동 잔재를 외형과 패턴으로 변환, ⑤ 비보스 서사는 선택형 잔류 기억으로 공개, ⑥ 유인 파동은 늦은 밤~이른 새벽 선의 0 인간만 유인, ⑦ 균열 태생체는 내부 생태계의 자연 생물이며 수호체와 일반 전투를 하지 않음, ⑧ 최종 분기는 진실 공개/은폐와 도시 인연 100% 여부로 진엔딩·희생·공존 엔딩을 결정함.
B5: 진행·콘텐츠 | J5: 서사·상태 | R5: 전투 | Z5: 가이드·편의 | AH5: 크기: 핵심(대) · 반복 조정(중) · 장면 조정(소)
B70: 큰 원은 플레이 전반에 미치는 영향이 큰 핵심 팩터이며, 작은 원은 장면·미션 단위에서 조정하는 세부 팩터임

Sheet PC DATA(대차대조표)
A1: 콘텐츠 진행 순서 | B1: 이름 | C1: 이미지 | D1: 콘텐츠명 | E1: 전투 상태 | F1: 기본 공격력 | G1: 공격력 변화(최초·일회성) | H1: 기본 방어력 | I1: 방어력 변화(획득·손상·파손) | J1: 스킬(최초 해금) | K1: 변경 근거·현재 상태
A2: 1 | B2: 차한해 | D2: 차한해의 과거 오프닝 감상 | E2: 전투 시스템 미개방 | F2: 10 | H2: 10 | J2: 거절 | K2: 기본 공격력 10 / 기본 방어력 10
A3: 2 | B3: 차한해 | D3: 아버지 회사 서류를 챙겨 식탁에 올려두기 | E3: 전투 시스템 미개방 | F3: 10 | H3: 10 | K3: 일반인 신체 능력 유지
A4: 3 | B4: 차한해 | D4: 빨래를 분류해 세탁기에 넣고 작동하기 | E4: 전투 시스템 미개방 | F4: 10 | H4: 10
A5: 4 | B5: 차한해 | D5: 어머니의 비싼 블라우스를 손세탁하기 | E5: 전투 시스템 미개방 | F5: 10 | H5: 10
A6: 5 | B6: 차한해 | D6: 건조기 완료음을 듣고 빨래를 꺼내 거실에서 개기 | E6: 전투 시스템 미개방 | F6: 10 | H6: 10
A7: 6 | B7: 차한해 | D7: 동생에게 신상 과자·헤어롤·팝콘 심부름 받기 | E7: 전투 시스템 미개방 | F7: 10 | H7: 10
A8: 7 | B8: 차한해 | D8: 엘리베이터에서 주민 모두에게 인사하며 밖으로 나가기 | E8: 전투 시스템 미개방 | F8: 10 | H8: 10
A9: 8 | B9: 차한해 | D9: 편의점에서 신상 과자가 아직 입고되지 않았음을 확인하기 | E9: 전투 시스템 미개방 | F9: 10 | H9: 10
A10: 9 | B10: 차한해 | D10: 알바생의 무거운 음료 박스 진열 부탁을 수락할지 선택하기 | E10: 전투 시스템 미개방 | F10: 10 | H10: 10
A11: 10 | B11: 차한해 | D11: 음료 박스를 가격표에 맞춰 진열하기 | E11: 전투 시스템 미개방 | F11: 10 | H11: 10
A12: 11 | B12: 차한해 | D12: 골목에서 들리는 예쁜 고양이 울음소리 확인하기 | E12: 전투 시스템 미개방 | F12: 10 | H12: 10
A13: 12 | B13: 차한해 | D13: 편의점에서 츄르 4개입 세트 구매하기 | E13: 전투 시스템 미개방 | F13: 10 | H13: 10
A14: 13 | B14: 차한해 | D14: 예쁜 고양이에게 첫 번째 츄르 건네기 | E14: 전투 시스템 미개방 | F14: 10 | H14: 10
A15: 14 | B15: 차한해 | D15: 다이소로 이동하기 | E15: 전투 시스템 미개방 | F15: 10 | H15: 10
... A79: 78 | B79: 차한해 | D79: 나 먼저와 정면으로 마주치기 | E79: 전투 시스템 미개방 | F79: 10 | H79: 10
A80: 79 | B80: 차한해 | D80: 두 눈을 감고 양손으로 괴물을 막기 | E80: 무의식적 일회성 발현 | F80: 10 | G80: [펑!] 연계 : 무의식적 선의 폭발 +990 순간 출력 1000 | H80: 10 | J80: 펑! | K80: 기본 공격력 10 / 무의식적 선의 폭발 +990 · 순간 출력 1000 / 기본 방어력 10
A81: 80 | B81: 차한해 | D81: 먼지처럼 사라진 괴물의 흔적 확인하기 | E81: 미개방·힘 재현 불가 | F81: 10 | G81: [펑!] 연계 종료 : +990 → 0 | H81: 10 | K81: 무의식적 선의 폭발 종료 : +990 → 0
A82: 81 | B82: 차한해 | D82: 어린아이를 공주님 안기로 구출하기 | E82: 미개방·힘 재현 불가 | F82: 10 | H82: 10 | K82: 첫 힘의 존재와 발동 방법을 인식하지 못함
A83: 82 | B83: 차한해 | D83: 아이의 ‘괴물 펑’ 목격담 듣기 | E83: 미개방·힘 재현 불가 | F83: 10 | H83: 10
A84: 83 | B84: 차한해 | D84: 1등 나와을 우회해 안전 구역으로 이동하기 | E84: 미개방·힘 재현 불가 | F84: 10 | H84: 10
A85: 84 | B85: 차한해 | D85: 놀잇감의 울음 파동을 피해 새벽 괴물 습격 구간 벗어나기 | E85: 미개방·힘 재현 불가 | F85: 10 | H85: 10
A86: 85 | B86: 차한해 | D86: 내 창고의 배회 경로를 피해 한도윤과 합류하기 | E86: 미개방·힘 재현 불가 | F86: 10 | H86: 10
A87: 86 | B87: 차한해 | D87: 임시 대피소 도착하기 | E87: 미개방·힘 재현 불가 | F87: 10 | H87: 10
A88: 87 | B88: 차한해 | D88: 맨몸으로 할머니를 구해 유명해진 청년의 뉴스 확인하기 | E88: 미개방·힘 재현 불가 | F88: 10 | H88: 10
A89: 88 | B89: 차한해 | D89: 선행으로 유명해진 청년의 인터뷰와 밈 확인하기 | E89: 미개방·힘 재현 불가 | F89: 10 | H89: 10
A90: 89 | B90: 차한해 | D90: 악질 채널 ‘클릭헌터’의 균열 접근 생방송 시청하기 | E90: 미개방·힘 재현 불가 | F90: 10 | H90: 10
A91: 90 | B91: 차한해 | D91: 클릭헌터에게 나타난 선의 수치 96 확인하기 | E91: 미개방·힘 재현 불가 | F91: 10 | H91: 10
A92: 91 | B92: 차한해 | D92: 기계가 정상 작동하는 균열 연구 현장 확인하기 | E92: 미개방·힘 재현 불가 | F92: 10 | H92: 10
A93: 92 | B93: 차한해 | D93: 유명 청년의 선의 수치 836 측정하기 | E93: 미개방·힘 재현 불가 | F93: 10 | H93: 10
A94: 93 | B94: 차한해 | D94: 새로운 수치를 ‘선의 수치’라고 부르는 과정 확인하기 | E94: 미개방·힘 재현 불가 | F94: 10 | H94: 10
... A118: 117 | B118: 차한해 | D118: 선의 수치 836 청년의 초기 구조 원칙 듣기 | E118: 미개방·힘 재현 불가 | F118: 10 | H118: 10
A119: 118 | B119: 차한해 | D119: 관리국 표준 대응 장비 8종·응급품 2종을 수령하고 상태 UI 확인하기 | E119: 전투 가능·비전투 콘텐츠 | F119: 80 | G119: 관리국 지급 권총 +20 관리국 대응 장갑 +3 비살상 충격탄 사용 시 +6 | H119: 100 | I119: 기본 보호 조끼 +30 관리국 방진 고글 +4 관리국 대응 장갑 +5 관리국 전술화 +6 관리국 방진 마스크 +3 | J119: 탕! 앗, 피해! 행동 제한 | K119: 관리국 표준 대응 세트 8종·응급 주사·비살상 충격탄 획득
A120: 119 | B120: 차한해 | D120: 관리국 지급 권총·비살상 충격탄·관리국 전술화를 이용해 사격과 회피 연습하기 | E120: 전투 가능 | F120: 100 | H120: 100 | K120: 기본 공격력 100 / 스킬 : 조준 사격 · 긴급 회피
A121: 120 | B121: 차한해 | D121: 출동 차량을 향해 환호하는 시민들 지나가기 | E121: 전투 가능·비전투 콘텐츠 | F121: 100 | H121: 100 | K121: 전투 수치 변화 없이 탐색·대화·이동 진행
A122: 121 | B122: 차한해 | D122: 도심 잔해 구역으로 이동하며 관리국 보급 상자에서 소형 방진 필터 챙기기 | E122: 전투 가능·비전투 콘텐츠 | F122: 100 | H122: 100 | K122: 소형 방진 필터 1개 획득
A123: 122 | B123: 차한해 | D123: 고립 시민 찾기 | E123: 전투 가능·비전투 콘텐츠 | F123: 100 | H123: 100
A124: 123 | B124: 차한해 | D124: 관리국 대응 장갑을 착용하고 잔해 제거하기 | E124: 전투 가능·비전투 콘텐츠 | F124: 100 | H124: 100
A125: 124 | B125: 차한해 | D125: 시민 대피 유도하기 | E125: 전투 가능·비전투 콘텐츠 | F125: 100 | H125: 100
A126: 125 | B126: 차한해 | D126: 관리국 무전 이어피스로 내 몫의 공격 예고 신호 파악하기 | E126: 전투 가능 | F126: 100 | H126: 100 | J126: 먼저 들었어 | K126: 스킬 : 공격 예고 판독
...

Sheet 아이템
A1: 이름 | B1: 타입 | C1: 참고 이미지 | D1: 사용 권한 | 획득 방식 | 획득 조건 | G1: 거래 제한 | H1: 사용 조건 | I1: 공격 수치 | 공격 보정 | K1: 방어 수치 | 방어 보정 | M1: 기타 수치 | N1: 세트 이름 | 효과 | 내용 | Q1: 수치 | R1: 최소 공격력 | S1: 최대 공격력 | T1: 아이템 속성
A2: 관리국 지급 권총 | B2: 무기 | D2: 선의관리국 요원 | E2: 퀘스트 | F2: 118번 | 관리국 표준 대응 장비 8종·응급품 2종을 수령하고 상태 UI 확인하기 | G2: 획득 시 귀속 | H2: 119번 이후 | 균열 대응 원거리 전투에서 사용 | I2: 20 | J2: 원거리 공격 보정 +5 | K2: 0 | N2: 관리국 표준 대응 세트 | O2: 2세트: 장비 교체 시간 -10% 5세트: 균열 오염 저항 +10 8세트: 자아 마모 누적량 -15% | P2: 물리·관통 | Q2: 100 | R2: 18 | S2: 22 | T2: 안정
A3: 기본 보호 조끼 | B3: 상의 | D3: 선의관리국 요원 | E3: 퀘스트 | F3: 118번 | 관리국 표준 대응 장비 8종·응급품 2종을 수령하고 상태 UI 확인하기 | G3: 획득 시 귀속 | H3: 130번 사용·131번 손상·188번 완전 파손 | I3: 0 | K3: 30 | L3: 충격 저항 +8 | N3: 관리국 표준 대응 세트 | P3: 충격 저항 | Q3: 100 | R3: 0 | S3: 0 | T3: 공명
A4: 관리국 방진 고글 | B4: 얼굴 | D4: 선의관리국 요원 | E4: 퀘스트 | F4: 118번 | 관리국 표준 대응 장비 8종·응급품 2종을 수령하고 상태 UI 확인하기 | G4: 획득 시 귀속 | H4: 128번 공명 흔적 추적·192번 먼지 보호 안경으로 교체 | I4: 0 | K4: 4 | L4: 분진·시야 방해 저항 +10 | M4: 균열 감지 범위 +2m | N4: 관리국 표준 대응 세트 | P4: 균열 감지 패시브 | Q4: +2m | R4: 0 | S4: 0
A5: 관리국 대응 장갑 | B5: 손 | D5: 선의관리국 요원 | E5: 퀘스트 | F5: 118번 | 관리국 표준 대응 장비 8종·응급품 2종을 수령하고 상태 UI 확인하기 | G5: 획득 시 귀속 | H5: 123번 잔해 제거·153번 공명 보호 장갑으로 교체 | I5: 3 | J5: 근접 공격 보정 +2 | K5: 5 | L5: 접촉 피해 감소 +5% | M5: 상호작용 속도 +5% | N5: 관리국 표준 대응 세트 | P5: 접촉 안정 패시브 | Q5: 피해 -5% | R5: 2 | S5: 4 | T5: 안정
A6: 관리국 전술화 | B6: 신발 | D6: 선의관리국 요원 | E6: 퀘스트 | F6: 118번 | 관리국 표준 대응 장비 8종·응급품 2종을 수령하고 상태 UI 확인하기 | G6: 획득 시 귀속 | H6: 119·126번 회피 훈련·196번 고밀도 충격 흡수 장화로 교체 | I6: 0 | K6: 6 | L6: 넘어짐 저항 +10% | M6: 회피 이동 거리 +5% | N6: 관리국 표준 대응 세트 | P6: 기동 보정 | Q6: +5% | R6: 0 | S6: 0 | T6: 안정
A7: 관리국 방진 마스크 | B7: 얼굴 | D7: 선의관리국 요원 | E7: 퀘스트 | F7: 118번 | 관리국 표준 대응 장비 8종·응급품 2종을 수령하고 상태 UI 확인하기 | G7: 획득 시 귀속 | H7: 128번 필터 교체 후 공명 흔적 추적·192번 균열 보호 마스크로 교체 | I7: 0 | K7: 3 | L7: 균열 오염 저항 +8 | M7: 자아 마모 저항 +3% | N7: 관리국 표준 대응 세트 | P7: 오염 저항 | Q7: 108 | R7: 0 | S7: 0
A8: 관리국 무전 이어피스 | B8: 액세서리 | D8: 선의관리국 요원 | E8: 퀘스트 | F8: 118번 | 관리국 표준 대응 장비 8종·응급품 2종을 수령하고 상태 UI 확인하기 | G8: 획득 시 귀속 | H8: 125번 공격 예고 판독에 사용 | I8: 0 | K8: 0 | M8: 공격 예고 판독 시간 +0.3초 | N8: 관리국 표준 대응 세트 | P8: 전술 정보 패시브 | Q8: +0.3초 | R8: 0 | S8: 0
A9: 관리국 상태 측정기 | B9: 액세서리 | D9: 선의관리국 요원 | E9: 퀘스트 | F9: 118번 | 관리국 표준 대응 장비 8종·응급품 2종을 수령하고 상태 UI 확인하기 | G9: 획득 시 귀속 | H9: 131번 장비 손상 확인·임무 종료 시 자동 동기화 | I9: 0 | K9: 0 | M9: 장비 내구도·자아 마모도 표시 | N9: 관리국 표준 대응 세트 | P9: 상태 확인 패시브 | Q9: UI 표시 | R9: 0 | S9: 0
A10: 보랏빛 철봉 | B10: 무기 | D10: 일반인 / 모든 선의 등급자 | E10: 콘텐츠 | F10: 129번 | 차한해에게만 보이는 보랏빛 아우라가 흐르는 철봉 회수 | H10: 130번 내꺼 챙겨 제압 후 132번 소멸 | I10: 80 | J10: 근접 강공격 보정 +10 | K10: 0 | M10: 경직 유발 +12% | P10: 충격 | Q10: 115 | R10: 72 | S10: 88 | T10: 공명
A11: 깨진 경찰 방패 | B11: 보조 장비 | D11: 일반인 / 모든 선의 등급자 | E11: 콘텐츠 | F11: 134번 | 구조한 경찰에게 깨진 경찰 방패와 휴대용 섬광 신호기 받기 | H11: 146번 닫힌 문지기 보스전·166번 파손 | I11: 0 | K11: 20 | L11: 전방 피해 감소 +12% | M11: 전방 방어 해금 | P11: 물리 저항 | Q11: 112 | R11: 0 | S11: 0 | T11: 차단
A12: 차단기 막대 | B12: 무기 | D12: 일반인 / 모든 선의 등급자 | E12: 콘텐츠 | F12: 140번 | 차한해에게만 보이는 보랏빛 공명의 차단기 막대 회수 | H12: 141번 유인·142번 여기도 내 집 제압 | I12: 90 | J12: 근접 공격 보정 +12 | K12: 0 | M12: 환경 유인 효과 +10% | P12: 전기·충격 | Q12: 120 | R12: 81 | S12: 99 | T12: 차단
A13: 나무판 보호대 | B13: 팔 방어구 | D13: 일반인 / 모든 선의 등급자 | E13: 제작 | F13: 145번 | 대피소 시민과 나무판 보호대 제작 | H13: 146~148번 닫힌 문지기 보스전 사용 후 파손 | I13: 0 | K13: 10 | L13: 근접 피해 감소 +5% | M13: 임시 장비 제작 | P13: 물리 저항 | Q13: 105 | R13: 0 | S13: 0 | T13: 차단
A14: 소방용 진압 도끼 | B14: 무기 | D14: 고등급자 / 선의관리국 요원 | E14: 콘텐츠 | F14: 185번 | 회사로 우회하며 소방 보급 상자에서 확보 | G14: 획득 시 귀속 | H14: 188번 붕괴 잔해 3개 파괴 후 반납 | I14: 75 | J14: 구조물 공격 보정 +30 | K14: 0 | M14: 구조 행동 속도 +15% | N14: 재난 구조 세트 | O14: 2세트: 구조 행동 속도 +10% 4세트: 화염·연기 피해 -15% | P14: 화염 대응 | Q14: 115 | R14: 68 | S14: 82
A15: 소방 방열복 | B15: 상의 | D15: 고등급자 / 선의관리국 요원 | E15: 퀘스트 | F15: 187번 | 부상당한 소방관 구조 후 임시 대여 | G15: 획득 시 귀속 | H15: 188번 고열·낙하물 구간 통과 후 반납 | I15: 0 | K15: 22 | L15: 화염 피해 감소 +20% | M15: 이동 속도 -5% | N15: 재난 구조 세트 | P15: 화염 저항 | Q15: 120 | R15: 0 | S15: 0
A16: 구조대 안전모 | B16: 머리 | D16: 일반인 / 모든 선의 등급자 | E16: 콘텐츠 | F16: 185번 | 회사로 우회하며 소방 보급 상자에서 확보 | H16: 186~188번 낙하물 피해 대응 후 반납 | I16: 0 | K16: 8 | L16: 낙하물 피해 감소 +15% | M16: 기절 시간 -10% | N16: 재난 구조 세트 | P16: 낙하 충격 저항 | Q16: 115 | R16: 0 | S16: 0
A17: 구조용 로프 발사기 | B17: 보조 장비 | D17: 고등급자 / 선의관리국 요원 | E17: 퀘스트 | F17: 185번 | 회사로 우회하며 소방 보급 상자에서 확보 | G17: 획득 시 귀속 | H17: 186번 1회·188번 1회 사용 후 2회분 소진 | I17: 12 | J17: 원거리 경직 보정 +5 | K17: 0 | M17: 구조 이동 경로 해금 | N17: 재난 구조 세트 | P17: 이동 보조 패시브 | Q17: 2회 | R17: 10 | S17: 14
A18: 오염 차단 전신복 | B18: 상의 | D18: 고등급자 | E18: 퀘스트 | F18: 196번 | 관리국 현장 보급함에서 수령·장착 | G18: 획득 시 귀속 | H18: 213~217번 폐교 오염 조사·270번 최종 장비로 교체 | I18: 0 | K18: 35 | L18: 균열 오염 저항 +20 | M18: 자아 마모 누적량 -8% | N18: 심층 균열 탐사 세트 | O18: 2세트: 균열 감지 범위 +3m 4세트: 자아 마모 누적량 -12% | P18: 균열 저항 | Q18: 120 | R18: 0 | S18: 0 | T18: 차단
A19: 심층 균열 탐사 헬멧 | B19: 머리 | D19: 고등급자 | E19: 퀘스트 | F19: 196번 | 관리국 현장 보급함에서 수령·장착 | G19: 획득 시 귀속 | H19: 213·217번 흔적·퍼즐 단서 탐지 | I19: 0 | K19: 12 | L19: 정신 피해 저항 +10 | M19: 균열 감지 범위 +4m | N19: 심층 균열 탐사 세트 | P19: 균열 감지 패시브 | Q19: +4m | R19: 0 | S19: 0
A20: 선의 안정 장치 | B20: 액세서리 | D20: 차한해 전용 | E20: 업적 | F20: 196번 | 시민 구조 누적 30회 달성 후 관리국 현장 보급함에서 추가 수령 | G20: 획득 시 귀속 | H20: 249번 친구 정체 확인 시 1회 자동 발동 | I20: 0 | K20: 0 | M20: 자아마모 수치 유지·입력 흔들림 10초 완화 | N20: 심층 균열 탐사 세트 | P20: 입력 안정 | Q20: 10초 | R20: 0 | S20: 0
A21: 고밀도 충격 흡수 장화 | B21: 신발 | D21: 고등급자 | E21: 퀘스트 | F21: 196번 | 관리국 현장 보급함에서 수령·장착 | G21: 획득 시 귀속 | H21: 215번 밀치기 방어·251번 친구 접근·270번 강화 전투화로 교체 | I21: 0 | K21: 10 | L21: 넘어짐·밀쳐짐 저항 +20% | M21: 회피 후 경직 시간 -10% | N21: 심층 균열 탐사 세트 | P21: 기동 안정 | Q21: 120 | R21: 0 | S21: 0 | T21: 안정
A22: 응급 압박 붕대 | B22: 소모품 | D22: 일반인 / 모든 선의 등급자 | E22: 보급 | F22: 144번 | 봉쇄 대피소 보급 상자에서 획득 | H22: 146번 닫힌 문지기 보스전에서 1회 사용 | I22: 0 | K22: 0 | M22: 체력 20% 회복 | P22: 회복 | Q22: 20 | R22: 0 | S22: 0
A23: 관리국 응급 주사 | B23: 소모품 | D23: 선의관리국 요원 | E23: 퀘스트 | F23: 118번 | 관리국 표준 대응 장비와 함께 지급 | G23: 획득 시 귀속 | H23: 168번 부품 수집가 보스전에서 1회 사용 | I23: 0 | K23: 0 | M23: 체력 35% 회복, 이동 속도 5초간 -10% | P23: 회복 | Q23: 35 | R23: 0 | S23: 0
A24: 안정 앰플 | B24: 소모품 | D24: 고등급자 / 차한해 전용 | E24: 퀘스트 | F24: 192번 | 나대진에게 환경 장비와 함께 수령 | G24: 획득 시 귀속 | H24: 250번 공격 중지 생존 구간에서 1회 사용 | I24: 0 | K24: 0 | M24: 자아마모 수치 유지·UI 간섭 8초 완화 | P24: UI 안정 | Q24: 8초 | R24: 0 | S24: 0
A25: 소형 방진 필터 | B25: 소모품 | D25: 일반인 / 모든 선의 등급자 | E25: 보급 | F25: 121번 | 도심 잔해 구역 이동 중 관리국 보급 상자에서 획득 | H25: 128번 관리국 방진 마스크에 1회 사용 | I25: 0 | K25: 0 | M25: 마스크 내구도 30 회복 | P25: 장비 회복 | Q25: 30 | R25: 0 | S25: 0
A26: 휴대용 섬광 신호기 | B26: 소모품 | D26: 일반인 / 모든 선의 등급자 | E26: 콘텐츠 | F26: 134번 | 구조한 경찰에게 깨진 방패와 함께 받기 | H26: 141번 내 자리야 유인에 1회 사용 | I26: 0 | K26: 0 | M26: 일반 괴물 주의 분산 4초 | P26: 시야 교란 | Q26: 4 | R26: 0 | S26: 0
A27: 비살상 충격탄 | B27: 탄약 | D27: 선의관리국 요원 | E27: 퀘스트 | F27: 118번 | 관리국 표준 대응 장비와 함께 지급 | G27: 획득 시 귀속 | H27: 119번 사격 훈련·125번 비살상 제압에 사용 | I27: 6 | J27: 경직 피해 +20% | K27: 0 | M27: 처치 대신 제압 게이지 증가 | P27: 비살상 충격 | Q27: 120 | R27: 5 | S27: 7 | T27: 안정
A28: 고등급자 공명 증폭기 | B28: 액세서리 | D28: 고등급자 | E28: 나대진 지급 | F28: 153번 | [나대진] 75% 이상에서 장비 지원으로 수령 | G28: 획득 시 귀속 | H28: 159번 공명 탐지·160번 소개비 제압 | I28: 15 | J28: 균열 개체 대상 피해 +8% | K28: 0 | M28: 공명 피해 증가·UI 간섭 +3% | P28: 공명 증폭 | Q28: 108 | R28: 13 | S28: 17 | T28: 공명
A29: 연구실 최고 권한 키카드 | B29: 접근 도구 | D29: 연구실 최고 권한자 | E29: 나대진 안내·현장 회수 | F29: 265번 | [나대진] 85% 이상에서 암호 경로를 따라 연구시설 책임자 단말에서 회수 | G29: 획득 시 귀속 | H29: 266번 | 첫 번째 연구시설 보안문 해제 | I29: 0 | K29: 0 | M29: 최고 보안 구역 접근 | P29: 접근 권한 | Q29: 최고 | R29: 0 | S29: 0
A30: 보안 요원 생체 인증 모듈 | B30: 접근 도구 | D30: 차한해 | E30: 몬스터 제압·회수 | F30: 265번 | 우리 쓸 것도 없어 제압 후 노출된 생체 인증 모듈 회수 | G30: 획득 시 귀속 | H30: 266번 | 두 번째 연구시설 생체 인식문 1회 해제 | I30: 0 | K30: 0 | M30: 보안 구역 접근 | P30: 생체 인증 | Q30: 1회 | R30: 0 | S30: 0
A31: 충격 보호대 | B31: 보조 장비 | D31: 차한해 | E31: 나대진 지급 | F31: 153번 | 충격 보호대·공명 보호 장갑·공명 증폭기 수령 | G31: 획득 시 귀속 | H31: 164~168번 부품 수집가 보스전에서 사용 | I31: 0 | K31: 20 | L31: 피격 경직 감소 | P31: 충격 보호 | Q31: 20 | R31: 0 | S31: 0 | T31: 공명
A32: 공명 보호 장갑 | B32: 손 | D32: 차한해 | E32: 나대진 지급 | F32: 153번 | 충격 보호대·공명 보호 장갑·공명 증폭기 수령 | G32: 획득 시 귀속 | H32: 159~168번 공명 무기·증폭기 사용 부담 완화 | I32: 0 | K32: 15 | L32: 공명 반동 감소 | P32: 공명 보호 | Q32: 15 | R32: 0 | S32: 0 | T32: 공명
A33: 전광판 쇠막대 | B33: 무기 | D33: 차한해 | E33: 현장 획득 | F33: 159번 | 차한해에게만 보이는 보랏빛 아우라와 공명 증폭기 반응이 겹치는 쇠막대 회수 | H33: 160번 소개비 제압 | I33: 100 | J33: 다수 정렬 타격 | K33: 0 | P33: 충격 | Q33: 100 | R33: 90 | S33: 110 | T33: 공명
A34: 군용 방탄판 | B34: 상의 | D34: 차한해 | E34: 군인 지원 | F34: 169번 | 구조된 군인에게 지원받기 | G34: 획득 시 귀속 | H34: 178~181번 최초의 영웅 보스전·181번 균열 | I34: 0 | K34: 35 | L34: 강한 공격 방어 | P34: 물리 저항 | Q34: 35 | R34: 0 | S34: 0 | T34: 안정
A35: 화염 보호복 | B35: 상의 | D35: 차한해 | E35: 소방관 지원 | F35: 187번 | 도시 인연 50% 이상에서 부상당한 소방관 구조 보상으로 획득 | G35: 획득 시 귀속 | H35: 188번 회사 화재 구조·손상 후 +10 유지 | I35: 0 | K35: 20 | L35: 화염 피해 대응 | P35: 화염 저항 | Q35: 20 | R35: 0 | S35: 0
A36: 먼지 보호 안경 | B36: 얼굴 | D36: 차한해 | E36: 나대진 지급 | F36: 192번 | 폐교 환경 장비 수령 | G36: 획득 시 귀속 | H36: 213~217번 폐교 분진·시야 방해 구간 | I36: 0 | K36: 10 | L36: 분진 시야 확보 | P36: 분진 저항 | Q36: 10 | R36: 0 | S36: 0
A37: 균열 보호 마스크 | B37: 얼굴 | D37: 차한해 | E37: 나대진 지급 | F37: 192번 | 폐교 환경 장비 수령 | G37: 획득 시 귀속 | H37: 213~217번 폐교 균열 오염 구간 | I37: 0 | K37: 15 | L37: 균열 오염 차단 | P37: 균열 저항 | Q37: 15 | R37: 0 | S37: 0 | T37: 차단
A38: 철판 보호대 | B38: 보조 장비 | D38: 차한해 | E38: 정비공 지원 | F38: 194번 | 구조받은 정비공에게 획득 | G38: 획득 시 귀속 | H38: 246~251번 변혜서전·251번 파손 | I38: 0 | K38: 25 | L38: 충격 보호 | P38: 물리 저항 | Q38: 25 | R38: 0 | S38: 0 | T38: 공명
A39: 사랑의 매 | B39: 무기 | D39: 차한해 | E39: 현장 획득 | F39: 237번 | 변혜서의 기억과 공명해 차한해에게만 보랏빛으로 보이는 사랑의 매 회수 | H39: 238번 시험·246번 변혜서 외피 파괴 | I39: 140 | J39: 공명 외피 파괴 | K39: 0 | P39: 공명 | Q39: 140 | R39: 126 | S39: 154 | T39: 공명
A40: 매트 보호대 | B40: 보조 장비 | D40: 차한해 | E40: 현장 제작 | F40: 242번 | 체육관 매트로 제작 | G40: 획득 시 귀속 | H40: 246~251번 변혜서전·251번 파손 | I40: 0 | K40: 15 | L40: 충격 완화 | P40: 물리 저항 | Q40: 15 | R40: 0 | S40: 0 | T40: 공명
...

Sheet 속성 대차대조표
A1: 1. 속성 정의 및 적용 대상
A2: 속성 | B2: 핵심 성질 | E2: 공격 속성 적용 | I2: 방어 속성 적용 | M2: 대표 표현
A3: 안정 | B3: 형태와 에너지의 상태를 고정하고 과도한 진동을 억제하는 파장 | E3: 공명 주기 고정, 흔들림 억제, 변이체의 움직임 안정화 | I3: 공명·진동 피해 완화, 밀려남과 흔들림을 억제하는 방호 상태 | M3: 청색 고정선, 입자가 한 지점으로 모이는 연출
A4: 공명 | B4: 파동을 반복·중첩하여 내부 진동과 에너지 증폭을 일으키는 파장 | E4: 반복 타격과 파동 중첩, 차단 한계 초과, 균열 확대 | I4: 외부 파장을 되울리거나 분산하여 충격을 흘려보내는 상태 | M4: 보라색 파문, 동심원과 진동 잔상
A5: 차단 | B5: 에너지·파장·오염의 전달 경로와 연결을 끊는 파장 | E5: 능력 연결 절단, 침식 확산 중단, 유지 에너지 공급 방해 | I5: 외부 에너지 유입과 상태이상 전이를 막는 방호 상태 | M5: 짙은 회색 단절선, 벽 형태의 끊김 연출
A6: 침식 | B6: 조직과 구조의 결합을 약화하고 형태를 점진적으로 붕괴시키는 파장 | E6: 고정 구조 붕괴, 방어 상태 약화, 균열 부위 확대 | I6: 공격 에너지를 분해·흡수하며 일부 피해를 약화하는 상태 | M6: 자홍색 번짐, 표면이 부식되듯 퍼지는 연출
A8: 2. 속성 대차대조표 및 피해 계산 검증
A9: 피해 매개 상수표 K | G9: 상성 순환
A10: 공격자＼방어자 | B10: 안정 | C10: 공명 | D10: 차단 | E10: 침식 | L10: 안정 → 공명 → 차단 → 침식 → 안정은 ×1.7의 강한 우위 관계이며, 반대 방향은 ×0.3의 강한 열위 관계로 적용함.
A11: 안정 | B11: 1 | C11: 1.7 | D11: 0.8 | E11: 0.3
A12: 공명 | B12: 0.3 | C12: 1 | D12: 1.7 | E12: 1.2
A13: 차단 | B13: 1.2 | C13: 0.3 | D13: 1 | E13: 1.7
A14: 침식 | B14: 1.7 | C14: 0.8 | D14: 0.3 | E14: 1
A16: 3. 수치 근거표
A17: 공격 속성 | B17: 방어 속성 | C17: 관계 유형 | E17: 매개 상수 | G17: 수치 적용 근거 | L17: 전투 표현
A18: 안정 | B18: 안정 | C18: 동일 | E18: 1 | G18: 동일한 파장끼리는 서로 우위가 없으므로 기존 피해식에 영향을 주지 않음. | L18: 기본 피해 수치와 기본 속성 이펙트 적용
A19: 안정 | B19: 공명 | C19: 강한 우위 | E19: 1.7 | G19: 안정 파장이 진동 주기를 고정하여 공명의 반복·증폭 작용을 직접 억제함. | L19: 파동이 멈추고 약점 적중 이펙트 강조
A20: 안정 | B20: 차단 | C20: 약한 열위 | E20: 0.8 | G20: 차단 상태가 안정 파장의 전달 경로를 일부 끊어 고정 효과가 충분히 도달하지 못함. | L20: 안정선이 끊기며 피해 표시를 약하게 표현
A21: 안정 | B21: 침식 | C21: 강한 열위 | E21: 0.3 | G21: 이미 침식된 구조는 고정할 원형과 기준이 약해 안정화 효과가 크게 감소함. | L21: 고정선이 번짐에 흡수되는 연출
A22: 공명 | B22: 안정 | C22: 강한 열위 | E22: 0.3 | G22: 안정된 구조가 진동의 확산과 파동 중첩을 막아 공명 증폭이 발생하기 어려움. | L22: 파문이 짧게 사라지는 연출
A23: 공명 | B23: 공명 | C23: 동일 | E23: 1 | G23: 동일한 파장끼리는 서로 우위가 없으므로 기존 피해식에 영향을 주지 않음. | L23: 기본 피해 수치와 기본 속성 이펙트 적용
A24: 공명 | B24: 차단 | C24: 강한 우위 | E24: 1.7 | G24: 반복되는 공명 파동이 차단 상태의 처리 한계를 넘어 과부하를 발생시킴. | L24: 차단벽에 균열이 번지고 파동이 관통하는 연출
A25: 공명 | B25: 침식 | C25: 약한 우위 | E25: 1.2 | G25: 침식으로 약해진 구조의 미세 균열을 진동이 확대하여 붕괴를 촉진함. | L25: 침식 부위가 파동에 따라 넓어지는 연출
A26: 차단 | B26: 안정 | C26: 약한 우위 | E26: 1.2 | G26: 안정 상태를 유지하는 에너지 공급과 연결을 끊어 구조의 유지력을 약화함. | L26: 고정선 일부가 끊기며 약점 이펙트 표시
A27: 차단 | B27: 공명 | C27: 강한 열위 | E27: 0.3 | G27: 공명은 파동이 누적된 뒤에도 영향이 남아 단일 연결 차단만으로 완전히 제거하기 어려움. | L27: 차단선 너머로 파문이 이어지는 연출
A28: 차단 | B28: 차단 | C28: 동일 | E28: 1 | G28: 동일한 파장끼리는 서로 우위가 없으므로 기존 피해식에 영향을 주지 않음. | L28: 기본 피해 수치와 기본 속성 이펙트 적용
A29: 차단 | B29: 침식 | C29: 강한 우위 | E29: 1.7 | G29: 침식 에너지의 접촉·전이·확산 경로를 끊어 핵심 작용을 직접 무력화함. | L29: 번짐이 절단되고 약점 적중 이펙트 강조
... A33: 침식 | B33: 침식 | C33: 동일 | E33: 1 | G33: 동일한 파장끼리는 서로 우위가 없으므로 기존 피해식에 영향을 주지 않음. | L33: 기본 피해 수치와 기본 속성 이펙트 적용

Sheet 스킬 DATA
A1: 스킬 ID | B1: 콘텐츠 번호 | C1: 지정 사용자 | D1: 구간 | E1: 최초 사용 콘텐츠 | F1: 사용 주체 | G1: 스킬명 | H1: 스킬 추가 설명 | I1: 스킬 아이콘 | J1: 스킬 타입 | K1: 지정 사용자 | L1: 상태 이상 값 | M1: 발동 조건 타입 | N1: 발동 필요 값 | O1: 피해 적용 타입 | P1: 피해 계수 | Q1: 피해 산정식 | R1: AI 발동 주기(초) | S1: AI 발동 확률 | T1: 쿨타임 타입 | U1: 쿨타임(초) | V1: 시전 필요 시간(초) | W1: 능력 변동 종류 | X1: 능력 변동 수치 | Y1: 단위 | Z1: 지속 시간(초) | AA1: 종료·취소 조건 | AB1: 연계 스킬 ID | AC1: 비고
A2: SKL-PC-001 | B2: 9 | C2: 차한해 | D2: 기본 상호작용 | E2: 9번 | 알바생의 무거운 음료 박스 진열 부탁을 수락할지 선택하기 | F2: PC | G2: 거절 | H2: 거절 가능한 부탁·요청에서 수락 대신 사용해 해당 요청을 종료하는 기본 상호작용 스킬. 거절한 콘텐츠의 인연·보상 획득 기회는 포기함. | J2: 액티브 | K2: 차한해 | M2: 입력 | N2: 수락 전 [거절] 선택 | O2: 없음 | P2: =IFERROR(VALUE(TRIM(MID(Q2,FIND("×",Q2)+1,FIND("%",Q2)-FIND("×",Q2)-1)))/100,0) -> 0 | Q2: 피해 없음 | T2: 없음 | U2: 0 | V2: 0 | W2: 없음 | X2: 0 | Y2: 없음 | Z2: 0 | AA2: 선택 확정 | AB2: 없음 | AC2: 게임 시작부터 해금·첫 사용 가능 콘텐츠 9번
A3: SKL-PC-002 | B3: 79 | C3: 차한해 | D3: 3장·첫 힘 발현 | E3: 79번 | 두 눈을 감고 양손으로 괴물을 막기 | F3: PC | G3: 펑! | H3: 괴물이 덮치기 직전 전용 UI에서 1회 발동하는 사건형 액티브. 무의식적 선의 폭발을 호출해 순간 출력 1000을 만들고 접촉 소멸까지 연쇄함. | J3: 연출용+액티브 | K3: 차한해 | M3: 1회 강제 발동 | N3: 나 먼저 접촉 직전 | O3: 없음 | P3: =IFERROR(VALUE(TRIM(MID(Q3,FIND("×",Q3)+1,FIND("%",Q3)-FIND("×",Q3)-1)))/100,0) -> 0 | Q3: 피해 없음 | T3: 없음 | U3: 0 | V3: 0.6 | W3: 공격력 | X3: 990 | Y3: + | Z3: 0 | AA3: 접촉 소멸 완료 | AB3: SKL-STS-011 → SKL-STS-012 | AC3: 스토리 필수 사용·해당 콘텐츠에만 적용
A4: SKL-PC-003 | B4: 119 | C4: 차한해 | D4: 정식 전투 | E4: 119번 | 관리국 지급 권총·비살상 충격탄·관리국 전술화를 이용해 사격과 회피 연습하기 | F4: PC | G4: 탕! | H4: 장착한 총기·원거리 무기의 공격 수치를 포함해 정면 표적 1체를 공격하는 기본 사격. | J4: 액티브 | K4: 차한해 | L4: 경직 0.20초 | M4: 입력 | N4: 공격 입력 1회 | O4: 기본 공격력 비율 | P4: =IFERROR(VALUE(TRIM(MID(Q4,FIND("×",Q4)+1,FIND("%",Q4)-FIND("×",Q4)-1)))/100,0) -> 1 | Q4: 기본 공격력 × 100% | T4: 개별 | U4: 0.45 | V4: 0.2 | W4: 없음 | X4: 0 | Y4: 없음 | Z4: 0 | AA4: 시전 종료 | AB4: SKL-STS-001 | AC4: 관리국 지급 권총을 기준으로 최초 훈련
A5: SKL-PC-004 | B5: 119 | C5: 차한해 | D5: 정식 전투 | E5: 119번 | 관리국 지급 권총·비살상 충격탄·관리국 전술화를 이용해 사격과 회피 연습하기 | F5: PC | G5: 앗, 피해! | H5: 입력 방향으로 짧게 이동하며 공격 판정을 피하는 기본 회피. 성공 시 일부 반격 스킬의 조건을 열어 줌. | J5: 액티브 | K5: 차한해 | M5: 입력 | N5: 회피 입력 1회 | O5: 없음 | P5: =IFERROR(VALUE(TRIM(MID(Q5,FIND("×",Q5)+1,FIND("%",Q5)-FIND("×",Q5)-1)))/100,0) -> 0 | Q5: 피해 없음 | T5: 개별 | U5: 1.8 | V5: 0.1 | W5: 이동 속도 | X5: 80 | Y5: % | Z5: 0.25 | AA5: 이동 종료 | AB5: 없음 | AC5: 훈련 이후 상시 사용
A6: SKL-PC-005 | B6: 146 | C6: 보스 | D6: 보스 공통 | E6: 146번 | 닫힌 문지기가 연속으로 닫는 방화문 다시 열기 | F6: PC | G6: 행동 제한 | H6: 보스전에서 딱 1번 사용할 수 있는 보조 스킬. 보스의 현재 행동을 1초간 멈춰 위험 패턴을 끊을 틈을 만듦. | J6: 액티브 | K6: 보스 | L6: 경직 1.00초 | M6: 전투당 1회 | N6: 보스전·미사용 상태 | O6: 없음 | P6: =IFERROR(VALUE(TRIM(MID(Q6,FIND("×",Q6)+1,FIND("%",Q6)-FIND("×",Q6)-1)))/100,0) -> 0 | Q6: 피해 없음 | T6: 전투당 1회 | U6: 0 | V6: 0.15 | W6: 없음 | X6: 0 | Y6: 없음 | Z6: 1 | AA6: 1초 종료 | AB6: SKL-STS-001 | AC6: 118번에서 해금·146번 첫 보스부터 실제 사용 가능
A7: SKL-PC-006 | B7: 125 | C7: 차한해 | D7: 전투 정보 | E7: 125번 | 관리국 무전 이어피스로 내 몫의 공격 예고 신호 파악하기 | F7: PC | G7: 먼저 들었어 | H7: 관리국 무전 이어피스의 공격 예고 신호를 판독해 적의 전조를 기본보다 0.3초 먼저 표시하는 패시브. | J7: 패시브 | K7: 차한해 | M7: 장비 착용 | N7: 관리국 무전 이어피스 장착 | O7: 없음 | P7: =IFERROR(VALUE(TRIM(MID(Q7,FIND("×",Q7)+1,FIND("%",Q7)-FIND("×",Q7)-1)))/100,0) -> 0 | Q7: 피해 없음 | T7: 없음 | U7: 0 | V7: 0 | W7: 전조 표시 시간 | X7: 0.3 | Y7: 초 | Z7: 0 | AA7: 장비 해제 | AB7: 없음 | AC7: 장비 효과를 스킬 형태로 표현
A8: SKL-PC-007 | B8: 126 | C8: 차한해 | D8: 정식 전투 | E8: 126번 | 나부터 살아의 후방 기습을 피하고 반격 타이밍 맞추기 | F8: PC | G8: 피했으면 내 차례 | H8: 직전 공격을 회피한 직후 짧은 반격 창에서 사용하는 대응 사격·타격. | J8: 액티브 | K8: 차한해 | L8: 경직 0.30초 | M8: 조건부 입력 | N8: 회피 성공 후 0.8초 이내 | O8: 기본 공격력 비율 | P8: =IFERROR(VALUE(TRIM(MID(Q8,FIND("×",Q8)+1,FIND("%",Q8)-FIND("×",Q8)-1)))/100,0) -> 1.15 | Q8: 기본 공격력 × 115% | T8: 개별 | U8: 2 | V8: 0.25 | W8: 없음 | X8: 0 | Y8: 없음 | Z8: 0 | AA8: 반격 창 종료 | AB8: SKL-STS-001 | AC8: 회피 성공을 공격 기회로 전환
A9: SKL-PC-008 | B9: 130 | C9: 차한해 | D9: 공명 전투 | E9: 130번 | 보랏빛 철봉으로 내꺼 챙겨 제압하기 | F9: PC | G9: 보라색, 여기! | H9: 차한해에게만 보이는 보랏빛 공명 반응 부위를 노려 타격해 일반 공격보다 큰 약점 피해를 줌. | J9: 액티브 | K9: 차한해 | M9: 약점 노출 | N9: 보랏빛 약점 표식 활성 | O9: 기본 공격력 비율 | P9: =IFERROR(VALUE(TRIM(MID(Q9,FIND("×",Q9)+1,FIND("%",Q9)-FIND("×",Q9)-1)))/100,0) -> 1.35 | Q9: 기본 공격력 × 135% | T9: 개별 | U9: 2.5 | V9: 0.35 | W9: 없음 | X9: 0 | Y9: 없음 | Z9: 0 | AA9: 약점 타격 종료 | AB9: 없음 | AC9: 공명 약점이 없는 대상에는 사용 불가
A10: SKL-PC-009 | B10: 134 | C10: 차한해 | D10: 방어 전투 | E10: 134번 | 구조한 경찰에게 깨진 경찰 방패와 휴대용 섬광 신호기 받기 | F10: PC | G10: 앞은 내가 막아 | H10: 깨진 경찰 방패 등 전방 방어 장비를 들어 정면 피해와 밀려남을 줄이는 유지형 방어. | J10: 액티브 | K10: 차한해 | M10: 입력 유지 | N10: 방어 장비 장착·방어 입력 유지 | O10: 없음 | P10: =IFERROR(VALUE(TRIM(MID(Q10,FIND("×",Q10)+1,FIND("%",Q10)-FIND("×",Q10)-1)))/100,0) -> 0 | Q10: 피해 없음 | T10: 유지형 | U10: 0 | V10: 0.15 | W10: 받는 정면 피해 | X10: -50 | Y10: % | Z10: 0 | AA10: 입력 해제·방패 파손 | AB10: 없음 | AC10: 보스·강한 공격에는 감소량이 낮아질 수 있음
A11: SKL-PC-010 | B11: 141 | C11: 일반 변이체 | D11: 환경 유인 | E11: 141번 | 휴대용 섬광 신호기와 차단기 막대로 내 자리야 유인하기 | F11: PC | G11: 저기 봐! | H11: 휴대용 섬광 신호기 1개를 소비해 일반 변이체의 주의를 설치 지점으로 4초간 돌리는 비전투·전투 겸용 스킬. | J11: 연출용+액티브 | K11: 일반 변이체 | L11: 주의 분산 4초 | M11: 아이템 사용 | N11: 휴대용 섬광 신호기 1회 소모 | O11: 없음 | P11: =IFERROR(VALUE(TRIM(MID(Q11,FIND("×",Q11)+1,FIND("%",Q11)-FIND("×",Q11)-1)))/100,0) -> 0 | Q11: 피해 없음 | T11: 아이템 횟수 | U11: 0 | V11: 0.4 | W11: 표적 인식 | X11: -1 | Y11: 대상 | Z11: 4 | AA11: 지속 종료·보스 면역 | AB11: SKL-STS-010 | AC11: PPT의 폭죽형 유틸리티 스킬과 같은 구조
A12: SKL-PC-011 | B12: 141 | C12: 차한해 | D12: 환경 유인 | E12: 141번 | 휴대용 섬광 신호기와 차단기 막대로 내 자리야 유인하기 | F12: PC | G12: 이쪽이야! | H12: 차단기 막대나 주변 소음 오브젝트를 이용해 주의가 분산된 적의 이동 목표를 열린 공간으로 유도함. | J12: 액티브 | K12: 차한해 | M12: 환경 상호작용 | N12: 유인 가능한 오브젝트 활성 | O12: 없음 | P12: =IFERROR(VALUE(TRIM(MID(Q12,FIND("×",Q12)+1,FIND("%",Q12)-FIND("×",Q12)-1)))/100,0) -> 0 | Q12: 피해 없음 | T12: 개별 | U12: 3 | V12: 0.3 | W12: 이동 목표 | X12: 1 | Y12: 지점 | Z12: 3 | AA12: 대상 도달·지속 종료 | AB12: SKL-STS-007 | AC12: 환경 지형과 함께 사용하는 전술형 스킬
A13: SKL-PC-012 | B13: 148 | C13: 차한해 | D13: 첫 보스 | E13: 148번 | 모든 문을 열린 채 고정하고 잠금 핵 무력화하기 | F13: PC | G13: 핵부터! | H13: 보스의 노출된 핵에 공격을 집중해 외피보다 큰 파괴 효율을 내는 상황형 집중 공격. | J13: 액티브 | K13: 차한해 | M13: 약점 노출 | N13: 보스 핵 노출 상태 | O13: 기본 공격력 비율 | P13: =IFERROR(VALUE(TRIM(MID(Q13,FIND("×",Q13)+1,FIND("%",Q13)-FIND("×",Q13)-1)))/100,0) -> 1.4 | Q13: 기본 공격력 × 140% | T13: 개별 | U13: 1.5 | V13: 0.3 | W13: 핵 피해 | X13: 40 | Y13: % | Z13: 0 | AA13: 핵 은폐 | AB13: 없음 | AC13: 노출 약점 전용
A14: SKL-PC-013 | B14: 153 | C14: 차한해 | D14: 공명 장비 | E14: 153번 | 나대진에게 충격 보호대·공명 보호 장갑·고등급자 공명 증폭기 수령하기 | F14: PC | G14: 증폭기, 켠다! | H14: 고등급자 공명 증폭기를 켜 공명 대상 공격력을 높이는 대신 화면 간섭을 함께 발생시키는 장비 액티브. | J14: 액티브 | K14: 차한해 | L14: UI 간섭 | M14: 장비 사용 | N14: 고등급자 공명 증폭기 장착 | O14: 없음 | P14: =IFERROR(VALUE(TRIM(MID(Q14,FIND("×",Q14)+1,FIND("%",Q14)-FIND("×",Q14)-1)))/100,0) -> 0 | Q14: 피해 없음 | T14: 개별 | U14: 8 | V14: 0.35 | W14: 공격력 | X14: 15 | Y14: + | Z14: 8 | AA14: 장비 해제·지속 종료 | AB14: 없음 | AC14: 공명 대상 피해 +8%·UI 간섭 +3%는 아이템 시트 값 적용
A15: SKL-PC-014 | B15: 160 | C15: 차한해 | D15: 다수 전투 | E15: 160번 | 공명 증폭기와 전광판 쇠막대로 승강장의 소개비 제압하기 | F15: PC | G15: 한 줄로 서! | H15: 전광판 쇠막대의 넓은 궤적으로 일렬에 겹친 여러 적을 한 번에 타격하는 정렬 공격. | J15: 액티브 | K15: 차한해 | M15: 입력 | N15: 2체 이상 일렬 정렬 | O15: 기본 공격력 비율 | P15: =IFERROR(VALUE(TRIM(MID(Q15,FIND("×",Q15)+1,FIND("%",Q15)-FIND("×",Q15)-1)))/100,0) -> 1.1 | Q15: 기본 공격력 × 110% | T15: 개별 | U15: 3.2 | V15: 0.5 | W15: 최대 타격 수 | X15: 3 | Y15: 체 | Z15: 0 | AA15: 시전 종료 | AB15: 없음 | AC15: 대상별 피해 동일
A16: SKL-PC-015 | B16: 163 | C16: 차한해 | D16: 융합 보스 | E16: 163번 | 부품 수집가의 단일 외피 공략하기 | F16: PC | G16: 둘 중 하나! | H16: 상반된 공격 전조를 읽고 이번 공격을 받아낼지 피할지 판별하는 판단형 패시브. | J16: 패시브 | K16: 차한해 | M16: 패턴 판독 | N16: 상반 전조 발생 | O16: 없음 | P16: =IFERROR(VALUE(TRIM(MID(Q16,FIND("×",Q16)+1,FIND("%",Q16)-FIND("×",Q16)-1)))/100,0) -> 0 | Q16: 피해 없음 | T16: 없음 | U16: 0 | V16: 0 | W16: 판독 표시 | X16: 1 | Y16: 회 | Z16: 0 | AA16: 해당 공격 종료 | AB16: 없음 | AC16: 잘못 판독하면 보스 패턴 페널티 적용
A17: SKL-PC-016 | B17: 168 | C17: 차한해 | D17: 융합 보스 | E17: 168번 | 관리국 응급 주사를 사용하고 폭력의 순환 핵 파괴하기 | F17: PC | G17: 하나, 둘—지금! | H17: 동시에 노출된 2개의 연결 핵을 짧은 허용 시간 안에 맞혀 폭력의 순환 연결을 끊는 동시 타격. | J17: 액티브 | K17: 차한해 | M17: 동시 조건 | N17: 연결 핵 2개 동시 노출 | O17: 기본 공격력 비율 | P17: =IFERROR(VALUE(TRIM(MID(Q17,FIND("×",Q17)+1,FIND("%",Q17)-FIND("×",Q17)-1)))/100,0) -> 1.2 | Q17: 기본 공격력 × 120% | T17: 개별 | U17: 5 | V17: 0.45 | W17: 동시 판정 시간 | X17: 0.6 | Y17: 초 | Z17: 0 | AA17: 핵 파괴·허용 시간 초과 | AB17: 없음 | AC17: 2개 핵 모두 적중해야 성공
A18: SKL-PC-017 | B18: 169 | C18: 차한해 | D18: 중장비 방어 | E18: 169번 | 구조된 군인에게 군용 방탄판 받기 | F18: PC | G18: 버텨! | H18: 군용 방탄판 등 중량 방어구를 이용해 강한 단발 공격을 정면에서 받아내고 밀려남을 크게 줄임. | J18: 액티브 | K18: 차한해 | M18: 조건부 입력 | N18: 강공격 전조 중 방어 입력 | O18: 없음 | P18: =IFERROR(VALUE(TRIM(MID(Q18,FIND("×",Q18)+1,FIND("%",Q18)-FIND("×",Q18)-1)))/100,0) -> 0 | Q18: 피해 없음 | T18: 개별 | U18: 4 | V18: 0.2 | W18: 받는 피해 | X18: -35 | Y18: % | Z18: 1 | AA18: 강공격 종료 | AB18: SKL-STS-002 | AC18: 방어구 내구도 소모
A19: SKL-PC-018 | B19: 179 | C19: 차한해 | D19: 갈채 보스 | E19: 179번 | 미담 전문의 보호막 부여를 차단하고 중계 카메라 끄기 | F19: PC | G19: 안 찍히면 돼 | H19: 카메라 시야와 스포트라이트를 피해 사각지대에서 이동하면 갈채 계열 적의 추적·강화 조건을 끊음. | J19: 패시브 | K19: 차한해 | M19: 위치 조건 | N19: 카메라 시야 밖 | O19: 없음 | P19: =IFERROR(VALUE(TRIM(MID(Q19,FIND("×",Q19)+1,FIND("%",Q19)-FIND("×",Q19)-1)))/100,0) -> 0 | Q19: 피해 없음 | T19: 없음 | U19: 0 | V19: 0 | W19: 갈채 획득 | X19: 0 | Y19: 고정 | Z19: 0 | AA19: 카메라 시야 진입 | AB19: SKL-STS-016 | AC19: 카메라 없는 행동이 보스 기믹을 약화
A20: SKL-PC-019 | B20: 181 | C20: 차한해 | D20: 갈채 보스 | E20: 181번 | 아무도 보지 않는 곳에서 시민을 구하고 최초의 영웅 제압하기 | F20: PC | G20: 아무도 안 봐도 | H20: 카메라가 없는 위치에서 실제 시민을 구조해 갈채와 무관한 선행을 증명하고 보스 보호막을 제거하는 사건형 행동. | J20: 연출용+액티브 | K20: 차한해 | M20: 사건 조건 | N20: 실제 시민 판별·카메라 비노출 | O20: 없음 | P20: =IFERROR(VALUE(TRIM(MID(Q20,FIND("×",Q20)+1,FIND("%",Q20)-FIND("×",Q20)-1)))/100,0) -> 0 | Q20: 피해 없음 | T20: 없음 | U20: 0 | V20: 1 | W20: 보호막 | X20: 0 | Y20: 고정 | Z20: 0 | AA20: 구조 완료 | AB20: SKL-STS-016 | AC20: 서사와 보스 공략을 직접 연결
A21: SKL-PC-020 | B21: 186 | C21: 지원 가능 NPC | D21: 회사 구조 | E21: 186번 | 구조용 로프 발사기로 한도윤과 회사 직원 대피시키기 | F21: PC | G21: 도움 요청 | H21: 현재 콘텐츠에 사전 정의된 지원 행동이 있고 해당 NPC의 인연·위치 조건을 만족할 때만 지원을 호출하는 제한형 스킬. | J21: 액티브 | K21: 지원 가능 NPC | M21: 상황 조건 | N21: 지원 가능 NPC·인연·콘텐츠 플래그 충족 | O21: 없음 | P21: =IFERROR(VALUE(TRIM(MID(Q21,FIND("×",Q21)+1,FIND("%",Q21)-FIND("×",Q21)-1)))/100,0) -> 0 | Q21: 피해 없음 | T21: 상황당 1회 | U21: 0 | V21: 0.3 | W21: 없음 | X21: 0 | Y21: 없음 | Z21: 0 | AA21: 지원 행동 완료 | AB21: SKL-NPC-001 / SKL-NPC-002 | AC21: 범용 동료 AI가 아니라 콘텐츠별 고정 지원 행동 호출
A22: SKL-PC-021 | B22: 186 | C22: 차한해 | D22: 회사 구조 | E22: 186번 | 구조용 로프 발사기로 한도윤과 회사 직원 대피시키기 | F22: PC | G22: 길 하나 만들게! | H22: 구조용 로프 발사기 1회를 소비해 끊어진 계단·붕괴 통로에 임시 이동 경로를 생성함. | J22: 연출용+액티브 | K22: 차한해 | M22: 아이템 사용 | N22: 구조용 로프 발사기 1회 소모 | O22: 없음 | P22: =IFERROR(VALUE(TRIM(MID(Q22,FIND("×",Q22)+1,FIND("%",Q22)-FIND("×",Q22)-1)))/100,0) -> 0 | Q22: 피해 없음 | T22: 아이템 횟수 | U22: 0 | V22: 0.8 | W22: 이동 경로 | X22: 1 | Y22: 개 | Z22: 0 | AA22: 경로 생성 완료 | AB22: 없음 | AC22: 186번·188번 총 2회 사용
A23: SKL-PC-022 | B23: 249 | C23: 차한해 | D23: 심층 탐사 | E23: 249번 | 변혜서가 변혜서임을 확정하고 선의 안정 장치 발동 견디기 | F23: PC | G23: 괜찮아, 아직. | H23: 선의 안정 장치가 큰 심리 충격으로 입력 흔들림이 발생할 때 1회 자동 발동해 자아마모 수치는 유지한 채 조작 흔들림만 완화함. | J23: 패시브+자동 | K23: 차한해 | M23: 사건 플래그 | N23: 선의 안정 장치 장착·친구 정체 확정 | O23: 없음 | P23: =IFERROR(VALUE(TRIM(MID(Q23,FIND("×",Q23)+1,FIND("%",Q23)-FIND("×",Q23)-1)))/100,0) -> 0 | Q23: 피해 없음 | T23: 1회 자동 | U23: 0 | V23: 0 | W23: 입력 흔들림 | X23: -100 | Y23: % | Z23: 10 | AA23: 10초 종료 | AB23: SKL-STS-013 | AC23: 196번에서 장치 획득·249번 첫 자동 발동
A24: SKL-PC-023 | B24: 215 | C24: 차한해 | D24: 폐교 은폐 | E24: 215번 | 고밀도 충격 흡수 장화로 엮이지 말자의 기습을 버티며 복도 통과하기 | F24: PC | G24: 쉿. | H24: 이동을 잠시 멈추고 소리 발생 행동을 제한해 청각 추적형 변이체의 추적 게이지를 끊음. | J24: 액티브 | K24: 차한해 | M24: 입력 유지 | N24: 1초간 이동·공격 입력 없음 | O24: 없음 | P24: =IFERROR(VALUE(TRIM(MID(Q24,FIND("×",Q24)+1,FIND("%",Q24)-FIND("×",Q24)-1)))/100,0) -> 0 | Q24: 피해 없음 | T24: 개별 | U24: 2.5 | V24: 1 | W24: 소음 발생량 | X24: -100 | Y24: % | Z24: 1.5 | AA24: 이동·공격 입력 | AB24: 없음 | AC24: 은폐 전용
A25: SKL-PC-024 | B25: 238 | C25: 차한해 | D25: 폐교 공명 | E25: 238번 | 보랏빛 사랑의 매로 기억 외피 공명 타격 시험하기 | F25: PC | G25: 껍데기부터 | H25: 사랑의 매로 보랏빛 공명 외피만 골라 때려 외피 방어를 먼저 제거하는 전용 공략 스킬. | J25: 액티브 | K25: 차한해 | M25: 약점 노출 | N25: 공명 외피 활성 | O25: 기본 공격력 비율 | P25: =IFERROR(VALUE(TRIM(MID(Q25,FIND("×",Q25)+1,FIND("%",Q25)-FIND("×",Q25)-1)))/100,0) -> 1.3 | Q25: 기본 공격력 × 130% | T25: 개별 | U25: 2.8 | V25: 0.45 | W25: 외피 피해 | X25: 50 | Y25: % | Z25: 0 | AA25: 외피 파괴 | AB25: 없음 | AC25: 본체 피해보다 외피 제거에 특화
A26: SKL-PC-025 | B26: 244 | C26: 차한해 | D26: 폐교 투척 | E26: 244번 | 농구공의 투척 궤적 익히기 | F26: PC | G26: 한 번 튕겨! | H26: 보랏빛 농구공을 벽·골대에 반사시켜 직선으로 닿지 않는 기억 핵을 타격함. | J26: 액티브 | K26: 차한해 | M26: 입력 | N26: 반사 경로 조준 완료 | O26: 기본 공격력 비율 | P26: =IFERROR(VALUE(TRIM(MID(Q26,FIND("×",Q26)+1,FIND("%",Q26)-FIND("×",Q26)-1)))/100,0) -> 1.1 | Q26: 기본 공격력 × 110% | T26: 개별 | U26: 2 | V26: 0.55 | W26: 반사 횟수 | X26: 1 | Y26: 회 | Z26: 0 | AA26: 공 회수·화면 밖 이탈 | AB26: 없음 | AC26: 반사 성공 시 기억 핵 판정 가능
... A31: SKL-PC-030 | B31: 287 | C31: 차한해·동료 | D31: 최종 보스 | E31: 287번 | 차한해에게 연결된 무한대 부담 장치 파괴하기 | F31: PC | G31: 이번엔 같이. | H31: 차한해 혼자 무한대 부담을 받아내지 않고 전장에 분산된 연결 장치를 동료와 동시 작동시키는 협력형 사건 스킬. | J31: 연출용+액티브 | K31: 차한해·동료 | M31: 동시 입력 | N31: 부담 연결 장치 4개 활성 | O31: 없음 | P31: =IFERROR(VALUE(TRIM(MID(Q31,FIND("×",Q31)+1,FIND("%",Q31)-FIND("×",Q31)-1)))/100,0) -> 0 | Q31: 피해 없음 | T31: 페이즈 1회 | U31: 0 | V31: 0.6 | W31: 부담 연결 | X31: -4 | Y31: 개 | Z31: 0 | AA31: 장치 4개 동시 파괴 | AB31: 없음 | AC31: 최종부 주제인 책임 분담을 전투 기믹으로 표현
A32: SKL-PC-031 | B32: 296 | C32: 도시 전체 시민 | D32: 희생 엔딩 | E32: 296번 | 모두가 각자 가까운 균열로 함께 들어가기 | F32: PC | G32: 눈물 | H32: 차한해가 혼자 균열로 들어가는 희생 경로에서 진입 직전 UI로 반드시 사용하는 마지막 스킬. 눈물 한 방울과 함께 기억·감정이 도시 전체로 공명됨. | J32: 연출용+액티브 | K32: 도시 전체 시민 | L32: 죄책감 | M32: 1회 강제 발동 | N32: 단독 희생 엔딩 확정·균열 진입 직전 | O32: 없음 | P32: =IFERROR(VALUE(TRIM(MID(Q32,FIND("×",Q32)+1,FIND("%",Q32)-FIND("×",Q32)-1)))/100,0) -> 0 | Q32: 피해 없음 | T32: 엔딩 1회 | U32: 0 | V32: 2 | W32: 없음 | X32: 0 | Y32: 없음 | Z32: 0 | AA32: 눈물 연출 종료·균열 진입 | AB32: SKL-STS-015 | AC32: 공동 진입 엔딩에서는 UI 자체가 나타나지 않음
A33: SKL-PC-032 | B33: 112 | C33: 차한해 | D33: 고유 특성 | E33: 112번 | 다른 측정기로 재측정하고 같은 오류 확인하기 | F33: PC | G33: 무한 선의 | H33: 차한해의 선의 감소 연산을 0으로 고정하고 측정 상한을 반복 초과시키는 태생적 패시브. 전투 행위 자체는 선의 감소 조건이 아님. | J33: 패시브 | K33: 차한해 | M33: 상시 | N33: 차한해 활성 상태 | O33: 없음 | P33: =IFERROR(VALUE(TRIM(MID(Q33,FIND("×",Q33)+1,FIND("%",Q33)-FIND("×",Q33)-1)))/100,0) -> 0 | Q33: 피해 없음 | T33: 없음 | U33: 0 | V33: 0 | W33: 선의 감소량 | X33: 0 | Y33: 고정값 | Z33: 0 | AA33: 해제 불가 | AB33: 없음 | AC33: 112번 재측정에서 시스템적으로 확정
A34: SKL-NPC-001 | B34: 186 | C34: 한도윤 | D34: 회사 구조 | E34: 186번 | 구조용 로프 발사기로 한도윤과 회사 직원 대피시키기 | F34: NPC | G34: 찾았어, 여기야! | H34: 한도윤 인연 100%에서 [도움 요청]로 호출되는 지원 행동. 마지막 직원의 위치를 무전과 표식으로 즉시 알려 줌. | J34: 지원+이벤트 | K34: 한도윤 | M34: 연계 호출 | N34: SKL-PC-020 사용·한도윤 인연 100% | O34: 없음 | P34: =IFERROR(VALUE(TRIM(MID(Q34,FIND("×",Q34)+1,FIND("%",Q34)-FIND("×",Q34)-1)))/100,0) -> 0 | Q34: 피해 없음 | T34: 상황당 1회 | U34: 0 | V34: 0.5 | W34: 탐색 후보 | X34: -1 | Y34: 구역 | Z34: 0 | AA34: 위치 표식 확인 | AB34: 없음 | AC34: 범용 AI 이동이 아니라 정보 지원
A35: SKL-NPC-002 | B35: 287 | C35: 나대진 | D35: 최종 보스 | E35: 287번 | 차한해에게 연결된 무한대 부담 장치 파괴하기 | F35: NPC | G35: 여기서 받쳐줄게 | H35: 나대진 인연 100%에서 [도움 요청]로 호출되는 원격 지원. 치명 피해 1회를 막고 가장 가까운 부담 장치 1개를 안정화함. | J35: 지원+이벤트 | K35: 나대진 | M35: 연계 호출 | N35: SKL-PC-020 사용·나대진 인연 100% | O35: 없음 | P35: =IFERROR(VALUE(TRIM(MID(Q35,FIND("×",Q35)+1,FIND("%",Q35)-FIND("×",Q35)-1)))/100,0) -> 0 | Q35: 피해 없음 | T35: 전투당 1회 | U35: 0 | V35: 0.4 | W35: 치명 피해 | X35: -100 | Y35: % | Z35: 0 | AA35: 지원 1회 소모 | AB35: 없음 | AC35: 270번에서 지원 조건 해금
A36: SKL-STS-001 | B36: 119 | C36: 피격 대상 | D36: 공용 상태 | E36: 최초 호출 | 119번 | F36: 상태/시스템 | G36: 경직 | H36: 일정 시간 대상의 이동·공격 입력 또는 AI 행동을 중단시키는 공용 상태. | J36: 상태이상 | K36: 피격 대상 | L36: 행동 불가 | M36: 연계 호출 | N36: 경직을 부여하는 스킬 적중 | O36: 없음 | P36: =IFERROR(VALUE(TRIM(MID(Q36,FIND("×",Q36)+1,FIND("%",Q36)-FIND("×",Q36)-1)))/100,0) -> 0 | Q36: 피해 없음 | T36: 없음 | U36: 0 | V36: 0 | W36: 행동 가능 여부 | X36: -1 | Y36: 상태 | Z36: 1 | AA36: 지속 종료 | AB36: 없음 | AC36: 호출 스킬이 지속 시간을 덮어씀
A37: SKL-STS-002 | B37: 130 | C37: 피격 대상 | D37: 공용 상태 | E37: 최초 호출 | 130번 | F37: 상태/시스템 | G37: 밀려남 | H37: 대상을 공격 방향 반대로 강제 이동시키는 공용 위치 제어 상태. | J37: 상태이상 | K37: 피격 대상 | L37: 강제 이동 | M37: 연계 호출 | N37: 밀치기·돌진·충격파 적중 | O37: 없음 | P37: =IFERROR(VALUE(TRIM(MID(Q37,FIND("×",Q37)+1,FIND("%",Q37)-FIND("×",Q37)-1)))/100,0) -> 0 | Q37: 피해 없음 | T37: 없음 | U37: 0 | V37: 0 | W37: 위치 이동 | X37: 1.5 | Y37: 칸 | Z37: 0 | AA37: 이동 완료 | AB37: 없음 | AC37: 보스·고정형 개체는 거리 감소
A38: SKL-STS-003 | B38: 160 | C38: 피격 대상 | D38: 공용 상태 | E38: 최초 호출 | 160번 | F38: 상태/시스템 | G38: 이동 둔화 | H38: 대상의 이동 속도를 일정 시간 낮추는 공용 상태. | J38: 상태이상 | K38: 피격 대상 | L38: 이동 속도 감소 | M38: 연계 호출 | N38: 이동 방해 계열 스킬 적중 | O38: 없음 | P38: =IFERROR(VALUE(TRIM(MID(Q38,FIND("×",Q38)+1,FIND("%",Q38)-FIND("×",Q38)-1)))/100,0) -> 0 | Q38: 피해 없음 | T38: 없음 | U38: 0 | V38: 0 | W38: 이동 속도 | X38: -40 | Y38: % | Z38: 3 | AA38: 지속 종료 | AB38: 없음 | AC38: 중첩 시 높은 값 우선
A39: SKL-STS-004 | B39: 103 | C39: 시전자·아군 | D39: 공용 상태 | E39: 최초 호출 | 103번 | F39: 상태/시스템 | G39: 공격 강화 | H39: 몬스터 또는 무리의 공격력을 일정 시간 높이는 공용 강화 상태. | J39: 버프 | K39: 시전자·아군 | M39: 연계 호출 | N39: 강화·가속·구호 계열 스킬 성공 | O39: 없음 | P39: =IFERROR(VALUE(TRIM(MID(Q39,FIND("×",Q39)+1,FIND("%",Q39)-FIND("×",Q39)-1)))/100,0) -> 0 | Q39: 피해 없음 | T39: 없음 | U39: 0 | V39: 0 | W39: 공격력 | X39: 20 | Y39: % | Z39: 6 | AA39: 지속 종료 | AB39: 없음 | AC39: 선도체·갈채 계열 공용
A40: SKL-STS-005 | B40: 179 | C40: 시전자·아군 | D40: 공용 상태 | E40: 최초 호출 | 179번 | F40: 상태/시스템 | G40: 보호막 | H40: 일정량의 피해를 본체보다 먼저 흡수하는 공용 방어 상태. | J40: 버프 | K40: 시전자·아군 | M40: 연계 호출 | N40: 보호막·외피 계열 스킬 성공 | O40: 없음 | P40: =IFERROR(VALUE(TRIM(MID(Q40,FIND("×",Q40)+1,FIND("%",Q40)-FIND("×",Q40)-1)))/100,0) -> 0 | Q40: 피해 없음 | T40: 없음 | U40: 0 | V40: 0 | W40: 보호막 | X40: 20 | Y40: % | Z40: 6 | AA40: 보호막 소진·지속 종료 | AB40: 없음 | AC40: 최대 HP 비율 기준
A41: SKL-STS-006 | B41: 222 | C41: 차한해 | D41: 공용 상태 | E41: 최초 호출 | 222번 | F41: 상태/시스템 | G41: 방향 혼란 | H41: 플레이어의 이동·전조 방향 정보를 짧게 뒤틀어 판단을 방해하는 상태. | J41: 디버프 | K41: 차한해 | L41: 방향 정보 왜곡 | M41: 연계 호출 | N41: 환각·혼란 계열 스킬 적중 | O41: 없음 | P41: =IFERROR(VALUE(TRIM(MID(Q41,FIND("×",Q41)+1,FIND("%",Q41)-FIND("×",Q41)-1)))/100,0) -> 0 | Q41: 피해 없음 | T41: 없음 | U41: 0 | V41: 0 | W41: 방향 판독 | X41: -1 | Y41: 단계 | Z41: 2.5 | AA41: 지속 종료 | AB41: 없음 | AC41: 접근성 설정에서 시각 왜곡 완화 가능
A42: SKL-STS-007 | B42: 103 | C42: 대상·위치 | D42: 공용 상태 | E42: 최초 호출 | 103번 | F42: 상태/시스템 | G42: 표적 지정 | H42: AI가 특정 대상 또는 위치를 우선 목표로 삼도록 바꾸는 공용 상태. | J42: 상태이상 | K42: 대상·위치 | L42: 우선 표적 변경 | M42: 연계 호출 | N42: 지정·호명·유인 계열 스킬 성공 | O42: 없음 | P42: =IFERROR(VALUE(TRIM(MID(Q42,FIND("×",Q42)+1,FIND("%",Q42)-FIND("×",Q42)-1)))/100,0) -> 0 | Q42: 피해 없음 | T42: 없음 | U42: 0 | V42: 0 | W42: AI 우선순위 | X42: 1 | Y42: 단계 | Z42: 4 | AA42: 대상 이탈·지속 종료 | AB42: 없음 | AC42: PC 유인과 몬스터 호명 모두 사용
A43: SKL-STS-008 | B43: 275 | C43: 연결 대상 | D43: 공용 상태 | E43: 최초 호출 | 275번 | F43: 상태/시스템 | G43: 피해 전가 | H43: 받을 피해 또는 상태이상을 연결된 다른 대상에게 넘기는 상태. | J43: 상태이상 | K43: 연결 대상 | L43: 피해 이전 | M43: 연계 호출 | N43: 전가 연결 활성 | O43: 없음 | P43: =IFERROR(VALUE(TRIM(MID(Q43,FIND("×",Q43)+1,FIND("%",Q43)-FIND("×",Q43)-1)))/100,0) -> 0 | Q43: 피해 없음 | T43: 없음 | U43: 0 | V43: 0 | W43: 피해 이전 | X43: 70 | Y43: % | Z43: 5 | AA43: 연결 해제·대상 소멸 | AB43: 없음 | AC43: 시민 환영 연결은 직접 피해 판정 없음
A44: SKL-STS-009 | B44: 276 | C44: 피격 대상 | D44: 공용 상태 | E44: 최초 호출 | 276번 | F44: 상태/시스템 | G44: 속박 | H44: 이동 또는 특정 행동 입력을 잠시 제한하는 공용 제어 상태. | J44: 상태이상 | K44: 피격 대상 | L44: 이동·행동 제한 | M44: 연계 호출 | N44: 속박·행동 봉쇄 적중 | O44: 없음 | P44: =IFERROR(VALUE(TRIM(MID(Q44,FIND("×",Q44)+1,FIND("%",Q44)-FIND("×",Q44)-1)))/100,0) -> 0 | Q44: 피해 없음 | T44: 없음 | U44: 0 | V44: 0 | W44: 이동 속도 | X44: -100 | Y44: % | Z44: 1.5 | AA44: 지속 종료·해제 입력 성공 | AB44: 없음 | AC44: 장비 저항으로 지속시간 감소
...

Sheet 몬스터
A1: 검증 항목 | B1: 값 | D1: 값 | F1: 작성 기준
A2: 전체 콘텐츠 수 | B2: 306 | D2: 306 | F2: [최신 몬스터 작성 기준] 1) 초기 변이체만 전신을 보라색 계열의 단순 단세포·세포막·점액 실루엣으로 구성함. 2) 일반·강화 변이체와 무리 선도체는 곤충·동물 단계 진화 컨셉을 폐기하고 각 인간의 반복된 이기심·범죄·방관·자기합리화가 형태와 행동으로 남도록 설계함. 3) 사람 1명 → 나쁜 부분의 총합 1개 → 외부 몬스터 1개. 인간 본체는 균열 내부에 껍데기로 남고 몬스터는 인간 본인 자체가 아님. 4) 강화·선도체의 강함은 죄의 크기가 아니라 부정적 행동 패턴의 안정성·복합성에서 발생함. 5) 비보스급은 결정적 사건을 필수로 두지 않으며 장기간 반복된 삶의 방식으로 선의 0에 도달할 수 있음. 6) 비보스급 서사는 선택형 '잔류 기억'으로 공개함. 초기·일반 1단계, 강화·무리 선도체 2~3단계 권장. 7) 잔류 기억은 일반인에게 보이지 않는 옅은 보랏빛으로 차한해에게만 보이며, 차한해는 무기와 마찬가지로 균열 흔적과 공명해 기억을 확인함. 8) 보라색은 초기 변이체에서 주색, 이후에는 균열핵·균열 자국·잔류 에너지에 제한적으로 사용함.
A3: 몬스터 배치 콘텐츠 수 | B3: =COUNTIF(B7:B312,"<>") -> 306 | D3: =COUNTIF(D7:D312,"<>") -> 43
A4: 몬스터 미배치 콘텐츠 수 | B4: =B2-B3 -> 0 | D4: =D2-D3 -> 263
A5: 콘텐츠 누락 개수 | B5: =B2-COUNT(#REF!) -> 306 | D5: =D2-COUNT(#REF!) -> 306
A6: 몬스터 이름 | B6: 콘텐츠 제시 순서 | D6: 몬스터 이름 | E6: 몬스터 이미지 | F6: 몬스터 타입 | G6: 몬스터 속성 | H6: 생명력 | I6: 공격력 | J6: 공격력 합산 STATUS | K6: 공격력 보정 | L6: 최종 공격력 | M6: 방어력 | N6: 방어력 합산 STATUS | O6: 방어력 보정 | P6: 최종 방어력 | Q6: 스킬1 | R6: 발동률1 | S6: 스킬2 | T6: 발동률2 | U6: 스킬3 | V6: 발동률3 | W6: 스킬4 | X6: 발동률4 | Y6: 비고
B7: 1 | L7: =IF(D7="","",I7+K7) | P7: =IF(D7="","",M7+O7)
B8: 2
B9: 3
B10: 4
B11: 5
B12: 6
B13: 7
B14: 8
B15: 9
B16: 10
B17: 11
B18: 12
B19: 13
... B70: 64
B71: 65 | L71: =IF(D71="","",I71+K71) | P71: =IF(D71="","",M71+O71)
B72: 66
B73: 67
B74: 68
B75: 69
B76: 70
B77: 71
B78: 72
B79: 73
A80: 나부터 | B80: 74 | C80: 조건부 선공 | D80: 나부터 | F80: 초기 변이체 | G80: 침식 | H80: 30 | I80: 4 | J80: 근접 본능 | K80: 1 | L80: 5 | M80: 0 | N80: 불완전한 외피 | O80: 0 | P80: 0 | Q80: 앞질러 | R80: 70 | S80: 밀어내기 | T80: 30 | V80: 0 | X80: 0 | Y80: 인간 시절 늘 자기 편의를 먼저 챙김. 엘리베이터 문 닫기·넘어진 사람 외면 등 사소한 이기심을 반복하며 자연스럽게 선의 0에 도달. 초기 대량 유입기에 형성된 단순 보라 단세포형. 잔류 기억 1개.
B81: 75
B82: 76
B83: 77
A84: 나 먼저 | B84: 78 | C84: 조건부 선공 | D84: 나 먼저 | F84: 초기 변이체 | G84: 안정 | H84: 60 | I84: 7 | J84: 기습 반응 | K84: 1 | L84: 8 | M84: 2 | N84: 웅크린 자세 | O84: 1 | P84: 3 | Q84: 끼어들기 | R84: 55 | S84: 먼저 간다 | T84: 45 | V84: 0 | X84: 0 | Y84: 줄과 순서를 반복해서 무시하고 늘 자신이 먼저 들어가던 사람의 나쁜 부분. 특별한 마지막 사건보다 '나 먼저'가 삶의 습관이 되어 선의 0에 도달. 초기 단세포형. 잔류 기억 1개.
B85: 79
B86: 80
B87: 81
B88: 82
A89: 1등 나와 | B89: 83 | C89: 선공 | D89: 1등 나와 | F89: 초기 변이체 | G89: 침식 | H89: 45 | I89: 5 | J89: 체중 충격 | K89: 1 | L89: 6 | M89: 1 | N89: 두꺼운 등 외피 | O89: 1 | P89: 2 | Q89: 끌어내려 | R89: 55 | S89: 순위 뒤집기 | T89: 45 | V89: 0 | X89: 0 | Y89: 전교 2등으로 1등을 끌어내리기 위해 노트 훼손·거짓 정보·방해를 반복. 경쟁 상대의 실패를 자신의 기회로만 보며 선의 0에 도달. 잔류 기억 1개.
A90: 놀잇감 | B90: 84 | C90: 비선공 | D90: 놀잇감 | F90: 초기 변이체 | G90: 공명 | H90: 35 | I90: 4 | J90: 공포 음파 | K90: 1 | L90: 5 | M90: 0 | N90: 얇은 외피 | O90: 0 | P90: 0 | Q90: 웃음거리 | R90: 60 | S90: 더 보여줘 | T90: 40 | V90: 0 | X90: 0 | Y90: 온라인에서 타인의 외모·실수·고통을 조롱거리로 소비하고 피해자의 호소까지 유흥거리로 퍼뜨림. 반복된 조롱으로 선의가 소진. 잔류 기억 1개.
...

Sheet 시뮬레이터
A1: 전투 대상 | B1: 나부터 | F1: 콘텐츠 번호 | G1: =몬스터_콘텐츠번호_가져오기 -> 74 | I1: PC 최대 HP | J1: 200 | L1: PC 공격 간격 | M1: 0.3 | O1: MON 공격 간격 | P1: 0.3 | R1: 금색 테두리 = 문서 미정의 · 직접 조정 입력값 | T1: 백중세
A3: MONSTER · 적 개체 | G3: BATTLE CORE | O3: PLAYER · 차한해 / INVENTORY
G4: VS | O4: =INDEX('PC DATA(대차대조표)'!$C$2:$C$307,MATCH(시뮬레이터!$G$1,'PC DATA(대차대조표)'!$A$2:$A$307,0)) -> 0
T5: 차한해
G6: 차한해 → 몬스터 | K6: 몬스터 → 차한해
G7: 공격 속성 | I7: =시뮬레이터!$Q$39 -> 공명 | K7: 공격 속성 | M7: =시뮬레이터!$C$16 -> 침식
G8: 방어 속성 | I8: =시뮬레이터!$C$16 -> 침식 | K8: 방어 속성 | M8: =시뮬레이터!$Q$43 -> 공명
G9: 상성 K | I9: =IF(OR(시뮬레이터!$I$7="",시뮬레이터!$I$8=""),1,INDEX('속성 대차대조표'!$B$11:$E$14,MATCH(시뮬레이터!$I$7,'속성 대차대조표'!$A$11:$A$14,0),MATCH(시뮬레이터!$I$8,'속성 대차대조표'!$B$10:$E$10,0))) -> 1.2 | J9: 0 | K9: 상성 K | M9: =IF(OR(시뮬레이터!$M$7="",시뮬레이터!$M$8=""),1,INDEX('속성 대차대조표'!$B$11:$E$14,MATCH(시뮬레이터!$M$7,'속성 대차대조표'!$A$11:$A$14,0),MATCH(시뮬레이터!$M$8,'속성 대차대조표'!$B$10:$E$10,0))) -> 0.8
G10: 공격력 | I10: =시뮬레이터!$Q$38 -> 93 | K10: 공격력 | M10: =시뮬레이터!$C$23 -> 5 | N10: 0
G11: 상대 방어력 | I11: =시뮬레이터!$C$27 -> 30 | K11: 상대 방어력 | M11: =시뮬레이터!$Q$42 -> 74
A12: 이름 | C12: =B1 -> 나부터 | G12: 1회 기본 공격 피해 | I12: =MAX(1,ROUND((시뮬레이터!$I$10-시뮬레이터!$I$11)*시뮬레이터!$I$9,0)) -> 76 | K12: 1회 기본 공격 피해 | M12: =MAX(1,ROUND((시뮬레이터!$M$10-시뮬레이터!$M$11)*시뮬레이터!$M$9,0)) -> 1 | O12: 이름 | Q12: =INDEX('PC DATA(대차대조표)'!$B$2:$B$307,MATCH(시뮬레이터!$G$1,'PC DATA(대차대조표)'!$A$2:$A$307,0)) -> 차한해
A13: 콘텐츠 | C13: =G1 -> 74 | G13: 몬스터 처치 필요 공격 | I13: =ROUNDUP(시뮬레이터!$C$19/시뮬레이터!$I$12,0) -> 1 | K13: PC 사망 필요 공격 | M13: =IF(시뮬레이터!$J$1="","",ROUNDUP(시뮬레이터!$J$1/시뮬레이터!$M$12,0)) -> 200 | O13: 콘텐츠명 | Q13: =INDEX('PC DATA(대차대조표)'!$D$2:$D$307,MATCH(시뮬레이터!$G$1,'PC DATA(대차대조표)'!$A$2:$A$307,0)) -> 아파트 계단으로 이동하며 ‘나부터’을 피해 숨기
A14: 타입 | C14: =몬스터_타입_가져오기 -> 초기 변이체 | G14: 공격 간격(초) | I14: =시뮬레이터!$M$1 -> 0.3 | J14: 0 | K14: 공격 간격(초) | M14: =시뮬레이터!$P$1 -> 0.3 | N14: 0 | O14: 전투 상태 | Q14: =INDEX('PC DATA(대차대조표)'!$E$2:$E$307,MATCH(시뮬레이터!$G$1,'PC DATA(대차대조표)'!$A$2:$A$307,0)) -> 전투 시스템 미개방
A15: 교전 | C15: =몬스터_선공_가져오기 -> 조건부 선공 | G15: TTK(초) | I15: =(시뮬레이터!$I$13-1)*시뮬레이터!$I$14 -> 0 | J15: 0 | K15: TTK(초) | M15: =IF(시뮬레이터!$M$13="","",(시뮬레이터!$M$13-1)*시뮬레이터!$M$14) -> 59.7 | N15: 0 | O15: 현재 스킬 | Q15: =IF(INDEX('PC DATA(대차대조표)'!$J$2:$J$307,MATCH(시뮬레이터!$G$1,'PC DATA(대차대조표)'!$A$2:$A$307,0))="","-",INDEX('PC DATA(대차대조표)'!$J$2:$J$307,MATCH(시뮬레이터!$G$1,'PC DATA(대차대조표)'!$A$2:$A$307,0))) -> -
A16: 속성 | C16: =몬스터_속성_가져오기 -> 침식 | G16: 상성 판정 | I16: =IF(시뮬레이터!$I$9>1,"우세",IF(시뮬레이터!$I$9<1,"열세","중립")) -> 우세 | J16: 0 | K16: 상성 판정 | M16: =IF(시뮬레이터!$M$9>1,"우세",IF(시뮬레이터!$M$9<1,"열세","중립")) -> 열세 | N16: 0
J17: 1 | N17: 1 | O17: CURRENT LOADOUT · 셀 내용 삭제 = 미착용
A18: COMBAT STATUS | G18: BATTLE RESULT | O18: 무기 | P18: ATK +0 / DEF +0 | S18: 방어구 | T18: ATK +0 / DEF +0
A19: 생명력 | C19: =INDEX(몬스터!$H$7:$H$312,MATCH(시뮬레이터!$B$1,몬스터!$D$7:$D$312,0)) -> 30 | G19: =IF(시뮬레이터!$J$1="","PC 최대 HP 입력 필요",IF(시뮬레이터!$I$15<시뮬레이터!$M$15,"차한해 승리",IF(시뮬레이터!$I$15>시뮬레이터!$M$15,"몬스터 승리","동시 처치"))) -> 차한해 승리 | O19: =IF(시뮬레이터!$Q19="","",INDEX(아이템!$C$2:$C$43,MATCH(시뮬레이터!$Q19,아이템!$A$2:$A$43,0))) -> 0 | Q19: 보랏빛 철봉 | S19: =IF(시뮬레이터!$U19="","",INDEX(아이템!$C$2:$C$43,MATCH(시뮬레이터!$U19,아이템!$A$2:$A$43,0))) -> 0 | U19: 기본 보호 조끼
