Workbook
Name 몬스터_가져오기: INDEX(몬스터_이미지,MATCH(시뮬레이터!$B$2,몬스터_이름,0))
Name 몬스터_스킬1_이름: 몬스터!$O$7:$O$290
Name 몬스터_이름: 몬스터!$C$7:$C$290
Name 몬스터_이미지: 몬스터!$D$7:$D$290
Name 캐릭터_가져오기: INDEX(캐릭터_이미지,MATCH(시뮬레이터!$F$2,캐릭터_이름,0))
Name 캐릭터_이름: 'PC DATA(대차대조표)'!$C$3:$C$308
Name 캐릭터_이미지: 'PC DATA(대차대조표)'!$D$3:$D$308
Name 스킬_콘텐츠_번호: '스킬 DATA'!$C$2:$C$212

Sheet 밸런스 문서
S1: 예상 플레이 시간
A2: 챕터 | B2: 콘텐츠 진행 순서 | C2: 플레이 난이도 | D2: 플레이 흥미도 | E2: 플레이 목표 | F2: 플레이 난관 | G2: 공략 방법 | H2: 체감 난이도 | I2: 수행 과제 수 | J2: 목표 달성 조건 | K2: 실패 결과 | L2: 예상 소요 시간 | M2: 난이도 조절 요소 | N2: 누적 플레이 시간 | O2: 스테이지 | P2: 콘텐츠 진행 포인트 (획득량) | Q2: 콘텐츠 진행 포인트 누적 | R2: 핵심 전투 기믹 | S2: 라이트 유저 (예상 시간 기준) | T2: 미들 유저 | U2: 헤비 유저 | V2: 자아마모도 변화(%) | W2: 인연 변화(%) | X2: 진행 관문 조건 | Y2: 선택·추가 콘텐츠 해금
A3: 1 | 평범한 하루 | B3: 1 | C3: 1 | D3: 8 | E3: 차한해의 과거 오프닝 감상 | F3: 입양 이후 가족 안에서 희생을 요구받아 온 과거를 보여주는 연출이 길게 이어져 플레이어가 핵심 정보를 놓칠 수 있음 | G3: 핵심 장면의 시선 유도와 짧은 자막을 통해 관계와 감정 변화를 이해함 | H3: 1/10 – 연출 길이와 정보량이 난이도를 결정함 | I3: 1 | J3: 오프닝 재생이 끝나면 자동 완료 | K3: - | L3: 45초 | M3: 스킵·다시 보기 기능 제공 | N3: 0.00052083333 | O3: 1-A | 집·튜토리얼 | P3: 3 | Q3: =P3 -> 3 | S3: 45초 | T3: 45초 | U3: 45초
A4: 1 | 평범한 하루 | B4: 2 | C4: 1 | D4: 3 | E4: 빨래 개기 | F4: 조사 가능한 가구가 많아 조작 가능한 대상을 바로 알아보기 어려움 | G4: 주인공 주변의 상호작용 표시를 확인하고 조사 키를 누름 | H4: 1/10 – 상호작용 표시의 가시성과 조사 범위가 난이도를 결정함 | I4: 1 | J4: 소파 옆 주인공에서 조사 입력 1회 완료 | K4: - | L4: 10초 | M4: 첫 상호작용 대상에 반짝임 표시 | N4: 0.00063657407 | O4: 1-A | 집·튜토리얼 | P4: 2 | Q4: =Q3+P4 -> 5 | S4: 10초 | T4: 10초 | U4: 10초
A5: 1 | 평범한 하루 | B5: 3 | C5: 1 | D5: 5 | E5: 동생에게 심부름 지시 받기 | F5: 대화 속에 다음 목적지와 필요한 물품 정보가 섞여 있음 | G5: 강조되는 핵심 단어와 NPC의 요구를 확인하며 대화를 끝까지 진행함 | H5: 1/10 – 대사 길이·핵심 정보의 명확성·선택지 수가 난이도를 결정함 | I5: 1 | J5: 신상 과자·헤어롤·팝콘 심부름에 관한 대화를 마지막 문장까지 진행 | K5: - | L5: 20초 | M5: 대화 종료 후 핵심 내용을 화면 한쪽에 요약 표시 | N5: 0.00086805556 | O5: 1-A | 집·튜토리얼 | P5: 3 | Q5: 8 | S5: 20초 | T5: 20초 | U5: 20초 | W5: [차우선] 기준 45%
A6: 1 | 평범한 하루 | B6: 4 | C6: 1 | D6: 3 | E6: 이동 조작 안내 확인 | F6: 여러 조작을 한 번에 제시하면 입력 방법을 혼동할 수 있음 | G6: 화면에 표시되는 키를 순서대로 입력하고 각 동작의 결과를 확인함 | H6: 1/10 – 동시에 제시되는 조작 수와 입력 허용 시간이 난이도를 결정함 | I6: 4 | J6: 상하좌우 이동과 조사 키를 안내 순서대로 모두 수행 | K6: - | L6: 30초 | M6: 입력하지 않은 키 안내를 계속 유지 | N6: 0.0012152778 | O6: 1-A | 집·튜토리얼 | P6: 3 | Q6: 11 | S6: 30초 | T6: 25초 | U6: 25초
A7: 1 | 평범한 하루 | B7: 5 | C7: 1 | D7: 3 | E7: 현관으로 이동하기 | F7: 갈림길과 주변 상호작용 오브젝트 때문에 목적지 방향을 놓칠 수 있음 | G7: 표지판·미니맵·NPC 이동 방향을 확인하며 거실에서 현관문까지 이동함 | H7: 1/10 – 맵 크기·갈림길 수·목적지 표식의 가시성이 난이도를 결정함 | I7: 1 | J7: 거실에서 현관문의 도착 트리거에 진입 | K7: - | L7: 15초 | M7: 일정 시간 정체 시 목적지 방향 화살표 표시 | N7: 0.0013888889 | O7: 1-A | 집·튜토리얼 | P7: 2 | Q7: 13 | S7: 15초 | T7: 15초 | U7: 15초
A8: 1 | 평범한 하루 | B8: 6 | C8: 1 | D8: 5 | E8: 집 밖으로 나가기 | F8: 조사 대상이 배경 오브젝트와 비슷해 상호작용 가능 여부를 놓칠 수 있음 | G8: 현관문 가까이 이동한 뒤 상호작용 아이콘이 나타날 때 조사함 | H8: 1/10 – 조사 대상의 크기·배경과의 대비·상호작용 범위가 난이도를 결정함 | I8: 1 | J8: 현관문 조사 완료 | K8: - | L8: 15초 | M8: 상호작용 가능 범위를 넓히고 아이콘 표시 | N8: 0.0015625 | O8: 1-A | 집·튜토리얼 | P8: 2 | Q8: 15 | S8: 15초 | T8: 15초 | U8: 15초 | X8: 이동·조사 튜토리얼 완료
A9: 1 | 평범한 하루 | B9: 7 | C9: 2 | D9: 5 | E9: 편의점으로 이동하기 | F9: 갈림길과 주변 상호작용 오브젝트 때문에 목적지 방향을 놓칠 수 있음 | G9: 표지판·미니맵·NPC 이동 방향을 확인하며 아파트에서 편의점까지 이동함 | H9: 2/10 – 맵 크기·갈림길 수·목적지 표식의 가시성이 난이도를 결정함 | I9: 1 | J9: 아파트에서 편의점의 도착 트리거에 진입 | K9: - | L9: 20초 | M9: 일정 시간 정체 시 목적지 방향 화살표 표시 | N9: 0.0017939815 | O9: 1-B | 편의점 | P9: 3 | Q9: 18 | S9: 20초 | T9: 20초 | U9: 20초
A10: 1 | 평범한 하루 | B10: 8 | C10: 2 | D10: 6 | E10: 신상 과자 진열대 찾기 | F10: 비슷한 오브젝트와 진열대가 많아 목표 대상을 한 번에 찾기 어려움 | G10: 구역별 표지와 상품 외형을 비교하며 편의점 안 신상 과자 진열대를 조사함 | H10: 2/10 – 후보 오브젝트 수·외형 유사도·탐색 범위가 난이도를 결정함 | I10: 4 | J10: 편의점 안 신상 과자 진열대 발견 및 조사 완료 | K10: - | L10: 30초 | M10: 30초 이상 미발견 시 목표 구역에 약한 반짝임 표시 | N10: 0.0021412037 | O10: 1-B | 편의점 | P10: 4 | Q10: 22 | S10: 30초 | T10: 25초 | U10: 25초
A11: 1 | 평범한 하루 | B11: 9 | C11: 1 | D11: 5 | E11: 품절 안내 조사하기 | F11: 조사 대상이 배경 오브젝트와 비슷해 상호작용 가능 여부를 놓칠 수 있음 | G11: 비어 있는 진열칸과 손글씨 품절 안내 가까이 이동한 뒤 상호작용 아이콘이 나타날 때 조사함 | H11: 1/10 – 조사 대상의 크기·배경과의 대비·상호작용 범위가 난이도를 결정함 | I11: 2 | J11: 비어 있는 진열칸과 손글씨 품절 안내 조사 완료 | K11: - | L11: 15초 | M11: 상호작용 가능 범위를 넓히고 아이콘 표시 | N11: 0.0023148148 | O11: 1-B | 편의점 | P11: 3 | Q11: 25 | S11: 15초 | T11: 15초 | U11: 15초
A12: 1 | 평범한 하루 | B12: 10 | C12: 1 | D12: 7 | E12: 알바생 NPC와 대화하고 이상 현상 뉴스 확인하기 | F12: 재입고 설명 중 편의점 TV의 짧은 정전·지반 흔들림 속보와 매장 조명 깜빡임이 겹쳐 필요한 정보와 이상 징후가 분산됨 | G12: 알바생의 재입고 설명을 확인한 뒤 TV 자막과 조명 변화를 관찰해 단순 사고로 보도되는 첫 이상 현상을 기억함 | H12: 1/10 – 대사와 배경 연출이 동시에 진행되는 정보량이 난이도를 결정함 | I12: 3 | J12: 재입고 시간·물류 트럭 정보와 이상 현상 뉴스 확인 | K12: - | L12: 30초 | M12: TV 자막을 잠시 고정하고 조명 변화 직전 효과음 제공 | N12: 0.002662037 | O12: 1-B | 편의점 | P12: 3 | Q12: 28 | S12: 30초 | T12: 25초 | U12: 25초
A13: 1 | 평범한 하루 | B13: 11 | C13: 2 | D13: 8 | E13: 골목에서 들리는 예쁜 고양이 울음소리 확인하기 | F13: 심부름 목적지가 따로 있어 작은 울음소리를 무시하고 지나칠 수 있음 | G13: 편의점 주변에서 반복되는 울음소리와 골목 그림자를 확인하되 조사하지 않고 진행할 수도 있음 | H13: 2/10 – 발견 여부와 선택에 따라 진행이 달라짐 | I13: 2 | J13: 울음소리가 들리는 골목 위치 확인 또는 선택적으로 지나침 | K13: - | L13: 50초 | M13: 자동 등록하지 않고 소리·행동·오브젝트로만 암시 | N13: 0.0032407407 | O13: 1-B | 편의점·고양이 선택 | P13: 3 | Q13: 31 | S13: 50초 | T13: 45초 | U13: 40초 | Y13: 서브 퀘스트 : 예쁜 고양이 인연 1단계 발견
A14: 1 | 평범한 하루 | B14: 12 | C14: 2 | D14: 8 | E14: 편의점에서 츄르 4개입 세트 구매하기 | F14: 구매 메뉴에는 심부름 물품 외에도 여러 상품이 있어 츄르를 직접 찾아야 함 | G14: 알바생 대화 후 ‘물건 구매하기’를 선택하고 반려동물 간식 칸에서 츄르 4개입을 구매함 | H14: 2/10 – 발견 여부와 선택에 따라 진행이 달라짐 | I14: 2 | J14: 츄르 4개입 세트 구매 완료 | K14: - | L14: 50초 | M14: 자동 등록하지 않고 소리·행동·오브젝트로만 암시 | N14: 0.0038194444 | O14: 1-B | 편의점·고양이 선택 | P14: 3 | Q14: 34 | S14: 50초 | T14: 45초 | U14: 40초 | Y14: 서브 퀘스트 : 이후 예쁜 고양이 인연 콘텐츠 4회 수행 가능
A15: 1 | 평범한 하루 | B15: 13 | C15: 2 | D15: 8 | E15: 예쁜 고양이에게 첫 번째 츄르 건네기 | F15: 예쁜 고양이는 처음 만난 차한해를 경계해 바로 가까이 오지 않음 | G15: 일정 거리에 츄르를 내려놓고 뒤로 물러난 뒤 고양이가 스스로 다가올 때까지 기다림 | H15: 2/10 – 발견 여부와 선택에 따라 진행이 달라짐 | I15: 2 | J15: 예쁜 고양이가 츄르를 먹고 도망가지 않은 채 차한해를 바라봄 | K15: - | L15: 50초 | M15: 자동 등록하지 않고 소리·행동·오브젝트로만 암시 | N15: 0.0043981481 | O15: 1-B | 편의점·고양이 선택 | P15: 3 | Q15: 37 | S15: 50초 | T15: 45초 | U15: 40초 | W15: [예쁜 고양이] +25% 선택 (최대 누적 25%) | Y15: 츄르 보유 시 수행 예쁜 고양이 인연 +25%
A16: 1 | 평범한 하루 | B16: 14 | C16: 2 | D16: 5 | E16: 다이소로 이동하기 | F16: 갈림길과 주변 상호작용 오브젝트 때문에 목적지 방향을 놓칠 수 있음 | G16: 표지판·미니맵·NPC 이동 방향을 확인하며 편의점에서 다이소까지 이동함 | H16: 2/10 – 맵 크기·갈림길 수·목적지 표식의 가시성이 난이도를 결정함 | I16: 1 | J16: 편의점에서 다이소의 도착 트리거에 진입 | K16: - | L16: 25초 | M16: 일정 시간 정체 시 목적지 방향 화살표 표시 | N16: 0.0046875 | O16: 1-C | 다이소 | P16: 3 | Q16: 40 | S16: 25초 | T16: 20초 | U16: 20초
A17: 1 | 평범한 하루 | B17: 15 | C17: 2 | D17: 6 | E17: 헤어롤 진열대 찾기 | F17: 비슷한 오브젝트와 진열대가 많아 목표 대상을 한 번에 찾기 어려움 | G17: 구역별 표지와 상품 외형을 비교하며 생활용품 코너의 헤어롤을 조사함 | H17: 2/10 – 후보 오브젝트 수·외형 유사도·탐색 범위가 난이도를 결정함 | I17: 5 | J17: 생활용품 코너의 헤어롤 발견 및 조사 완료 | K17: - | L17: 40초 | M17: 30초 이상 미발견 시 목표 구역에 약한 반짝임 표시 | N17: 0.005150463 | O17: 1-C | 다이소 | P17: 4 | Q17: 44 | S17: 40초 | T17: 30초 | U17: 30초
A18: 1 | 평범한 하루 | B18: 16 | C18: 1 | D18: 5 | E18: 헤어롤 구매하기 | F18: 구매 대상·수량·결제 순서를 잘못 선택할 수 있음 | G18: 요청받은 품목을 확인하고 상품 선택→계산대 상호작용→결제를 순서대로 진행함 | H18: 1/10 – 상품 후보 수·품목 유사도·구매 단계 수가 난이도를 결정함 | I18: 3 | J18: 헤어롤 1개 구매 후 인벤토리에 등록 | K18: 잘못된 품목 구매 시 다시 선택해야 함 | L18: 20초 | M18: 요청 품목에 작은 임무 아이콘 표시 | N18: 0.0053819444 | O18: 1-C | 다이소 | P18: 3 | Q18: 47 | S18: 20초 | T18: 20초 | U18: 20초
A19: 1 | 평범한 하루 | B19: 17 | C19: 2 | D19: 5 | E19: 영화관으로 이동하기 | F19: 갈림길과 주변 상호작용 오브젝트 때문에 목적지 방향을 놓칠 수 있음 | G19: 표지판·미니맵·NPC 이동 방향을 확인하며 다이소에서 영화관까지 이동함 | H19: 2/10 – 맵 크기·갈림길 수·목적지 표식의 가시성이 난이도를 결정함 | I19: 1 | J19: 다이소에서 영화관의 도착 트리거에 진입 | K19: - | L19: 35초 | M19: 일정 시간 정체 시 목적지 방향 화살표 표시 | N19: 0.005787037 | O19: 1-D | 영화관 | P19: 3 | Q19: 50 | S19: 35초 | T19: 30초 | U19: 30초
A20: 1 | 평범한 하루 | B20: 18 | C20: 2 | D20: 5 | E20: 팝콘 구매하기 | F20: 구매 대상·수량·결제 순서를 잘못 선택할 수 있음 | G20: 요청받은 품목을 확인하고 상품 선택→계산대 상호작용→결제를 순서대로 진행함 | H20: 2/10 – 상품 후보 수·품목 유사도·구매 단계 수가 난이도를 결정함 | I20: 3 | J20: 동생이 지정한 팝콘 구매 후 인벤토리에 등록 | K20: 잘못된 품목 구매 시 다시 선택해야 함 | L20: 30초 | M20: 요청 품목에 작은 임무 아이콘 표시 | N20: 0.0061342593 | O20: 1-D | 영화관 | P20: 3 | Q20: 53 | S20: 30초 | T20: 30초 | U20: 30초
A21: 1 | 평범한 하루 | B21: 19 | C21: 2 | D21: 8 | E21: 치킨집 앞 두 손님의 주문 대화 엿듣기 | F21: 힙한 여성과 청순한 친구가 서로 다른 주문을 말해 실제 주문 내용을 파악하기 어려움 | G21: 대화에서 치킨 종류·소스·음료·추가 요청을 구분해 기억함 | H21: 2/10 – 발견 여부와 선택에 따라 진행이 달라짐 | I21: 2 | J21: 두 손님의 최종 주문 항목 확인 | K21: - | L21: 50초 | M21: 자동 등록하지 않고 소리·행동·오브젝트로만 암시 | N21: 0.006712963 | O21: 1-E | 치킨집 알바 서브 | P21: 3 | Q21: 56 | S21: 50초 | T21: 45초 | U21: 40초 | Y21: 서브 퀘스트 : 치킨집 알바하기
A22: 1 | 평범한 하루 | B22: 20 | C22: 2 | D22: 8 | E22: 바쁜 치킨집 직원의 도움 요청 확인하기 | F22: 밀린 주문과 손님 대화가 겹쳐 직원의 부탁을 놓칠 수 있음 | G22: 카운터 직원의 호출을 확인하고 잠시 포장을 도울지 선택함 | H22: 2/10 – 발견 여부와 선택에 따라 진행이 달라짐 | I22: 2 | J22: 도움 요청 대화 확인 | K22: - | L22: 50초 | M22: 자동 등록하지 않고 소리·행동·오브젝트로만 암시 | N22: 0.0072916667 | O22: 1-E | 치킨집 알바 서브 | P22: 3 | Q22: 59 | S22: 50초 | T22: 45초 | U22: 40초 | Y22: 알바를 거절하면 서브 퀘스트 종료
A23: 1 | 평범한 하루 | B23: 21 | C23: 1 | D23: 8 | E23: 치킨집 알바를 도울지 선택하기 | F23: 동생 심부름 일정과 직원의 부탁 사이에서 선택해야 함 | G23: ‘돕는다’ 또는 ‘심부름을 계속한다’를 선택하며 거절해도 메인 진행에는 영향이 없음 | H23: 2/10 – 핵심 정보와 감정의 연결을 이해해야 함 | I23: 2 | J23: 알바 수락 또는 거절 선택 완료 | K23: - | L23: 45초 | M23: 핵심 문장 강조·대화 다시 보기·선택 시간 제한 없음 | N23: 0.0078125 | O23: 1-E | 치킨집 알바 서브 | P23: 4 | Q23: 63 | S23: 45초 | T23: 40초 | U23: 35초 | Y23: 수락 시 포장 미니게임 해금
A24: 1 | 평범한 하루 | B24: 22 | C24: 4 | D24: 8 | E24: 주문표의 치킨·소스·음료 확인하기 | F24: 여러 주문표가 동시에 놓여 있어 주문 번호와 구성품을 혼동하기 쉬움 | G24: 주문 번호를 기준으로 치킨 종류·무·소스·음료 수량을 순서대로 확인함 | H24: 4/10 – 순서·수량·제한시간을 함께 확인해야 함 | I24: 5 | J24: 선택한 주문표의 필수 항목 5개 확인 | K24: 오답 누적 시 현재 단계부터 다시 진행 | L24: 2분 | M24: 오답 항목 강조·반복 실패 시 제한시간 완화 | N24: 0.0092013889 | O24: 1-E | 치킨집 알바 서브 | P24: 6 | Q24: 69 | S24: 2분 | T24: 1분 40초 | U24: 1분 20초
A25: 1 | 평범한 하루 | B25: 23 | C25: 4 | D25: 8 | E25: 주문에 맞게 치킨 포장하기 | F25: 힙한 여성과 친구가 주문을 번복하는 대사를 해 현재 확정된 구성과 혼동을 줌 | G25: 확정 주문표만 기준으로 상자·무·소스·음료를 올바른 포장 칸에 넣음 | H25: 4/10 – 순서·수량·제한시간을 함께 확인해야 함 | I25: 5 | J25: 주문 구성품 5종을 모두 올바르게 포장 | K25: 오답 누적 시 현재 단계부터 다시 진행 | L25: 2분 | M25: 오답 항목 강조·반복 실패 시 제한시간 완화 | N25: 0.010590278 | O25: 1-E | 치킨집 알바 서브 | P25: 6 | Q25: 75 | S25: 2분 | T25: 1분 40초 | U25: 1분 20초
A26: 1 | 평범한 하루 | B26: 24 | C26: 4 | D26: 8 | E26: 잘못 포장된 주문 수정하기 | F26: 다른 주문의 소스와 음료가 섞여 있어 오류 항목만 찾아 교체해야 함 | G26: 완성된 포장과 주문표를 대조해 잘못 들어간 구성품을 제거하고 올바르게 바꿈 | H26: 4/10 – 순서·수량·제한시간을 함께 확인해야 함 | I26: 5 | J26: 오포장 항목 전부 수정 | K26: 오답 누적 시 현재 단계부터 다시 진행 | L26: 1분 30초 | M26: 오답 항목 강조·반복 실패 시 제한시간 완화 | N26: 0.011631944 | O26: 1-E | 치킨집 알바 서브 | P26: 6 | Q26: 81 | S26: 1분 30초 | T26: 1분 15초 | U26: 1분
A27: 1 | 평범한 하루 | B27: 25 | C27: 2 | D27: 8 | E27: 손님에게 주문 전달하고 알바 보상 받기 | F27: 주문 번호가 비슷한 두 손님 중 올바른 사람에게 전달해야 함 | G27: 주문 대화에서 확인한 특징과 번호를 대조해 포장된 치킨을 전달함 | H27: 2/10 – 발견 여부와 선택에 따라 진행이 달라짐 | I27: 2 | J27: 올바른 손님에게 주문 전달 및 알바비·감사 대사 획득 | K27: - | L27: 50초 | M27: 자동 등록하지 않고 소리·행동·오브젝트로만 암시 | N27: 0.012210648 | O27: 1-E | 치킨집 알바 서브 | P27: 3 | Q27: 84 | S27: 50초 | T27: 45초 | U27: 40초 | Y27: 서브 퀘스트 완료 보상·추가 코미디 대화
A28: 1 | 평범한 하루 | B28: 26 | C28: 1 | D28: 8 | E28: 편의점 물류 트럭과 꺼지는 가로등 발견하기 | F28: 물류 트럭이 지나가는 순간 도로의 가로등이 이동 방향을 따라 차례로 꺼져 트럭과 이상 현상을 동시에 놓칠 수 있음 | G28: 카메라 이동과 효과음을 따라 물류 트럭을 확인하고 뒤이어 꺼지는 가로등의 순서를 관찰함 | H28: 1/10 – 대상 노출 시간·가로등 소등 속도·시선 유도 강도가 난이도를 결정함 | I28: 2 | J28: 편의점 물류 트럭과 이동 방향을 따라 꺼지는 가로등 확인 | K28: 대상을 놓치면 짧은 연출이 다시 재생됨 | L28: 15초 | M28: 트럭 등장 직전 효과음과 첫 번째 가로등에 화면 가장자리 표시 | N28: 0.012384259 | O28: 1-D | 영화관 | P28: 3 | Q28: 87 | S28: 15초 | T28: 10초 | U28: 10초
A29: 1 | 평범한 하루 | B29: 27 | C29: 3 | D29: 7 | E29: 배송 상자의 재입고 표식 기억하기 | F29: 움직이는 트럭의 적재함이 잠깐 열리며 비슷한 상자 표식이 동시에 노출됨 | G29: 상자의 줄무늬·색 띠·배송 코드를 순서대로 기억해 편의점 재입고 상자를 판별함 | H29: 3/10 – 표식 노출 시간·유사 표식 수·기억해야 할 순서가 난이도를 결정함 | I29: 3 | J29: 재입고 상자 표식 3개를 순서대로 선택 | K29: 오답 3회 시 트럭 등장 연출부터 다시 확인 | L29: 30초 | M29: 첫 시도에는 표식을 순차적으로 확대하고 오답 후 다른 표식 하나를 제거 | N29: 0.012731481 | O29: 1-E | 편의점 재입고 | P29: 4 | Q29: 91 | S29: 30초 | T29: 25초 | U29: 25초
A30: 1 | 평범한 하루 | B30: 28 | C30: 5 | D30: 8 | E30: 편의점 물류 트럭 따라가기 | F30: 대상이 빠르게 이동하고 시민과 건물이 시야를 가려 추적이 끊길 수 있음 | G30: 목표 아이콘과 도로 방향을 보며 허용 거리 안에서 물류 트럭을 따라감 | H30: 5/10 – 플레이어와 대상의 속도 차이·허용 거리·시야 차단물이 난이도를 결정함 | I30: 1 | J30: 허용 거리 안에서 추적 종료 지점 도착 | K30: 대상과 6초 이상 거리 초과 시 추격 구간 재시작 | L30: 35초 | M30: 실패 2회 후 대상 속도 감소 및 경로 화살표 표시 | N30: 0.013136574 | O30: 1-E | 편의점 재입고 | P30: 5 | Q30: 96 | S30: 35초 | T30: 30초 | U30: 30초
A31: 1 | 평범한 하루 | B31: 29 | C31: 5 | D31: 9 | E31: 골목 지름길의 장애물과 이상 진동 돌파하기 | F31: 보행자·자전거·배송 상자가 골목을 막는 동안 조명이 흔들리고 길고양이가 빈 벽을 경계해 이동 경로와 이상 징후가 동시에 제시됨 | G31: 장애물의 이동 방향을 예측해 지름길을 선택하고 고양이의 시선과 바닥 진동이 강해지는 벽면을 피해 이동함 | H31: 5/10 – 장애물 밀도·트럭과의 거리·이상 진동 구역·지름길 선택 시간이 난이도를 결정함 | I31: 6 | J31: 추적 거리 게이지를 유지하고 진동 구역을 피한 채 편의점 후문 도착 | K31: 거리 게이지가 0이 되거나 진동 구역에 3회 진입하면 골목 입구 체크포인트에서 재시작 | L31: 40초 | M31: 재시도마다 트럭 속도를 낮추고 고양이가 바라보는 위험 벽면을 짧게 강조 | N31: 0.013599537 | O31: 1-E | 편의점 재입고 | P31: 6 | Q31: 102 | S31: 40초 | T31: 30초 | U31: 30초
A32: 1 | 평범한 하루 | B32: 30 | C32: 4 | D32: 7 | E32: 신상 과자 오픈런 참가하기 | F32: 여러 NPC가 동시에 진열대로 이동해 접근 경로와 상호작용 위치가 막힘 | G32: 군중의 이동 방향을 예측하고 빈 공간으로 우회해 편의점 진열대 앞 군중에 접근함 | H32: 4/10 – 경쟁 NPC 수·충돌 범위·재고 수량·접근 가능 시간이 난이도를 결정함 | I32: 4 | J32: 재고가 남아 있을 때 목표 상품 상호작용 성공 | K32: 재고가 모두 소진되면 직전 체크포인트에서 재시도 | L32: 40초 | M32: 재시도 시 경쟁 NPC 수 1명 감소 | N32: 0.0140625 | O32: 1-E | 편의점 재입고 | P32: 5 | Q32: 107 | S32: 40초 | T32: 35초 | U32: 35초
A33: 1 | 평범한 하루 | B33: 31 | C33: 2 | D33: 5 | E33: 신상 과자 구매하기 | F33: 구매 대상·수량·결제 순서를 잘못 선택할 수 있음 | G33: 요청받은 품목을 확인하고 상품 선택→계산대 상호작용→결제를 순서대로 진행함 | H33: 2/10 – 상품 후보 수·품목 유사도·구매 단계 수가 난이도를 결정함 | I33: 3 | J33: 신상 과자 1봉 구매 후 인벤토리에 등록 | K33: 잘못된 품목 구매 시 다시 선택해야 함 | L33: 20초 | M33: 요청 품목에 작은 임무 아이콘 표시 | N33: 0.014293981 | O33: 1-E | 편의점 재입고 | P33: 3 | Q33: 110 | S33: 20초 | T33: 20초 | U33: 20초
A34: 1 | 평범한 하루 | B34: 32 | C34: 1 | D34: 5 | E34: 동생 연락 받기 | F34: 대화 속에 다음 목적지와 필요한 물품 정보가 섞여 있음 | G34: 강조되는 핵심 단어와 NPC의 요구를 확인하며 대화를 끝까지 진행함 | H34: 1/10 – 대사 길이·핵심 정보의 명확성·선택지 수가 난이도를 결정함 | I34: 1 | J34: 중고 거래 물품 수령 요청에 관한 대화를 마지막 문장까지 진행 | K34: - | L34: 20초 | M34: 대화 종료 후 핵심 내용을 화면 한쪽에 요약 표시 | N34: 0.014525463 | O34: 1-E | 편의점 재입고 | P34: 3 | Q34: 113 | S34: 20초 | T34: 20초 | U34: 20초 | W34: [차우선] +5% (누적 50%) | Y34: 차우선 인연 50% 이상 : 귀가 후 추가 통화 해금
A35: 1 | 평범한 하루 | B35: 33 | C35: 2 | D35: 5 | E35: 지하철역으로 이동하기 | F35: 갈림길과 주변 상호작용 오브젝트 때문에 목적지 방향을 놓칠 수 있음 | G35: 표지판·미니맵·NPC 이동 방향을 확인하며 편의점에서 지하철역 개찰구까지 이동함 | H35: 2/10 – 맵 크기·갈림길 수·목적지 표식의 가시성이 난이도를 결정함 | I35: 1 | J35: 편의점에서 지하철역 개찰구의 도착 트리거에 진입 | K35: - | L35: 40초 | M35: 일정 시간 정체 시 목적지 방향 화살표 표시 | N35: 0.014988426 | O35: 1-F | 지하철역 | P35: 3 | Q35: 116 | S35: 40초 | T35: 35초 | U35: 35초
A36: 1 | 평범한 하루 | B36: 34 | C36: 2 | D36: 7 | E36: 거래자 후보 3명 관찰하기 | F36: 중요한 단서가 여러 인물과 배경 오브젝트 사이에 분산되어 있음 | G36: 시선·행동·복장·주변 오브젝트를 순서대로 확인해 회색 후드 특징이 겹치는 세 명의 후보의 특징을 파악함 | H36: 2/10 – 관찰 대상 수·단서의 명확성·외형 유사도가 난이도를 결정함 | I36: 3 | J36: 필수 관찰 대상 모두 조사 | K36: - | L36: 30초 | M36: 필수 대상 위에 짧은 시선 유도 아이콘 표시 | N36: 0.015335648 | O36: 1-F | 지하철역 | P36: 4 | Q36: 120 | S36: 30초 | T36: 25초 | U36: 25초
A37: 1 | 평범한 하루 | B37: 35 | C37: 3 | D37: 8 | E37: 중고 거래자 찾기 | F37: 후보들이 공통 특징을 가지고 있어 한 가지 단서만으로는 구별할 수 없음 | G37: 복장·소지품·대화 반응을 함께 비교해 대화 단서와 복장 단서가 일치하는 거래자를 선택함 | H37: 3/10 – 후보 수·공통 특징 수·추가 단서의 명확성이 난이도를 결정함 | I37: 4 | J37: 올바른 거래자와 대화 시작 | K37: 오답 후보 선택 시 경계 대사가 출력되고 다시 선택 | L37: 40초 | M37: 오답 2회 후 확인하지 않은 단서 목록 표시 | N37: 0.015798611 | O37: 1-F | 지하철역 | P37: 5 | Q37: 125 | S37: 40초 | T37: 30초 | U37: 30초
A38: 1 | 평범한 하루 | B38: 36 | C38: 1 | D38: 5 | E38: 중고 거래 완료하기 | F38: 구매 대상·수량·결제 순서를 잘못 선택할 수 있음 | G38: 요청받은 품목을 확인하고 상품 선택→계산대 상호작용→결제를 순서대로 진행함 | H38: 1/10 – 상품 후보 수·품목 유사도·구매 단계 수가 난이도를 결정함 | I38: 3 | J38: 동생이 부탁한 중고 물품 구매 후 인벤토리에 등록 | K38: 잘못된 품목 구매 시 다시 선택해야 함 | L38: 25초 | M38: 요청 품목에 작은 임무 아이콘 표시 | N38: 0.016087963 | O38: 1-F | 지하철역 | P38: 3 | Q38: 128 | S38: 25초 | T38: 20초 | U38: 20초 | W38: [차우선] +5% (누적 55%)
A39: 1 | 평범한 하루 | B39: 37 | C39: 2 | D39: 8 | E39: 집으로 돌아가는 길에 공원의 섬광 확인하기 | F39: 축제 종료 공원 쪽에서 순간적인 보랏빛 섬광과 낮은 굉음이 발생하지만 주변 시민들은 전기 설비 사고로 여기고 지나침 | G39: 공원 방향 표지와 시민들의 시선을 따라 이동하며 섬광이 발생한 축제 종료 공원에 진입함 | H39: 2/10 – 목적지 탐색과 짧은 이상 연출의 위치 파악이 난이도를 결정함 | I39: 2 | J39: 보랏빛 섬광을 확인하고 축제 종료 공원의 도착 트리거에 진입 | K39: - | L39: 35초 | M39: 섬광 발생 순간 화면 밝기 변화와 방향성 있는 굉음 제공 | N39: 0.016493056 | O39: 1-G | 공원 전조 | P39: 4 | Q39: 132 | S39: 35초 | T39: 30초 | U39: 30초 | X39: 심부름 핵심 목표 3종 완료
A40: 2 | 금이 간 일상 | B40: 38 | C40: 1 | D40: 7 | E40: 축제 종료 현장과 남은 이상 징후 관찰하기 | F40: 떠나는 시민·쌓인 쓰레기·간헐적으로 깜빡이는 조명 사이에 섬광의 원인을 추정할 단서가 분산되어 있음 | G40: 시민의 행동과 쓰레기 상태를 살펴본 뒤 조명 깜빡임과 바닥의 미세한 떨림을 차례로 확인함 | H40: 1/10 – 관찰 대상 수·이상 징후의 미세함·단서 분산 정도가 난이도를 결정함 | I40: 5 | J40: 시민·쓰레기·조명·바닥 진동에 관한 필수 관찰 대상 확인 | K40: - | L40: 25초 | M40: 이상 징후가 발생할 때 효과음과 짧은 시선 유도 아이콘 표시 | N40: 0.016782407 | O40: 2-A | 공원 축제·청소 | P40: 3 | Q40: 135 | S40: 25초 | T40: 25초 | U40: 25초
...

Sheet PC DATA(대차대조표)
A1: 콘텐츠 진행 순서 | B1: 콘텐츠명 | C1: 이름 | D1: 이미지 | E1: 전투 상태 | F1: 기본 공격력 | G1: 공격력 변화(최초·일회성) | H1: 기본 방어력 | I1: 방어력 변화(획득·손상·파손) | J1: 스킬(최초 해금) | K1: 변경 근거·현재 상태
A2: ※ 밸런스 문서의 콘텐츠 진행 순서 1~306에서 현재 기본 공격력·기본 방어력과 전투 상태를 확인할 수 있음. 장비와 스킬은 처음 획득·교체·손상·파손되는 시점에만 기록함. 소모품·접근 도구의 획득과 사용은 아이템 시트와 밸런스 문서의 동일한 콘텐츠 번호로 검증함. 일반인 상태는 공격력 10·방어력 10이며, 첫 힘 발현은 해당 콘텐츠에만 적용되는 +990 일회성 보정임.
A3: 1 | B3: 차한해의 과거 오프닝 감상 | C3: 차한해 | E3: 전투 시스템 미개방 | F3: 10 | H3: 10 | K3: 기본 공격력 10 / 기본 방어력 10
A4: 2 | B4: 빨래 개기 | C4: 차한해 | E4: 전투 시스템 미개방 | F4: 10 | H4: 10 | K4: 일반인 신체 능력 유지
A5: 3 | B5: 동생에게 심부름 지시 받기 | C5: 차한해 | E5: 전투 시스템 미개방 | F5: 10 | H5: 10
A6: 4 | B6: 이동 조작 안내 확인 | C6: 차한해 | E6: 전투 시스템 미개방 | F6: 10 | H6: 10
A7: 5 | B7: 현관으로 이동하기 | C7: 차한해 | E7: 전투 시스템 미개방 | F7: 10 | H7: 10
A8: 6 | B8: 집 밖으로 나가기 | C8: 차한해 | E8: 전투 시스템 미개방 | F8: 10 | H8: 10
A9: 7 | B9: 편의점으로 이동하기 | C9: 차한해 | E9: 전투 시스템 미개방 | F9: 10 | H9: 10
A10: 8 | B10: 신상 과자 진열대 찾기 | C10: 차한해 | E10: 전투 시스템 미개방 | F10: 10 | H10: 10
A11: 9 | B11: 품절 안내 조사하기 | C11: 차한해 | E11: 전투 시스템 미개방 | F11: 10 | H11: 10
A12: 10 | B12: 알바생 NPC와 대화하고 이상 현상 뉴스 확인하기 | C12: 차한해 | E12: 전투 시스템 미개방 | F12: 10 | H12: 10
A13: 11 | B13: 골목에서 들리는 예쁜 고양이 울음소리 확인하기 | C13: 차한해 | E13: 전투 시스템 미개방 | F13: 10 | H13: 10
A14: 12 | B14: 편의점에서 츄르 4개입 세트 구매하기 | C14: 차한해 | E14: 전투 시스템 미개방 | F14: 10 | H14: 10
A15: 13 | B15: 예쁜 고양이에게 첫 번째 츄르 건네기 | C15: 차한해 | E15: 전투 시스템 미개방 | F15: 10 | H15: 10
A16: 14 | B16: 다이소로 이동하기 | C16: 차한해 | E16: 전투 시스템 미개방 | F16: 10 | H16: 10
... A80: 78 | B80: 문 앞에 웅크린 자와 정면으로 마주치기 | C80: 차한해 | E80: 전투 시스템 미개방 | F80: 10 | H80: 10
A81: 79 | B81: 두 눈을 감고 양손으로 괴물을 막기 | C81: 차한해 | E81: 무의식적 일회성 발현 | F81: 10 | G81: 무의식적 선의 폭발 +990 순간 출력 1000 | H81: 10 | K81: 기본 공격력 10 / 무의식적 선의 폭발 +990 · 순간 출력 1000 / 기본 방어력 10
A82: 80 | B82: 먼지처럼 사라진 괴물의 흔적 확인하기 | C82: 차한해 | E82: 미개방·힘 재현 불가 | F82: 10 | G82: 무의식적 선의 폭발 종료 : +990 → 0 | H82: 10 | K82: 무의식적 선의 폭발 종료 : +990 → 0
A83: 81 | B83: 어린아이를 공주님 안기로 구출하기 | C83: 차한해 | E83: 미개방·힘 재현 불가 | F83: 10 | H83: 10 | K83: 첫 힘의 존재와 발동 방법을 인식하지 못함
A84: 82 | B84: 아이의 ‘괴물 펑’ 목격담 듣기 | C84: 차한해 | E84: 미개방·힘 재현 불가 | F84: 10 | H84: 10
A85: 83 | B85: 몸을 끄는 자를 우회해 안전 구역으로 이동하기 | C85: 차한해 | E85: 미개방·힘 재현 불가 | F85: 10 | H85: 10
A86: 84 | B86: 울음이 남은 자의 울음 파동을 피해 새벽 괴물 습격 구간 벗어나기 | C86: 차한해 | E86: 미개방·힘 재현 불가 | F86: 10 | H86: 10
A87: 85 | B87: 길을 잃은 자의 배회 경로를 피해 한도윤과 합류하기 | C87: 차한해 | E87: 미개방·힘 재현 불가 | F87: 10 | H87: 10
A88: 86 | B88: 임시 대피소 도착하기 | C88: 차한해 | E88: 미개방·힘 재현 불가 | F88: 10 | H88: 10
A89: 87 | B89: 맨몸으로 할머니를 구한 청년의 뉴스 확인하기 | C89: 차한해 | E89: 미개방·힘 재현 불가 | F89: 10 | H89: 10
A90: 88 | B90: 청년의 ‘구해야겠다는 생각뿐’ 인터뷰와 밈 확인하기 | C90: 차한해 | E90: 미개방·힘 재현 불가 | F90: 10 | H90: 10
A91: 89 | B91: 악질 유튜버의 균열 접근 생방송 시청하기 | C91: 차한해 | E91: 미개방·힘 재현 불가 | F91: 10 | H91: 10
A92: 90 | B92: 유튜버에게 나타난 수치 96 확인하기 | C92: 차한해 | E92: 미개방·힘 재현 불가 | F92: 10 | H92: 10
A93: 91 | B93: 기계가 정상 작동하는 균열 연구 현장 확인하기 | C93: 차한해 | E93: 미개방·힘 재현 불가 | F93: 10 | H93: 10
A94: 92 | B94: 할머니를 구한 청년의 수치 836 측정하기 | C94: 차한해 | E94: 미개방·힘 재현 불가 | F94: 10 | H94: 10
A95: 93 | B95: 새로운 수치를 ‘선의 수치’라고 부르는 과정 확인하기 | C95: 차한해 | E95: 미개방·힘 재현 불가 | F95: 10 | H95: 10
... A119: 117 | B119: 선의 수치 836 청년의 구조 원칙 듣기 | C119: 차한해 | E119: 미개방·힘 재현 불가 | F119: 10 | H119: 10
A120: 118 | B120: 관리국 표준 대응 장비 8종·응급품 2종을 수령하고 상태 UI 확인하기 | C120: 차한해 | E120: 전투 가능·비전투 콘텐츠 | F120: 80 | G120: 관리국 지급 권총 +20 관리국 대응 장갑 +3 비살상 충격탄 사용 시 +6 | H120: 100 | I120: 기본 보호 조끼 +30 관리국 방진 고글 +4 관리국 대응 장갑 +5 관리국 전술화 +6 관리국 방진 마스크 +3 | J120: 상태 UI 확인 비살상 제압 게이지 무전 전조 알림 | K120: 관리국 표준 대응 세트 8종·응급 주사·비살상 충격탄 획득
A121: 119 | B121: 관리국 지급 권총·비살상 충격탄·관리국 전술화를 이용해 사격과 회피 연습하기 | C121: 차한해 | E121: 전투 가능 | F121: 100 | H121: 100 | J121: 조준 사격 긴급 회피 | K121: 기본 공격력 100 / 스킬 : 조준 사격 · 긴급 회피
A122: 120 | B122: 출동 차량을 향해 환호하는 시민들 지나가기 | C122: 차한해 | E122: 전투 가능·비전투 콘텐츠 | F122: 100 | H122: 100 | K122: 전투 수치 변화 없이 탐색·대화·이동 진행
A123: 121 | B123: 도심 잔해 구역으로 이동하며 관리국 보급 상자에서 소형 방진 필터 챙기기 | C123: 차한해 | E123: 전투 가능·비전투 콘텐츠 | F123: 100 | H123: 100 | K123: 소형 방진 필터 1개 획득
A124: 122 | B124: 고립 시민 찾기 | C124: 차한해 | E124: 전투 가능·비전투 콘텐츠 | F124: 100 | H124: 100
A125: 123 | B125: 관리국 대응 장갑을 착용하고 잔해 제거하기 | C125: 차한해 | E125: 전투 가능·비전투 콘텐츠 | F125: 100 | H125: 100
A126: 124 | B126: 시민 대피 유도하기 | C126: 차한해 | E126: 전투 가능·비전투 콘텐츠 | F126: 100 | H126: 100
...

Sheet PC DATA
A1: 플레이어 고유명(CLASS) | B1: 이미지 | C1: 콘텐츠 진행 순서 | D1: 기본 공격력 | E1: 공격력 합산 요소(최초·일회성 변화) | F1: 기본 방어력 | G1: 방어력 합산 요소(획득·손상·파손) | H1: 스킬(최초 해금)
A2: ※ 일반인 상태의 기본 공격력·기본 방어력은 각각 10으로 시작함. 79번 콘텐츠에서 무의식적 선의 폭발 +990이 한 번만 적용되어 순간 출력 1000이 되지만 다음 콘텐츠에서 보정이 0으로 돌아감. 정식 전투 능력과 관리국 표준 대응 장비는 118번부터 개방되며, 무기·방어구·스킬은 최초 획득·교체·손상·파손 시점만 기록함. 소모품·접근 도구는 아이템 시트와 밸런스 문서에서 별도로 관리함.
A3: 차한해 | C3: 1 | D3: 10 | F3: 10
C4: 79 | D4: 10 | E4: 무의식적 선의 폭발 +990 순간 출력 1000 | F4: 10
C5: 80 | E5: 무의식적 선의 폭발 종료 : +990 → 0
C6: 118 | D6: 80 | E6: 관리국 지급 권총 +20 관리국 대응 장갑 +3 비살상 충격탄 사용 시 +6 | F6: 100 | G6: 기본 보호 조끼 +30 관리국 방진 고글 +4 관리국 대응 장갑 +5 관리국 전술화 +6 관리국 방진 마스크 +3 | H6: 상태 UI 확인 비살상 제압 게이지 무전 전조 알림
C7: 119 | D7: 100 | H7: 조준 사격 긴급 회피
C8: 125 | H8: 공격 예고 판독
C9: 126 | D9: 120 | H9: 회피 반격
C10: 129 | E10: 보랏빛 철봉 +80
C11: 130 | D11: 160 | H11: 공명 약점 타격
C12: 131 | F12: 110 | G12: 기본 보호 조끼 손상: +30 → +15 | H12: 장비 내구도 확인
C13: 134 | G13: 깨진 경찰 방패 +20 | H13: 전방 방어 섬광 주의 분산
C14: 140 | E14: 차단기 막대 +90
C15: 141 | H15: 환경 유인
C16: 142 | D16: 180
C17: 145 | G17: 나무판 보호대 +10 | H17: 임시 장비 제작
C18: 148 | D18: 220 | F18: 120 | G18: 나무판 보호대 파손: 사용 불가 | H18: 보스 핵 집중 공격
C19: 153 | E19: 고등급자 공명 증폭기 +15 | G19: 충격 보호대 +20 관리국 대응 장갑 해제 : +5 → 0 공명 보호 장갑 +15 | H19: 장비 효과 비교 공명 증폭
C20: 159 | E20: 전광판 쇠막대 +100
C21: 160 | D21: 250 | H21: 다수 정렬 타격 공명 증폭기 운용
C22: 163 | H22: 상반 전조 판별
C23: 166 | G23: 깨진 경찰 방패 파손: 사용 불가
C24: 168 | D24: 300 | F24: 135 | H24: 동시 핵 파괴 응급 주사 사용
C25: 169 | G25: 군용 방탄판 +35 | H25: 강한 공격 방어
C26: 179 | H26: 카메라 사각지대 이동
C27: 181 | D27: 340 | F27: 150 | G27: 군용 방탄판 균열: +35 → +15 | H27: 비공개 구조
C28: 185 | E28: 소방용 진압 도끼 +75 구조용 로프 발사기 +12 | G28: 구조대 안전모 +8 | H28: 구조 이동 경로 해금
C29: 187 | G29: 소방 방열복 +22 화염 보호복 +20 | H29: 화염 피해 대응
C30: 188 | D30: 380 | E30: 소방용 진압 도끼·구조용 로프 발사기 반납 : +87 → 0 | F30: 165 | G30: 구조대 안전모·소방 방열복 반납 : +30 → 0 기본 보호 조끼 완전 파손 : 사용 불가 화염 보호복 손상 : +20 → +10 | H30: 환경 파괴 구조
C31: 192 | G31: 관리국 방진 고글 해제 : +4 → 0 관리국 방진 마스크 해제 : +3 → 0 먼지 보호 안경 +10 균열 보호 마스크 +15 | H31: 환경별 장비 조합 안정 앰플 등록
C32: 194 | G32: 철판 보호대 +25 | H32: 시민 지원 장비
C33: 196 | G33: 오염 차단 전신복 +35 심층 균열 탐사 헬멧 +12 관리국 전술화 해제 : +6 → 0 고밀도 충격 흡수 장화 +10 | H33: 선의 안정 장치
C34: 215 | H34: 청각 추적 끊기
C35: 237 | E35: 사랑의 매 +140
C36: 238 | D36: 430 | H36: 공명 외피 파괴
C37: 242 | G37: 매트 보호대 +15 | H37: 현장 방어구 제작
C38: 243 | E38: 보랏빛 농구공 +120
C39: 244 | H39: 반사 투척
C40: 249 | D40: 470 | H40: 근·원거리 무기 전환 선의 안정 장치 자동 발동
...

Sheet 스킬 DATA
A1: 지정 사용자 | B1: 구간 | C1: 콘텐츠 번호 | D1: 최초 사용 콘텐츠 | E1: 사용 주체 | F1: 스킬명 | G1: 스킬 추가 설명 | H1: 스킬 아이콘 | I1: 스킬 타입 | J1: 지정 사용자 | K1: 상태 이상 값 | L1: 발동 조건 타입 | M1: 발동 필요 값 | N1: 피해 적용 타입 | O1: 피해 계수 | P1: 고정 피해 | Q1: 피해 산정식 | R1: AI 발동 주기(초) | S1: AI 발동 확률 | T1: 쿨타임 타입 | U1: 쿨타임(초) | V1: 시전 필요 시간(초) | W1: 능력 변동 종류 | X1: 능력 변동 수치 | Y1: 단위 | Z1: 지속 시간(초) | AA1: 종료·취소 조건 | AB1: 연계 스킬 ID | AC1: 비고
A2: 차한해 | B2: 기본 상호작용 | C2: 9 | D2: 9번 | 알바생의 무거운 음료 박스 진열 부탁을 수락할지 선택하기 | E2: PC | F2: 싫어요. | G2: 거절 가능한 부탁·요청에서 수락 대신 사용해 해당 요청을 종료하는 기본 상호작용 스킬. 거절한 콘텐츠의 인연·보상 획득 기회는 포기함. | I2: 액티브 | J2: 차한해 | L2: 입력 | M2: 수락 전 [싫어요.] 선택 | N2: 없음 | O2: 0 | P2: 0 | Q2: 피해 없음 | T2: 없음 | U2: 0 | V2: 0 | W2: 없음 | X2: 0 | Y2: 없음 | Z2: 0 | AA2: 선택 확정 | AB2: 없음 | AC2: 게임 시작부터 해금·첫 사용 가능 콘텐츠 9번
A3: 차한해 | B3: 3장·첫 힘 발현 | C3: 79 | D3: 79번 | 두 눈을 감고 양손으로 괴물을 막기 | E3: PC | F3: 펑! | G3: 괴물이 덮치기 직전 전용 UI에서 1회 발동하는 사건형 액티브. 무의식적 선의 폭발을 호출해 순간 출력 1000을 만들고 접촉 소멸까지 연쇄함. | I3: 연출용+액티브 | J3: 차한해 | L3: 1회 강제 발동 | M3: 문틈젤리 접촉 직전 | N3: 없음 | O3: 0 | P3: 0 | Q3: 피해 없음 | T3: 없음 | U3: 0 | V3: 0.6 | W3: 공격력 | X3: 990 | Y3: + | Z3: 0 | AA3: 접촉 소멸 완료 | AB3: SKL-STS-011 → SKL-STS-012 | AC3: 스토리 필수 사용·해당 콘텐츠에만 적용
A4: 차한해 | B4: 정식 전투 | C4: 119 | D4: 119번 | 관리국 지급 권총·비살상 충격탄·관리국 전술화를 이용해 사격과 회피 연습하기 | E4: PC | F4: 탕! | G4: 장착한 총기·원거리 무기의 공격 수치를 포함해 정면 표적 1체를 공격하는 기본 사격. | I4: 액티브 | J4: 차한해 | K4: 경직 0.20초 | L4: 입력 | M4: 공격 입력 1회 | N4: 기본 공격력 비율 | O4: 1 | P4: 0 | Q4: 기본 공격력 × 100% | T4: 개별 | U4: 0.45 | V4: 0.2 | W4: 없음 | X4: 0 | Y4: 없음 | Z4: 0 | AA4: 시전 종료 | AB4: SKL-STS-001 | AC4: 관리국 지급 권총을 기준으로 최초 훈련
A5: 차한해 | B5: 정식 전투 | C5: 119 | D5: 119번 | 관리국 지급 권총·비살상 충격탄·관리국 전술화를 이용해 사격과 회피 연습하기 | E5: PC | F5: 앗, 피해! | G5: 입력 방향으로 짧게 이동하며 공격 판정을 피하는 기본 회피. 성공 시 일부 반격 스킬의 조건을 열어 줌. | I5: 액티브 | J5: 차한해 | L5: 입력 | M5: 회피 입력 1회 | N5: 없음 | O5: 0 | P5: 0 | Q5: 피해 없음 | T5: 개별 | U5: 1.8 | V5: 0.1 | W5: 이동 속도 | X5: 80 | Y5: % | Z5: 0.25 | AA5: 이동 종료 | AB5: 없음 | AC5: 훈련 이후 상시 사용
A6: 보스 | B6: 보스 공통 | C6: 146 | D6: 146번 | 나만 살아서 다행이 연속으로 닫는 방화문 다시 열기 | E6: PC | F6: 잠깐만! | G6: 보스전에서 딱 1번 사용할 수 있는 보조 스킬. 보스의 현재 행동을 1초간 멈춰 위험 패턴을 끊을 틈을 만듦. | I6: 액티브 | J6: 보스 | K6: 경직 1.00초 | L6: 전투당 1회 | M6: 보스전·미사용 상태 | N6: 없음 | O6: 0 | P6: 0 | Q6: 피해 없음 | T6: 전투당 1회 | U6: 0 | V6: 0.15 | W6: 없음 | X6: 0 | Y6: 없음 | Z6: 1 | AA6: 1초 종료 | AB6: SKL-STS-001 | AC6: 118번에서 해금·146번 첫 보스부터 실제 사용 가능
A7: 차한해 | B7: 전투 정보 | C7: 125 | D7: 125번 | 관리국 무전 이어피스로 똑똑소라의 공격 예고 신호 파악하기 | E7: PC | F7: 먼저 들었어 | G7: 관리국 무전 이어피스의 공격 예고 신호를 판독해 적의 전조를 기본보다 0.3초 먼저 표시하는 패시브. | I7: 패시브 | J7: 차한해 | L7: 장비 착용 | M7: 관리국 무전 이어피스 장착 | N7: 없음 | O7: 0 | P7: 0 | Q7: 피해 없음 | T7: 없음 | U7: 0 | V7: 0 | W7: 전조 표시 시간 | X7: 0.3 | Y7: 초 | Z7: 0 | AA7: 장비 해제 | AB7: 없음 | AC7: 장비 효과를 스킬 형태로 표현
A8: 차한해 | B8: 정식 전투 | C8: 126 | D8: 126번 | 문틈새우의 후방 기습을 피하고 반격 타이밍 맞추기 | E8: PC | F8: 피했으면 내 차례 | G8: 직전 공격을 회피한 직후 짧은 반격 창에서 사용하는 대응 사격·타격. | I8: 액티브 | J8: 차한해 | K8: 경직 0.30초 | L8: 조건부 입력 | M8: 회피 성공 후 0.8초 이내 | N8: 기본 공격력 비율 | O8: 1.15 | P8: 0 | Q8: 기본 공격력 × 115% | T8: 개별 | U8: 2 | V8: 0.25 | W8: 없음 | X8: 0 | Y8: 없음 | Z8: 0 | AA8: 반격 창 종료 | AB8: SKL-STS-001 | AC8: 회피 성공을 공격 기회로 전환
A9: 차한해 | B9: 공명 전투 | C9: 130 | D9: 130번 | 보랏빛 철봉으로 밖으로 나가재 제압하기 | E9: PC | F9: 보라색, 여기! | G9: 차한해에게만 보이는 보랏빛 공명 반응 부위를 노려 타격해 일반 공격보다 큰 약점 피해를 줌. | I9: 액티브 | J9: 차한해 | L9: 약점 노출 | M9: 보랏빛 약점 표식 활성 | N9: 기본 공격력 비율 | O9: 1.35 | P9: 0 | Q9: 기본 공격력 × 135% | T9: 개별 | U9: 2.5 | V9: 0.35 | W9: 없음 | X9: 0 | Y9: 없음 | Z9: 0 | AA9: 약점 타격 종료 | AB9: 없음 | AC9: 공명 약점이 없는 대상에는 사용 불가
A10: 차한해 | B10: 방어 전투 | C10: 134 | D10: 134번 | 구조한 경찰에게 깨진 경찰 방패와 휴대용 섬광 신호기 받기 | E10: PC | F10: 앞은 내가 막아 | G10: 깨진 경찰 방패 등 전방 방어 장비를 들어 정면 피해와 밀려남을 줄이는 유지형 방어. | I10: 액티브 | J10: 차한해 | L10: 입력 유지 | M10: 방어 장비 장착·방어 입력 유지 | N10: 없음 | O10: 0 | P10: 0 | Q10: 피해 없음 | T10: 유지형 | U10: 0 | V10: 0.15 | W10: 받는 정면 피해 | X10: -50 | Y10: % | Z10: 0 | AA10: 입력 해제·방패 파손 | AB10: 없음 | AC10: 보스·강한 공격에는 감소량이 낮아질 수 있음
A11: 일반 변이체 | B11: 환경 유인 | C11: 141 | D11: 141번 | 휴대용 섬광 신호기와 차단기 막대로 내자리산호 유인하기 | E11: PC | F11: 저기 봐! | G11: 휴대용 섬광 신호기 1개를 소비해 일반 변이체의 주의를 설치 지점으로 4초간 돌리는 비전투·전투 겸용 스킬. | I11: 연출용+액티브 | J11: 일반 변이체 | K11: 주의 분산 4초 | L11: 아이템 사용 | M11: 휴대용 섬광 신호기 1회 소모 | N11: 없음 | O11: 0 | P11: 0 | Q11: 피해 없음 | T11: 아이템 횟수 | U11: 0 | V11: 0.4 | W11: 표적 인식 | X11: -1 | Y11: 대상 | Z11: 4 | AA11: 지속 종료·보스 면역 | AB11: SKL-STS-010 | AC11: PPT의 폭죽형 유틸리티 스킬과 같은 구조
A12: 차한해 | B12: 환경 유인 | C12: 141 | D12: 141번 | 휴대용 섬광 신호기와 차단기 막대로 내자리산호 유인하기 | E12: PC | F12: 이쪽이야! | G12: 차단기 막대나 주변 소음 오브젝트를 이용해 주의가 분산된 적의 이동 목표를 열린 공간으로 유도함. | I12: 액티브 | J12: 차한해 | L12: 환경 상호작용 | M12: 유인 가능한 오브젝트 활성 | N12: 없음 | O12: 0 | P12: 0 | Q12: 피해 없음 | T12: 개별 | U12: 3 | V12: 0.3 | W12: 이동 목표 | X12: 1 | Y12: 지점 | Z12: 3 | AA12: 대상 도달·지속 종료 | AB12: SKL-STS-007 | AC12: 환경 지형과 함께 사용하는 전술형 스킬
A13: 차한해 | B13: 첫 보스 | C13: 148 | D13: 148번 | 모든 문을 열린 채 고정하고 잠금 핵 무력화하기 | E13: PC | F13: 핵부터! | G13: 보스의 노출된 핵에 공격을 집중해 외피보다 큰 파괴 효율을 내는 상황형 집중 공격. | I13: 액티브 | J13: 차한해 | L13: 약점 노출 | M13: 보스 핵 노출 상태 | N13: 기본 공격력 비율 | O13: 1.4 | P13: 0 | Q13: 기본 공격력 × 140% | T13: 개별 | U13: 1.5 | V13: 0.3 | W13: 핵 피해 | X13: 40 | Y13: % | Z13: 0 | AA13: 핵 은폐 | AB13: 없음 | AC13: 노출 약점 전용
A14: 차한해 | B14: 공명 장비 | C14: 153 | D14: 153번 | 나대진에게 충격 보호대·공명 보호 장갑·고등급자 공명 증폭기 수령하기 | E14: PC | F14: 증폭기, 켠다! | G14: 고등급자 공명 증폭기를 켜 공명 대상 공격력을 높이는 대신 화면 간섭을 함께 발생시키는 장비 액티브. | I14: 액티브 | J14: 차한해 | K14: UI 간섭 | L14: 장비 사용 | M14: 고등급자 공명 증폭기 장착 | N14: 없음 | O14: 0 | P14: 0 | Q14: 피해 없음 | T14: 개별 | U14: 8 | V14: 0.35 | W14: 공격력 | X14: 15 | Y14: + | Z14: 8 | AA14: 장비 해제·지속 종료 | AB14: 없음 | AC14: 공명 대상 피해 +8%·UI 간섭 +3%는 아이템 시트 값 적용
A15: 차한해 | B15: 다수 전투 | C15: 160 | D15: 160번 | 공명 증폭기와 전광판 쇠막대로 승강장의 찰싹진드기 제압하기 | E15: PC | F15: 한 줄로 서! | G15: 전광판 쇠막대의 넓은 궤적으로 일렬에 겹친 여러 적을 한 번에 타격하는 정렬 공격. | I15: 액티브 | J15: 차한해 | L15: 입력 | M15: 2체 이상 일렬 정렬 | N15: 기본 공격력 비율 | O15: 1.1 | P15: 0 | Q15: 기본 공격력 × 110% | T15: 개별 | U15: 3.2 | V15: 0.5 | W15: 최대 타격 수 | X15: 3 | Y15: 체 | Z15: 0 | AA15: 시전 종료 | AB15: 없음 | AC15: 대상별 피해 동일
A16: 차한해 | B16: 융합 보스 | C16: 163 | D16: 163번 | 합치면 강해진댔잖아의 단일 외피 공략하기 | E16: PC | F16: 둘 중 하나! | G16: 상반된 공격 전조를 읽고 이번 공격을 받아낼지 피할지 판별하는 판단형 패시브. | I16: 패시브 | J16: 차한해 | L16: 패턴 판독 | M16: 상반 전조 발생 | N16: 없음 | O16: 0 | P16: 0 | Q16: 피해 없음 | T16: 없음 | U16: 0 | V16: 0 | W16: 판독 표시 | X16: 1 | Y16: 회 | Z16: 0 | AA16: 해당 공격 종료 | AB16: 없음 | AC16: 잘못 판독하면 보스 패턴 페널티 적용
A17: 차한해 | B17: 융합 보스 | C17: 168 | D17: 168번 | 관리국 응급 주사를 사용하고 폭력의 순환 핵 파괴하기 | E17: PC | F17: 하나, 둘—지금! | G17: 동시에 노출된 2개의 연결 핵을 짧은 허용 시간 안에 맞혀 폭력의 순환 연결을 끊는 동시 타격. | I17: 액티브 | J17: 차한해 | L17: 동시 조건 | M17: 연결 핵 2개 동시 노출 | N17: 기본 공격력 비율 | O17: 1.2 | P17: 0 | Q17: 기본 공격력 × 120% | T17: 개별 | U17: 5 | V17: 0.45 | W17: 동시 판정 시간 | X17: 0.6 | Y17: 초 | Z17: 0 | AA17: 핵 파괴·허용 시간 초과 | AB17: 없음 | AC17: 2개 핵 모두 적중해야 성공
A18: 차한해 | B18: 중장비 방어 | C18: 169 | D18: 169번 | 구조된 군인에게 군용 방탄판 받기 | E18: PC | F18: 버텨! | G18: 군용 방탄판 등 중량 방어구를 이용해 강한 단발 공격을 정면에서 받아내고 밀려남을 크게 줄임. | I18: 액티브 | J18: 차한해 | L18: 조건부 입력 | M18: 강공격 전조 중 방어 입력 | N18: 없음 | O18: 0 | P18: 0 | Q18: 피해 없음 | T18: 개별 | U18: 4 | V18: 0.2 | W18: 받는 피해 | X18: -35 | Y18: % | Z18: 1 | AA18: 강공격 종료 | AB18: SKL-STS-002 | AC18: 방어구 내구도 소모
A19: 차한해 | B19: 갈채 보스 | C19: 179 | D19: 179번 | 추앙풍뎅이의 보호막 부여를 차단하고 중계 카메라 끄기 | E19: PC | F19: 안 찍히면 돼 | G19: 카메라 시야와 스포트라이트를 피해 사각지대에서 이동하면 갈채 계열 적의 추적·강화 조건을 끊음. | I19: 패시브 | J19: 차한해 | L19: 위치 조건 | M19: 카메라 시야 밖 | N19: 없음 | O19: 0 | P19: 0 | Q19: 피해 없음 | T19: 없음 | U19: 0 | V19: 0 | W19: 갈채 획득 | X19: 0 | Y19: 고정 | Z19: 0 | AA19: 카메라 시야 진입 | AB19: SKL-STS-016 | AC19: 카메라 없는 행동이 보스 기믹을 약화
A20: 차한해 | B20: 갈채 보스 | C20: 181 | D20: 181번 | 아무도 보지 않는 곳에서 시민을 구하고 박수 없인 못 살아 제압하기 | E20: PC | F20: 아무도 안 봐도 | G20: 카메라가 없는 위치에서 실제 시민을 구조해 갈채와 무관한 선행을 증명하고 보스 보호막을 제거하는 사건형 행동. | I20: 연출용+액티브 | J20: 차한해 | L20: 사건 조건 | M20: 실제 시민 판별·카메라 비노출 | N20: 없음 | O20: 0 | P20: 0 | Q20: 피해 없음 | T20: 없음 | U20: 0 | V20: 1 | W20: 보호막 | X20: 0 | Y20: 고정 | Z20: 0 | AA20: 구조 완료 | AB20: SKL-STS-016 | AC20: 서사와 보스 공략을 직접 연결
A21: 지원 가능 NPC | B21: 회사 구조 | C21: 186 | D21: 186번 | 구조용 로프 발사기로 한도윤과 회사 직원 대피시키기 | E21: PC | F21: 도와줘! | G21: 현재 콘텐츠에 사전 정의된 지원 행동이 있고 해당 NPC의 인연·위치 조건을 만족할 때만 지원을 호출하는 제한형 스킬. | I21: 액티브 | J21: 지원 가능 NPC | L21: 상황 조건 | M21: 지원 가능 NPC·인연·콘텐츠 플래그 충족 | N21: 없음 | O21: 0 | P21: 0 | Q21: 피해 없음 | T21: 상황당 1회 | U21: 0 | V21: 0.3 | W21: 없음 | X21: 0 | Y21: 없음 | Z21: 0 | AA21: 지원 행동 완료 | AB21: SKL-NPC-001 / SKL-NPC-002 | AC21: 범용 동료 AI가 아니라 콘텐츠별 고정 지원 행동 호출
A22: 차한해 | B22: 회사 구조 | C22: 186 | D22: 186번 | 구조용 로프 발사기로 한도윤과 회사 직원 대피시키기 | E22: PC | F22: 길 하나 만들게! | G22: 구조용 로프 발사기 1회를 소비해 끊어진 계단·붕괴 통로에 임시 이동 경로를 생성함. | I22: 연출용+액티브 | J22: 차한해 | L22: 아이템 사용 | M22: 구조용 로프 발사기 1회 소모 | N22: 없음 | O22: 0 | P22: 0 | Q22: 피해 없음 | T22: 아이템 횟수 | U22: 0 | V22: 0.8 | W22: 이동 경로 | X22: 1 | Y22: 개 | Z22: 0 | AA22: 경로 생성 완료 | AB22: 없음 | AC22: 186번·188번 총 2회 사용
A23: 차한해 | B23: 심층 탐사 | C23: 249 | D23: 249번 | 별을 삼킨 강당가 변혜서임을 확정하고 선의 안정 장치 발동 견디기 | E23: PC | F23: 괜찮아, 아직. | G23: 선의 안정 장치가 큰 심리 충격으로 입력 흔들림이 발생할 때 1회 자동 발동해 자아마모 수치는 유지한 채 조작 흔들림만 완화함. | I23: 패시브+자동 | J23: 차한해 | L23: 사건 플래그 | M23: 선의 안정 장치 장착·친구 정체 확정 | N23: 없음 | O23: 0 | P23: 0 | Q23: 피해 없음 | T23: 1회 자동 | U23: 0 | V23: 0 | W23: 입력 흔들림 | X23: -100 | Y23: % | Z23: 10 | AA23: 10초 종료 | AB23: SKL-STS-013 | AC23: 196번에서 장치 획득·249번 첫 자동 발동
A24: 차한해 | B24: 폐교 은폐 | C24: 215 | D24: 215번 | 고밀도 충격 흡수 장화로 등 뒤 한 칸의 기습을 버티며 복도 통과하기 | E24: PC | F24: 쉿. | G24: 이동을 잠시 멈추고 소리 발생 행동을 제한해 청각 추적형 변이체의 추적 게이지를 끊음. | I24: 액티브 | J24: 차한해 | L24: 입력 유지 | M24: 1초간 이동·공격 입력 없음 | N24: 없음 | O24: 0 | P24: 0 | Q24: 피해 없음 | T24: 개별 | U24: 2.5 | V24: 1 | W24: 소음 발생량 | X24: -100 | Y24: % | Z24: 1.5 | AA24: 이동·공격 입력 | AB24: 없음 | AC24: 은폐 전용
A25: 차한해 | B25: 폐교 공명 | C25: 238 | D25: 238번 | 보랏빛 사랑의 매로 기억 외피 공명 타격 시험하기 | E25: PC | F25: 껍데기부터 | G25: 사랑의 매로 보랏빛 공명 외피만 골라 때려 외피 방어를 먼저 제거하는 전용 공략 스킬. | I25: 액티브 | J25: 차한해 | L25: 약점 노출 | M25: 공명 외피 활성 | N25: 기본 공격력 비율 | O25: 1.3 | P25: 0 | Q25: 기본 공격력 × 130% | T25: 개별 | U25: 2.8 | V25: 0.45 | W25: 외피 피해 | X25: 50 | Y25: % | Z25: 0 | AA25: 외피 파괴 | AB25: 없음 | AC25: 본체 피해보다 외피 제거에 특화
A26: 차한해 | B26: 폐교 투척 | C26: 244 | D26: 244번 | 농구공의 투척 궤적 익히기 | E26: PC | F26: 한 번 튕겨! | G26: 보랏빛 농구공을 벽·골대에 반사시켜 직선으로 닿지 않는 기억 핵을 타격함. | I26: 액티브 | J26: 차한해 | L26: 입력 | M26: 반사 경로 조준 완료 | N26: 기본 공격력 비율 | O26: 1.1 | P26: 0 | Q26: 기본 공격력 × 110% | T26: 개별 | U26: 2 | V26: 0.55 | W26: 반사 횟수 | X26: 1 | Y26: 회 | Z26: 0 | AA26: 공 회수·화면 밖 이탈 | AB26: 없음 | AC26: 반사 성공 시 기억 핵 판정 가능
... A31: 차한해·동료 | B31: 최종 보스 | C31: 287 | D31: 287번 | 차한해에게 연결된 무한대 부담 장치 파괴하기 | E31: PC | F31: 이번엔 같이. | G31: 차한해 혼자 무한대 부담을 받아내지 않고 전장에 분산된 연결 장치를 동료와 동시 작동시키는 협력형 사건 스킬. | I31: 연출용+액티브 | J31: 차한해·동료 | L31: 동시 입력 | M31: 부담 연결 장치 4개 활성 | N31: 없음 | O31: 0 | P31: 0 | Q31: 피해 없음 | T31: 페이즈 1회 | U31: 0 | V31: 0.6 | W31: 부담 연결 | X31: -4 | Y31: 개 | Z31: 0 | AA31: 장치 4개 동시 파괴 | AB31: 없음 | AC31: 최종부 주제인 책임 분담을 전투 기믹으로 표현
A32: 도시 전체 시민 | B32: 희생 엔딩 | C32: 296 | D32: 296번 | 모두가 각자 가까운 균열로 함께 들어가기 | E32: PC | F32: 눈물 | G32: 차한해가 혼자 균열로 들어가는 희생 경로에서 진입 직전 UI로 반드시 사용하는 마지막 스킬. 눈물 한 방울과 함께 기억·감정이 도시 전체로 공명됨. | I32: 연출용+액티브 | J32: 도시 전체 시민 | K32: 죄책감 | L32: 1회 강제 발동 | M32: 단독 희생 엔딩 확정·균열 진입 직전 | N32: 없음 | O32: 0 | P32: 0 | Q32: 피해 없음 | T32: 엔딩 1회 | U32: 0 | V32: 2 | W32: 없음 | X32: 0 | Y32: 없음 | Z32: 0 | AA32: 눈물 연출 종료·균열 진입 | AB32: SKL-STS-015 | AC32: 공동 진입 엔딩에서는 UI 자체가 나타나지 않음
A33: 차한해 | B33: 고유 특성 | C33: 112 | D33: 112번 | 다른 측정기로 재측정하고 같은 오류 확인하기 | E33: PC | F33: 무한 선의 | G33: 차한해의 선의 감소 연산을 0으로 고정하고 측정 상한을 반복 초과시키는 태생적 패시브. 전투 행위 자체는 선의 감소 조건이 아님. | I33: 패시브 | J33: 차한해 | L33: 상시 | M33: 차한해 활성 상태 | N33: 없음 | O33: 0 | P33: 0 | Q33: 피해 없음 | T33: 없음 | U33: 0 | V33: 0 | W33: 선의 감소량 | X33: 0 | Y33: 고정값 | Z33: 0 | AA33: 해제 불가 | AB33: 없음 | AC33: 112번 재측정에서 시스템적으로 확정
A34: 한도윤 | B34: 회사 구조 | C34: 186 | D34: 186번 | 구조용 로프 발사기로 한도윤과 회사 직원 대피시키기 | E34: NPC | F34: 찾았어, 여기야! | G34: 한도윤 인연 100%에서 [도와줘!]로 호출되는 지원 행동. 마지막 직원의 위치를 무전과 표식으로 즉시 알려 줌. | I34: 지원+이벤트 | J34: 한도윤 | L34: 연계 호출 | M34: SKL-PC-020 사용·한도윤 인연 100% | N34: 없음 | O34: 0 | P34: 0 | Q34: 피해 없음 | T34: 상황당 1회 | U34: 0 | V34: 0.5 | W34: 탐색 후보 | X34: -1 | Y34: 구역 | Z34: 0 | AA34: 위치 표식 확인 | AB34: 없음 | AC34: 범용 AI 이동이 아니라 정보 지원
A35: 나대진 | B35: 최종 보스 | C35: 287 | D35: 287번 | 차한해에게 연결된 무한대 부담 장치 파괴하기 | E35: NPC | F35: 여기서 받쳐줄게 | G35: 나대진 인연 100%에서 [도와줘!]로 호출되는 원격 지원. 치명 피해 1회를 막고 가장 가까운 부담 장치 1개를 안정화함. | I35: 지원+이벤트 | J35: 나대진 | L35: 연계 호출 | M35: SKL-PC-020 사용·나대진 인연 100% | N35: 없음 | O35: 0 | P35: 0 | Q35: 피해 없음 | T35: 전투당 1회 | U35: 0 | V35: 0.4 | W35: 치명 피해 | X35: -100 | Y35: % | Z35: 0 | AA35: 지원 1회 소모 | AB35: 없음 | AC35: 270번에서 지원 조건 해금
A36: 피격 대상 | B36: 공용 상태 | C36: 119 | D36: 최초 호출 | 119번 | E36: 상태/시스템 | F36: 경직 | G36: 일정 시간 대상의 이동·공격 입력 또는 AI 행동을 중단시키는 공용 상태. | I36: 상태이상 | J36: 피격 대상 | K36: 행동 불가 | L36: 연계 호출 | M36: 경직을 부여하는 스킬 적중 | N36: 없음 | O36: 0 | P36: 0 | Q36: 피해 없음 | T36: 없음 | U36: 0 | V36: 0 | W36: 행동 가능 여부 | X36: -1 | Y36: 상태 | Z36: 1 | AA36: 지속 종료 | AB36: 없음 | AC36: 호출 스킬이 지속 시간을 덮어씀
A37: 피격 대상 | B37: 공용 상태 | C37: 130 | D37: 최초 호출 | 130번 | E37: 상태/시스템 | F37: 밀려남 | G37: 대상을 공격 방향 반대로 강제 이동시키는 공용 위치 제어 상태. | I37: 상태이상 | J37: 피격 대상 | K37: 강제 이동 | L37: 연계 호출 | M37: 밀치기·돌진·충격파 적중 | N37: 없음 | O37: 0 | P37: 0 | Q37: 피해 없음 | T37: 없음 | U37: 0 | V37: 0 | W37: 위치 이동 | X37: 1.5 | Y37: 칸 | Z37: 0 | AA37: 이동 완료 | AB37: 없음 | AC37: 보스·고정형 개체는 거리 감소
A38: 피격 대상 | B38: 공용 상태 | C38: 160 | D38: 최초 호출 | 160번 | E38: 상태/시스템 | F38: 이동 둔화 | G38: 대상의 이동 속도를 일정 시간 낮추는 공용 상태. | I38: 상태이상 | J38: 피격 대상 | K38: 이동 속도 감소 | L38: 연계 호출 | M38: 이동 방해 계열 스킬 적중 | N38: 없음 | O38: 0 | P38: 0 | Q38: 피해 없음 | T38: 없음 | U38: 0 | V38: 0 | W38: 이동 속도 | X38: -40 | Y38: % | Z38: 3 | AA38: 지속 종료 | AB38: 없음 | AC38: 중첩 시 높은 값 우선
A39: 시전자·아군 | B39: 공용 상태 | C39: 103 | D39: 최초 호출 | 103번 | E39: 상태/시스템 | F39: 공격 강화 | G39: 몬스터 또는 무리의 공격력을 일정 시간 높이는 공용 강화 상태. | I39: 버프 | J39: 시전자·아군 | L39: 연계 호출 | M39: 강화·가속·구호 계열 스킬 성공 | N39: 없음 | O39: 0 | P39: 0 | Q39: 피해 없음 | T39: 없음 | U39: 0 | V39: 0 | W39: 공격력 | X39: 20 | Y39: % | Z39: 6 | AA39: 지속 종료 | AB39: 없음 | AC39: 선도체·갈채 계열 공용
A40: 시전자·아군 | B40: 공용 상태 | C40: 179 | D40: 최초 호출 | 179번 | E40: 상태/시스템 | F40: 보호막 | G40: 일정량의 피해를 본체보다 먼저 흡수하는 공용 방어 상태. | I40: 버프 | J40: 시전자·아군 | L40: 연계 호출 | M40: 보호막·외피 계열 스킬 성공 | N40: 없음 | O40: 0 | P40: 0 | Q40: 피해 없음 | T40: 없음 | U40: 0 | V40: 0 | W40: 보호막 | X40: 20 | Y40: % | Z40: 6 | AA40: 보호막 소진·지속 종료 | AB40: 없음 | AC40: 최대 HP 비율 기준
A41: 차한해 | B41: 공용 상태 | C41: 222 | D41: 최초 호출 | 222번 | E41: 상태/시스템 | F41: 방향 혼란 | G41: 플레이어의 이동·전조 방향 정보를 짧게 뒤틀어 판단을 방해하는 상태. | I41: 디버프 | J41: 차한해 | K41: 방향 정보 왜곡 | L41: 연계 호출 | M41: 환각·혼란 계열 스킬 적중 | N41: 없음 | O41: 0 | P41: 0 | Q41: 피해 없음 | T41: 없음 | U41: 0 | V41: 0 | W41: 방향 판독 | X41: -1 | Y41: 단계 | Z41: 2.5 | AA41: 지속 종료 | AB41: 없음 | AC41: 접근성 설정에서 시각 왜곡 완화 가능
A42: 대상·위치 | B42: 공용 상태 | C42: 103 | D42: 최초 호출 | 103번 | E42: 상태/시스템 | F42: 표적 지정 | G42: AI가 특정 대상 또는 위치를 우선 목표로 삼도록 바꾸는 공용 상태. | I42: 상태이상 | J42: 대상·위치 | K42: 우선 표적 변경 | L42: 연계 호출 | M42: 지정·호명·유인 계열 스킬 성공 | N42: 없음 | O42: 0 | P42: 0 | Q42: 피해 없음 | T42: 없음 | U42: 0 | V42: 0 | W42: AI 우선순위 | X42: 1 | Y42: 단계 | Z42: 4 | AA42: 대상 이탈·지속 종료 | AB42: 없음 | AC42: PC 유인과 몬스터 호명 모두 사용
A43: 연결 대상 | B43: 공용 상태 | C43: 275 | D43: 최초 호출 | 275번 | E43: 상태/시스템 | F43: 피해 전가 | G43: 받을 피해 또는 상태이상을 연결된 다른 대상에게 넘기는 상태. | I43: 상태이상 | J43: 연결 대상 | K43: 피해 이전 | L43: 연계 호출 | M43: 전가 연결 활성 | N43: 없음 | O43: 0 | P43: 0 | Q43: 피해 없음 | T43: 없음 | U43: 0 | V43: 0 | W43: 피해 이전 | X43: 70 | Y43: % | Z43: 5 | AA43: 연결 해제·대상 소멸 | AB43: 없음 | AC43: 시민 환영 연결은 직접 피해 판정 없음
A44: 피격 대상 | B44: 공용 상태 | C44: 276 | D44: 최초 호출 | 276번 | E44: 상태/시스템 | F44: 속박 | G44: 이동 또는 특정 행동 입력을 잠시 제한하는 공용 제어 상태. | I44: 상태이상 | J44: 피격 대상 | K44: 이동·행동 제한 | L44: 연계 호출 | M44: 속박·행동 봉쇄 적중 | N44: 없음 | O44: 0 | P44: 0 | Q44: 피해 없음 | T44: 없음 | U44: 0 | V44: 0 | W44: 이동 속도 | X44: -100 | Y44: % | Z44: 1.5 | AA44: 지속 종료·해제 입력 성공 | AB44: 없음 | AC44: 장비 저항으로 지속시간 감소
...

Sheet 아이템
A1: 이름 | B1: 타입 | C1: 참고 이미지 | D1: 사용 권한 | 획득 방식 | 획득 조건 | G1: 거래 제한 | H1: 사용 조건 | I1: 공격 수치 | 공격 보정 | K1: 방어 수치 | 방어 보정 | M1: 기타 수치 | N1: 세트 이름 | 효과 | 내용 | Q1: 수치 | R1: 최소 공격력 | S1: 최대 공격력
A2: 관리국 지급 권총 | B2: 무기 | D2: 선의관리국 요원 | E2: 퀘스트 | F2: 118번 | 관리국 표준 대응 장비 8종·응급품 2종을 수령하고 상태 UI 확인하기 | G2: 획득 시 귀속 | H2: 119번 이후 | 균열 대응 원거리 전투에서 사용 | I2: 20 | J2: 원거리 공격 보정 +5 | K2: 0 | N2: 관리국 표준 대응 세트 | O2: 2세트: 장비 교체 시간 -10% 5세트: 균열 오염 저항 +10 8세트: 자아 마모 누적량 -15% | P2: 물리·관통 | Q2: 100 | R2: 18 | S2: 22
A3: 기본 보호 조끼 | B3: 상의 | D3: 선의관리국 요원 | E3: 퀘스트 | F3: 118번 | 관리국 표준 대응 장비 8종·응급품 2종을 수령하고 상태 UI 확인하기 | G3: 획득 시 귀속 | H3: 130번 사용·131번 손상·188번 완전 파손 | I3: 0 | K3: 30 | L3: 충격 저항 +8 | N3: 관리국 표준 대응 세트 | P3: 충격 저항 | Q3: 100 | R3: 0 | S3: 0
A4: 관리국 방진 고글 | B4: 얼굴 | D4: 선의관리국 요원 | E4: 퀘스트 | F4: 118번 | 관리국 표준 대응 장비 8종·응급품 2종을 수령하고 상태 UI 확인하기 | G4: 획득 시 귀속 | H4: 128번 공명 흔적 추적·192번 먼지 보호 안경으로 교체 | I4: 0 | K4: 4 | L4: 분진·시야 방해 저항 +10 | M4: 균열 감지 범위 +2m | N4: 관리국 표준 대응 세트 | P4: 균열 감지 패시브 | Q4: +2m | R4: 0 | S4: 0
A5: 관리국 대응 장갑 | B5: 손 | D5: 선의관리국 요원 | E5: 퀘스트 | F5: 118번 | 관리국 표준 대응 장비 8종·응급품 2종을 수령하고 상태 UI 확인하기 | G5: 획득 시 귀속 | H5: 123번 잔해 제거·153번 공명 보호 장갑으로 교체 | I5: 3 | J5: 근접 공격 보정 +2 | K5: 5 | L5: 접촉 피해 감소 +5% | M5: 상호작용 속도 +5% | N5: 관리국 표준 대응 세트 | P5: 접촉 안정 패시브 | Q5: 피해 -5% | R5: 2 | S5: 4
A6: 관리국 전술화 | B6: 신발 | D6: 선의관리국 요원 | E6: 퀘스트 | F6: 118번 | 관리국 표준 대응 장비 8종·응급품 2종을 수령하고 상태 UI 확인하기 | G6: 획득 시 귀속 | H6: 119·126번 회피 훈련·196번 고밀도 충격 흡수 장화로 교체 | I6: 0 | K6: 6 | L6: 넘어짐 저항 +10% | M6: 회피 이동 거리 +5% | N6: 관리국 표준 대응 세트 | P6: 기동 보정 | Q6: +5% | R6: 0 | S6: 0
A7: 관리국 방진 마스크 | B7: 얼굴 | D7: 선의관리국 요원 | E7: 퀘스트 | F7: 118번 | 관리국 표준 대응 장비 8종·응급품 2종을 수령하고 상태 UI 확인하기 | G7: 획득 시 귀속 | H7: 128번 필터 교체 후 공명 흔적 추적·192번 균열 보호 마스크로 교체 | I7: 0 | K7: 3 | L7: 균열 오염 저항 +8 | M7: 자아 마모 저항 +3% | N7: 관리국 표준 대응 세트 | P7: 오염 저항 | Q7: 108 | R7: 0 | S7: 0
A8: 관리국 무전 이어피스 | B8: 액세서리 | D8: 선의관리국 요원 | E8: 퀘스트 | F8: 118번 | 관리국 표준 대응 장비 8종·응급품 2종을 수령하고 상태 UI 확인하기 | G8: 획득 시 귀속 | H8: 125번 공격 예고 판독에 사용 | I8: 0 | K8: 0 | M8: 공격 예고 판독 시간 +0.3초 | N8: 관리국 표준 대응 세트 | P8: 전술 정보 패시브 | Q8: +0.3초 | R8: 0 | S8: 0
A9: 관리국 상태 측정기 | B9: 액세서리 | D9: 선의관리국 요원 | E9: 퀘스트 | F9: 118번 | 관리국 표준 대응 장비 8종·응급품 2종을 수령하고 상태 UI 확인하기 | G9: 획득 시 귀속 | H9: 131번 장비 손상 확인·임무 종료 시 자동 동기화 | I9: 0 | K9: 0 | M9: 장비 내구도·자아 마모도 표시 | N9: 관리국 표준 대응 세트 | P9: 상태 확인 패시브 | Q9: UI 표시 | R9: 0 | S9: 0
A10: 보랏빛 철봉 | B10: 무기 | D10: 일반인 / 모든 선의 등급자 | E10: 콘텐츠 | F10: 129번 | 붕괴 표지판의 보랏빛 철봉 회수하기 | H10: 130번 밖으로 밀어내는 자 제압 후 132번 소멸 | I10: 80 | J10: 근접 강공격 보정 +10 | K10: 0 | M10: 경직 유발 +12% | P10: 충격 | Q10: 115 | R10: 72 | S10: 88
A11: 깨진 경찰 방패 | B11: 보조 장비 | D11: 일반인 / 모든 선의 등급자 | E11: 콘텐츠 | F11: 134번 | 구조한 경찰에게 깨진 경찰 방패와 휴대용 섬광 신호기 받기 | H11: 146번 닫힌 문지기 보스전·166번 파손 | I11: 0 | K11: 20 | L11: 전방 피해 감소 +12% | M11: 전방 방어 해금 | P11: 물리 저항 | Q11: 112 | R11: 0 | S11: 0
A12: 차단기 막대 | B12: 무기 | D12: 일반인 / 모든 선의 등급자 | E12: 콘텐츠 | F12: 140번 | 주차 차단기 막대의 공명을 확인하고 회수·무기 등록 | H12: 141번 유인·142번 출구를 가로막는 자 제압 | I12: 90 | J12: 근접 공격 보정 +12 | K12: 0 | M12: 환경 유인 효과 +10% | P12: 전기·충격 | Q12: 120 | R12: 81 | S12: 99
A13: 나무판 보호대 | B13: 팔 방어구 | D13: 일반인 / 모든 선의 등급자 | E13: 제작 | F13: 145번 | 대피소 시민과 나무판 보호대 제작 | H13: 146~148번 닫힌 문지기 보스전 사용 후 파손 | I13: 0 | K13: 10 | L13: 근접 피해 감소 +5% | M13: 임시 장비 제작 | P13: 물리 저항 | Q13: 105 | R13: 0 | S13: 0
A14: 소방용 진압 도끼 | B14: 무기 | D14: 고등급자 / 선의관리국 요원 | E14: 콘텐츠 | F14: 185번 | 회사로 우회하며 소방 보급 상자에서 확보 | G14: 획득 시 귀속 | H14: 188번 붕괴 잔해 3개 파괴 후 반납 | I14: 75 | J14: 구조물 공격 보정 +30 | K14: 0 | M14: 구조 행동 속도 +15% | N14: 재난 구조 세트 | O14: 2세트: 구조 행동 속도 +10% 4세트: 화염·연기 피해 -15% | P14: 화염 대응 | Q14: 115 | R14: 68 | S14: 82
A15: 소방 방열복 | B15: 상의 | D15: 고등급자 / 선의관리국 요원 | E15: 퀘스트 | F15: 187번 | 부상당한 소방관 구조 후 임시 대여 | G15: 획득 시 귀속 | H15: 188번 고열·낙하물 구간 통과 후 반납 | I15: 0 | K15: 22 | L15: 화염 피해 감소 +20% | M15: 이동 속도 -5% | N15: 재난 구조 세트 | P15: 화염 저항 | Q15: 120 | R15: 0 | S15: 0
A16: 구조대 안전모 | B16: 머리 | D16: 일반인 / 모든 선의 등급자 | E16: 콘텐츠 | F16: 185번 | 회사로 우회하며 소방 보급 상자에서 확보 | H16: 186~188번 낙하물 피해 대응 후 반납 | I16: 0 | K16: 8 | L16: 낙하물 피해 감소 +15% | M16: 기절 시간 -10% | N16: 재난 구조 세트 | P16: 낙하 충격 저항 | Q16: 115 | R16: 0 | S16: 0
A17: 구조용 로프 발사기 | B17: 보조 장비 | D17: 고등급자 / 선의관리국 요원 | E17: 퀘스트 | F17: 185번 | 회사로 우회하며 소방 보급 상자에서 확보 | G17: 획득 시 귀속 | H17: 186번 1회·188번 1회 사용 후 2회분 소진 | I17: 12 | J17: 원거리 경직 보정 +5 | K17: 0 | M17: 구조 이동 경로 해금 | N17: 재난 구조 세트 | P17: 이동 보조 패시브 | Q17: 2회 | R17: 10 | S17: 14
A18: 오염 차단 전신복 | B18: 상의 | D18: 고등급자 | E18: 퀘스트 | F18: 196번 | 관리국 현장 보급함에서 수령·장착 | G18: 획득 시 귀속 | H18: 213~217번 폐교 오염 조사·270번 최종 장비로 교체 | I18: 0 | K18: 35 | L18: 균열 오염 저항 +20 | M18: 자아 마모 누적량 -8% | N18: 심층 균열 탐사 세트 | O18: 2세트: 균열 감지 범위 +3m 4세트: 자아 마모 누적량 -12% | P18: 균열 저항 | Q18: 120 | R18: 0 | S18: 0
A19: 심층 균열 탐사 헬멧 | B19: 머리 | D19: 고등급자 | E19: 퀘스트 | F19: 196번 | 관리국 현장 보급함에서 수령·장착 | G19: 획득 시 귀속 | H19: 213·217번 흔적·퍼즐 단서 탐지 | I19: 0 | K19: 12 | L19: 정신 피해 저항 +10 | M19: 균열 감지 범위 +4m | N19: 심층 균열 탐사 세트 | P19: 균열 감지 패시브 | Q19: +4m | R19: 0 | S19: 0
A20: 선의 안정 장치 | B20: 액세서리 | D20: 차한해 전용 | E20: 업적 | F20: 196번 | 시민 구조 누적 30회 달성 후 관리국 현장 보급함에서 추가 수령 | G20: 획득 시 귀속 | H20: 249번 친구 정체 확인 시 1회 자동 발동 | I20: 0 | K20: 0 | M20: 자아마모 수치 유지·입력 흔들림 10초 완화 | N20: 심층 균열 탐사 세트 | P20: 입력 안정 | Q20: 10초 | R20: 0 | S20: 0
A21: 고밀도 충격 흡수 장화 | B21: 신발 | D21: 고등급자 | E21: 퀘스트 | F21: 196번 | 관리국 현장 보급함에서 수령·장착 | G21: 획득 시 귀속 | H21: 215번 밀치기 방어·251번 친구 접근·270번 강화 전투화로 교체 | I21: 0 | K21: 10 | L21: 넘어짐·밀쳐짐 저항 +20% | M21: 회피 후 경직 시간 -10% | N21: 심층 균열 탐사 세트 | P21: 기동 안정 | Q21: 120 | R21: 0 | S21: 0
A22: 응급 압박 붕대 | B22: 소모품 | D22: 일반인 / 모든 선의 등급자 | E22: 보급 | F22: 144번 | 봉쇄 대피소 보급 상자에서 획득 | H22: 146번 닫힌 문지기 보스전에서 1회 사용 | I22: 0 | K22: 0 | M22: 체력 20% 회복 | P22: 회복 | Q22: 20 | R22: 0 | S22: 0
A23: 관리국 응급 주사 | B23: 소모품 | D23: 선의관리국 요원 | E23: 퀘스트 | F23: 118번 | 관리국 표준 대응 장비와 함께 지급 | G23: 획득 시 귀속 | H23: 168번 융합된 괴물 보스전에서 1회 사용 | I23: 0 | K23: 0 | M23: 체력 35% 회복, 이동 속도 5초간 -10% | P23: 회복 | Q23: 35 | R23: 0 | S23: 0
A24: 안정 앰플 | B24: 소모품 | D24: 고등급자 / 차한해 전용 | E24: 퀘스트 | F24: 192번 | 나대진에게 환경 장비와 함께 수령 | G24: 획득 시 귀속 | H24: 250번 공격 중지 생존 구간에서 1회 사용 | I24: 0 | K24: 0 | M24: 자아마모 수치 유지·UI 간섭 8초 완화 | P24: UI 안정 | Q24: 8초 | R24: 0 | S24: 0
A25: 소형 방진 필터 | B25: 소모품 | D25: 일반인 / 모든 선의 등급자 | E25: 보급 | F25: 121번 | 도심 잔해 구역 이동 중 관리국 보급 상자에서 획득 | H25: 128번 관리국 방진 마스크에 1회 사용 | I25: 0 | K25: 0 | M25: 마스크 내구도 30 회복 | P25: 장비 회복 | Q25: 30 | R25: 0 | S25: 0
A26: 휴대용 섬광 신호기 | B26: 소모품 | D26: 일반인 / 모든 선의 등급자 | E26: 콘텐츠 | F26: 134번 | 구조한 경찰에게 깨진 방패와 함께 받기 | H26: 141번 안쪽을 차지한 자 유인에 1회 사용 | I26: 0 | K26: 0 | M26: 일반 괴물 주의 분산 4초 | P26: 시야 교란 | Q26: 4 | R26: 0 | S26: 0
A27: 비살상 충격탄 | B27: 탄약 | D27: 선의관리국 요원 | E27: 퀘스트 | F27: 118번 | 관리국 표준 대응 장비와 함께 지급 | G27: 획득 시 귀속 | H27: 119번 사격 훈련·125번 비살상 제압에 사용 | I27: 6 | J27: 경직 피해 +20% | K27: 0 | M27: 처치 대신 제압 게이지 증가 | P27: 비살상 충격 | Q27: 120 | R27: 5 | S27: 7
A28: 고등급자 공명 증폭기 | B28: 액세서리 | D28: 고등급자 | E28: 나대진 지급 | F28: 153번 | [나대진] 75% 이상에서 장비 지원으로 수령 | G28: 획득 시 귀속 | H28: 159번 공명 탐지·160번 달라붙은 자 제압 | I28: 15 | J28: 균열 개체 대상 피해 +8% | K28: 0 | M28: 공명 피해 증가·UI 간섭 +3% | P28: 공명 증폭 | Q28: 108 | R28: 13 | S28: 17
A29: 연구실 최고 권한 키카드 | B29: 접근 도구 | D29: 연구실 최고 권한자 | E29: 지원 | F29: 265번 | [나대진] 85% 이상에서 암호 메시지를 확인하고 회수 | G29: 획득 시 귀속 | H29: 266번 첫 번째 연구실 보안문 해제 | I29: 0 | K29: 0 | M29: 최고 보안 구역 접근 | P29: 접근 권한 | Q29: 최고 | R29: 0 | S29: 0
A30: 보안 요원 생체 인증 모듈 | B30: 접근 도구 | D30: 차한해 | E30: 나대진·보안 요원 지원 | F30: 265번 | [나대진] 85% 이상에서 협조한 보안 요원이 발급하고 나대진이 전달한 모듈 회수 | G30: 획득 시 귀속 | H30: 266번 두 번째 연구실 생체 인식문 해제 | I30: 0 | K30: 0 | M30: 보안 구역 접근 | P30: 생체 인증 | Q30: 1회 | R30: 0 | S30: 0
A31: 충격 보호대 | B31: 보조 장비 | D31: 차한해 | E31: 나대진 지급 | F31: 153번 | 충격 보호대·공명 보호 장갑·공명 증폭기 수령 | G31: 획득 시 귀속 | H31: 164~168번 융합된 괴물 보스전에서 사용 | I31: 0 | K31: 20 | L31: 피격 경직 감소 | P31: 충격 보호 | Q31: 20 | R31: 0 | S31: 0
A32: 공명 보호 장갑 | B32: 손 | D32: 차한해 | E32: 나대진 지급 | F32: 153번 | 충격 보호대·공명 보호 장갑·공명 증폭기 수령 | G32: 획득 시 귀속 | H32: 159~168번 공명 무기·증폭기 사용 부담 완화 | I32: 0 | K32: 15 | L32: 공명 반동 감소 | P32: 공명 보호 | Q32: 15 | R32: 0 | S32: 0
A33: 전광판 쇠막대 | B33: 무기 | D33: 차한해 | E33: 현장 획득 | F33: 159번 | 공명 증폭기로 승강장 전광판 쇠막대 회수 | H33: 160번 달라붙은 자 제압 | I33: 100 | J33: 다수 정렬 타격 | K33: 0 | P33: 충격 | Q33: 100 | R33: 90 | S33: 110
A34: 군용 방탄판 | B34: 상의 | D34: 차한해 | E34: 군인 지원 | F34: 169번 | 구조된 군인에게 지원받기 | G34: 획득 시 귀속 | H34: 178~181번 갈채를 먹는 자 보스전·181번 균열 | I34: 0 | K34: 35 | L34: 강한 공격 방어 | P34: 물리 저항 | Q34: 35 | R34: 0 | S34: 0
A35: 화염 보호복 | B35: 상의 | D35: 차한해 | E35: 소방관 지원 | F35: 187번 | 도시 인연 50% 이상에서 부상당한 소방관 구조 보상으로 획득 | G35: 획득 시 귀속 | H35: 188번 회사 화재 구조·손상 후 +10 유지 | I35: 0 | K35: 20 | L35: 화염 피해 대응 | P35: 화염 저항 | Q35: 20 | R35: 0 | S35: 0
A36: 먼지 보호 안경 | B36: 얼굴 | D36: 차한해 | E36: 나대진 지급 | F36: 192번 | 폐교 환경 장비 수령 | G36: 획득 시 귀속 | H36: 213~217번 폐교 분진·시야 방해 구간 | I36: 0 | K36: 10 | L36: 분진 시야 확보 | P36: 분진 저항 | Q36: 10 | R36: 0 | S36: 0
A37: 균열 보호 마스크 | B37: 얼굴 | D37: 차한해 | E37: 나대진 지급 | F37: 192번 | 폐교 환경 장비 수령 | G37: 획득 시 귀속 | H37: 213~217번 폐교 균열 오염 구간 | I37: 0 | K37: 15 | L37: 균열 오염 차단 | P37: 균열 저항 | Q37: 15 | R37: 0 | S37: 0
A38: 철판 보호대 | B38: 보조 장비 | D38: 차한해 | E38: 정비공 지원 | F38: 194번 | 구조받은 정비공에게 획득 | G38: 획득 시 귀속 | H38: 246~251번 폐교의 보스전·251번 파손 | I38: 0 | K38: 25 | L38: 충격 보호 | P38: 물리 저항 | Q38: 25 | R38: 0 | S38: 0
A39: 사랑의 매 | B39: 무기 | D39: 차한해 | E39: 현장 획득 | F39: 237번 | 공명 확인 후 회수·무기 등록 | H39: 238번 시험·246번 폐교의 보스 외피 파괴 | I39: 140 | J39: 공명 외피 파괴 | K39: 0 | P39: 공명 | Q39: 140 | R39: 126 | S39: 154
A40: 매트 보호대 | B40: 보조 장비 | D40: 차한해 | E40: 현장 제작 | F40: 242번 | 체육관 매트로 제작 | G40: 획득 시 귀속 | H40: 246~251번 폐교의 보스전·251번 파손 | I40: 0 | K40: 15 | L40: 충격 완화 | P40: 물리 저항 | Q40: 15 | R40: 0 | S40: 0
...

Sheet 속성 대차대조표
A1: 1. 속성 정의 및 적용 대상
A2: 속성 | B2: 핵심 성질 | E2: 공격 속성 적용 | I2: 방어 속성 적용 | M2: 대표 표현
A3: 안정 | B3: 형태와 에너지의 상태를 고정하고 과도한 진동을 억제하는 파장 | E3: 공명 주기 고정, 흔들림 억제, 변이체의 움직임 안정화 | I3: 공명·진동 피해 완화, 밀려남과 흔들림을 억제하는 방호 상태 | M3: 청색 고정선, 입자가 한 지점으로 모이는 연출
A4: 공명 | B4: 파동을 반복·중첩하여 내부 진동과 에너지 증폭을 일으키는 파장 | E4: 반복 타격과 파동 중첩, 차단 한계 초과, 균열 확대 | I4: 외부 파장을 되울리거나 분산하여 충격을 흘려보내는 상태 | M4: 보라색 파문, 동심원과 진동 잔상
A5: 차단 | B5: 에너지·파장·오염의 전달 경로와 연결을 끊는 파장 | E5: 능력 연결 절단, 침식 확산 중단, 유지 에너지 공급 방해 | I5: 외부 에너지 유입과 상태이상 전이를 막는 방호 상태 | M5: 짙은 회색 단절선, 벽 형태의 끊김 연출
A6: 침식 | B6: 조직과 구조의 결합을 약화하고 형태를 점진적으로 붕괴시키는 파장 | E6: 고정 구조 붕괴, 방어 상태 약화, 균열 부위 확대 | I6: 공격 에너지를 분해·흡수하며 일부 피해를 약화하는 상태 | M6: 자홍색 번짐, 표면이 부식되듯 퍼지는 연출
A8: 2. 속성 대차대조표 및 피해 계산 검증
A9: 피해 매개 상수표 K | G9: 상성 순환
A10: 공격자＼방어자 | B10: 안정 | C10: 공명 | D10: 차단 | E10: 침식 | L10: 안정 → 공명 → 차단 → 침식 → 안정은 ×1.7의 강한 우위 관계이며, 반대 방향은 ×0.3의 강한 열위 관계로 적용함.
A11: 안정 | B11: 1 | C11: 1.7 | D11: 0.8 | E11: 0.3
A12: 공명 | B12: 0.3 | C12: 1 | D12: 1.7 | E12: 1.2
A13: 차단 | B13: 1.2 | C13: 0.3 | D13: 1 | E13: 1.7
A14: 침식 | B14: 1.7 | C14: 0.8 | D14: 0.3 | E14: 1
A16: 3. 수치 근거표
A17: 공격 속성 | B17: 방어 속성 | C17: 관계 유형 | E17: 매개 상수 | G17: 수치 적용 근거 | L17: 전투 표현
A18: 안정 | B18: 안정 | C18: 동일 | E18: 1 | G18: 동일한 파장끼리는 서로 우위가 없으므로 기존 피해식에 영향을 주지 않음. | L18: 기본 피해 수치와 기본 속성 이펙트 적용
A19: 안정 | B19: 공명 | C19: 강한 우위 | E19: 1.7 | G19: 안정 파장이 진동 주기를 고정하여 공명의 반복·증폭 작용을 직접 억제함. | L19: 파동이 멈추고 약점 적중 이펙트 강조
A20: 안정 | B20: 차단 | C20: 약한 열위 | E20: 0.8 | G20: 차단 상태가 안정 파장의 전달 경로를 일부 끊어 고정 효과가 충분히 도달하지 못함. | L20: 안정선이 끊기며 피해 표시를 약하게 표현
A21: 안정 | B21: 침식 | C21: 강한 열위 | E21: 0.3 | G21: 이미 침식된 구조는 고정할 원형과 기준이 약해 안정화 효과가 크게 감소함. | L21: 고정선이 번짐에 흡수되는 연출
A22: 공명 | B22: 안정 | C22: 강한 열위 | E22: 0.3 | G22: 안정된 구조가 진동의 확산과 파동 중첩을 막아 공명 증폭이 발생하기 어려움. | L22: 파문이 짧게 사라지는 연출
A23: 공명 | B23: 공명 | C23: 동일 | E23: 1 | G23: 동일한 파장끼리는 서로 우위가 없으므로 기존 피해식에 영향을 주지 않음. | L23: 기본 피해 수치와 기본 속성 이펙트 적용
A24: 공명 | B24: 차단 | C24: 강한 우위 | E24: 1.7 | G24: 반복되는 공명 파동이 차단 상태의 처리 한계를 넘어 과부하를 발생시킴. | L24: 차단벽에 균열이 번지고 파동이 관통하는 연출
A25: 공명 | B25: 침식 | C25: 약한 우위 | E25: 1.2 | G25: 침식으로 약해진 구조의 미세 균열을 진동이 확대하여 붕괴를 촉진함. | L25: 침식 부위가 파동에 따라 넓어지는 연출
A26: 차단 | B26: 안정 | C26: 약한 우위 | E26: 1.2 | G26: 안정 상태를 유지하는 에너지 공급과 연결을 끊어 구조의 유지력을 약화함. | L26: 고정선 일부가 끊기며 약점 이펙트 표시
A27: 차단 | B27: 공명 | C27: 강한 열위 | E27: 0.3 | G27: 공명은 파동이 누적된 뒤에도 영향이 남아 단일 연결 차단만으로 완전히 제거하기 어려움. | L27: 차단선 너머로 파문이 이어지는 연출
A28: 차단 | B28: 차단 | C28: 동일 | E28: 1 | G28: 동일한 파장끼리는 서로 우위가 없으므로 기존 피해식에 영향을 주지 않음. | L28: 기본 피해 수치와 기본 속성 이펙트 적용
A29: 차단 | B29: 침식 | C29: 강한 우위 | E29: 1.7 | G29: 침식 에너지의 접촉·전이·확산 경로를 끊어 핵심 작용을 직접 무력화함. | L29: 번짐이 절단되고 약점 적중 이펙트 강조
... A33: 침식 | B33: 침식 | C33: 동일 | E33: 1 | G33: 동일한 파장끼리는 서로 우위가 없으므로 기존 피해식에 영향을 주지 않음. | L33: 기본 피해 수치와 기본 속성 이펙트 적용

Sheet 몬스터
B1: 검증 항목 | C1: 값 | E1: 작성 기준
B2: 전체 콘텐츠 수 | C2: 306 | E2: ▶향후 콘텐츠 및 이벤트의 추가·삭제·수정에 따른 순서 변경과 연계 오류에 유연하게 대응할 수 있도록, 몬스터가 배치되지 않은 구간을 포함해 게임 시작부터 종료까지의 전체 콘텐츠 흐름을 작성함. ▶관련 정보가 없는 항목은 공란으로 유지하여 실제 배치 여부를 명확히 구분하고, 문서의 확장성·추적성· 유지보수성을 확보함.
B3: 몬스터 배치 콘텐츠 수 | C3: =COUNTIF(C7:C312,"<>") -> 42
B4: 몬스터 미배치 콘텐츠 수 | C4: =C2-C3 -> 264
B5: 콘텐츠 누락 개수 | C5: =C2-COUNT(A7:A312) -> 0
A6: 콘텐츠 제시 순서 | C6: 몬스터 이름 | D6: 몬스터 이미지 | E6: 몬스터 타입 | F6: 생명력 | G6: 공격력 | H6: 공격력 합산 STATUS | I6: 공격력 보정 | J6: 최종 공격력 | K6: 방어력 | L6: 방어력 합산 STATUS | M6: 방어력 보정 | N6: 최종 방어력 | O6: 스킬1 | P6: 발동률1 | Q6: 스킬2 | R6: 발동률2 | S6: 스킬3 | T6: 발동률3 | U6: 스킬4 | V6: 발동률4 | W6: 비고
A7: 1 | J7: =IF(C7="","",G7+I7) | N7: =IF(C7="","",K7+M7)
A8: 2
A9: 3
A10: 4
A11: 5
A12: 6
A13: 7
A14: 8
A15: 9
A16: 10
A17: 11
A18: 12
A19: 13
... A70: 64
A71: 65 | J71: =IF(C71="","",G71+I71) | N71: =IF(C71="","",K71+M71)
A72: 66
A73: 67
A74: 68
A75: 69
A76: 70
A77: 71
A78: 72
A79: 73
A80: 74 | B80: 조건부 선공 | C80: 균열에서 기어 나온 자 | E80: 초기 변이체 | F80: 30 | G80: 4 | H80: 근접 본능 | I80: 1 | J80: 5 | K80: 0 | L80: 불완전한 외피 | M80: 0 | N80: 0 | O80: 느린 할퀴기 | P80: 70 | Q80: 비틀거리며 접근 | R80: 30 | T80: 0 | V80: 0 | W80: 차한해의 첫 괴물 조우용. 1~2챕터에는 괴물이 등장하지 않으며, 3챕터 새벽 재난부터 은폐·회피로 처음 마주침.
A81: 75
A82: 76
A83: 77
A84: 78 | B84: 조건부 선공 | C84: 문 앞에 웅크린 자 | E84: 초기 변이체 | F84: 60 | G84: 7 | H84: 기습 반응 | I84: 1 | J84: 8 | K84: 2 | L84: 웅크린 자세 | M84: 1 | N84: 3 | O84: 갑작스러운 덮치기 | P84: 45 | Q84: 문 앞 버티기 | R84: 35 | S84: 고개 들기 | T84: 20 | V84: 0 | W84: 차한해의 접촉으로 괴물이 처음 소멸하는 연출에 사용함. 차한해는 당시 자신이 처치했다는 사실을 인지하지 못함.
A85: 79
A86: 80
A87: 81
A88: 82
A89: 83 | B89: 선공 | C89: 몸을 끄는 자 | E89: 초기 변이체 | F89: 45 | G89: 5 | H89: 체중 충격 | I89: 1 | J89: 6 | K89: 1 | L89: 두꺼운 등 외피 | M89: 1 | N89: 2 | O89: 몸통 내려찍기 | P89: 60 | Q89: 느린 추격 | R89: 40 | T89: 0 | V89: 0 | W89: 아파트를 빠져나온 뒤 안전 구역으로 이동하는 대피 구간에 배치함. 차한해는 직접 전투하지 않고 우회함.
A90: 84 | B90: 비선공 | C90: 울음이 남은 자 | E90: 초기 변이체 | F90: 35 | G90: 4 | H90: 공포 음파 | I90: 1 | J90: 5 | K90: 0 | L90: 얇은 외피 | M90: 0 | N90: 0 | O90: 울음 파동 | P90: 45 | Q90: 뒤로 물러나기 | R90: 35 | S90: 멈춰 서기 | T90: 20 | V90: 0 | W90: 인간과 유사한 울음으로 괴물의 인간 기원을 복선으로 제시하되, 3챕터에서는 정체를 공개하지 않음.
...

Sheet 시뮬레이터
B2: 폐교의 보스 | F2: 차한해
B4: 생명력 | C4: =VLOOKUP($B$2,몬스터!$C$7:$W$290,4,0) -> 6200 | F4: 생명력 | G4: =VLOOKUP($F$2,'PC DATA(대차대조표)'!C3:K308,6,0) -> 10
B5: 공격력 | C5: =VLOOKUP($B$2,몬스터!$C$7:$W$290,5,0) -> 84 | F5: 공격력 | G5: =VLOOKUP($F$2,'PC DATA(대차대조표)'!C4:K309,4,0) -> 10
B6: 공격력 보정 | C6: =VLOOKUP($B$2,몬스터!$C$7:$W$290,7,0) -> 18 | F6: 방어력 | G6: =VLOOKUP($F$2,'PC DATA(대차대조표)'!C5:K310,6,0) -> 10
B7: 최종 공격력 | C7: =VLOOKUP($B$2,몬스터!$C$7:$W$290,8,0) -> 102 | F7: 스킬 | G7: =VLOOKUP($F$2,'PC DATA(대차대조표)'!C6:K311,8,0) -> 0
B8: 방어력 | C8: =VLOOKUP($B$2,몬스터!$C$7:$W$290,9,0) -> 54 | G8: =VLOOKUP($F$2,'PC DATA(대차대조표)'!C7:K312,6,0) -> 10
B9: 방어력 보정 | C9: =VLOOKUP($B$2,몬스터!$C$7:$W$290,11,0) -> 16 | G9: =VLOOKUP($F$2,'PC DATA(대차대조표)'!C8:K313,6,0) -> 10
B10: 최종 방어력 | C10: =VLOOKUP($B$2,몬스터!$C$7:$W$290,12,0) -> 70 | G10: =VLOOKUP($F$2,'PC DATA(대차대조표)'!C9:K314,6,0) -> 10
B11: 타입 | C11: =VLOOKUP($B$2,몬스터!C7:W290,3,0) -> 챕터 보스 | G11: =VLOOKUP($F$2,'PC DATA(대차대조표)'!C10:K315,6,0) -> 10
B12: 스킬 | C12: 연속 할퀴기

Sheet 밸런스 팩터
B2: 밸런스 팩터
B3: 게임 「넌 착해!」의 플레이 경험을 조절하는 요소. 원 하나에는 요소 하나만 배치하며 원의 크기는 전체 플레이 영향도와 사용 빈도를 반영함. 최신 핵심 연결은 ① 일반인 공격·방어 10과 첫 힘의 일회성 순간 출력 1000, ② 선의 수치 96·836·999 ERROR의 발견과 고등급자 제도, ③ 고등급자 특혜·거짓 주장·폭력시위·이용익의 여론 압박으로 상승하는 자아마모도, ④ 메인 기본 60%·선택 최대 100%의 도시 인연과 75/100% 엔딩 임계치, ⑤ 선택 만남 4회로 0~100%가 되는 예쁜 고양이 인연과 대장 고양이 휴식 퀘스트, ⑥ 급식실·강당 기억 체험과 친구의 완전 소멸, ⑦ 거울 미로·방향 반전·또 다른 차한해·껍데기의 바다·균열 수호체·선의 계량자 동기화, ⑧ 관리국 표준 대응·재난 구조·심층 균열 탐사·최종 균열 장비로 이어지는 42종 아이템의 획득·사용·교체 흐름, ⑨ 경찰·시민·군인의 장비 지원과 후반 비난의 대비임
B5: 진행·콘텐츠 | J5: 서사·상태 | R5: 전투 | Z5: 가이드·편의 | AH5: 크기: 핵심(대) · 반복 조정(중) · 장면 조정(소)
B70: 큰 원은 플레이 전반에 미치는 영향이 큰 핵심 팩터이며, 작은 원은 장면·미션 단위에서 조정하는 세부 팩터임

Sheet 작성 기준
A1: 게임 「넌 착해!」 밸런스 문서 작성 기준
A2: 모든 시트가 7챕터·콘텐츠 진행 순서 1~306, 문서 전체·대표 경로 시간, 자아마모도, 도시·예쁜 고양이 인연, PC 성장·장비 변화와 다중 엔딩 조건을 동일하게 사용하도록 검증하는 기준표
A3: 1. 밸런스 문서 핵심 항목
A4: 항목 | B4: 작성 방식 | C4: 값/형식 | D4: 우리 게임 적용 기준
A5: 플레이 난이도 | B5: 플레이어가 실제 입력을 수행할 때 느끼는 조작 난도 | C5: 1~10 정수 | D5: 1은 단순 확인·대화, 10은 빠른 보스 패턴과 복합 입력
A6: 플레이 흥미도 | B6: 기획자가 해당 구간에서 기대하는 재미의 목표값 | C6: 1~10 정수 | D6: 탐색·긴장·감정·반전·성취를 포함하며 실제 테스트값과 구분
A7: 콘텐츠 진행 순서 | B7: 게임 시작부터 엔딩까지 해금되는 모든 플레이 내용을 순서대로 기록 | C7: 1부터 연속 넘버링 | D7: 이동·조사·대화·전투·연출·선택 콘텐츠·장비 변화·엔딩 분기를 포함하며 현재 총 306개·7챕터
A8: 플레이 목표 | B8: 제목만 읽어도 플레이어가 해야 할 행동이 보이도록 작성 | C8: 행동형 제목 | D8: 예: 신상 과자 진열대 찾기, 아파트 계단에서 괴물을 피해 숨기
A9: 플레이 난관 | B9: 목표를 바로 달성하지 못하게 만드는 맵·NPC·시간·정보·전투 요소 | C9: 구체적 서술 | D9: 후보 수·시야 차단·시간 압박·감정적 부담 등을 기록
A10: 공략 방법 | B10: 플레이 난관을 해결하기 위해 관찰·판단·조작해야 하는 절차 | C10: 구체적 플레이 절차 | D10: 표에서 가장 핵심적인 항목으로 작성
A11: 체감 난이도 | B11: 플레이 난관 자체의 어려움과 원인을 함께 기록 | C11: 숫자/10 + 원인 | D11: 정보량·후보 수·패턴 수·시간 압박을 함께 평가
A12: 수행 과제 수 | B12: 해당 행을 완료하기 위해 필요한 행동·대상·단계의 수 | C12: 정수 | D12: 수거 8개, 단서 5개, 보스 패턴 3회 등
A13: 목표 달성 조건 | B13: 시스템이 완료를 판정할 수 있는 명확한 조건 | C13: 구체적 판정 조건 | D13: 목표 수량·트리거·퍼즐·보스 기믹 완료 등
A14: 실패 결과 | B14: 실패 시 재시작 지점이나 보상 감소 등 결과를 기록 | C14: 구체적 결과 또는 - | D14: 체력 0·시민 피해·오답 누적·시간 초과 등을 반영
A15: 예상 소요 시간 | B15: 라이트 유저가 초회 플레이에서 완료하는 기준 시간 | C15: 분·초 텍스트 | D15: 라이트 유저 열과 동일하게 작성
... A30: 전투 숙련 단계 | B30: 해당 전투를 안정적으로 공략하기 위한 조작·판단 수준 | C30: 1~9 또는 — | D30: PC DATA 기본 공격력 상승 시점과 전투 복잡도 검증에 사용
A31: 2. PC DATA 작성 기준
A32: 항목 | B32: 작성 방식 | C32: 값/형식 | D32: 우리 게임 적용 기준
A33: 플레이어 고유명(CLASS) | B33: 주인공의 고유명 또는 클래스 정체성 | C33: 텍스트 | D33: 닉네임이 아니라 차한해를 기록
A34: 콘텐츠 진행 순서 | B34: 능력치·장비·스킬이 최초 변화하는 시점 | C34: 밸런스 문서 번호 | D34: PC DATA는 능력치·장비·스킬이 처음 변하는 시점만 기록하고, PC DATA(대차대조표)는 1~306 모든 콘텐츠의 챕터·콘텐츠명·전투 상태·현재 기본 수치와 변화 근거를 기록
A35: 기본 공격력 | B35: 장비를 제외한 차한해의 전투 숙련 공격력 | C35: 10~560 정수 | D35: 일반인 기본 공격력 10. 79번에서 일회성 +990으로 순간 출력 1000, 118번부터 정식 전투 공격력 80→560 계단형 상승
A36: 공격력 합산 요소 | B36: 무기·공명 등 공격력에 더해지는 요소 | C36: 이름 + 보정값 | D36: 무기·공명·일회성 출력 변화는 최초 획득 또는 종료 시점만 기록
A37: 기본 방어력 | B37: 장비를 제외한 차한해의 피해 대응 숙련도 | C37: 10~220 정수 | D37: 일반인 기본 방어력 10. 정식 전투 개방 시 100으로 상승하고 공격 예측·충격 흘리기 숙련에 따라 220까지 증가
A38: 방어력 합산 요소 | B38: 방어구·보호 장비의 획득·파손·보정 변화 | C38: 이름 + 보정값 또는 변화값 | D38: 방어구는 획득·손상·성능 감소·완전 파손 시점만 기록
A39: 스킬 | B39: 새로 해금되는 조작·판단 능력의 이름 | C39: 이름만 기록 | D39: 수치·설명은 별도 스킬 시트가 생길 때 분리
A40: 최초 등장·변화 원칙 | B40: 무기·스킬은 최초 등장, 방어구는 획득·성능 변화 시 기록 | C40: 변화 시점만 기록 | D40: PC DATA와 대차대조표 모두 무기·방어구·스킬을 매 행 누적 반복하지 않음. 변화 열은 최초 획득·교체·손상·파손 시점만 쓰고 나머지는 공란으로 유지
A41: 3. 우리 게임에서 제외한 항목
A42: 항목 | B42: 작성 방식 | C42: 값/형식 | D42: 우리 게임 적용 기준
A43: Lv·레벨업 필요 경험치·전직 퀘스트 | B43: 레벨과 전직 시스템이 없음 | C43: 챕터·스테이지·진행 관문 | D43: 삭제
A44: 몬스터 1체 경험치·퀘스트 보상 경험치 | B44: 처치 반복으로 성장하는 구조가 아님 | C44: 콘텐츠 진행 포인트 | D44: 삭제
A45: 레벨업 전투시간·필요 처치 수 | B45: 반복 사냥과 레벨업 루프가 없음 | C45: 전투 예상 시간·전투 숙련 단계 | D45: 삭제
A46: 파티플레이 보상 경험치 비율 | B46: 파티 경험치 분배 시스템이 없음 | C46: 인연 변화·다인 협력 기믹 | D46: 삭제
A47: 아이템 구매 기준가격·필요 처치 수 | B47: 전투 파밍 상점 경제가 핵심이 아님 | C47: 필요 시 별도 경제 시트 | D47: 전투 파밍 상점 경제는 제외하되 실제 아이템 42종 모두에 획득 콘텐츠를 부여하고, 획득 순서·사용 콘텐츠·수치를 아이템 시트와 밸런스 문서에 연결
A48: 보스 경험치·레벨별 보스 분포 수 | B48: 보스가 레벨업 보상을 제공하지 않음 | C48: 보스 스테이지 수·스테이지 점수 | D48: 삭제
A49: 보스 타입 A/B 공통 시간 | B49: 보스마다 서사·기믹·페이즈가 달라 평균이 부정확함 | C49: 보스별 실제 페이즈 합 | D49: 삭제
A50: 퀘스트 레벨별 분포 개수 | B50: 퀘스트 레벨 구간이 없음 | C50: 챕터별 콘텐츠 수·진행 순서 | D50: 삭제
A51: 이동속도 A/B 고정 열 | B51: 일부 추격·호위에서만 필요해 대부분 공란 | C51: 난관·난이도 조절·밸런스 팩터 | D51: 필요 시 별도 시트
A52: 4. 시트 간 통일성 검증
A53: 항목 | B53: 작성 방식 | C53: 값/형식 | D53: 우리 게임 적용 기준
A54: 누적 플레이 시간 | B54: 예상 소요 시간 합계와 일치하는지 확인 | C54: 오차 0초 | D54: 문서 전체 라이트 5시간 51분 10초 · 미들 5시간 · 헤비 4시간 38분 30초 / 대표 진엔딩 경로 라이트 5시간 25분 15초 · 미들 4시간 37분 5초 · 헤비 4시간 18분 35초
...

Sheet 밸런스 곡선
A1: 전체 밸런스 곡선 요약
A2: 문서 전체 합산 라이트 5시간 48분 40초 · 미들 4시간 58분 · 헤비 4시간 36분 55초 / 선택 콘텐츠를 제외한 대표 진엔딩 경로 라이트 5시간 22분 45초 · 미들 4시간 35분 5초 · 헤비 4시간 17분 — 선의 수치 발견, 고등급자 공동 출동과 배신, 예쁜 고양이 인연, 폐교 기억 체험, 균열 내부·다중 엔딩을 통합함 | B2: 문서 전체 합산 라이트 5시간 51분 10초 · 미들 5시간 · 헤비 4시간 38분 30초 / 선택 콘텐츠를 제외한 대표 진엔딩 경로 라이트 5시간 25분 15초 · 미들 4시간 37분 5초 · 헤비 4시간 18분 35초 — 선의 수치 발견, 고등급자 공동 출동과 배신, 42종 아이템의 획득·사용, 예쁜 고양이 인연, 폐교 기억 체험, 균열 내부·다중 엔딩을 통합함
A3: 총 콘텐츠 수 | B3: 306 | C3: 평균 플레이 난이도 | D3: 2.86 | E3: 평균 플레이 흥미도 | F3: 8.12 | G3: 보스 스테이지 수 | H3: 5 | I3: 대표 진엔딩 예상 시간(미들 기준) | J3: 0.19241898
A4: 콘텐츠 진행 순서 | B4: 콘텐츠 진행 포인트 누적 | C4: 상위 스테이지 해금 요구 포인트 | D4: 누적 플레이 시간(라이트)
A5: 1 | B5: 3 | C5: 0 | D5: 0.00052083333
A6: 2 | B6: 5 | C6: 0 | D6: 0.00063657407
A7: 3 | B7: 8 | C7: 0 | D7: 0.00086805556
A8: 4 | B8: 11 | C8: 0 | D8: 0.0012152778
A9: 5 | B9: 13 | C9: 0 | D9: 0.0013888889
A10: 6 | B10: 15 | C10: 0 | D10: 0.0015625
A11: 7 | B11: 18 | C11: 15 | D11: 0.0017939815
A12: 8 | B12: 22 | C12: 15 | D12: 0.0021412037
A13: 9 | B13: 25 | C13: 15 | D13: 0.0023148148
A14: 10 | B14: 28 | C14: 15 | D14: 0.002662037
A15: 11 | B15: 31 | C15: 28 | D15: 0.0032407407
A16: 12 | B16: 34 | C16: 28 | D16: 0.0038194444
... A27: 23 | B27: 75 | C27: 53 | D27: 0.010590278
A28: 24 | B28: 81 | C28: 53 | D28: 0.011631944 | F28: 챕터 | G28: 콘텐츠 수 | H28: 라이트 | I28: 미들 | J28: 헤비
A29: 25 | B29: 84 | C29: 53 | D29: 0.012210648 | F29: 1 | 평범한 하루 | G29: 37 | H29: 0.016493056 | I29: 0.014351852 | J29: 0.013310185
A30: 26 | B30: 87 | C30: 84 | D30: 0.012384259 | F30: 2 | 금이 간 일상 | G30: 32 | H30: 0.014467593 | I30: 0.01255787 | J30: 0.012094907
A31: 27 | B31: 91 | C31: 87 | D31: 0.012731481 | F31: 3 | 선택된 선의 | G31: 45 | H31: 0.0265625 | I31: 0.023321759 | J31: 0.020833333
