Workbook

Sheet 시뮬레이터
B1: BATTLE BALANCE SIMULATOR
B2: 몬스터 × 차한해 전투 수치·속성 상성 비교
B4: MONSTER · 적 개체 선택 | M4: PLAYER · 차한해 전투 시점
B5: 비상구대게 | M5: 콘텐츠 진행 순서 | P5: 249
M6: =IFERROR(VLOOKUP($P$5,'[1]PC DATA(대차대조표)'!$A$2:$K$307,2,FALSE),"") -> 차한해
B7: MONSTER IMAGE 선택 몬스터 이미지 영역 | M7: PLAYER IMAGE 차한해 이미지 영역
I8: VS
I11: 선택값 변경 시 전투 데이터 자동 갱신
B16: 타입 | D16: =IFERROR(VLOOKUP($B$5,[1]몬스터!$C$7:$X$312,3,FALSE),"") -> 무리 선도체 | M16: 캐릭터 | O16: =IFERROR(VLOOKUP($P$5,'[1]PC DATA(대차대조표)'!$A$2:$K$307,3,FALSE),"") -> 0
B17: 출현 콘텐츠 | D17: =IFERROR(INDEX([1]몬스터!$A$7:$A$312,MATCH($B$5,[1]몬스터!$C$7:$C$312,0)),"") -> 142 | M17: 전투 상태 | O17: =IFERROR(VLOOKUP($P$5,'[1]PC DATA(대차대조표)'!$A$2:$K$307,4,FALSE),"") -> 별을 삼킨 강당가 변혜서임을 확정하고 선의 안정 장치 발동 견디기
B18: 속성 | D18: =IFERROR(VLOOKUP($B$5,[1]몬스터!$C$7:$X$312,21,FALSE),"") -> 침식 | M18: 신규 해금 | O18: =IFERROR(VLOOKUP($P$5,'[1]PC DATA(대차대조표)'!$A$2:$K$307,9,FALSE),"-") -> 0
B20: COMBAT STATUS · 핵심 능력치 비교
I21: MONSTER | J21: STAT | K21: PLAYER
B22: 생명력 | D22: =IFERROR(VLOOKUP($B$5,[1]몬스터!$C$7:$X$312,4,FALSE),0) -> 430 | I22: =IFERROR(VLOOKUP($B$5,[1]몬스터!$C$7:$X$312,8,FALSE),0) -> 41 | J22: 최종 공격력 | K22: =IFERROR(VLOOKUP($P$5,'[1]PC DATA(대차대조표)'!$A$2:$K$307,5,FALSE),0) -> 보스 전투 | M22: 현재 공격력 | O22: =IFERROR(VLOOKUP($P$5,'[1]PC DATA(대차대조표)'!$A$2:$K$307,5,FALSE),"-") -> 보스 전투
B23: 기본 공격력 | D23: =IFERROR(VLOOKUP($B$5,[1]몬스터!$C$7:$X$312,5,FALSE),0) -> 34 | I23: =IFERROR(VLOOKUP($B$5,[1]몬스터!$C$7:$X$312,12,FALSE),0) -> 26 | J23: 최종 방어력 | K23: =IFERROR(VLOOKUP($P$5,'[1]PC DATA(대차대조표)'!$A$2:$K$307,7,FALSE),0) -> 0 | M23: 공격 변화 | O23: =IFERROR(VLOOKUP($P$5,'[1]PC DATA(대차대조표)'!$A$2:$K$307,6,FALSE),"-") -> 470
B24: 공격 보정 | D24: =IFERROR(VLOOKUP($B$5,[1]몬스터!$C$7:$X$312,7,FALSE),0) -> 7 | M24: 현재 방어력 | O24: =IFERROR(VLOOKUP($P$5,'[1]PC DATA(대차대조표)'!$A$2:$K$307,7,FALSE),"-") -> 0
B25: 최종 공격력 | D25: =IFERROR(VLOOKUP($B$5,[1]몬스터!$C$7:$X$312,8,FALSE),0) -> 41 | M25: 방어 변화 | O25: =IFERROR(VLOOKUP($P$5,'[1]PC DATA(대차대조표)'!$A$2:$K$307,8,FALSE),"-") -> 165
B26: 기본 방어력 | D26: =IFERROR(VLOOKUP($B$5,[1]몬스터!$C$7:$X$312,9,FALSE),0) -> 20
B27: 방어 보정 | D27: =IFERROR(VLOOKUP($B$5,[1]몬스터!$C$7:$X$312,11,FALSE),0) -> 6
B28: 최종 방어력 | D28: =IFERROR(VLOOKUP($B$5,[1]몬스터!$C$7:$X$312,12,FALSE),0) -> 26
B31: ATTRIBUTE MATCH-UP · 속성 대차대조표 연동
B32: 차한해 공격 속성 | H32: 공격 상성 | M32: 차한해 방어 속성
B33: 공명 | H33: =$B$33&" VS "&IFERROR(VLOOKUP($B$5,[1]몬스터!$C$7:$X$312,21,FALSE),"") -> 공명 VS 침식 | J33: VS | M33: 안정
B35: 차한해 → 몬스터 | H35: 비교 지표 실제 피해량 공식이 문서에 정의되어 있지 않으므로, 최종 공격력 × 속성 K와 상대 방어력의 차이를 ‘밸런스 비교용 지표’로만 표시함. | M35: 몬스터 → 차한해
B36: 상성 매개 상수 K | E36: =IFERROR(INDEX(#REF!,MATCH($B$33,#REF!,0),MATCH($D$18,#REF!,0)),1) -> 1 | M36: 상성 매개 상수 K | P36: =IFERROR(INDEX(#REF!,MATCH($D$18,#REF!,0),MATCH($M$33,#REF!,0)),1) -> 1
B37: 상성 적용 공격 지표 | E37: =ROUND($K$22*$E$36,1) -> #VALUE! | M37: 상성 적용 공격 지표 | P37: =ROUND($I$22*$P$36,1) -> 41
B38: 상대 방어력 | E38: =$I$23 -> 26 | M38: 상대 방어력 | P38: =$K$23 -> 0
B39: 공격-방어 격차 | E39: =ROUND($E$37-$E$38,1) -> #VALUE! | M39: 공격-방어 격차 | P39: =ROUND($P$37-$P$38,1) -> 41
B40: =IF($E$39>0,"공격 우세",IF($E$39=0,"균형","방어 우세")) -> #VALUE! | M40: =IF($P$39>0,"몬스터 공격 우세",IF($P$39=0,"균형","차한해 방어 우세")) -> 몬스터 공격 우세
B43: SKILL LOADOUT · 선택 개체 스킬 구성 및 상세
B44: MONSTER SKILLS | M44: PLAYER CONTEXT
B45: =IFERROR(VLOOKUP($B$5,[1]몬스터!$C$7:$X$312,13,FALSE),"-") -> 비상구 폐쇄! | F45: =IFERROR(VLOOKUP($B$5,[1]몬스터!$C$7:$X$312,14,FALSE),0)&"%" -> 30% | M45: 해당 시점 스킬 | P45: =IFERROR(VLOOKUP($P$5,'[1]PC DATA(대차대조표)'!$A$2:$K$307,9,FALSE),"-") -> 0
B46: =IFERROR(VLOOKUP($B$5,[1]몬스터!$C$7:$X$312,15,FALSE),"-") -> 자리 바꿔! | F46: =IFERROR(VLOOKUP($B$5,[1]몬스터!$C$7:$X$312,16,FALSE),0)&"%" -> 25% | M46: 공격 변화 | P46: =IFERROR(VLOOKUP($P$5,'[1]PC DATA(대차대조표)'!$A$2:$K$307,6,FALSE),"-") -> 470
B47: =IFERROR(VLOOKUP($B$5,[1]몬스터!$C$7:$X$312,17,FALSE),"-") -> 다 같이 밀어! | F47: =IFERROR(VLOOKUP($B$5,[1]몬스터!$C$7:$X$312,18,FALSE),0)&"%" -> 30% | M47: 방어 변화 | P47: =IFERROR(VLOOKUP($P$5,'[1]PC DATA(대차대조표)'!$A$2:$K$307,8,FALSE),"-") -> 165
B48: =IFERROR(VLOOKUP($B$5,[1]몬스터!$C$7:$X$312,19,FALSE),"-") -> 집게 한 번 | F48: =IFERROR(VLOOKUP($B$5,[1]몬스터!$C$7:$X$312,20,FALSE),0)&"%" -> 15% | M48: 현재 상태 메모 | P48: =IFERROR(VLOOKUP($P$5,'[1]PC DATA(대차대조표)'!$A$2:$K$307,10,FALSE),"-") -> 바꿔가며!
B50: 때리지 마. | M50: 바꿔가며!
B51: 스킬 타입 | D51: =IFERROR(VLOOKUP($B$50,'[1]스킬 DATA'!$G$2:$AD$212,4,FALSE),"-") -> 액티브 | M51: 스킬 타입 | O51: =IFERROR(VLOOKUP($M$50,'[1]스킬 DATA'!$G$2:$AD$212,4,FALSE),"-") -> 액티브
B52: 추가 설명 | D52: =IFERROR(VLOOKUP($B$50,'[1]스킬 DATA'!$G$2:$AD$212,2,FALSE),"-") -> '공격 중지·접근' 행동을 수행해 위치·전투 리듬을 변화시킴. | M52: 추가 설명 | O52: =IFERROR(VLOOKUP($M$50,'[1]스킬 DATA'!$G$2:$AD$212,2,FALSE),"-") -> 근거리 사랑의 매와 원거리 보랏빛 농구공을 빠르게 전환해 보스의 거리별 기억 패턴에 대응함.
B54: 발동 조건 | D54: =IFERROR(VLOOKUP($B$50,'[1]스킬 DATA'!$G$2:$AD$212,8,FALSE),"-") -> 현재 페이즈에서 사용 가능·가중치 판정 | M54: 발동 조건 | O54: =IFERROR(VLOOKUP($M$50,'[1]스킬 DATA'!$G$2:$AD$212,8,FALSE),"-") -> 보유 무기 2종
B55: 피해 계수 | D55: =IFERROR(VLOOKUP($B$50,'[1]스킬 DATA'!$G$2:$AD$212,10,FALSE),"-") -> 0 | M55: 피해 계수 | O55: =IFERROR(VLOOKUP($M$50,'[1]스킬 DATA'!$G$2:$AD$212,10,FALSE),"-") -> 0
...
