Workbook

Sheet 밸런스 문서
Q1: a | R1: b
M2: 경험치 그래프 | Q2: 3 | R2: 15
Q3: =Q2*0.01 -> 0.03 | R3: =R2*0.01 -> 0.15 | AB3: 스테이지 1회 클리어 시간
A4: 챕터 | B4: 콘텐츠 진행 순서 | C4: 플레이 난이도 | D4: 플레이 흥미도 | E4: 플레이 목표 | F4: 플레이 난관 | G4: 공략 방법 | H4: 체감 난이도 | I4: 수행 과제 수 | J4: 목표 달성 조건 | K4: 실패 결과 | L4: 예상 소요 시간 | M4: 난이도 조절 요소 | N4: 누적 플레이 시간 | O4: 스테이지 | P4: 콘텐츠 진행 포인트 누적 | Q4: X 콘텐츠 진행 포인트 | R4: Y 레벨업을 위한 필요 경험치 | S4: 한마리 몬스터가 주는 경험치 | T4: 한마리 몬스터와 전투시간 | U4: 레벨 업을 위한 전투시간 | V4: 레벨 업을 위해 잡아야하는 몬스터 수 | W4: 스테이지 점수 산정 기준 | X4: S (100%) | Y4: A (85%) | Z4: B (70%) | AA4: C (55%) | AB4: 예상 기준 (미들) | AC4: 라이트 유저 | AD4: 미들 유저 | AE4: 헤비 유저
A5: 1 | 동생 심부름 | B5: 1 | C5: 1 | D5: 8 | E5: 차한해의 과거 오프닝 감상 | F5: 입양 이후 가족 안에서 희생을 요구받아 온 과거를 보여주는 연출이 길게 이어져 플레이어가 핵심 정보를 놓칠 수 있음 | G5: 핵심 장면의 시선 유도와 짧은 자막을 통해 관계와 감정 변화를 이해함 | H5: 1 – 연출 길이와 정보량이 난이도를 결정함 | I5: 1 | J5: 오프닝 재생이 끝나면 자동 완료 | K5: - | L5: 1분 30초 | M5: 스킵·다시 보기 기능 제공 | N5: =(IFERROR(VALUE(LEFT(L5,FIND("분",L5)-1))*60,0)+IFERROR(VALUE(TRIM(MID(L5,IFERROR(FIND("분",L5),0)+1,FIND("초",L5)-IFERROR(FIND("분",L5),0)-1))),0))/86400 -> 0.0010416667 | O5: 1-A | 집·튜토리얼 | P5: 6 | Q5: 3 | R5: =$Q$3*P5*P5+$R$3*P5 -> 1.98
A6: 1 | 동생 심부름 | B6: 2 | C6: 1 | D6: 3 | E6: 빨래 개기 | F6: 조사 가능한 가구가 많아 조작 가능한 대상을 바로 알아보기 어려움 | G6: 주인공 주변의 상호작용 표시를 확인하고 조사 키를 누름 | H6: 1 – 상호작용 표시의 가시성과 조사 범위가 난이도를 결정함 | I6: 1 | J6: 소파 옆 주인공에서 조사 입력 1회 완료 | K6: - | L6: 20초 | M6: 첫 상호작용 대상에 반짝임 표시 | N6: =N5+(IFERROR(VALUE(LEFT(L6,FIND("분",L6)-1))*60,0)+IFERROR(VALUE(TRIM(MID(L6,IFERROR(FIND("분",L6),0)+1,FIND("초",L6)-IFERROR(FIND("분",L6),0)-1))),0))/86400 -> 0.0012731481 | O6: 1-A | 집·튜토리얼 | P6: =P5+2 -> 8 | Q6: 2 | R6: =$Q$3*P6*P6+$R$3*P6 -> 3.12
A7: 1 | 동생 심부름 | B7: 3 | C7: 1 | D7: 5 | E7: 동생에게 심부름 지시 받기 | F7: 대화 속에 다음 목적지와 필요한 물품 정보가 섞여 있음 | G7: 강조되는 핵심 단어와 NPC의 요구를 확인하며 대화를 끝까지 진행함 | H7: 1 – 대사 길이·핵심 정보의 명확성·선택지 수가 난이도를 결정함 | I7: 1 | J7: 신상 과자·헤어롤·팝콘 심부름에 관한 대화를 마지막 문장까지 진행 | K7: - | L7: 1분 | M7: 대화 종료 후 핵심 내용을 화면 한쪽에 요약 표시 | N7: =N6+(IFERROR(VALUE(LEFT(L7,FIND("분",L7)-1))*60,0)+IFERROR(VALUE(TRIM(MID(L7,IFERROR(FIND("분",L7),0)+1,FIND("초",L7)-IFERROR(FIND("분",L7),0)-1))),0))/86400 -> 0.0019675926 | O7: 1-A | 집·튜토리얼 | P7: =P6+4 -> 12 | Q7: 4 | R7: =$Q$3*P7*P7+$R$3*P7 -> 6.12
A8: 1 | 동생 심부름 | B8: 4 | C8: 1 | D8: 3 | E8: 이동 조작 안내 확인 | F8: 여러 조작을 한 번에 제시하면 입력 방법을 혼동할 수 있음 | G8: 화면에 표시되는 키를 순서대로 입력하고 각 동작의 결과를 확인함 | H8: 1 – 동시에 제시되는 조작 수와 입력 허용 시간이 난이도를 결정함 | I8: 4 | J8: 상하좌우 이동과 조사 키를 안내 순서대로 모두 수행 | K8: - | L8: 40초 | M8: 입력하지 않은 키 안내를 계속 유지 | N8: =N7+(IFERROR(VALUE(LEFT(L8,FIND("분",L8)-1))*60,0)+IFERROR(VALUE(TRIM(MID(L8,IFERROR(FIND("분",L8),0)+1,FIND("초",L8)-IFERROR(FIND("분",L8),0)-1))),0))/86400 -> 0.0024305556 | O8: 1-A | 집·튜토리얼 | P8: =P7+3 -> 15 | Q8: 3 | R8: =$Q$3*P8*P8+$R$3*P8 -> 9
A9: 1 | 동생 심부름 | B9: 5 | C9: 1 | D9: 3 | E9: 현관으로 이동하기 | F9: 갈림길과 주변 상호작용 오브젝트 때문에 목적지 방향을 놓칠 수 있음 | G9: 표지판·미니맵·NPC 이동 방향을 확인하며 거실에서 현관문까지 이동함 | H9: 1 – 맵 크기·갈림길 수·목적지 표식의 가시성이 난이도를 결정함 | I9: 1 | J9: 거실에서 현관문의 도착 트리거에 진입 | K9: - | L9: 30초 | M9: 일정 시간 정체 시 목적지 방향 화살표 표시 | N9: =N8+(IFERROR(VALUE(LEFT(L9,FIND("분",L9)-1))*60,0)+IFERROR(VALUE(TRIM(MID(L9,IFERROR(FIND("분",L9),0)+1,FIND("초",L9)-IFERROR(FIND("분",L9),0)-1))),0))/86400 -> 0.0027777778 | O9: 1-A | 집·튜토리얼 | P9: =P8+3 -> 18 | Q9: 3 | R9: =$Q$3*P9*P9+$R$3*P9 -> 12.42
A10: 1 | 동생 심부름 | B10: 6 | C10: 1 | D10: 5 | E10: 집 밖으로 나가기 | F10: 조사 대상이 배경 오브젝트와 비슷해 상호작용 가능 여부를 놓칠 수 있음 | G10: 현관문 가까이 이동한 뒤 상호작용 아이콘이 나타날 때 조사함 | H10: 1 – 조사 대상의 크기·배경과의 대비·상호작용 범위가 난이도를 결정함 | I10: 1 | J10: 현관문 조사 완료 | K10: - | L10: 20초 | M10: 상호작용 가능 범위를 넓히고 아이콘 표시 | N10: =N9+(IFERROR(VALUE(LEFT(L10,FIND("분",L10)-1))*60,0)+IFERROR(VALUE(TRIM(MID(L10,IFERROR(FIND("분",L10),0)+1,FIND("초",L10)-IFERROR(FIND("분",L10),0)-1))),0))/86400 -> 0.0030092593 | O10: 1-A | 집·튜토리얼 | P10: =P9+3 -> 21 | Q10: 3 | R10: =$Q$3*P10*P10+$R$3*P10 -> 16.38
A11: 1 | 동생 심부름 | B11: 7 | C11: 2 | D11: 5 | E11: 편의점으로 이동하기 | F11: 갈림길과 주변 상호작용 오브젝트 때문에 목적지 방향을 놓칠 수 있음 | G11: 표지판·미니맵·NPC 이동 방향을 확인하며 아파트에서 편의점까지 이동함 | H11: 2 – 맵 크기·갈림길 수·목적지 표식의 가시성이 난이도를 결정함 | I11: 1 | J11: 아파트에서 편의점의 도착 트리거에 진입 | K11: - | L11: 1분 15초 | M11: 일정 시간 정체 시 목적지 방향 화살표 표시 | N11: =N10+(IFERROR(VALUE(LEFT(L11,FIND("분",L11)-1))*60,0)+IFERROR(VALUE(TRIM(MID(L11,IFERROR(FIND("분",L11),0)+1,FIND("초",L11)-IFERROR(FIND("분",L11),0)-1))),0))/86400 -> 0.0038773148 | O11: 1-B | 편의점 | P11: =P10+5 -> 26 | Q11: 5 | R11: =$Q$3*P11*P11+$R$3*P11 -> 24.18
A12: 1 | 동생 심부름 | B12: 8 | C12: 2 | D12: 6 | E12: 신상 과자 진열대 찾기 | F12: 비슷한 오브젝트와 진열대가 많아 목표 대상을 한 번에 찾기 어려움 | G12: 구역별 표지와 상품 외형을 비교하며 편의점 안 신상 과자 진열대를 조사함 | H12: 3 – 후보 오브젝트 수·외형 유사도·탐색 범위가 난이도를 결정함 | I12: 4 | J12: 편의점 안 신상 과자 진열대 발견 및 조사 완료 | K12: - | L12: 1분 30초 | M12: 30초 이상 미발견 시 목표 구역에 약한 반짝임 표시 | N12: =N11+(IFERROR(VALUE(LEFT(L12,FIND("분",L12)-1))*60,0)+IFERROR(VALUE(TRIM(MID(L12,IFERROR(FIND("분",L12),0)+1,FIND("초",L12)-IFERROR(FIND("분",L12),0)-1))),0))/86400 -> 0.0049189815 | O12: 1-B | 편의점 | P12: =P11+6 -> 32 | Q12: 6 | R12: =$Q$3*P12*P12+$R$3*P12 -> 35.52
A13: 1 | 동생 심부름 | B13: 9 | C13: 1 | D13: 5 | E13: 품절 안내 조사하기 | F13: 조사 대상이 배경 오브젝트와 비슷해 상호작용 가능 여부를 놓칠 수 있음 | G13: 비어 있는 진열칸과 손글씨 품절 안내 가까이 이동한 뒤 상호작용 아이콘이 나타날 때 조사함 | H13: 2 – 조사 대상의 크기·배경과의 대비·상호작용 범위가 난이도를 결정함 | I13: 2 | J13: 비어 있는 진열칸과 손글씨 품절 안내 조사 완료 | K13: - | L13: 35초 | M13: 상호작용 가능 범위를 넓히고 아이콘 표시 | N13: =N12+(IFERROR(VALUE(LEFT(L13,FIND("분",L13)-1))*60,0)+IFERROR(VALUE(TRIM(MID(L13,IFERROR(FIND("분",L13),0)+1,FIND("초",L13)-IFERROR(FIND("분",L13),0)-1))),0))/86400 -> 0.0053240741 | O13: 1-B | 편의점 | P13: =P12+4 -> 36 | Q13: 4 | R13: =$Q$3*P13*P13+$R$3*P13 -> 44.28
A14: 1 | 동생 심부름 | B14: 10 | C14: 1 | D14: 6 | E14: 알바생 NPC와 대화하기 | F14: 대화 속에 다음 목적지와 필요한 물품 정보가 섞여 있음 | G14: 강조되는 핵심 단어와 NPC의 요구를 확인하며 대화를 끝까지 진행함 | H14: 2 – 대사 길이·핵심 정보의 명확성·선택지 수가 난이도를 결정함 | I14: 1 | J14: 재입고 시간과 물류 트럭 정보에 관한 대화를 마지막 문장까지 진행 | K14: - | L14: 1분 15초 | M14: 대화 종료 후 핵심 내용을 화면 한쪽에 요약 표시 | N14: =N13+(IFERROR(VALUE(LEFT(L14,FIND("분",L14)-1))*60,0)+IFERROR(VALUE(TRIM(MID(L14,IFERROR(FIND("분",L14),0)+1,FIND("초",L14)-IFERROR(FIND("분",L14),0)-1))),0))/86400 -> 0.0061921296 | O14: 1-B | 편의점 | P14: =P13+5 -> 41 | Q14: 5 | R14: =$Q$3*P14*P14+$R$3*P14 -> 56.58
A15: 1 | 동생 심부름 | B15: 11 | C15: 2 | D15: 5 | E15: 다이소로 이동하기 | F15: 갈림길과 주변 상호작용 오브젝트 때문에 목적지 방향을 놓칠 수 있음 | G15: 표지판·미니맵·NPC 이동 방향을 확인하며 편의점에서 다이소까지 이동함 | H15: 2 – 맵 크기·갈림길 수·목적지 표식의 가시성이 난이도를 결정함 | I15: 1 | J15: 편의점에서 다이소의 도착 트리거에 진입 | K15: - | L15: 1분 30초 | M15: 일정 시간 정체 시 목적지 방향 화살표 표시 | N15: =N14+(IFERROR(VALUE(LEFT(L15,FIND("분",L15)-1))*60,0)+IFERROR(VALUE(TRIM(MID(L15,IFERROR(FIND("분",L15),0)+1,FIND("초",L15)-IFERROR(FIND("분",L15),0)-1))),0))/86400 -> 0.0072337963 | O15: 1-C | 다이소 | P15: =P14+6 -> 47 | Q15: 6 | R15: =$Q$3*P15*P15+$R$3*P15 -> 73.32
A16: 1 | 동생 심부름 | B16: 12 | C16: 2 | D16: 6 | E16: 헤어롤 진열대 찾기 | F16: 비슷한 오브젝트와 진열대가 많아 목표 대상을 한 번에 찾기 어려움 | G16: 구역별 표지와 상품 외형을 비교하며 생활용품 코너의 헤어롤을 조사함 | H16: 3 – 후보 오브젝트 수·외형 유사도·탐색 범위가 난이도를 결정함 | I16: 5 | J16: 생활용품 코너의 헤어롤 발견 및 조사 완료 | K16: - | L16: 1분 50초 | M16: 30초 이상 미발견 시 목표 구역에 약한 반짝임 표시 | N16: =N15+(IFERROR(VALUE(LEFT(L16,FIND("분",L16)-1))*60,0)+IFERROR(VALUE(TRIM(MID(L16,IFERROR(FIND("분",L16),0)+1,FIND("초",L16)-IFERROR(FIND("분",L16),0)-1))),0))/86400 -> 0.0085069444 | O16: 1-C | 다이소 | P16: =P15+7 -> 54 | Q16: 7 | R16: =$Q$3*P16*P16+$R$3*P16 -> 95.58
A17: 1 | 동생 심부름 | B17: 13 | C17: 1 | D17: 5 | E17: 헤어롤 구매하기 | F17: 구매 대상·수량·결제 순서를 잘못 선택할 수 있음 | G17: 요청받은 품목을 확인하고 상품 선택→계산대 상호작용→결제를 순서대로 진행함 | H17: 2 – 상품 후보 수·품목 유사도·구매 단계 수가 난이도를 결정함 | I17: 3 | J17: 헤어롤 1개 구매 후 인벤토리에 등록 | K17: 잘못된 품목 구매 시 다시 선택해야 함 | L17: 50초 | M17: 요청 품목에 작은 임무 아이콘 표시 | N17: =N16+(IFERROR(VALUE(LEFT(L17,FIND("분",L17)-1))*60,0)+IFERROR(VALUE(TRIM(MID(L17,IFERROR(FIND("분",L17),0)+1,FIND("초",L17)-IFERROR(FIND("분",L17),0)-1))),0))/86400 -> 0.0090856481 | O17: 1-C | 다이소 | P17: =P16+4 -> 58 | Q17: 4 | R17: =$Q$3*P17*P17+$R$3*P17 -> 109.62
A18: 1 | 동생 심부름 | B18: 14 | C18: 2 | D18: 5 | E18: 영화관으로 이동하기 | F18: 갈림길과 주변 상호작용 오브젝트 때문에 목적지 방향을 놓칠 수 있음 | G18: 표지판·미니맵·NPC 이동 방향을 확인하며 다이소에서 영화관까지 이동함 | H18: 2 – 맵 크기·갈림길 수·목적지 표식의 가시성이 난이도를 결정함 | I18: 1 | J18: 다이소에서 영화관의 도착 트리거에 진입 | K18: - | L18: 2분 | M18: 일정 시간 정체 시 목적지 방향 화살표 표시 | N18: =N17+(IFERROR(VALUE(LEFT(L18,FIND("분",L18)-1))*60,0)+IFERROR(VALUE(TRIM(MID(L18,IFERROR(FIND("분",L18),0)+1,FIND("초",L18)-IFERROR(FIND("분",L18),0)-1))),0))/86400 -> 0.010474537 | O18: 1-D | 영화관 | P18: =P17+7 -> 65 | Q18: 7 | R18: =$Q$3*P18*P18+$R$3*P18 -> 136.5
A19: 1 | 동생 심부름 | B19: 15 | C19: 2 | D19: 5 | E19: 팝콘 구매하기 | F19: 구매 대상·수량·결제 순서를 잘못 선택할 수 있음 | G19: 요청받은 품목을 확인하고 상품 선택→계산대 상호작용→결제를 순서대로 진행함 | H19: 2 – 상품 후보 수·품목 유사도·구매 단계 수가 난이도를 결정함 | I19: 3 | J19: 동생이 지정한 팝콘 구매 후 인벤토리에 등록 | K19: 잘못된 품목 구매 시 다시 선택해야 함 | L19: 1분 20초 | M19: 요청 품목에 작은 임무 아이콘 표시 | N19: =N18+(IFERROR(VALUE(LEFT(L19,FIND("분",L19)-1))*60,0)+IFERROR(VALUE(TRIM(MID(L19,IFERROR(FIND("분",L19),0)+1,FIND("초",L19)-IFERROR(FIND("분",L19),0)-1))),0))/86400 -> 0.011400463 | O19: 1-D | 영화관 | P19: =P18+6 -> 71 | Q19: 6 | R19: =$Q$3*P19*P19+$R$3*P19 -> 161.88
A20: 1 | 동생 심부름 | B20: 16 | C20: 1 | D20: 7 | E20: 편의점 물류 트럭 발견하기 | F20: 짧은 시간 동안 화면을 지나가는 대상이라 시선을 다른 곳에 두면 놓칠 수 있음 | G20: 카메라 이동과 NPC 시선을 따라 영화관 출구 앞을 지나가는 편의점 물류 트럭을 확인함 | H20: 2 – 대상 노출 시간·화면 내 이동속도·시선 유도 강도가 난이도를 결정함 | I20: 1 | J20: 영화관 출구 앞을 지나가는 편의점 물류 트럭을 화면 안에서 확인 | K20: 대상을 놓치면 짧은 연출이 다시 재생됨 | L20: 25초 | M20: 대상 등장 직전 효과음과 화면 가장자리 표시 | N20: =N19+(IFERROR(VALUE(LEFT(L20,FIND("분",L20)-1))*60,0)+IFERROR(VALUE(TRIM(MID(L20,IFERROR(FIND("분",L20),0)+1,FIND("초",L20)-IFERROR(FIND("분",L20),0)-1))),0))/86400 -> 0.011689815 | O20: 1-D | 영화관 | P20: =P19+4 -> 75 | Q20: 4 | R20: =$Q$3*P20*P20+$R$3*P20 -> 180
A21: 1 | 동생 심부름 | B21: 17 | C21: 5 | D21: 8 | E21: 편의점 물류 트럭 따라가기 | F21: 대상이 빠르게 이동하고 시민과 건물이 시야를 가려 추적이 끊길 수 있음 | G21: 목표 아이콘과 도로 방향을 보며 허용 거리 안에서 물류 트럭을 따라감 | H21: 6 – 플레이어와 대상의 속도 차이·허용 거리·시야 차단물이 난이도를 결정함 | I21: 1 | J21: 허용 거리 안에서 추적 종료 지점 도착 | K21: 대상과 6초 이상 거리 초과 시 추격 구간 재시작 | L21: 2분 | M21: 실패 2회 후 대상 속도 감소 및 경로 화살표 표시 | N21: =N20+(IFERROR(VALUE(LEFT(L21,FIND("분",L21)-1))*60,0)+IFERROR(VALUE(TRIM(MID(L21,IFERROR(FIND("분",L21),0)+1,FIND("초",L21)-IFERROR(FIND("분",L21),0)-1))),0))/86400 -> 0.013078704 | O21: 1-E | 편의점 재입고 | P21: =P20+9 -> 84 | Q21: 9 | R21: =$Q$3*P21*P21+$R$3*P21 -> 224.28
A22: 1 | 동생 심부름 | B22: 18 | C22: 4 | D22: 7 | E22: 신상 과자 오픈런 참가하기 | F22: 여러 NPC가 동시에 진열대로 이동해 접근 경로와 상호작용 위치가 막힘 | G22: 군중의 이동 방향을 예측하고 빈 공간으로 우회해 편의점 진열대 앞 군중에 접근함 | H22: 6 – 경쟁 NPC 수·충돌 범위·재고 수량·접근 가능 시간이 난이도를 결정함 | I22: 4 | J22: 재고가 남아 있을 때 목표 상품 상호작용 성공 | K22: 재고가 모두 소진되면 직전 체크포인트에서 재시도 | L22: 1분 40초 | M22: 재시도 시 경쟁 NPC 수 1명 감소 | N22: =N21+(IFERROR(VALUE(LEFT(L22,FIND("분",L22)-1))*60,0)+IFERROR(VALUE(TRIM(MID(L22,IFERROR(FIND("분",L22),0)+1,FIND("초",L22)-IFERROR(FIND("분",L22),0)-1))),0))/86400 -> 0.014236111 | O22: 1-E | 편의점 재입고 | P22: =P21+8 -> 92 | Q22: 8 | R22: =$Q$3*P22*P22+$R$3*P22 -> 267.72 | W22: 목표 상품 확보 50 / 추격 거리·충돌 25 / 재시도 15 / 시간 10 | X22: =ROUND($X22*1,0) -> 40 | Y22: =X22*0.8 -> 32 | Z22: =X22*0.6 -> 24 | AA22: =X22*0.5 -> 20 | AB22: 0.0025462963 | AC22: =$AD22*1.45 -> 0.0036921296 | AD22: =$AD22 -> 0.0025462963 | AE22: =$AD22*0.75 -> 0.0019097222
A23: 1 | 동생 심부름 | B23: 19 | C23: 2 | D23: 5 | E23: 신상 과자 구매하기 | F23: 구매 대상·수량·결제 순서를 잘못 선택할 수 있음 | G23: 요청받은 품목을 확인하고 상품 선택→계산대 상호작용→결제를 순서대로 진행함 | H23: 3/10 – 상품 후보 수·품목 유사도·구매 단계 수가 난이도를 결정함 | I23: 3 | J23: 신상 과자 1봉 구매 후 인벤토리에 등록 | K23: 잘못된 품목 구매 시 다시 선택해야 함 | L23: 55초 | M23: 요청 품목에 작은 임무 아이콘 표시 | N23: =N22+(IFERROR(VALUE(LEFT(L23,FIND("분",L23)-1))*60,0)+IFERROR(VALUE(TRIM(MID(L23,IFERROR(FIND("분",L23),0)+1,FIND("초",L23)-IFERROR(FIND("분",L23),0)-1))),0))/86400 -> 0.014872685 | O23: 1-E | 편의점 재입고 | P23: =P22+5 -> 97 | Q23: 5 | R23: =$Q$3*P23*P23+$R$3*P23 -> 296.82 | X23: 30 | Y23: =ROUND(X23*0.8,0) -> 24 | Z23: =X23*0.6 -> 18 | AA23: =X23*0.5 -> 15 | AC23: =(IFERROR(VALUE(LEFT(AE23,FIND("분",AE23)-1))*60,0)+IFERROR(VALUE(MID(AE23,IFERROR(FIND("분",AE23),0)+1,FIND("초",AE23)-IFERROR(FIND("분",AE23),0)-1)),0))/86400*2 -> 0.0012731481 | AD23: =(IFERROR(VALUE(LEFT(AE23,FIND("분",AE23)-1))*60,0)+IFERROR(VALUE(MID(AE23,IFERROR(FIND("분",AE23),0)+1,FIND("초",AE23)-IFERROR(FIND("분",AE23),0)-1)),0))/86400*1.4 -> 0.0008912037 | AE23: =L23 -> 55초
A24: 1 | 동생 심부름 | B24: 20 | C24: 1 | D24: 5 | E24: 동생 연락 받기 | F24: 대화 속에 다음 목적지와 필요한 물품 정보가 섞여 있음 | G24: 강조되는 핵심 단어와 NPC의 요구를 확인하며 대화를 끝까지 진행함 | H24: 2/10 – 대사 길이·핵심 정보의 명확성·선택지 수가 난이도를 결정함 | I24: 1 | J24: 중고 거래 물품 수령 요청에 관한 대화를 마지막 문장까지 진행 | K24: - | L24: 1분 10초 | M24: 대화 종료 후 핵심 내용을 화면 한쪽에 요약 표시 | N24: =N23+(IFERROR(VALUE(LEFT(L24,FIND("분",L24)-1))*60,0)+IFERROR(VALUE(TRIM(MID(L24,IFERROR(FIND("분",L24),0)+1,FIND("초",L24)-IFERROR(FIND("분",L24),0)-1))),0))/86400 -> 0.01568287 | O24: 1-E | 편의점 재입고 | P24: =P23+5 -> 102 | Q24: 5 | R24: =$Q$3*P24*P24+$R$3*P24 -> 327.42
A25: 1 | 동생 심부름 | B25: 21 | C25: 2 | D25: 5 | E25: 지하철역으로 이동하기 | F25: 갈림길과 주변 상호작용 오브젝트 때문에 목적지 방향을 놓칠 수 있음 | G25: 표지판·미니맵·NPC 이동 방향을 확인하며 편의점에서 지하철역 개찰구까지 이동함 | H25: 2/10 – 맵 크기·갈림길 수·목적지 표식의 가시성이 난이도를 결정함 | I25: 1 | J25: 편의점에서 지하철역 개찰구의 도착 트리거에 진입 | K25: - | L25: 2분 30초 | M25: 일정 시간 정체 시 목적지 방향 화살표 표시 | N25: =N24+(IFERROR(VALUE(LEFT(L25,FIND("분",L25)-1))*60,0)+IFERROR(VALUE(TRIM(MID(L25,IFERROR(FIND("분",L25),0)+1,FIND("초",L25)-IFERROR(FIND("분",L25),0)-1))),0))/86400 -> 0.017418981 | O25: 1-F | 지하철역 | P25: =P24+7 -> 109 | Q25: 7 | R25: =$Q$3*P25*P25+$R$3*P25 -> 372.78
A26: 1 | 동생 심부름 | B26: 22 | C26: 2 | D26: 7 | E26: 거래자 후보 3명 관찰하기 | F26: 중요한 단서가 여러 인물과 배경 오브젝트 사이에 분산되어 있음 | G26: 시선·행동·복장·주변 오브젝트를 순서대로 확인해 회색 후드 특징이 겹치는 세 명의 후보의 특징을 파악함 | H26: 5/10 – 관찰 대상 수·단서의 명확성·외형 유사도가 난이도를 결정함 | I26: 3 | J26: 필수 관찰 대상 모두 조사 | K26: - | L26: 1분 30초 | M26: 필수 대상 위에 짧은 시선 유도 아이콘 표시 | N26: =N25+(IFERROR(VALUE(LEFT(L26,FIND("분",L26)-1))*60,0)+IFERROR(VALUE(TRIM(MID(L26,IFERROR(FIND("분",L26),0)+1,FIND("초",L26)-IFERROR(FIND("분",L26),0)-1))),0))/86400 -> 0.018460648 | O26: 1-F | 지하철역 | P26: =P25+7 -> 116 | Q26: 7 | R26: =$Q$3*P26*P26+$R$3*P26 -> 421.08
A27: 1 | 동생 심부름 | B27: 23 | C27: 3 | D27: 8 | E27: 중고 거래자 찾기 | F27: 후보들이 공통 특징을 가지고 있어 한 가지 단서만으로는 구별할 수 없음 | G27: 복장·소지품·대화 반응을 함께 비교해 대화 단서와 복장 단서가 일치하는 거래자를 선택함 | H27: 6/10 – 후보 수·공통 특징 수·추가 단서의 명확성이 난이도를 결정함 | I27: 4 | J27: 올바른 거래자와 대화 시작 | K27: 오답 후보 선택 시 경계 대사가 출력되고 다시 선택 | L27: 2분 | M27: 오답 2회 후 확인하지 않은 단서 목록 표시 | N27: =N26+(IFERROR(VALUE(LEFT(L27,FIND("분",L27)-1))*60,0)+IFERROR(VALUE(TRIM(MID(L27,IFERROR(FIND("분",L27),0)+1,FIND("초",L27)-IFERROR(FIND("분",L27),0)-1))),0))/86400 -> 0.019849537 | O27: 1-F | 지하철역 | P27: =P26+9 -> 125 | Q27: 9 | R27: =$Q$3*P27*P27+$R$3*P27 -> 487.5 | W27: 거래자 판별 50 / 필수 단서 확인 25 / 오답 15 / 시간 10 | X27: =ROUND($X27*1,0) -> 20 | Y27: =ROUND(X27*0.8,0) -> 16 | Z27: =X27*0.6 -> 12 | AA27: =X27*0.5 -> 10 | AB27: 0.0024305556 | AC27: =$AD27*1.35 -> 0.00328125 | AD27: =$AD27 -> 0.0024305556 | AE27: =$AD27*0.8 -> 0.0019444444
A28: 1 | 동생 심부름 | B28: 24 | C28: 1 | D28: 5 | E28: 중고 거래 완료하기 | F28: 구매 대상·수량·결제 순서를 잘못 선택할 수 있음 | G28: 요청받은 품목을 확인하고 상품 선택→계산대 상호작용→결제를 순서대로 진행함 | H28: 2/10 – 상품 후보 수·품목 유사도·구매 단계 수가 난이도를 결정함 | I28: 3 | J28: 동생이 부탁한 중고 물품 구매 후 인벤토리에 등록 | K28: 잘못된 품목 구매 시 다시 선택해야 함 | L28: 1분 5초 | M28: 요청 품목에 작은 임무 아이콘 표시 | N28: =N27+(IFERROR(VALUE(LEFT(L28,FIND("분",L28)-1))*60,0)+IFERROR(VALUE(TRIM(MID(L28,IFERROR(FIND("분",L28),0)+1,FIND("초",L28)-IFERROR(FIND("분",L28),0)-1))),0))/86400 -> 0.020601852 | O28: 1-F | 지하철역 | P28: =P27+5 -> 130 | Q28: 5 | R28: =$Q$3*P28*P28+$R$3*P28 -> 526.5
A29: 1 | 동생 심부름 | B29: 25 | C29: 2 | D29: 5 | E29: 집으로 돌아가는 길에 공원 진입하기 | F29: 갈림길과 주변 상호작용 오브젝트 때문에 목적지 방향을 놓칠 수 있음 | G29: 표지판·미니맵·NPC 이동 방향을 확인하며 지하철역에서 축제 종료 공원까지 이동함 | H29: 2/10 – 맵 크기·갈림길 수·목적지 표식의 가시성이 난이도를 결정함 | I29: 1 | J29: 지하철역에서 축제 종료 공원의 도착 트리거에 진입 | K29: - | L29: 1분 50초 | M29: 일정 시간 정체 시 목적지 방향 화살표 표시 | N29: =N28+(IFERROR(VALUE(LEFT(L29,FIND("분",L29)-1))*60,0)+IFERROR(VALUE(TRIM(MID(L29,IFERROR(FIND("분",L29),0)+1,FIND("초",L29)-IFERROR(FIND("분",L29),0)-1))),0))/86400 -> 0.021875 | O29: 1-G | 공원 진입 | P29: =P28+6 -> 136 | Q29: 6 | R29: =$Q$3*P29*P29+$R$3*P29 -> 575.28
A30: 2 | 공원 청소 | B30: 26 | C30: 1 | D30: 5 | E30: 축제 종료 현장 관찰하기 | F30: 중요한 단서가 여러 인물과 배경 오브젝트 사이에 분산되어 있음 | G30: 시선·행동·복장·주변 오브젝트를 순서대로 확인해 떠나는 시민과 공원에 남은 쓰레기의 특징을 파악함 | H30: 3/10 – 관찰 대상 수·단서의 명확성·외형 유사도가 난이도를 결정함 | I30: 4 | J30: 필수 관찰 대상 모두 조사 | K30: - | L30: 1분 15초 | M30: 필수 대상 위에 짧은 시선 유도 아이콘 표시 | N30: =N29+(IFERROR(VALUE(LEFT(L30,FIND("분",L30)-1))*60,0)+IFERROR(VALUE(TRIM(MID(L30,IFERROR(FIND("분",L30),0)+1,FIND("초",L30)-IFERROR(FIND("분",L30),0)-1))),0))/86400 -> 0.022743056 | O30: 2-A | 공원 축제·청소 | P30: =P29+5 -> 141 | Q30: 5 | R30: =$Q$3*P30*P30+$R$3*P30 -> 617.58
A31: 2 | 공원 청소 | B31: 27 | C31: 1 | D31: 6 | E31: 아이가 쓰레기에 걸려 넘어질 뻔한 장면 목격하기 | F31: 짧은 연출 안에서 사건의 원인과 인물의 태도를 동시에 이해해야 함 | G31: 카메라가 강조하는 인물과 오브젝트를 보며 아이와 가족의 행동을 확인함 | H31: 1/10 – 연출 속도·동시에 제시되는 정보량이 난이도를 결정함 | I31: 1 | J31: 사건 연출 종료 | K31: - | L31: 35초 | M31: 핵심 오브젝트에 카메라 줌과 효과음 적용 | N31: =N30+(IFERROR(VALUE(LEFT(L31,FIND("분",L31)-1))*60,0)+IFERROR(VALUE(TRIM(MID(L31,IFERROR(FIND("분",L31),0)+1,FIND("초",L31)-IFERROR(FIND("분",L31),0)-1))),0))/86400 -> 0.023148148 | O31: 2-A | 공원 축제·청소 | P31: =P30+4 -> 145 | Q31: 4 | R31: =$Q$3*P31*P31+$R$3*P31 -> 652.5
A32: 2 | 공원 청소 | B32: 28 | C32: 1 | D32: 5 | E32: 쓰레기를 치우기로 결정하기 | F32: 두 선택 모두 이후 상황에 영향을 주므로 감정적 판단 부담이 발생함 | G32: 현재 상황과 주인공의 독백을 확인한 뒤 공원을 지나갈지 쓰레기를 치울지 판단에 대한 행동을 결정함 | H32: 3/10 – 정보의 불완전성·결과 예측 가능성·감정적 부담이 난이도를 결정함 | I32: 1 | J32: 선택지 1개 확정 | K32: - | L32: 45초 | M32: 선택 직전 핵심 상황을 한 문장으로 다시 표시 | N32: =N31+(IFERROR(VALUE(LEFT(L32,FIND("분",L32)-1))*60,0)+IFERROR(VALUE(TRIM(MID(L32,IFERROR(FIND("분",L32),0)+1,FIND("초",L32)-IFERROR(FIND("분",L32),0)-1))),0))/86400 -> 0.023668981 | O32: 2-A | 공원 축제·청소 | P32: =P31+4 -> 149 | Q32: 4 | R32: =$Q$3*P32*P32+$R$3*P32 -> 688.38
A33: 2 | 공원 청소 | B33: 29 | C33: 2 | D33: 5 | E33: 청소 도구 찾기 | F33: 비슷한 오브젝트와 진열대가 많아 목표 대상을 한 번에 찾기 어려움 | G33: 구역별 표지와 상품 외형을 비교하며 공원 관리함의 집게와 봉투를 조사함 | H33: 3/10 – 후보 오브젝트 수·외형 유사도·탐색 범위가 난이도를 결정함 | I33: 4 | J33: 공원 관리함의 집게와 봉투 발견 및 조사 완료 | K33: - | L33: 1분 25초 | M33: 30초 이상 미발견 시 목표 구역에 약한 반짝임 표시 | N33: =N32+(IFERROR(VALUE(LEFT(L33,FIND("분",L33)-1))*60,0)+IFERROR(VALUE(TRIM(MID(L33,IFERROR(FIND("분",L33),0)+1,FIND("초",L33)-IFERROR(FIND("분",L33),0)-1))),0))/86400 -> 0.024652778 | O33: 2-A | 공원 축제·청소 | P33: =P32+6 -> 155 | Q33: 6 | R33: =$Q$3*P33*P33+$R$3*P33 -> 744
A34: 2 | 공원 청소 | B34: 30 | C34: 1 | D34: 5 | E34: 첫 쓰레기 줍기 | F34: 수거 대상과 배경 장식의 차이를 처음에는 구별하기 어려움 | G34: 반짝임 표시가 있는 산책로의 첫 쓰레기에 접근해 줍기 입력을 수행함 | H34: 2/10 – 대상 가시성·입력 단계 수가 난이도를 결정함 | I34: 3 | J34: 안내된 수거 행동 3회 완료 | K34: - | L34: 55초 | M34: 수거 대상 반짝임과 상호작용 범위를 크게 설정 | N34: =N33+(IFERROR(VALUE(LEFT(L34,FIND("분",L34)-1))*60,0)+IFERROR(VALUE(TRIM(MID(L34,IFERROR(FIND("분",L34),0)+1,FIND("초",L34)-IFERROR(FIND("분",L34),0)-1))),0))/86400 -> 0.025289352 | O34: 2-A | 공원 축제·청소 | P34: =P33+4 -> 159 | Q34: 4 | R34: =$Q$3*P34*P34+$R$3*P34 -> 782.28
A35: 2 | 공원 청소 | B35: 31 | C35: 2 | D35: 6 | E35: 잔디 구역 쓰레기 수거하기 | F35: 쓰레기가 넓은 구역과 가려진 틈에 흩어져 있어 남은 대상을 찾기 어려움 | G35: 구역을 일정한 방향으로 순회하고 반짝임·잔여 개수 UI를 확인하며 잔디 구역 쓰레기 8개를 수거함 | H35: 4/10 – 목표 수량·배치 밀도·가림 오브젝트·탐색 범위가 난이도를 결정함 | I35: 8 | J35: 잔디 구역 쓰레기 8개 전부 수거 | K35: 필수 수량을 채우지 못하면 다음 구역 진행 불가 | L35: 3분 | M35: 60초 이상 미발견 시 가장 가까운 미수거 대상 방향 표시 | N35: =N34+(IFERROR(VALUE(LEFT(L35,FIND("분",L35)-1))*60,0)+IFERROR(VALUE(TRIM(MID(L35,IFERROR(FIND("분",L35),0)+1,FIND("초",L35)-IFERROR(FIND("분",L35),0)-1))),0))/86400 -> 0.027372685 | O35: 2-A | 공원 축제·청소 | P35: =P34+9 -> 168 | Q35: 9 | R35: =$Q$3*P35*P35+$R$3*P35 -> 871.92
A36: 2 | 공원 청소 | B36: 32 | C36: 2 | D36: 6 | E36: 산책로 쓰레기 수거하기 | F36: 쓰레기가 넓은 구역과 가려진 틈에 흩어져 있어 남은 대상을 찾기 어려움 | G36: 구역을 일정한 방향으로 순회하고 반짝임·잔여 개수 UI를 확인하며 산책로 쓰레기 7개를 수거함 | H36: 4/10 – 목표 수량·배치 밀도·가림 오브젝트·탐색 범위가 난이도를 결정함 | I36: 7 | J36: 산책로 쓰레기 7개 전부 수거 | K36: 필수 수량을 채우지 못하면 다음 구역 진행 불가 | L36: 2분 40초 | M36: 60초 이상 미발견 시 가장 가까운 미수거 대상 방향 표시 | N36: =N35+(IFERROR(VALUE(LEFT(L36,FIND("분",L36)-1))*60,0)+IFERROR(VALUE(TRIM(MID(L36,IFERROR(FIND("분",L36),0)+1,FIND("초",L36)-IFERROR(FIND("분",L36),0)-1))),0))/86400 -> 0.029224537 | O36: 2-A | 공원 축제·청소 | P36: =P35+9 -> 177 | Q36: 9 | R36: =$Q$3*P36*P36+$R$3*P36 -> 966.42
A37: 2 | 공원 청소 | B37: 33 | C37: 3 | D37: 6 | E37: 벤치 주변 쓰레기 수거하기 | F37: 쓰레기가 넓은 구역과 가려진 틈에 흩어져 있어 남은 대상을 찾기 어려움 | G37: 구역을 일정한 방향으로 순회하고 반짝임·잔여 개수 UI를 확인하며 벤치와 가려진 틈의 쓰레기 6개를 수거함 | H37: 5/10 – 목표 수량·배치 밀도·가림 오브젝트·탐색 범위가 난이도를 결정함 | I37: 6 | J37: 벤치와 가려진 틈의 쓰레기 6개 전부 수거 | K37: 필수 수량을 채우지 못하면 다음 구역 진행 불가 | L37: 2분 30초 | M37: 60초 이상 미발견 시 가장 가까운 미수거 대상 방향 표시 | N37: =N36+(IFERROR(VALUE(LEFT(L37,FIND("분",L37)-1))*60,0)+IFERROR(VALUE(TRIM(MID(L37,IFERROR(FIND("분",L37),0)+1,FIND("초",L37)-IFERROR(FIND("분",L37),0)-1))),0))/86400 -> 0.030960648 | O37: 2-A | 공원 축제·청소 | P37: =P36+9 -> 186 | Q37: 9 | R37: =$Q$3*P37*P37+$R$3*P37 -> 1065.78
A38: 2 | 공원 청소 | B38: 34 | C38: 1 | D38: 5 | E38: 한도윤과 대화하기 | F38: 대화 속에 다음 목적지와 필요한 물품 정보가 섞여 있음 | G38: 강조되는 핵심 단어와 NPC의 요구를 확인하며 대화를 끝까지 진행함 | H38: 2/10 – 대사 길이·핵심 정보의 명확성·선택지 수가 난이도를 결정함 | I38: 1 | J38: 혼자 청소하는 이유와 도움 제안에 관한 대화를 마지막 문장까지 진행 | K38: - | L38: 1분 30초 | M38: 대화 종료 후 핵심 내용을 화면 한쪽에 요약 표시 | N38: =N37+(IFERROR(VALUE(LEFT(L38,FIND("분",L38)-1))*60,0)+IFERROR(VALUE(TRIM(MID(L38,IFERROR(FIND("분",L38),0)+1,FIND("초",L38)-IFERROR(FIND("분",L38),0)-1))),0))/86400 -> 0.032002315 | O38: 2-A | 공원 축제·청소 | P38: =P37+5 -> 191 | Q38: 5 | R38: =$Q$3*P38*P38+$R$3*P38 -> 1123.08
A39: 2 | 공원 청소 | B39: 35 | C39: 2 | D39: 5 | E39: 한도윤과 구역 분담하기 | F39: 동료가 담당하는 구역과 플레이어 구역이 겹치면 불필요한 이동이 발생함 | G39: 대화에서 정한 담당 구역을 확인하고 서로 다른 공원 구역를 순서대로 처리함 | H39: 4/10 – 구역 수·동료 행동 예측 가능성·이동 동선이 난이도를 결정함 | I39: 4 | J39: 플레이어 담당 구역의 목표 수량 달성 | K39: - | L39: 2분 20초 | M39: 미니맵에 담당 구역을 서로 다른 테두리로 표시 | N39: =N38+(IFERROR(VALUE(LEFT(L39,FIND("분",L39)-1))*60,0)+IFERROR(VALUE(TRIM(MID(L39,IFERROR(FIND("분",L39),0)+1,FIND("초",L39)-IFERROR(FIND("분",L39),0)-1))),0))/86400 -> 0.033622685 | O39: 2-A | 공원 축제·청소 | P39: =P38+8 -> 199 | Q39: 8 | R39: =$Q$3*P39*P39+$R$3*P39 -> 1217.88
A40: 2 | 공원 청소 | B40: 36 | C40: 2 | D40: 6 | E40: 우정 반지 단서 발견하기 | F40: 작은 단서가 쓰레기와 배경에 섞여 있어 일반 수거물로 오인할 수 있음 | G40: 중학생이 잃어버린 반지의 흔적의 형태와 주변 대사를 확인하고 별도 조사함 | H40: 4/10 – 단서 크기·배경 대비·오인 가능성이 난이도를 결정함 | I40: 3 | J40: 필수 단서 모두 조사 | K40: 단서를 버리려 하면 경고 후 행동 취소 | L40: 1분 15초 | M40: 단서에 일반 쓰레기와 다른 약한 빛 효과 적용 | N40: =N39+(IFERROR(VALUE(LEFT(L40,FIND("분",L40)-1))*60,0)+IFERROR(VALUE(TRIM(MID(L40,IFERROR(FIND("분",L40),0)+1,FIND("초",L40)-IFERROR(FIND("분",L40),0)-1))),0))/86400 -> 0.034490741 | O40: 2-A | 공원 축제·청소 | P40: =P39+6 -> 205 | Q40: 6 | R40: =$Q$3*P40*P40+$R$3*P40 -> 1291.5
...

Sheet 밸런스 팩터
B2: 밸런스 팩터
B4: 게임 「넌 착해!」의 플레이 경험에 영향을 주는 주요 조정 요소를 원형으로 정리
B70: 큰 원은 플레이 전반에 미치는 영향이 큰 핵심 팩터이며, 작은 원은 장면·미션 단위에서 조정하는 세부 팩터임

Sheet 작성 기준
A1: 밸런스 문서 작성 기준
A3: 항목 | B3: 작성 방식 | C3: 값/형식 | D3: 우리 게임 적용 기준
A4: 조작난이도 | B4: 플레이어가 실제 입력을 수행할 때 느끼는 손 조작의 어려움 | C4: 1~10 숫자 | D4: 1은 단순 확인·대화, 10은 빠른 보스 패턴과 복합 입력
A5: 재미율 | B5: 기획자가 해당 구간이 이 정도로 재미있기를 기대하며 정하는 정성적 목표값 | C5: 1~10 숫자 | D5: 탐색·긴장·감정·반전·성취를 모두 포함하며 실제 테스트값이 아님
A6: 컨텐츠 제시순서 | B6: 게임 시작부터 엔딩까지 해금되는 모든 플레이 내용을 순서대로 기록 | C6: 1부터 연속 넘버링 | D6: UI 미션뿐 아니라 이동·조사·대화·전투·업적성 행동·연출 확인까지 포함
A7: 미션 | B7: 제목만 읽어도 플레이어가 무엇을 해야 하는지 보이도록 작성 | C7: 행동형 제목 | D7: 예: 신상 과자 진열대 찾기, 균열 괴물과 첫 전투 치르기
A8: 방해요소 | B8: 목표를 바로 달성하지 못하게 만드는 맵·NPC·시간·정보·전투 요소 | C8: 구체적 서술 | D8: 비슷한 후보, 넓은 탐색 범위, 제한시간, 시야 차단, 감정적 압박 등
A9: 방해요소 공략 | B9: 방해요소를 해결하기 위해 플레이어가 관찰·판단·조작해야 하는 내용 | C9: 구체적 플레이 절차 | D9: 이 표에서 가장 핵심적인 항목으로 작성
A10: 방해요인의 난이도 | B10: 관찰·판단·공략의 어려움과 그 난이도를 만드는 요인을 함께 기록 | C10: 숫자/10 + 원인 설명 | D10: 후보 수, 맵 크기, 속도 차이, 제한시간, 패턴 수 등
A11: 미션개수 | B11: 해당 행의 목표를 완료하기 위해 필요한 행동·대상·단계의 수 | C11: 정수 | D11: 수거 8개, 단서 5개, 대화 1회, 보스 패턴 6회 등
A12: 성공 미션조건 | B12: 시스템이 완료를 판정할 수 있는 명확한 조건 | C12: 구체적 판정 조건 | D12: 목표 수량 달성, 트리거 진입, 보스 체력 0 등
A13: 실패 미션조건 | B13: 실패가 존재하는 경우 재시작·페널티가 발생하는 조건 | C13: 구체적 판정 조건 또는 실패 없음 | D13: 추격 거리 초과, 체력 0, 제한시간 종료, 오답 누적 등
A14: 예상 플레이타임 | B14: 초회 플레이어가 해당 콘텐츠를 완료하는 데 걸릴 것으로 예상하는 시간 | C14: 초/분 | D14: 이동거리·미션개수·대사량·재시도 가능성을 함께 고려
... A18: 문서 범위 | B18: 게임 시작부터 엔딩까지 모든 콘텐츠를 작성 | C18: 최소 50개 이상 | D18: 현재 문서에는 총 119개 콘텐츠를 기록

Sheet 밸런스 곡선
A1: 전체 밸런스 곡선 요약
A3: 총 콘텐츠 수 | B3: 119 | C3: 평균 조작난이도 | D3: =AVERAGE('밸런스 문서'!C5:C123) -> 2.907563 | E3: 평균 재미율 | F3: =AVERAGE('밸런스 문서'!D5:D123) -> 7.2857143 | G3: 최고 조작난이도 | H3: =MAX('밸런스 문서'!C5:C123) -> 10 | I3: 최고 재미율 | J3: =MAX('밸런스 문서'!D5:D123) -> 10
A5: 구간 | B5: 콘텐츠 수 | C5: 평균 조작난이도 | D5: 평균 재미율 | E5: 최고 방해요인 난이도
A6: Q1 동생 심부름 | B6: 25 | C6: =AVERAGE('밸런스 문서'!C5:C29) -> 1.76 | D6: =AVERAGE('밸런스 문서'!D5:D29) -> 5.48 | E6: 6
A7: Q2 공원 청소 | B7: 23 | C7: =AVERAGE('밸런스 문서'!C30:C52) -> 1.7826087 | D7: =AVERAGE('밸런스 문서'!D30:D52) -> 6.1304348 | E7: 7
A8: Q3 재난 대응과 영웅화 | B8: 26 | C8: =AVERAGE('밸런스 문서'!C53:C78) -> 3.1538462 | D8: =AVERAGE('밸런스 문서'!D53:D78) -> 7.7307692 | E8: 7
A9: Q4 폐교 보스 | B9: 26 | C9: =AVERAGE('밸런스 문서'!C79:C104) -> 4.3461538 | D9: =AVERAGE('밸런스 문서'!D79:D104) -> 7.8846154 | E9: 10
A10: Q5 균열 탐색과 결말 | B10: 19 | C10: =AVERAGE('밸런스 문서'!C105:C123) -> 3.4736842 | D10: =AVERAGE('밸런스 문서'!D105:D123) -> 9.6315789 | E10: 10
A14: 컨텐츠 제시순서 | B14: 조작난이도 | C14: 재미율
A15: 1 | B15: 1 | C15: 7
A16: 2 | B16: 1 | C16: 4
A17: 3 | B17: 1 | C17: 5
A18: 4 | B18: 1 | C18: 4
A19: 5 | B19: 1 | C19: 4
A20: 6 | B20: 1 | C20: 5
A21: 7 | B21: 2 | C21: 5
A22: 8 | B22: 2 | C22: 6
A23: 9 | B23: 1 | C23: 5
A24: 10 | B24: 1 | C24: 6
A25: 11 | B25: 2 | C25: 5
A26: 12 | B26: 2 | C26: 6
... A133: 119 | B133: 1 | C133: 9
