Workbook

Sheet 밸런스 문서
A1: 챕터 | B1: 콘텐츠 진행 순서 | C1: 플레이 난이도 | D1: 플레이 흥미도 | E1: 플레이 목표 | F1: 플레이 난관 | G1: 공략 방법 | H1: 체감 난이도 | I1: 수행 과제 수 | J1: 목표 달성 조건 | K1: 실패 결과 | L1: 예상 소요 시간 | M1: 난이도 조절 요소 | N1: 누적 플레이 시간 | O1: 스테이지 | P1: 콘텐츠 진행 포인트 누적 | Q1: X 콘텐츠 진행 포인트 | R1: Y 레벨업을 위한 필요 경험치 | S1: 한마리 몬스터가 주는 경험치 | T1: 한마리 몬스터와 전투시간(초) | U1: 레벨 업을 위한 전투시간(초) | V1: 레벨 업을 위해 잡아야하는 몬스터 수
A2: 1 | 동생 심부름 | B2: 1 | C2: 1 | D2: 8 | E2: 차한해의 과거 오프닝 감상 | F2: 입양 이후 가족 안에서 희생을 요구받아 온 과거를 보여주는 연출이 길게 이어져 플레이어가 핵심 정보를 놓칠 수 있음 | G2: 핵심 장면의 시선 유도와 짧은 자막을 통해 관계와 감정 변화를 이해함 | H2: 1 – 연출 길이와 정보량이 난이도를 결정함 | I2: 1 | J2: 오프닝 재생이 끝나면 자동 완료 | K2: - | L2: 1분 30초 | M2: 스킵·다시 보기 기능 제공 | N2: =(IFERROR(VALUE(LEFT(L2,FIND("분",L2)-1))*60,0)+IFERROR(VALUE(TRIM(MID(L2,IFERROR(FIND("분",L2),0)+1,FIND("초",L2)-IFERROR(FIND("분",L2),0)-1))),0))/86400 -> 0.0010416667 | O2: 1-A | 집·튜토리얼 | P2: =#REF!+Q2 -> #REF! | Q2: 3 | R2: =ROUND(#REF!*Q2*Q2+#REF!*Q2,2) -> #REF! | S2: =IF(OR(V2="",V2=0),"",ROUND(R2/V2,2)) | U2: =IF(OR(T2="",V2="",V2=0),"",T2*V2)
A3: 1 | 동생 심부름 | B3: 2 | C3: 1 | D3: 3 | E3: 빨래 개기 | F3: 조사 가능한 가구가 많아 조작 가능한 대상을 바로 알아보기 어려움 | G3: 주인공 주변의 상호작용 표시를 확인하고 조사 키를 누름 | H3: 1 – 상호작용 표시의 가시성과 조사 범위가 난이도를 결정함 | I3: 1 | J3: 소파 옆 주인공에서 조사 입력 1회 완료 | K3: - | L3: 20초 | M3: 첫 상호작용 대상에 반짝임 표시 | N3: =N2+(IFERROR(VALUE(LEFT(L3,FIND("분",L3)-1))*60,0)+IFERROR(VALUE(TRIM(MID(L3,IFERROR(FIND("분",L3),0)+1,FIND("초",L3)-IFERROR(FIND("분",L3),0)-1))),0))/86400 -> 0.0012731481 | O3: 1-A | 집·튜토리얼 | P3: =P2+Q3 -> #REF! | Q3: 2 | R3: =ROUND(#REF!*Q3*Q3+#REF!*Q3,2) -> #REF! | S3: =IF(OR(V3="",V3=0),"",ROUND(R3/V3,2)) | U3: =IF(OR(T3="",V3="",V3=0),"",T3*V3)
A4: 1 | 동생 심부름 | B4: 3 | C4: 1 | D4: 5 | E4: 동생에게 심부름 지시 받기 | F4: 대화 속에 다음 목적지와 필요한 물품 정보가 섞여 있음 | G4: 강조되는 핵심 단어와 NPC의 요구를 확인하며 대화를 끝까지 진행함 | H4: 1 – 대사 길이·핵심 정보의 명확성·선택지 수가 난이도를 결정함 | I4: 1 | J4: 신상 과자·헤어롤·팝콘 심부름에 관한 대화를 마지막 문장까지 진행 | K4: - | L4: 1분 | M4: 대화 종료 후 핵심 내용을 화면 한쪽에 요약 표시 | N4: =N3+(IFERROR(VALUE(LEFT(L4,FIND("분",L4)-1))*60,0)+IFERROR(VALUE(TRIM(MID(L4,IFERROR(FIND("분",L4),0)+1,FIND("초",L4)-IFERROR(FIND("분",L4),0)-1))),0))/86400 -> 0.0019675926 | O4: 1-A | 집·튜토리얼 | P4: =P3+Q4 -> #REF! | Q4: 4 | R4: =ROUND(#REF!*Q4*Q4+#REF!*Q4,2) -> #REF! | S4: =IF(OR(V4="",V4=0),"",ROUND(R4/V4,2)) | U4: =IF(OR(T4="",V4="",V4=0),"",T4*V4)
A5: 1 | 동생 심부름 | B5: 4 | C5: 1 | D5: 3 | E5: 이동 조작 안내 확인 | F5: 여러 조작을 한 번에 제시하면 입력 방법을 혼동할 수 있음 | G5: 화면에 표시되는 키를 순서대로 입력하고 각 동작의 결과를 확인함 | H5: 1 – 동시에 제시되는 조작 수와 입력 허용 시간이 난이도를 결정함 | I5: 4 | J5: 상하좌우 이동과 조사 키를 안내 순서대로 모두 수행 | K5: - | L5: 40초 | M5: 입력하지 않은 키 안내를 계속 유지 | N5: =N4+(IFERROR(VALUE(LEFT(L5,FIND("분",L5)-1))*60,0)+IFERROR(VALUE(TRIM(MID(L5,IFERROR(FIND("분",L5),0)+1,FIND("초",L5)-IFERROR(FIND("분",L5),0)-1))),0))/86400 -> 0.0024305556 | O5: 1-A | 집·튜토리얼 | P5: =P4+Q5 -> #REF! | Q5: 3 | R5: =ROUND(#REF!*Q5*Q5+#REF!*Q5,2) -> #REF! | S5: =IF(OR(V5="",V5=0),"",ROUND(R5/V5,2)) | U5: =IF(OR(T5="",V5="",V5=0),"",T5*V5)
A6: 1 | 동생 심부름 | B6: 5 | C6: 1 | D6: 3 | E6: 현관으로 이동하기 | F6: 갈림길과 주변 상호작용 오브젝트 때문에 목적지 방향을 놓칠 수 있음 | G6: 표지판·미니맵·NPC 이동 방향을 확인하며 거실에서 현관문까지 이동함 | H6: 1 – 맵 크기·갈림길 수·목적지 표식의 가시성이 난이도를 결정함 | I6: 1 | J6: 거실에서 현관문의 도착 트리거에 진입 | K6: - | L6: 30초 | M6: 일정 시간 정체 시 목적지 방향 화살표 표시 | N6: =N5+(IFERROR(VALUE(LEFT(L6,FIND("분",L6)-1))*60,0)+IFERROR(VALUE(TRIM(MID(L6,IFERROR(FIND("분",L6),0)+1,FIND("초",L6)-IFERROR(FIND("분",L6),0)-1))),0))/86400 -> 0.0027777778 | O6: 1-A | 집·튜토리얼 | P6: =P5+Q6 -> #REF! | Q6: 3 | R6: =ROUND(#REF!*Q6*Q6+#REF!*Q6,2) -> #REF! | S6: =IF(OR(V6="",V6=0),"",ROUND(R6/V6,2)) | U6: =IF(OR(T6="",V6="",V6=0),"",T6*V6)
A7: 1 | 동생 심부름 | B7: 6 | C7: 1 | D7: 5 | E7: 집 밖으로 나가기 | F7: 조사 대상이 배경 오브젝트와 비슷해 상호작용 가능 여부를 놓칠 수 있음 | G7: 현관문 가까이 이동한 뒤 상호작용 아이콘이 나타날 때 조사함 | H7: 1 – 조사 대상의 크기·배경과의 대비·상호작용 범위가 난이도를 결정함 | I7: 1 | J7: 현관문 조사 완료 | K7: - | L7: 20초 | M7: 상호작용 가능 범위를 넓히고 아이콘 표시 | N7: =N6+(IFERROR(VALUE(LEFT(L7,FIND("분",L7)-1))*60,0)+IFERROR(VALUE(TRIM(MID(L7,IFERROR(FIND("분",L7),0)+1,FIND("초",L7)-IFERROR(FIND("분",L7),0)-1))),0))/86400 -> 0.0030092593 | O7: 1-A | 집·튜토리얼 | P7: =P6+Q7 -> #REF! | Q7: 3 | R7: =ROUND(#REF!*Q7*Q7+#REF!*Q7,2) -> #REF! | S7: =IF(OR(V7="",V7=0),"",ROUND(R7/V7,2)) | U7: =IF(OR(T7="",V7="",V7=0),"",T7*V7)
A8: 1 | 동생 심부름 | B8: 7 | C8: 2 | D8: 5 | E8: 편의점으로 이동하기 | F8: 갈림길과 주변 상호작용 오브젝트 때문에 목적지 방향을 놓칠 수 있음 | G8: 표지판·미니맵·NPC 이동 방향을 확인하며 아파트에서 편의점까지 이동함 | H8: 2 – 맵 크기·갈림길 수·목적지 표식의 가시성이 난이도를 결정함 | I8: 1 | J8: 아파트에서 편의점의 도착 트리거에 진입 | K8: - | L8: 1분 15초 | M8: 일정 시간 정체 시 목적지 방향 화살표 표시 | N8: =N7+(IFERROR(VALUE(LEFT(L8,FIND("분",L8)-1))*60,0)+IFERROR(VALUE(TRIM(MID(L8,IFERROR(FIND("분",L8),0)+1,FIND("초",L8)-IFERROR(FIND("분",L8),0)-1))),0))/86400 -> 0.0038773148 | O8: 1-B | 편의점 | P8: =P7+Q8 -> #REF! | Q8: 5 | R8: =ROUND(#REF!*Q8*Q8+#REF!*Q8,2) -> #REF! | S8: =IF(OR(V8="",V8=0),"",ROUND(R8/V8,2)) | U8: =IF(OR(T8="",V8="",V8=0),"",T8*V8)
A9: 1 | 동생 심부름 | B9: 8 | C9: 2 | D9: 6 | E9: 신상 과자 진열대 찾기 | F9: 비슷한 오브젝트와 진열대가 많아 목표 대상을 한 번에 찾기 어려움 | G9: 구역별 표지와 상품 외형을 비교하며 편의점 안 신상 과자 진열대를 조사함 | H9: 3 – 후보 오브젝트 수·외형 유사도·탐색 범위가 난이도를 결정함 | I9: 4 | J9: 편의점 안 신상 과자 진열대 발견 및 조사 완료 | K9: - | L9: 1분 30초 | M9: 30초 이상 미발견 시 목표 구역에 약한 반짝임 표시 | N9: =N8+(IFERROR(VALUE(LEFT(L9,FIND("분",L9)-1))*60,0)+IFERROR(VALUE(TRIM(MID(L9,IFERROR(FIND("분",L9),0)+1,FIND("초",L9)-IFERROR(FIND("분",L9),0)-1))),0))/86400 -> 0.0049189815 | O9: 1-B | 편의점 | P9: =P8+Q9 -> #REF! | Q9: 6 | R9: =ROUND(#REF!*Q9*Q9+#REF!*Q9,2) -> #REF! | S9: =IF(OR(V9="",V9=0),"",ROUND(R9/V9,2)) | U9: =IF(OR(T9="",V9="",V9=0),"",T9*V9)
A10: 1 | 동생 심부름 | B10: 9 | C10: 1 | D10: 5 | E10: 품절 안내 조사하기 | F10: 조사 대상이 배경 오브젝트와 비슷해 상호작용 가능 여부를 놓칠 수 있음 | G10: 비어 있는 진열칸과 손글씨 품절 안내 가까이 이동한 뒤 상호작용 아이콘이 나타날 때 조사함 | H10: 2 – 조사 대상의 크기·배경과의 대비·상호작용 범위가 난이도를 결정함 | I10: 2 | J10: 비어 있는 진열칸과 손글씨 품절 안내 조사 완료 | K10: - | L10: 35초 | M10: 상호작용 가능 범위를 넓히고 아이콘 표시 | N10: =N9+(IFERROR(VALUE(LEFT(L10,FIND("분",L10)-1))*60,0)+IFERROR(VALUE(TRIM(MID(L10,IFERROR(FIND("분",L10),0)+1,FIND("초",L10)-IFERROR(FIND("분",L10),0)-1))),0))/86400 -> 0.0053240741 | O10: 1-B | 편의점 | P10: =P9+Q10 -> #REF! | Q10: 4 | R10: =ROUND(#REF!*Q10*Q10+#REF!*Q10,2) -> #REF! | S10: =IF(OR(V10="",V10=0),"",ROUND(R10/V10,2)) | U10: =IF(OR(T10="",V10="",V10=0),"",T10*V10)
A11: 1 | 동생 심부름 | B11: 10 | C11: 1 | D11: 6 | E11: 알바생 NPC와 대화하기 | F11: 대화 속에 다음 목적지와 필요한 물품 정보가 섞여 있음 | G11: 강조되는 핵심 단어와 NPC의 요구를 확인하며 대화를 끝까지 진행함 | H11: 2 – 대사 길이·핵심 정보의 명확성·선택지 수가 난이도를 결정함 | I11: 1 | J11: 재입고 시간과 물류 트럭 정보에 관한 대화를 마지막 문장까지 진행 | K11: - | L11: 1분 15초 | M11: 대화 종료 후 핵심 내용을 화면 한쪽에 요약 표시 | N11: =N10+(IFERROR(VALUE(LEFT(L11,FIND("분",L11)-1))*60,0)+IFERROR(VALUE(TRIM(MID(L11,IFERROR(FIND("분",L11),0)+1,FIND("초",L11)-IFERROR(FIND("분",L11),0)-1))),0))/86400 -> 0.0061921296 | O11: 1-B | 편의점 | P11: =P10+Q11 -> #REF! | Q11: 5 | R11: =ROUND(#REF!*Q11*Q11+#REF!*Q11,2) -> #REF! | S11: =IF(OR(V11="",V11=0),"",ROUND(R11/V11,2)) | U11: =IF(OR(T11="",V11="",V11=0),"",T11*V11)
A12: 1 | 동생 심부름 | B12: 11 | C12: 2 | D12: 5 | E12: 다이소로 이동하기 | F12: 갈림길과 주변 상호작용 오브젝트 때문에 목적지 방향을 놓칠 수 있음 | G12: 표지판·미니맵·NPC 이동 방향을 확인하며 편의점에서 다이소까지 이동함 | H12: 2 – 맵 크기·갈림길 수·목적지 표식의 가시성이 난이도를 결정함 | I12: 1 | J12: 편의점에서 다이소의 도착 트리거에 진입 | K12: - | L12: 1분 30초 | M12: 일정 시간 정체 시 목적지 방향 화살표 표시 | N12: =N11+(IFERROR(VALUE(LEFT(L12,FIND("분",L12)-1))*60,0)+IFERROR(VALUE(TRIM(MID(L12,IFERROR(FIND("분",L12),0)+1,FIND("초",L12)-IFERROR(FIND("분",L12),0)-1))),0))/86400 -> 0.0072337963 | O12: 1-C | 다이소 | P12: =P11+Q12 -> #REF! | Q12: 6 | R12: =ROUND(#REF!*Q12*Q12+#REF!*Q12,2) -> #REF! | S12: =IF(OR(V12="",V12=0),"",ROUND(R12/V12,2)) | U12: =IF(OR(T12="",V12="",V12=0),"",T12*V12)
A13: 1 | 동생 심부름 | B13: 12 | C13: 2 | D13: 6 | E13: 헤어롤 진열대 찾기 | F13: 비슷한 오브젝트와 진열대가 많아 목표 대상을 한 번에 찾기 어려움 | G13: 구역별 표지와 상품 외형을 비교하며 생활용품 코너의 헤어롤을 조사함 | H13: 3 – 후보 오브젝트 수·외형 유사도·탐색 범위가 난이도를 결정함 | I13: 5 | J13: 생활용품 코너의 헤어롤 발견 및 조사 완료 | K13: - | L13: 1분 50초 | M13: 30초 이상 미발견 시 목표 구역에 약한 반짝임 표시 | N13: =N12+(IFERROR(VALUE(LEFT(L13,FIND("분",L13)-1))*60,0)+IFERROR(VALUE(TRIM(MID(L13,IFERROR(FIND("분",L13),0)+1,FIND("초",L13)-IFERROR(FIND("분",L13),0)-1))),0))/86400 -> 0.0085069444 | O13: 1-C | 다이소 | P13: =P12+Q13 -> #REF! | Q13: 7 | R13: =ROUND(#REF!*Q13*Q13+#REF!*Q13,2) -> #REF! | S13: =IF(OR(V13="",V13=0),"",ROUND(R13/V13,2)) | U13: =IF(OR(T13="",V13="",V13=0),"",T13*V13)
A14: 1 | 동생 심부름 | B14: 13 | C14: 1 | D14: 5 | E14: 헤어롤 구매하기 | F14: 구매 대상·수량·결제 순서를 잘못 선택할 수 있음 | G14: 요청받은 품목을 확인하고 상품 선택→계산대 상호작용→결제를 순서대로 진행함 | H14: 2 – 상품 후보 수·품목 유사도·구매 단계 수가 난이도를 결정함 | I14: 3 | J14: 헤어롤 1개 구매 후 인벤토리에 등록 | K14: 잘못된 품목 구매 시 다시 선택해야 함 | L14: 50초 | M14: 요청 품목에 작은 임무 아이콘 표시 | N14: =N13+(IFERROR(VALUE(LEFT(L14,FIND("분",L14)-1))*60,0)+IFERROR(VALUE(TRIM(MID(L14,IFERROR(FIND("분",L14),0)+1,FIND("초",L14)-IFERROR(FIND("분",L14),0)-1))),0))/86400 -> 0.0090856481 | O14: 1-C | 다이소 | P14: =P13+Q14 -> #REF! | Q14: 4 | R14: =ROUND(#REF!*Q14*Q14+#REF!*Q14,2) -> #REF! | S14: =IF(OR(V14="",V14=0),"",ROUND(R14/V14,2)) | U14: =IF(OR(T14="",V14="",V14=0),"",T14*V14)
... A69: 3 | 재난 대응 | B69: 68 | C69: 2 | D69: 8 | E69: 첫 합동 토벌 임무 수락하기 | F69: 임무 브리핑에 목표 괴물·파티 역할·후퇴 조건·민간인 보호 규칙이 한 번에 제시됨 | G69: 자신의 역할과 파티원의 담당 구역을 확인하고 임무 순서를 체크리스트로 정리함 | H69: 4/10 – 브리핑 정보량·파티원 수·역할 차이·실패 조건 수가 난이도를 결정함 | I69: 4 | J69: 합동 토벌의 필수 브리핑 항목 확인 후 임무 수락 | K69: 필수 역할을 확인하지 않으면 출동 준비 완료 불가 | L69: 1분 50초 | M69: 수락 후 파티 역할과 전투 순서를 화면에 고정 표시 | N69: =N68+(IFERROR(VALUE(LEFT(L69,FIND("분",L69)-1))*60,0)+IFERROR(VALUE(TRIM(MID(L69,IFERROR(FIND("분",L69),0)+1,FIND("초",L69)-IFERROR(FIND("분",L69),0)-1))),0))/86400 -> 0.077199074 | O69: 3-E | 고등급자 합동 전투 | P69: =P68+Q69 -> #REF! | Q69: 7 | R69: =ROUND(#REF!*Q69*Q69+#REF!*Q69,2) -> #REF! | S69: =IF(OR(V69="",V69=0),"",ROUND(R69/V69,2)) | U69: =IF(OR(T69="",V69="",V69=0),"",T69*V69)
A70: 3 | 재난 대응 | B70: 69 | C70: 6 | D70: 9 | E70: 하급 괴물 무리와 첫 합동 전투하기 | F70: 공격·회피·회복 조작을 처음 익히는 동시에 파티원의 이동과 공격 대상을 확인해야 함 | G70: 방어 역할의 동료가 공격을 끌어낸 뒤 한 마리씩 표식을 맞춰 집중 공격하고 공격 예고 때 회피함 | H70: 7/10 – 적 수·공격 빈도·회피 타이밍·파티원 위치·회복 수단이 난이도를 결정함 | I70: 3 | J70: 하급 괴물 3마리 전부 처치 및 파티원 생존 | K70: 주인공 체력 0 또는 파티 전멸 시 전투 시작 지점 재시작 | L70: 3분 30초 | M70: 첫 괴물의 공격 예고 시간을 늘리고 집중 공격 대상 아이콘을 표시 | N70: =N69+(IFERROR(VALUE(LEFT(L70,FIND("분",L70)-1))*60,0)+IFERROR(VALUE(TRIM(MID(L70,IFERROR(FIND("분",L70),0)+1,FIND("초",L70)-IFERROR(FIND("분",L70),0)-1))),0))/86400 -> 0.07962963 | O70: 3-E | 고등급자 합동 전투 | P70: =P69+Q70 -> #REF! | Q70: 11 | R70: =ROUND(#REF!*Q70*Q70+#REF!*Q70,2) -> #REF! | S70: =IF(OR(V70="",V70=0),"",ROUND(R70/V70,2)) -> #REF! | T70: 45 | U70: =IF(OR(T70="",V70="",V70=0),"",T70*V70) -> 135 | V70: 3
A71: 3 | 재난 대응 | B71: 70 | C71: 7 | D71: 9 | E71: 도심 골목의 중급 괴물과 합동 전투하기 | F71: 근접형과 원거리형 괴물이 좁은 골목 양쪽을 막아 한 방향만 회피하면 포위됨 | G71: 원거리형을 먼저 끊고 동료의 방어 범위 안에서 근접형의 돌진을 유도한 뒤 빈틈에 공격함 | H71: 8/10 – 적 유형 조합·통로 폭·돌진 속도·원거리 공격 빈도가 난이도를 결정함 | I71: 2 | J71: 중급 괴물 2마리 처치 후 골목 안전 확보 | K71: 파티 전멸 또는 민간인 대피선이 파괴되면 전투 재시작 | L71: 4분 | M71: 첫 실패 후 원거리 공격 예고선과 안전 구역을 더 오래 표시 | N71: =N70+(IFERROR(VALUE(LEFT(L71,FIND("분",L71)-1))*60,0)+IFERROR(VALUE(TRIM(MID(L71,IFERROR(FIND("분",L71),0)+1,FIND("초",L71)-IFERROR(FIND("분",L71),0)-1))),0))/86400 -> 0.082407407 | O71: 3-E | 고등급자 합동 전투 | P71: =P70+Q71 -> #REF! | Q71: 12 | R71: =ROUND(#REF!*Q71*Q71+#REF!*Q71,2) -> #REF! | S71: =IF(OR(V71="",V71=0),"",ROUND(R71/V71,2)) -> #REF! | T71: 75 | U71: =IF(OR(T71="",V71="",V71=0),"",T71*V71) -> 150 | V71: 2
A72: 3 | 재난 대응 | B72: 71 | C72: 7 | D72: 9 | E72: 시민 구조 중 증원 괴물 막기 | F72: 시민 대피와 전투가 동시에 진행되어 괴물을 빠르게 처치하지 못하면 구조 대상이 공격받음 | G72: 동료 둘은 시민을 유도하게 두고 주인공은 접근하는 괴물의 이동 경로를 끊어 순서대로 처치함 | H72: 8/10 – 적 수·시민 이동속도·방어 구역 크기·증원 간격이 난이도를 결정함 | I72: 4 | J72: 증원 괴물 4마리 처치 및 시민 전원 안전 지점 도착 | K72: 시민 1명 체력 0 또는 파티 전멸 시 체크포인트 재시작 | L72: 4분 20초 | M72: 위험한 시민 방향과 다음 증원 위치를 화면 가장자리에 표시 | N72: =N71+(IFERROR(VALUE(LEFT(L72,FIND("분",L72)-1))*60,0)+IFERROR(VALUE(TRIM(MID(L72,IFERROR(FIND("분",L72),0)+1,FIND("초",L72)-IFERROR(FIND("분",L72),0)-1))),0))/86400 -> 0.085416667 | O72: 3-E | 고등급자 합동 전투 | P72: =P71+Q72 -> #REF! | Q72: 13 | R72: =ROUND(#REF!*Q72*Q72+#REF!*Q72,2) -> #REF! | S72: =IF(OR(V72="",V72=0),"",ROUND(R72/V72,2)) -> #REF! | T72: 50 | U72: =IF(OR(T72="",V72="",V72=0),"",T72*V72) -> 200 | V72: 4
A73: 3 | 재난 대응 | B73: 72 | C73: 2 | D73: 8 | E73: 고등급자들의 출동 기피를 확인하기 | F73: 동료들이 선의 수치 하락을 괴물 처치의 결과로 믿으며 서로 임무를 미루는 대화가 간접적으로 제시됨 | G73: 출동 기록·선의 측정 결과·동료 대화를 비교해 파티가 해체되고 주인공에게 임무가 몰리는 이유를 파악함 | H73: 5/10 – 정보 분산 정도·대사 속 숨은 의도·기록 항목 수·감정적 부담이 난이도를 결정함 | I73: 4 | J73: 출동 기피와 선의 수치 하락에 관한 필수 기록·대화 확인 | K73: - | L73: 2분 10초 | M73: 확인한 기록과 동료별 발언을 비교할 수 있는 요약 창 제공 | N73: =N72+(IFERROR(VALUE(LEFT(L73,FIND("분",L73)-1))*60,0)+IFERROR(VALUE(TRIM(MID(L73,IFERROR(FIND("분",L73),0)+1,FIND("초",L73)-IFERROR(FIND("분",L73),0)-1))),0))/86400 -> 0.086921296 | O73: 3-E | 고등급자 합동 전투 | P73: =P72+Q73 -> #REF! | Q73: 6 | R73: =ROUND(#REF!*Q73*Q73+#REF!*Q73,2) -> #REF! | S73: =IF(OR(V73="",V73=0),"",ROUND(R73/V73,2)) | U73: =IF(OR(T73="",V73="",V73=0),"",T73*V73)
A74: 3 | 재난 대응 | B74: 73 | C74: 7 | D74: 9 | E74: 첫 단독 괴물 토벌하기 | F74: 파티의 방어와 회복 지원 없이 서로 다른 공격 패턴의 괴물을 혼자 상대해야 함 | G74: 지형의 좁은 통로로 적을 분리하고 원거리형부터 처치한 뒤 회복 자원을 아껴 사용함 | H74: 8/10 – 적 수·유형 조합·회복 자원·지형 활용도·지원 부재가 난이도를 결정함 | I74: 3 | J74: 괴물 3마리 전부 처치하고 주인공 생존 | K74: 체력 0 시 단독 토벌 시작 지점 재시작 | L74: 4분 10초 | M74: 첫 단독 임무에 한해 회복 아이템 1개 추가 지급과 적 분리 경로 표시 | N74: =N73+(IFERROR(VALUE(LEFT(L74,FIND("분",L74)-1))*60,0)+IFERROR(VALUE(TRIM(MID(L74,IFERROR(FIND("분",L74),0)+1,FIND("초",L74)-IFERROR(FIND("분",L74),0)-1))),0))/86400 -> 0.089814815 | O74: 3-F | 단독 출동·자아 마모 | P74: =P73+Q74 -> #REF! | Q74: 13 | R74: =ROUND(#REF!*Q74*Q74+#REF!*Q74,2) -> #REF! | S74: =IF(OR(V74="",V74=0),"",ROUND(R74/V74,2)) -> #REF! | T74: 70 | U74: =IF(OR(T74="",V74="",V74=0),"",T74*V74) -> 210 | V74: 3
A75: 3 | 재난 대응 | B75: 74 | C75: 8 | D75: 9 | E75: 연속 단독 출동에서 괴물 무리 처치하기 | F75: 휴식 없이 이어진 출동으로 회복 자원이 부족하고 근접형·원거리형·돌진형 괴물이 연속으로 등장함 | G75: 원거리형을 우선 제거하고 장애물로 돌진형을 막은 뒤 웨이브 사이에만 회복해 자원을 유지함 | H75: 9/10 – 적 수·웨이브 간격·유형 조합·회복 제한·누적 피로가 난이도를 결정함 | I75: 5 | J75: 괴물 5마리 전부 처치 후 자아 마모도 변화 연출 확인 | K75: 체력 0 시 현재 웨이브 재시작하며 민간인 피해 누적 시 임무 평가 감소 | L75: 5분 30초 | M75: 반복 실패 시 현재 웨이브의 적 체력을 낮추고 회복 자원 1개 추가 | N75: =N74+(IFERROR(VALUE(LEFT(L75,FIND("분",L75)-1))*60,0)+IFERROR(VALUE(TRIM(MID(L75,IFERROR(FIND("분",L75),0)+1,FIND("초",L75)-IFERROR(FIND("분",L75),0)-1))),0))/86400 -> 0.093634259 | O75: 3-F | 단독 출동·자아 마모 | P75: =P74+Q75 -> #REF! | Q75: 12 | R75: =ROUND(#REF!*Q75*Q75+#REF!*Q75,2) -> #REF! | S75: =IF(OR(V75="",V75=0),"",ROUND(R75/V75,2)) -> #REF! | T75: 55 | U75: =IF(OR(T75="",V75="",V75=0),"",T75*V75) -> 275 | V75: 5
A76: 4 | 폐교 탐색 | B76: 75 | C76: 1 | D76: 7 | E76: 폐교 조사 명령 받기 | F76: 관리국의 공식 목표와 주인공이 느끼는 개인적 목적이 다름 | G76: 대화와 자료를 확인해 폐교 균열 조사와 실종자 수색의 공식 목표와 숨은 위험을 구분함 | H76: 3/10 – 목표 간 충돌 정도·브리핑 정보량이 난이도를 결정함 | I76: 2 | J76: 명령 브리핑 종료 | K76: - | L76: 1분 40초 | M76: 브리핑 종료 후 공식 목표와 개인 목표를 분리 표시 | N76: =N75+(IFERROR(VALUE(LEFT(L76,FIND("분",L76)-1))*60,0)+IFERROR(VALUE(TRIM(MID(L76,IFERROR(FIND("분",L76),0)+1,FIND("초",L76)-IFERROR(FIND("분",L76),0)-1))),0))/86400 -> 0.094791667 | O76: 4-A | 출동 준비 | P76: =P75+Q76 -> #REF! | Q76: 7 | R76: =ROUND(#REF!*Q76*Q76+#REF!*Q76,2) -> #REF! | S76: =IF(OR(V76="",V76=0),"",ROUND(R76/V76,2)) | U76: =IF(OR(T76="",V76="",V76=0),"",T76*V76)
A77: 4 | 폐교 탐색 | B77: 76 | C77: 2 | D77: 6 | E77: 조사 장비 수령하기 | F77: 장비 칸이 제한되어 탐색과 전투 장비를 모두 챙길 수 없음 | G77: 예상 위험에 맞춰 손전등·회복품·탐지기·전투 장비 중 필수 장비를 선택함 | H77: 4/10 – 장비 후보 수·슬롯 제한·역할 중복이 난이도를 결정함 | I77: 5 | J77: 필수 장비가 포함된 상태로 준비 완료 | K77: 필수 장비 누락 시 출발 불가 | L77: 1분 40초 | M77: 장비 역할과 추천 조합 표시 | N77: =N76+(IFERROR(VALUE(LEFT(L77,FIND("분",L77)-1))*60,0)+IFERROR(VALUE(TRIM(MID(L77,IFERROR(FIND("분",L77),0)+1,FIND("초",L77)-IFERROR(FIND("분",L77),0)-1))),0))/86400 -> 0.095949074 | O77: 4-A | 출동 준비 | P77: =P76+Q77 -> #REF! | Q77: 6 | R77: =ROUND(#REF!*Q77*Q77+#REF!*Q77,2) -> #REF! | S77: =IF(OR(V77="",V77=0),"",ROUND(R77/V77,2)) | U77: =IF(OR(T77="",V77="",V77=0),"",T77*V77)
A78: 4 | 폐교 탐색 | B78: 77 | C78: 2 | D78: 7 | E78: 고등급자 파티에 합류하기 | F78: 동료마다 역할과 행동 우선순위가 달라 협력 방식을 이해해야 함 | G78: 대화를 통해 역할이 다른 고등급자 3명의 역할과 지원 조건을 확인함 | H78: 4/10 – 파티원 수·역할 차이·지원 조건 수가 난이도를 결정함 | I78: 4 | J78: 모든 파티원 소개 및 역할 확인 | K78: - | L78: 2분 | M78: 전투 UI에 역할 아이콘 고정 표시 | N78: =N77+(IFERROR(VALUE(LEFT(L78,FIND("분",L78)-1))*60,0)+IFERROR(VALUE(TRIM(MID(L78,IFERROR(FIND("분",L78),0)+1,FIND("초",L78)-IFERROR(FIND("분",L78),0)-1))),0))/86400 -> 0.097337963 | O78: 4-A | 출동 준비 | P78: =P77+Q78 -> #REF! | Q78: 7 | R78: =ROUND(#REF!*Q78*Q78+#REF!*Q78,2) -> #REF! | S78: =IF(OR(V78="",V78=0),"",ROUND(R78/V78,2)) | U78: =IF(OR(T78="",V78="",V78=0),"",T78*V78)
A79: 4 | 폐교 탐색 | B79: 78 | C79: 3 | D79: 7 | E79: 폐교 정문에 도착하기 | F79: 목적지 주변에 잘못된 진입로와 위험 오브젝트가 배치되어 있음 | G79: 탐지기와 표지물을 확인하며 폐교 정문의 안전한 진입로로 이동함 | H79: 4/10 – 진입로 수·위험 구역 범위·탐지기 명확성이 난이도를 결정함 | I79: 1 | J79: 목적지 도착 | K79: 위험 지역 진입 후 체력 0 시 체크포인트 재시작 | L79: 2분 10초 | M79: 안전 진입로에 탐지기 반응 강화 | N79: =N78+(IFERROR(VALUE(LEFT(L79,FIND("분",L79)-1))*60,0)+IFERROR(VALUE(TRIM(MID(L79,IFERROR(FIND("분",L79),0)+1,FIND("초",L79)-IFERROR(FIND("분",L79),0)-1))),0))/86400 -> 0.098842593 | O79: 4-B | 폐교 정문 | P79: =P78+Q79 -> #REF! | Q79: 8 | R79: =ROUND(#REF!*Q79*Q79+#REF!*Q79,2) -> #REF! | S79: =IF(OR(V79="",V79=0),"",ROUND(R79/V79,2)) | U79: =IF(OR(T79="",V79="",V79=0),"",T79*V79)
A80: 4 | 폐교 탐색 | B80: 79 | C80: 3 | D80: 7 | E80: 정문 봉인 해제하기 | F80: 여러 장치와 열쇠 조건을 올바른 순서로 충족해야 함 | G80: 주변 단서와 장치 반응을 확인해 균열 문양 4개를 순서대로 해제함 | H80: 6/10 – 단계 수·단서 위치·오답 초기화 범위가 난이도를 결정함 | I80: 4 | J80: 모든 봉인 조건 해제 | K80: 오답 입력 5회 시 장치 초기화 | L80: 2분 30초 | M80: 오답 후 잘못된 단계만 표시 | N80: =N79+(IFERROR(VALUE(LEFT(L80,FIND("분",L80)-1))*60,0)+IFERROR(VALUE(TRIM(MID(L80,IFERROR(FIND("분",L80),0)+1,FIND("초",L80)-IFERROR(FIND("분",L80),0)-1))),0))/86400 -> 0.1005787 | O80: 4-B | 폐교 정문 | P80: =P79+Q80 -> #REF! | Q80: 9 | R80: =ROUND(#REF!*Q80*Q80+#REF!*Q80,2) -> #REF! | S80: =IF(OR(V80="",V80=0),"",ROUND(R80/V80,2)) | U80: =IF(OR(T80="",V80="",V80=0),"",T80*V80)
A81: 4 | 폐교 탐색 | B81: 80 | C81: 4 | D81: 8 | E81: 본관 1층 탐색하기 | F81: 방 구조가 반복되고 일부 길이 연결되어 현재 위치를 잃기 쉬움 | G81: 지도에 방문 구역을 표시하며 교실·교무실·복도를 한 방향으로 탐색함 | H81: 6/10 – 방 수·연결 구조·지도 정보량이 난이도를 결정함 | I81: 6 | J81: 필수 구역과 상호작용 대상 모두 확인 | K81: - | L81: 3분 30초 | M81: 방문한 문과 미방문 문을 아이콘으로 구분 | N81: =N80+(IFERROR(VALUE(LEFT(L81,FIND("분",L81)-1))*60,0)+IFERROR(VALUE(TRIM(MID(L81,IFERROR(FIND("분",L81),0)+1,FIND("초",L81)-IFERROR(FIND("분",L81),0)-1))),0))/86400 -> 0.10300926 | O81: 4-C | 폐교 본관 1층 | P81: =P80+Q81 -> #REF! | Q81: 10 | R81: =ROUND(#REF!*Q81*Q81+#REF!*Q81,2) -> #REF! | S81: =IF(OR(V81="",V81=0),"",ROUND(R81/V81,2)) | U81: =IF(OR(T81="",V81="",V81=0),"",T81*V81)
A82: 4 | 폐교 탐색 | B82: 81 | C82: 6 | D82: 9 | E82: 환영체 회피하기 | F82: 적이 소리에 반응하고 시야 밖에서도 이동해 안전 구간을 예측하기 어려움 | G82: 적 이동 소리와 순찰 경로를 확인해 소리에 반응하는 환영체를 피하며 이동함 | H82: 7/10 – 적 감지 범위·순찰 주기·은폐물 간격이 난이도를 결정함 | I82: 5 | J82: 발각되지 않거나 추적을 끊고 종료 지점 도착 | K82: 연속 발각 3회 또는 체력 0 시 체크포인트 재시작 | L82: 3분 | M82: 실패 후 적 청각 범위 감소 | N82: =N81+(IFERROR(VALUE(LEFT(L82,FIND("분",L82)-1))*60,0)+IFERROR(VALUE(TRIM(MID(L82,IFERROR(FIND("분",L82),0)+1,FIND("초",L82)-IFERROR(FIND("분",L82),0)-1))),0))/86400 -> 0.10509259 | O82: 4-C | 폐교 본관 1층 | P82: =P81+Q82 -> #REF! | Q82: 8 | R82: =ROUND(#REF!*Q82*Q82+#REF!*Q82,2) -> #REF! | S82: =IF(OR(V82="",V82=0),"",ROUND(R82/V82,2)) | U82: =IF(OR(T82="",V82="",V82=0),"",T82*V82)
A83: 4 | 폐교 탐색 | B83: 82 | C83: 7 | D83: 9 | E83: 본관 1층 환영체 무리 처치하기 | F83: 환영체가 교실 문과 사물함 사이를 순간 이동하며 파티원을 분산시켜 한 대상을 집중 공격하기 어려움 | G83: 환영체가 실체화되는 순간을 기다리고 파티원 표식에 맞춰 한 마리씩 집중 공격함 | H83: 8/10 – 적 수·순간 이동 주기·실체화 시간·파티 간 거리가 난이도를 결정함 | I83: 4 | J83: 환영체 4마리 전부 처치 및 파티원 생존 | K83: 파티 전멸 또는 필수 동료 체력 0 시 구간 재시작 | L83: 4분 10초 | M83: 첫 실체화 시간을 길게 유지하고 집중 공격 대상 아이콘 표시 | N83: =N82+(IFERROR(VALUE(LEFT(L83,FIND("분",L83)-1))*60,0)+IFERROR(VALUE(TRIM(MID(L83,IFERROR(FIND("분",L83),0)+1,FIND("초",L83)-IFERROR(FIND("분",L83),0)-1))),0))/86400 -> 0.10798611 | O83: 4-C | 폐교 본관 1층 | P83: =P82+Q83 -> #REF! | Q83: 13 | R83: =ROUND(#REF!*Q83*Q83+#REF!*Q83,2) -> #REF! | S83: =IF(OR(V83="",V83=0),"",ROUND(R83/V83,2)) -> #REF! | T83: 50 | U83: =IF(OR(T83="",V83="",V83=0),"",T83*V83) -> 200 | V83: 4
A84: 4 | 폐교 탐색 | B84: 83 | C84: 3 | D84: 8 | E84: 교실 기억 단서 수집하기 | F84: 필수 단서가 여러 방에 흩어져 있고 일부는 환영 연출 뒤에 숨겨짐 | G84: 방문 기록과 단서 목록을 확인하며 친구의 과거를 보여주는 기억 단서 5개를 수집함 | H84: 6/10 – 단서 수·방 분산 정도·환영 연출 길이가 난이도를 결정함 | I84: 5 | J84: 필수 기억 단서 전부 수집 | K84: 단서 부족 시 다음 퍼즐 활성화 불가 | L84: 3분 20초 | M84: 미수집 단서가 있는 방에 지도 표시 | N84: =N83+(IFERROR(VALUE(LEFT(L84,FIND("분",L84)-1))*60,0)+IFERROR(VALUE(TRIM(MID(L84,IFERROR(FIND("분",L84),0)+1,FIND("초",L84)-IFERROR(FIND("분",L84),0)-1))),0))/86400 -> 0.11030093 | O84: 4-C | 폐교 본관 1층 | P84: =P83+Q84 -> #REF! | Q84: 10 | R84: =ROUND(#REF!*Q84*Q84+#REF!*Q84,2) -> #REF! | S84: =IF(OR(V84="",V84=0),"",ROUND(R84/V84,2)) | U84: =IF(OR(T84="",V84="",V84=0),"",T84*V84)
A85: 4 | 폐교 탐색 | B85: 84 | C85: 5 | D85: 8 | E85: 컴퓨터 잠금 퍼즐 해결하기 | F85: 여러 단서를 조합해 입력 순서나 의미를 추론해야 함 | G85: 수집한 기록을 비교하고 교실 단서를 순서대로 입력하는 잠금 장치의 규칙에 맞게 단계별로 입력함 | H85: 7/10 – 단서 수·추론 단계·오답 페널티·초기화 범위가 난이도를 결정함 | I85: 4 | J85: 정답 순서 완성 | K85: 오답 누적 시 퍼즐 단계 일부 초기화 | L85: 3분 20초 | M85: 오답 3회 후 사용하지 않은 단서 강조 | N85: =N84+(IFERROR(VALUE(LEFT(L85,FIND("분",L85)-1))*60,0)+IFERROR(VALUE(TRIM(MID(L85,IFERROR(FIND("분",L85),0)+1,FIND("초",L85)-IFERROR(FIND("분",L85),0)-1))),0))/86400 -> 0.11261574 | O85: 4-C | 폐교 본관 1층 | P85: =P84+Q85 -> #REF! | Q85: 10 | R85: =ROUND(#REF!*Q85*Q85+#REF!*Q85,2) -> #REF! | S85: =IF(OR(V85="",V85=0),"",ROUND(R85/V85,2)) | U85: =IF(OR(T85="",V85="",V85=0),"",T85*V85)
A86: 4 | 폐교 탐색 | B86: 85 | C86: 4 | D86: 7 | E86: 본관 2층으로 이동하기 | F86: 좁은 통로·어두운 조명·장애물로 이동 경로가 제한됨 | G86: 손전등과 안전한 발판을 확인하며 붕괴된 계단를 통과함 | H86: 5/10 – 통로 폭·시야 범위·장애물 간격이 난이도를 결정함 | I86: 1 | J86: 다음 층 도착 트리거 진입 | K86: 낙하 또는 장애물 피격 3회 시 구간 재시작 | L86: 1분 40초 | M86: 안전 발판 테두리와 체크포인트 제공 | N86: =N85+(IFERROR(VALUE(LEFT(L86,FIND("분",L86)-1))*60,0)+IFERROR(VALUE(TRIM(MID(L86,IFERROR(FIND("분",L86),0)+1,FIND("초",L86)-IFERROR(FIND("분",L86),0)-1))),0))/86400 -> 0.11377315 | O86: 4-D | 폐교 본관 2층 | P86: =P85+Q86 -> #REF! | Q86: 7 | R86: =ROUND(#REF!*Q86*Q86+#REF!*Q86,2) -> #REF! | S86: =IF(OR(V86="",V86=0),"",ROUND(R86/V86,2)) | U86: =IF(OR(T86="",V86="",V86=0),"",T86*V86)
A87: 4 | 폐교 탐색 | B87: 86 | C87: 3 | D87: 8 | E87: 학교폭력 흔적 조사하기 | F87: 중요한 단서가 여러 인물과 배경 오브젝트 사이에 분산되어 있음 | G87: 시선·행동·복장·주변 오브젝트를 순서대로 확인해 낙서·찢어진 공책·잠긴 사물함의 특징을 파악함 | H87: 6/10 – 관찰 대상 수·단서의 명확성·외형 유사도가 난이도를 결정함 | I87: 6 | J87: 필수 관찰 대상 모두 조사 | K87: - | L87: 3분 10초 | M87: 필수 대상 위에 짧은 시선 유도 아이콘 표시 | N87: =N86+(IFERROR(VALUE(LEFT(L87,FIND("분",L87)-1))*60,0)+IFERROR(VALUE(TRIM(MID(L87,IFERROR(FIND("분",L87),0)+1,FIND("초",L87)-IFERROR(FIND("분",L87),0)-1))),0))/86400 -> 0.11597222 | O87: 4-D | 폐교 본관 2층 | P87: =P86+Q87 -> #REF! | Q87: 7 | R87: =ROUND(#REF!*Q87*Q87+#REF!*Q87,2) -> #REF! | S87: =IF(OR(V87="",V87=0),"",ROUND(R87/V87,2)) | U87: =IF(OR(T87="",V87="",V87=0),"",T87*V87)
A88: 4 | 폐교 탐색 | B88: 87 | C88: 7 | D88: 9 | E88: 학교폭력 흔적을 지키는 환영체 처치하기 | F88: 환영체가 단서 주변을 방패처럼 이용해 무작정 공격하면 조사 오브젝트가 훼손됨 | G88: 환영체를 단서에서 떨어뜨린 뒤 범위 공격을 제한하고 약점이 드러날 때 정밀 공격함 | H88: 8/10 – 적 수·단서 위치·공격 범위·오브젝트 내구도·유인 거리가 난이도를 결정함 | I88: 3 | J88: 환영체 3마리 처치 및 핵심 단서 3개 보존 | K88: 핵심 단서 전부 훼손 또는 파티 전멸 시 체크포인트 재시작 | L88: 4분 | M88: 단서 근처 공격 시 경고 테두리와 공격 취소 여유 제공 | N88: =N87+(IFERROR(VALUE(LEFT(L88,FIND("분",L88)-1))*60,0)+IFERROR(VALUE(TRIM(MID(L88,IFERROR(FIND("분",L88),0)+1,FIND("초",L88)-IFERROR(FIND("분",L88),0)-1))),0))/86400 -> 0.11875 | O88: 4-D | 폐교 본관 2층 | P88: =P87+Q88 -> #REF! | Q88: 13 | R88: =ROUND(#REF!*Q88*Q88+#REF!*Q88,2) -> #REF! | S88: =IF(OR(V88="",V88=0),"",ROUND(R88/V88,2)) -> #REF! | T88: 60 | U88: =IF(OR(T88="",V88="",V88=0),"",T88*V88) -> 180 | V88: 3
A89: 4 | 폐교 탐색 | B89: 88 | C89: 6 | D89: 8 | E89: 선택의 분기 퍼즐 해결하기 | F89: 여러 단서를 조합해 입력 순서나 의미를 추론해야 함 | G89: 수집한 기록을 비교하고 서로 다른 기억 문을 선택하는 퍼즐의 규칙에 맞게 단계별로 입력함 | H89: 8/10 – 단서 수·추론 단계·오답 페널티·초기화 범위가 난이도를 결정함 | I89: 5 | J89: 정답 순서 완성 | K89: 오답 누적 시 퍼즐 단계 일부 초기화 | L89: 4분 | M89: 오답 3회 후 사용하지 않은 단서 강조 | N89: =N88+(IFERROR(VALUE(LEFT(L89,FIND("분",L89)-1))*60,0)+IFERROR(VALUE(TRIM(MID(L89,IFERROR(FIND("분",L89),0)+1,FIND("초",L89)-IFERROR(FIND("분",L89),0)-1))),0))/86400 -> 0.12152778 | O89: 4-D | 폐교 본관 2층 | P89: =P88+Q89 -> #REF! | Q89: 11 | R89: =ROUND(#REF!*Q89*Q89+#REF!*Q89,2) -> #REF! | S89: =IF(OR(V89="",V89=0),"",ROUND(R89/V89,2)) | U89: =IF(OR(T89="",V89="",V89=0),"",T89*V89)
A90: 4 | 폐교 탐색 | B90: 89 | C90: 4 | D90: 7 | E90: 아군 환영 구분하기 | F90: 환영이 동료의 외형과 목소리를 복제해 단순 외형만으로 구분할 수 없음 | G90: 이전 대화와 행동 습관을 비교해 동료와 똑같이 행동하는 환영을 판별함 | H90: 8/10 – 후보 수·복제 정확도·행동 단서의 명확성이 난이도를 결정함 | I90: 5 | J90: 진짜 동료 전원 선택 | K90: 환영 선택 시 전투 또는 체력 감소 발생 | L90: 3분 30초 | M90: 오답 후 구분 가능한 행동 단서 1개 표시 | N90: =N89+(IFERROR(VALUE(LEFT(L90,FIND("분",L90)-1))*60,0)+IFERROR(VALUE(TRIM(MID(L90,IFERROR(FIND("분",L90),0)+1,FIND("초",L90)-IFERROR(FIND("분",L90),0)-1))),0))/86400 -> 0.12395833 | O90: 4-D | 폐교 본관 2층 | P90: =P89+Q90 -> #REF! | Q90: 8 | R90: =ROUND(#REF!*Q90*Q90+#REF!*Q90,2) -> #REF! | S90: =IF(OR(V90="",V90=0),"",ROUND(R90/V90,2)) | U90: =IF(OR(T90="",V90="",V90=0),"",T90*V90)
A91: 4 | 폐교 탐색 | B91: 90 | C91: 7 | D91: 9 | E91: 아군으로 위장한 환영체 처치하기 | F91: 환영체가 동료의 외형·목소리·전투 행동을 복제해 공격 대상을 잘못 선택할 위험이 큼 | G91: 이전 대화와 역할 아이콘의 불일치를 확인해 가짜를 표시한 뒤 파티와 동시에 공격함 | H91: 8/10 – 복제 정확도·판별 시간·가짜 수·오인 공격 페널티가 난이도를 결정함 | I91: 3 | J91: 진짜 동료를 보호하며 위장 환영체 3마리 처치 | K91: 진짜 동료 오인 공격 3회 또는 파티 전멸 시 구간 재시작 | L91: 4분 10초 | M91: 오인 공격 후 환영체가 복제하지 못한 행동 단서 1개 강조 | N91: =N90+(IFERROR(VALUE(LEFT(L91,FIND("분",L91)-1))*60,0)+IFERROR(VALUE(TRIM(MID(L91,IFERROR(FIND("분",L91),0)+1,FIND("초",L91)-IFERROR(FIND("분",L91),0)-1))),0))/86400 -> 0.12685185 | O91: 4-D | 폐교 본관 2층 | P91: =P90+Q91 -> #REF! | Q91: 12 | R91: =ROUND(#REF!*Q91*Q91+#REF!*Q91,2) -> #REF! | S91: =IF(OR(V91="",V91=0),"",ROUND(R91/V91,2)) -> #REF! | T91: 70 | U91: =IF(OR(T91="",V91="",V91=0),"",T91*V91) -> 210 | V91: 3
A92: 4 | 폐교 탐색 | B92: 91 | C92: 4 | D92: 7 | E92: 본관 3층으로 이동하기 | F92: 좁은 통로·어두운 조명·장애물로 이동 경로가 제한됨 | G92: 손전등과 안전한 발판을 확인하며 환영이 반복되는 계단를 통과함 | H92: 6/10 – 통로 폭·시야 범위·장애물 간격이 난이도를 결정함 | I92: 1 | J92: 다음 층 도착 트리거 진입 | K92: 낙하 또는 장애물 피격 3회 시 구간 재시작 | L92: 1분 50초 | M92: 안전 발판 테두리와 체크포인트 제공 | N92: =N91+(IFERROR(VALUE(LEFT(L92,FIND("분",L92)-1))*60,0)+IFERROR(VALUE(TRIM(MID(L92,IFERROR(FIND("분",L92),0)+1,FIND("초",L92)-IFERROR(FIND("분",L92),0)-1))),0))/86400 -> 0.128125 | O92: 4-E | 폐교 본관 3층 | P92: =P91+Q92 -> #REF! | Q92: 8 | R92: =ROUND(#REF!*Q92*Q92+#REF!*Q92,2) -> #REF! | S92: =IF(OR(V92="",V92=0),"",ROUND(R92/V92,2)) | U92: =IF(OR(T92="",V92="",V92=0),"",T92*V92)
A93: 4 | 폐교 탐색 | B93: 92 | C93: 5 | D93: 7 | E93: 친구의 목소리 추적하기 | F93: 반사음과 가짜 목소리 때문에 실제 방향을 잘못 판단할 수 있음 | G93: 소리 크기 변화와 파티원의 반응을 비교하며 복도마다 방향이 달라지는 목소리를 추적함 | H93: 7/10 – 가짜 신호 수·방향 변화 빈도·이동 거리의 차이가 난이도를 결정함 | I93: 4 | J93: 올바른 강당 방향 도착 | K93: 가짜 경로 끝에 도달하면 추가 환영 전투 발생 | L93: 3분 10초 | M93: 정체 45초 후 실제 방향의 음량을 강화 | N93: =N92+(IFERROR(VALUE(LEFT(L93,FIND("분",L93)-1))*60,0)+IFERROR(VALUE(TRIM(MID(L93,IFERROR(FIND("분",L93),0)+1,FIND("초",L93)-IFERROR(FIND("분",L93),0)-1))),0))/86400 -> 0.13032407 | O93: 4-E | 폐교 본관 3층 | P93: =P92+Q93 -> #REF! | Q93: 8 | R93: =ROUND(#REF!*Q93*Q93+#REF!*Q93,2) -> #REF! | S93: =IF(OR(V93="",V93=0),"",ROUND(R93/V93,2)) | U93: =IF(OR(T93="",V93="",V93=0),"",T93*V93)
A94: 4 | 폐교 탐색 | B94: 93 | C94: 7 | D94: 9 | E94: 친구의 목소리를 따라가며 매복 괴물 처치하기 | F94: 가짜 목소리가 전투 구역으로 유도하고 좁은 복도 양쪽에서 괴물이 동시에 나타남 | G94: 목소리 방향보다 파티 반응과 바닥 흔적을 확인하고 후방 적부터 제거해 퇴로를 확보함 | H94: 8/10 – 매복 방향 수·적 수·통로 폭·가짜 신호 빈도·후퇴 공간이 난이도를 결정함 | I94: 4 | J94: 매복 괴물 4마리 처치 후 강당 방향 도착 | K94: 파티 전멸 또는 후퇴로가 막힌 상태에서 체력 0 시 재시작 | L94: 4분 20초 | M94: 첫 매복 때 후방 경고음과 안전 지점을 표시 | N94: =N93+(IFERROR(VALUE(LEFT(L94,FIND("분",L94)-1))*60,0)+IFERROR(VALUE(TRIM(MID(L94,IFERROR(FIND("분",L94),0)+1,FIND("초",L94)-IFERROR(FIND("분",L94),0)-1))),0))/86400 -> 0.13333333 | O94: 4-E | 폐교 본관 3층 | P94: =P93+Q94 -> #REF! | Q94: 13 | R94: =ROUND(#REF!*Q94*Q94+#REF!*Q94,2) -> #REF! | S94: =IF(OR(V94="",V94=0),"",ROUND(R94/V94,2)) -> #REF! | T94: 50 | U94: =IF(OR(T94="",V94="",V94=0),"",T94*V94) -> 200 | V94: 4
...

Sheet 밸런스 팩터
B2: 밸런스 팩터
B4: 게임 「넌 착해!」의 플레이 경험에 영향을 주는 주요 조정 요소를 원형으로 정리
B70: 큰 원은 플레이 전반에 미치는 영향이 큰 핵심 팩터이며, 작은 원은 장면·미션 단위에서 조정하는 세부 팩터임

Sheet 작성 기준
A1: 밸런스 문서 작성 기준
A3: 항목 | B3: 작성 방식 | C3: 값/형식 | D3: 우리 게임 적용 기준
A4: 조작난이도 | B4: 플레이어가 실제 입력을 수행할 때 느끼는 손 조작의 어려움 | C4: 1~10 숫자 | D4: 1은 단순 확인·대화, 10은 빠른 보스 패턴과 복합 입력
A5: 재미율 | B5: 기획자가 해당 구간이 이 정도로 재미있기를 기대하며 정하는 정성적 목표값 | C5: 1~10 숫자 | D5: 탐색·긴장·감정·반전·성취를 모두 포함하며 실제 테스트값이 아님
A6: 컨텐츠 제시순서 | B6: 게임 시작부터 엔딩까지 해금되는 모든 플레이 내용을 순서대로 기록 | C6: 1부터 연속 넘버링 | D6: UI 미션뿐 아니라 이동·조사·대화·전투·업적성 행동·연출 확인까지 포함
A7: 미션 | B7: 제목만 읽어도 플레이어가 무엇을 해야 하는지 보이도록 작성 | C7: 행동형 제목 | D7: 예: 신상 과자 진열대 찾기, 균열 괴물과 첫 전투 치르기
A8: 방해요소 | B8: 목표를 바로 달성하지 못하게 만드는 맵·NPC·시간·정보·전투 요소 | C8: 구체적 서술 | D8: 비슷한 후보, 넓은 탐색 범위, 제한시간, 시야 차단, 감정적 압박 등
A9: 방해요소 공략 | B9: 방해요소를 해결하기 위해 플레이어가 관찰·판단·조작해야 하는 내용 | C9: 구체적 플레이 절차 | D9: 이 표에서 가장 핵심적인 항목으로 작성
A10: 방해요인의 난이도 | B10: 관찰·판단·공략의 어려움과 그 난이도를 만드는 요인을 함께 기록 | C10: 숫자/10 + 원인 설명 | D10: 후보 수, 맵 크기, 속도 차이, 제한시간, 패턴 수 등
A11: 미션개수 | B11: 해당 행의 목표를 완료하기 위해 필요한 행동·대상·단계의 수 | C11: 정수 | D11: 수거 8개, 단서 5개, 대화 1회, 보스 패턴 6회 등
A12: 성공 미션조건 | B12: 시스템이 완료를 판정할 수 있는 명확한 조건 | C12: 구체적 판정 조건 | D12: 목표 수량 달성, 트리거 진입, 보스 체력 0 등
A13: 실패 미션조건 | B13: 실패가 존재하는 경우 재시작·페널티가 발생하는 조건 | C13: 구체적 판정 조건 또는 실패 없음 | D13: 추격 거리 초과, 체력 0, 제한시간 종료, 오답 누적 등
A14: 예상 플레이타임 | B14: 초회 플레이어가 해당 콘텐츠를 완료하는 데 걸릴 것으로 예상하는 시간 | C14: 초/분 | D14: 이동거리·미션개수·대사량·재시도 가능성을 함께 고려
... A18: 문서 범위 | B18: 게임 시작부터 엔딩까지 모든 콘텐츠를 작성 | C18: 최소 50개 이상 | D18: 현재 문서에는 총 119개 콘텐츠를 기록

Sheet 밸런스 곡선
A1: 전체 밸런스 곡선 요약
A3: 총 콘텐츠 수 | B3: =COUNTA('밸런스 문서'!B2:B124) -> 123 | C3: 평균 조작난이도 | D3: =AVERAGE('밸런스 문서'!C2:C124) -> 3.097561 | E3: 평균 재미율 | F3: =AVERAGE('밸런스 문서'!D2:D124) -> 7.495935 | G3: 최고 조작난이도 | H3: =MAX('밸런스 문서'!C2:C124) -> 10 | I3: 최고 재미율 | J3: =MAX('밸런스 문서'!D2:D124) -> 10
A5: 구간 | B5: 콘텐츠 수 | C5: 평균 조작난이도 | D5: 평균 재미율 | E5: 최고 방해요인 난이도
A6: Q1 동생 심부름 | B6: 25 | C6: =AVERAGE('밸런스 문서'!C2:C26) -> 1.76 | D6: =AVERAGE('밸런스 문서'!D2:D26) -> 5.48 | E6: 6
A7: Q2 공원 청소 | B7: 23 | C7: =AVERAGE('밸런스 문서'!C27:C49) -> 1.7826087 | D7: =AVERAGE('밸런스 문서'!D27:D49) -> 6.1304348 | E7: 7
A8: Q3 재난 대응과 영웅화 | B8: 26 | C8: =AVERAGE('밸런스 문서'!C50:C75) -> 3.4230769 | D8: =AVERAGE('밸런스 문서'!D50:D75) -> 8.1153846 | E8: 9
A9: Q4 폐교 보스 | B9: 30 | C9: =AVERAGE('밸런스 문서'!C76:C105) -> 4.7 | D9: =AVERAGE('밸런스 문서'!D76:D105) -> 8.3333333 | E9: 10
A10: Q5 균열 탐색과 결말 | B10: 19 | C10: =AVERAGE('밸런스 문서'!C106:C124) -> 3.4736842 | D10: =AVERAGE('밸런스 문서'!D106:D124) -> 9.6315789 | E10: 10
A14: 컨텐츠 제시순서 | B14: 조작난이도 | C14: 재미율 | E14: X 콘텐츠 진행 포인트 | F14: Y 레벨업을 위한 필요 경험치
A15: 1 | B15: 1 | C15: 8 | E15: 1 | F15: =ROUND('밸런스 문서'!#REF!*E15*E15+'밸런스 문서'!#REF!*E15,2) -> #REF!
A16: 2 | B16: 1 | C16: 3 | E16: 2 | F16: =ROUND('밸런스 문서'!#REF!*E16*E16+'밸런스 문서'!#REF!*E16,2) -> #REF!
A17: 3 | B17: 1 | C17: 5 | E17: 3 | F17: =ROUND('밸런스 문서'!#REF!*E17*E17+'밸런스 문서'!#REF!*E17,2) -> #REF!
A18: 4 | B18: 1 | C18: 3 | E18: 4 | F18: =ROUND('밸런스 문서'!#REF!*E18*E18+'밸런스 문서'!#REF!*E18,2) -> #REF!
A19: 5 | B19: 1 | C19: 3 | E19: 5 | F19: =ROUND('밸런스 문서'!#REF!*E19*E19+'밸런스 문서'!#REF!*E19,2) -> #REF!
A20: 6 | B20: 1 | C20: 5 | E20: 6 | F20: =ROUND('밸런스 문서'!#REF!*E20*E20+'밸런스 문서'!#REF!*E20,2) -> #REF!
A21: 7 | B21: 2 | C21: 5 | E21: 7 | F21: =ROUND('밸런스 문서'!#REF!*E21*E21+'밸런스 문서'!#REF!*E21,2) -> #REF!
A22: 8 | B22: 2 | C22: 6 | E22: 8 | F22: =ROUND('밸런스 문서'!#REF!*E22*E22+'밸런스 문서'!#REF!*E22,2) -> #REF!
A23: 9 | B23: 1 | C23: 5 | E23: 9 | F23: =ROUND('밸런스 문서'!#REF!*E23*E23+'밸런스 문서'!#REF!*E23,2) -> #REF!
A24: 10 | B24: 1 | C24: 6 | E24: 10 | F24: =ROUND('밸런스 문서'!#REF!*E24*E24+'밸런스 문서'!#REF!*E24,2) -> #REF!
A25: 11 | B25: 2 | C25: 5 | E25: 11 | F25: =ROUND('밸런스 문서'!#REF!*E25*E25+'밸런스 문서'!#REF!*E25,2) -> #REF!
A26: 12 | B26: 2 | C26: 6 | E26: 12 | F26: =ROUND('밸런스 문서'!#REF!*E26*E26+'밸런스 문서'!#REF!*E26,2) -> #REF!
... A34: 20 | B34: 1 | C34: 5 | E34: 20 | F34: =ROUND('밸런스 문서'!#REF!*E34*E34+'밸런스 문서'!#REF!*E34,2) -> #REF!
A35: 21 | B35: 2 | C35: 5
A36: 22 | B36: 2 | C36: 7
A37: 23 | B37: 3 | C37: 8
A38: 24 | B38: 1 | C38: 5
A39: 25 | B39: 2 | C39: 5
A40: 26 | B40: 1 | C40: 5
A41: 27 | B41: 1 | C41: 6
A42: 28 | B42: 1 | C42: 5
A43: 29 | B43: 2 | C43: 5
A44: 30 | B44: 1 | C44: 5
A45: 31 | B45: 2 | C45: 6
A46: 32 | B46: 2 | C46: 6
... A137: 123 | B137: 1 | C137: 9
